{"type":"open","side":"buy","price":"2442.39000000","order_id":"bd9aa2ff-005b-45b7-962c-414dc3c43911","remaining_size":"0.50000000","product_id":"BTC-USD","sequence":3342835631,"time":"2017-06-17T02:38:35.553000Z"}
{"type":"done","side":"sell","order_id":"5c6f2d24-508b-4c53-8b57-43c273208e4f","reason":"canceled","product_id":"BTC-USD","price":"2447.53000000","remaining_size":"0.08985400","sequence":3342835632,"time":"2017-06-17T02:38:35.561000Z"}
{"type":"received","order_id":"386dffb0-1b86-4d7b-86ac-59ec941a0acb","order_type":"limit","size":"0.20000000","price":"2449.17000000","side":"sell","client_oid":"db6b876b-6679-4197-bc78-8d54a4c9896e","product_id":"BTC-USD","sequence":3342835633,"time":"2017-06-17T02:38:36.322000Z"}
{"type":"open","side":"sell","price":"2449.17000000","order_id":"386dffb0-1b86-4d7b-86ac-59ec941a0acb","remaining_size":"0.20000000","product_id":"BTC-USD","sequence":3342835634,"time":"2017-06-17T02:38:36.322000Z"}
{"type":"received","order_id":"29e09bef-a2b4-4108-8dd5-f43bc78cf9dc","order_type":"limit","size":"0.10000000","price":"2447.15000000","side":"sell","client_oid":"3e3070c0-038f-4c38-bce6-44f22fe2ee6f","product_id":"BTC-USD","sequence":3342835635,"time":"2017-06-17T02:38:36.329000Z"}
{"type":"open","side":"sell","price":"2447.15000000","order_id":"29e09bef-a2b4-4108-8dd5-f43bc78cf9dc","remaining_size":"0.10000000","product_id":"BTC-USD","sequence":3342835636,"time":"2017-06-17T02:38:36.329000Z"}
{"type":"done","side":"sell","order_id":"386dffb0-1b86-4d7b-86ac-59ec941a0acb","reason":"canceled","product_id":"BTC-USD","price":"2449.17000000","remaining_size":"0.20000000","sequence":3342835637,"time":"2017-06-17T02:38:36.334000Z"}
{"type":"received","order_id":"fcb958ef-3ced-4be5-bb4d-4116cac7af05","order_type":"limit","size":"0.25000000","price":"2442.77000000","side":"buy","client_oid":"1b34b4cb-8514-46de-9677-3c9db8b617e9","product_id":"BTC-USD","sequence":3342835638,"time":"2017-06-17T02:38:36.350000Z"}
{"type":"open","side":"buy","price":"2442.77000000","order_id":"fcb958ef-3ced-4be5-bb4d-4116cac7af05","remaining_size":"0.25000000","product_id":"BTC-USD","sequence":3342835639,"time":"2017-06-17T02:38:36.350000Z"}
{"type":"received","order_id":"0d76d1d6-a648-4e9b-a994-95df4ca7414f","order_type":"limit","size":"0.08985400","price":"2449.17000000","side":"sell","client_oid":"a2556231-481e-4a16-81a5-09c79ae220be","product_id":"BTC-USD","sequence":3342835640,"time":"2017-06-17T02:38:36.352000Z"}
{"type":"open","side":"sell","price":"2449.17000000","order_id":"0d76d1d6-a648-4e9b-a994-95df4ca7414f","remaining_size":"0.08985400","product_id":"BTC-USD","sequence":3342835641,"time":"2017-06-17T02:38:36.352000Z"}
{"type":"received","order_id":"6c5392f9-cdab-479c-95b9-073e13e7bd43","order_type":"limit","size":"0.20000000","price":"2449.16000000","side":"sell","client_oid":"9a761228-a541-40a8-b676-5f6ffbbaeaff","product_id":"BTC-USD","sequence":3342835642,"time":"2017-06-17T02:38:36.362000Z"}
{"type":"open","side":"sell","price":"2449.16000000","order_id":"6c5392f9-cdab-479c-95b9-073e13e7bd43","remaining_size":"0.20000000","product_id":"BTC-USD","sequence":3342835643,"time":"2017-06-17T02:38:36.362000Z"}
{"type":"done","side":"sell","order_id":"0d76d1d6-a648-4e9b-a994-95df4ca7414f","reason":"canceled","product_id":"BTC-USD","price":"2449.17000000","remaining_size":"0.08985400","sequence":3342835644,"time":"2017-06-17T02:38:36.369000Z"}
{"type":"done","side":"sell","order_id":"6c5392f9-cdab-479c-95b9-073e13e7bd43","reason":"canceled","product_id":"BTC-USD","price":"2449.16000000","remaining_size":"0.20000000","sequence":3342835645,"time":"2017-06-17T02:38:36.379000Z"}
{"type":"received","order_id":"16a9bc56-724a-4b70-96cb-bffac5fd846c","order_type":"limit","size":"0.10000000","price":"2447.14000000","side":"sell","client_oid":"bff1066a-78f2-4afe-b2cf-3bcbd3b2caf9","product_id":"BTC-USD","sequence":3342835646,"time":"2017-06-17T02:38:36.386000Z"}
{"type":"open","side":"sell","price":"2447.14000000","order_id":"16a9bc56-724a-4b70-96cb-bffac5fd846c","remaining_size":"0.10000000","product_id":"BTC-USD","sequence":3342835647,"time":"2017-06-17T02:38:36.386000Z"}
{"type":"done","side":"sell","order_id":"29e09bef-a2b4-4108-8dd5-f43bc78cf9dc","reason":"canceled","product_id":"BTC-USD","price":"2447.15000000","remaining_size":"0.10000000","sequence":3342835648,"time":"2017-06-17T02:38:36.387000Z"}
{"type":"received","order_id":"d82fb5d8-b568-41c9-8313-19362ba47e45","order_type":"limit","size":"0.08985400","price":"2447.53000000","side":"sell","client_oid":"8cd44a46-2d9a-4f66-8311-323c1f9c683f","product_id":"BTC-USD","sequence":3342835649,"time":"2017-06-17T02:38:36.398000Z"}
{"type":"open","side":"sell","price":"2447.53000000","order_id":"d82fb5d8-b568-41c9-8313-19362ba47e45","remaining_size":"0.08985400","product_id":"BTC-USD","sequence":3342835650,"time":"2017-06-17T02:38:36.398000Z"}
{"type":"received","order_id":"8d1f81ba-a231-4d99-b5df-87108d550f2c","order_type":"limit","size":"0.02100000","price":"2442.99000000","side":"buy","product_id":"BTC-USD","sequence":3342835651,"time":"2017-06-17T02:38:36.401000Z"}
{"type":"open","side":"buy","price":"2442.99000000","order_id":"8d1f81ba-a231-4d99-b5df-87108d550f2c","remaining_size":"0.02100000","product_id":"BTC-USD","sequence":3342835652,"time":"2017-06-17T02:38:36.401000Z"}
{"type":"received","order_id":"b0fc8c8f-3d84-4079-be94-d81c65ef93aa","order_type":"limit","size":"0.20000000","price":"2447.53000000","side":"sell","client_oid":"18c2720b-f55c-4df8-b4e5-2083e4726691","product_id":"BTC-USD","sequence":3342835653,"time":"2017-06-17T02:38:36.404000Z"}
{"type":"open","side":"sell","price":"2447.53000000","order_id":"b0fc8c8f-3d84-4079-be94-d81c65ef93aa","remaining_size":"0.20000000","product_id":"BTC-USD","sequence":3342835654,"time":"2017-06-17T02:38:36.404000Z"}
{"type":"done","side":"sell","order_id":"16a9bc56-724a-4b70-96cb-bffac5fd846c","reason":"canceled","product_id":"BTC-USD","price":"2447.14000000","remaining_size":"0.10000000","sequence":3342835655,"time":"2017-06-17T02:38:36.422000Z"}
{"type":"done","side":"sell","order_id":"b0fc8c8f-3d84-4079-be94-d81c65ef93aa","reason":"canceled","product_id":"BTC-USD","price":"2447.53000000","remaining_size":"0.20000000","sequence":3342835656,"time":"2017-06-17T02:38:36.423000Z"}
{"type":"done","side":"sell","order_id":"d82fb5d8-b568-41c9-8313-19362ba47e45","reason":"canceled","product_id":"BTC-USD","price":"2447.53000000","remaining_size":"0.08985400","sequence":3342835657,"time":"2017-06-17T02:38:36.423000Z"}
{"type":"received","order_id":"6ed95b0b-ac07-4833-8a97-0d835cc24abc","order_type":"limit","size":"0.08985400","price":"2447.52000000","side":"sell","client_oid":"4286912a-2448-47a9-9965-15d658656900","product_id":"BTC-USD","sequence":3342835658,"time":"2017-06-17T02:38:36.433000Z"}
{"type":"open","side":"sell","price":"2447.52000000","order_id":"6ed95b0b-ac07-4833-8a97-0d835cc24abc","remaining_size":"0.08985400","product_id":"BTC-USD","sequence":3342835659,"time":"2017-06-17T02:38:36.433000Z"}
{"type":"done","side":"sell","order_id":"cd41f883-6f92-4b6c-bc1c-1ffa4205dbb3","reason":"canceled","product_id":"BTC-USD","price":"2464.99000000","remaining_size":"5.14220200","sequence":3342835660,"time":"2017-06-17T02:38:36.435000Z"}
{"type":"done","side":"buy","order_id":"fcb958ef-3ced-4be5-bb4d-4116cac7af05","reason":"canceled","product_id":"BTC-USD","price":"2442.77000000","remaining_size":"0.25000000","sequence":3342835661,"time":"2017-06-17T02:38:36.437000Z"}
{"type":"received","order_id":"a2627ea6-3e2e-4f2d-b67d-a8394af98452","order_type":"limit","size":"0.20000000","price":"2447.52000000","side":"sell","client_oid":"a6a66451-1de1-4afc-84a7-f6a5b8056410","product_id":"BTC-USD","sequence":3342835662,"time":"2017-06-17T02:38:36.440000Z"}
{"type":"open","side":"sell","price":"2447.52000000","order_id":"a2627ea6-3e2e-4f2d-b67d-a8394af98452","remaining_size":"0.20000000","product_id":"BTC-USD","sequence":3342835663,"time":"2017-06-17T02:38:36.440000Z"}
{"type":"received","order_id":"62514f17-b43b-43dd-8752-d3293ccd21d4","order_type":"limit","size":"5.22242500","price":"2464.03000000","side":"sell","product_id":"BTC-USD","sequence":3342835664,"time":"2017-06-17T02:38:36.460000Z"}
{"type":"open","side":"sell","price":"2464.03000000","order_id":"62514f17-b43b-43dd-8752-d3293ccd21d4","remaining_size":"5.22242500","product_id":"BTC-USD","sequence":3342835665,"time":"2017-06-17T02:38:36.460000Z"}
{"type":"done","side":"sell","order_id":"6ed95b0b-ac07-4833-8a97-0d835cc24abc","reason":"canceled","product_id":"BTC-USD","price":"2447.52000000","remaining_size":"0.08985400","sequence":3342835666,"time":"2017-06-17T02:38:36.468000Z"}
{"type":"done","side":"sell","order_id":"a2627ea6-3e2e-4f2d-b67d-a8394af98452","reason":"canceled","product_id":"BTC-USD","price":"2447.52000000","remaining_size":"0.20000000","sequence":3342835667,"time":"2017-06-17T02:38:36.470000Z"}
{"type":"received","order_id":"eab2daee-4e67-40e7-9c3c-48a1bd8eda28","order_type":"limit","size":"0.10000000","price":"2447.13000000","side":"sell","client_oid":"eaea7231-0f30-45d9-bef6-e200b626879e","product_id":"BTC-USD","sequence":3342835668,"time":"2017-06-17T02:38:36.474000Z"}
{"type":"open","side":"sell","price":"2447.13000000","order_id":"eab2daee-4e67-40e7-9c3c-48a1bd8eda28","remaining_size":"0.10000000","product_id":"BTC-USD","sequence":3342835669,"time":"2017-06-17T02:38:36.474000Z"}
{"type":"received","order_id":"b214abc1-1d07-427c-b0e2-3a74e03dac79","order_type":"limit","size":"0.25000000","price":"2442.78000000","side":"buy","client_oid":"d3acd4bc-b36f-4ac9-9e21-c7e2f7727a7f","product_id":"BTC-USD","sequence":3342835670,"time":"2017-06-17T02:38:36.475000Z"}
{"type":"open","side":"buy","price":"2442.78000000","order_id":"b214abc1-1d07-427c-b0e2-3a74e03dac79","remaining_size":"0.25000000","product_id":"BTC-USD","sequence":3342835671,"time":"2017-06-17T02:38:36.475000Z"}
{"type":"received","order_id":"928abff1-c2b3-4385-9330-46db9222c85b","order_type":"limit","size":"0.08985400","price":"2447.51000000","side":"sell","client_oid":"6cdd9ee4-f386-4b61-bdaa-c77886366f62","product_id":"BTC-USD","sequence":3342835672,"time":"2017-06-17T02:38:36.481000Z"}
{"type":"open","side":"sell","price":"2447.51000000","order_id":"928abff1-c2b3-4385-9330-46db9222c85b","remaining_size":"0.08985400","product_id":"BTC-USD","sequence":3342835673,"time":"2017-06-17T02:38:36.481000Z"}
{"type":"received","order_id":"836ddd38-6084-4bf9-9c3d-c9f14cf5b1b3","order_type":"limit","size":"0.20000000","price":"2447.51000000","side":"sell","client_oid":"dd8b09ff-7618-4c99-ba5d-5af8dd2fb420","product_id":"BTC-USD","sequence":3342835674,"time":"2017-06-17T02:38:36.499000Z"}
{"type":"open","side":"sell","price":"2447.51000000","order_id":"836ddd38-6084-4bf9-9c3d-c9f14cf5b1b3","remaining_size":"0.20000000","product_id":"BTC-USD","sequence":3342835675,"time":"2017-06-17T02:38:36.499000Z"}
{"type":"done","side":"sell","order_id":"928abff1-c2b3-4385-9330-46db9222c85b","reason":"canceled","product_id":"BTC-USD","price":"2447.51000000","remaining_size":"0.08985400","sequence":3342835676,"time":"2017-06-17T02:38:36.514000Z"}
{"type":"done","side":"sell","order_id":"eab2daee-4e67-40e7-9c3c-48a1bd8eda28","reason":"canceled","product_id":"BTC-USD","price":"2447.13000000","remaining_size":"0.10000000","sequence":3342835677,"time":"2017-06-17T02:38:36.515000Z"}
{"type":"done","side":"sell","order_id":"836ddd38-6084-4bf9-9c3d-c9f14cf5b1b3","reason":"canceled","product_id":"BTC-USD","price":"2447.51000000","remaining_size":"0.20000000","sequence":3342835678,"time":"2017-06-17T02:38:36.517000Z"}
{"type":"received","order_id":"a17a917b-2d1c-4f0e-985c-e958e46cfef5","order_type":"limit","size":"0.10000000","price":"2447.12000000","side":"sell","client_oid":"7800275e-b911-4e01-aa0f-af5dffbba784","product_id":"BTC-USD","sequence":3342835679,"time":"2017-06-17T02:38:36.522000Z"}
{"type":"open","side":"sell","price":"2447.12000000","order_id":"a17a917b-2d1c-4f0e-985c-e958e46cfef5","remaining_size":"0.10000000","product_id":"BTC-USD","sequence":3342835680,"time":"2017-06-17T02:38:36.522000Z"}
{"type":"received","order_id":"09db2c7d-6122-45f2-8c31-e060839d41ee","order_type":"limit","size":"0.20000000","price":"2447.53000000","side":"sell","client_oid":"e26e5937-b7ec-44e4-a860-f9aaf2c285f1","product_id":"BTC-USD","sequence":3342835681,"time":"2017-06-17T02:38:36.527000Z"}
{"type":"open","side":"sell","price":"2447.53000000","order_id":"09db2c7d-6122-45f2-8c31-e060839d41ee","remaining_size":"0.20000000","product_id":"BTC-USD","sequence":3342835682,"time":"2017-06-17T02:38:36.527000Z"}
{"type":"received","order_id":"1daf2992-8924-40ca-98c0-957b444cb339","order_type":"limit","size":"0.08985400","price":"2447.53000000","side":"sell","client_oid":"05037cb1-64f0-403d-8999-4ee4da2f4f93","product_id":"BTC-USD","sequence":3342835683,"time":"2017-06-17T02:38:36.538000Z"}
{"type":"open","side":"sell","price":"2447.53000000","order_id":"1daf2992-8924-40ca-98c0-957b444cb339","remaining_size":"0.08985400","product_id":"BTC-USD","sequence":3342835684,"time":"2017-06-17T02:38:36.538000Z"}
{"type":"done","side":"buy","order_id":"b214abc1-1d07-427c-b0e2-3a74e03dac79","reason":"canceled","product_id":"BTC-USD","price":"2442.78000000","remaining_size":"0.25000000","sequence":3342835685,"time":"2017-06-17T02:38:36.552000Z"}
{"type":"done","side":"sell","order_id":"a17a917b-2d1c-4f0e-985c-e958e46cfef5","reason":"canceled","product_id":"BTC-USD","price":"2447.12000000","remaining_size":"0.10000000","sequence":3342835686,"time":"2017-06-17T02:38:36.557000Z"}
{"type":"done","side":"sell","order_id":"1daf2992-8924-40ca-98c0-957b444cb339","reason":"canceled","product_id":"BTC-USD","price":"2447.53000000","remaining_size":"0.08985400","sequence":3342835687,"time":"2017-06-17T02:38:36.558000Z"}
{"type":"done","side":"sell","order_id":"09db2c7d-6122-45f2-8c31-e060839d41ee","reason":"canceled","product_id":"BTC-USD","price":"2447.53000000","remaining_size":"0.20000000","sequence":3342835688,"time":"2017-06-17T02:38:36.558000Z"}
{"type":"received","order_id":"ebd0ab62-b67e-4f7f-8e12-8b6e032e82c1","order_type":"limit","size":"0.10000000","price":"2447.11000000","side":"sell","client_oid":"d0f72212-603a-4623-8b9b-1a56f802925c","product_id":"BTC-USD","sequence":3342835689,"time":"2017-06-17T02:38:36.566000Z"}
{"type":"open","side":"sell","price":"2447.11000000","order_id":"ebd0ab62-b67e-4f7f-8e12-8b6e032e82c1","remaining_size":"0.10000000","product_id":"BTC-USD","sequence":3342835690,"time":"2017-06-17T02:38:36.566000Z"}
{"type":"received","order_id":"24becf34-705f-4645-af5a-0f768f080ac3","order_type":"limit","size":"0.25000000","price":"2442.79000000","side":"buy","client_oid":"a3204f31-4b5a-43d1-88d6-30e97abd82e1","product_id":"BTC-USD","sequence":3342835691,"time":"2017-06-17T02:38:36.568000Z"}
{"type":"open","side":"buy","price":"2442.79000000","order_id":"24becf34-705f-4645-af5a-0f768f080ac3","remaining_size":"0.25000000","product_id":"BTC-USD","sequence":3342835692,"time":"2017-06-17T02:38:36.568000Z"}
{"type":"received","order_id":"da1f20ca-ef2e-4fdf-a32d-3402d22c1cc1","order_type":"limit","size":"0.20000000","price":"2447.52000000","side":"sell","client_oid":"54c0c076-beeb-45d4-8663-50619aa6248f","product_id":"BTC-USD","sequence":3342835693,"time":"2017-06-17T02:38:36.571000Z"}
{"type":"open","side":"sell","price":"2447.52000000","order_id":"da1f20ca-ef2e-4fdf-a32d-3402d22c1cc1","remaining_size":"0.20000000","product_id":"BTC-USD","sequence":3342835694,"time":"2017-06-17T02:38:36.571000Z"}
{"type":"received","order_id":"895e2c2f-5f46-4881-a186-01d8360a7eae","order_type":"limit","size":"0.08985400","price":"2447.52000000","side":"sell","client_oid":"6eee8faf-3685-40b8-b191-442a76659f52","product_id":"BTC-USD","sequence":3342835695,"time":"2017-06-17T02:38:36.577000Z"}
{"type":"open","side":"sell","price":"2447.52000000","order_id":"895e2c2f-5f46-4881-a186-01d8360a7eae","remaining_size":"0.08985400","product_id":"BTC-USD","sequence":3342835696,"time":"2017-06-17T02:38:36.577000Z"}
{"type":"done","side":"sell","order_id":"ebd0ab62-b67e-4f7f-8e12-8b6e032e82c1","reason":"canceled","product_id":"BTC-USD","price":"2447.11000000","remaining_size":"0.10000000","sequence":3342835697,"time":"2017-06-17T02:38:36.601000Z"}
{"type":"done","side":"sell","order_id":"da1f20ca-ef2e-4fdf-a32d-3402d22c1cc1","reason":"canceled","product_id":"BTC-USD","price":"2447.52000000","remaining_size":"0.20000000","sequence":3342835698,"time":"2017-06-17T02:38:36.601000Z"}
{"type":"done","side":"sell","order_id":"895e2c2f-5f46-4881-a186-01d8360a7eae","reason":"canceled","product_id":"BTC-USD","price":"2447.52000000","remaining_size":"0.08985400","sequence":3342835699,"time":"2017-06-17T02:38:36.604000Z"}
{"type":"received","order_id":"f6c08d28-1426-487b-9a69-7445facd0453","order_type":"limit","size":"0.10000000","price":"2447.10000000","side":"sell","client_oid":"3d47e076-e4fe-48a3-a7ca-3def516ccca4","product_id":"BTC-USD","sequence":3342835700,"time":"2017-06-17T02:38:36.611000Z"}
{"type":"open","side":"sell","price":"2447.10000000","order_id":"f6c08d28-1426-487b-9a69-7445facd0453","remaining_size":"0.10000000","product_id":"BTC-USD","sequence":3342835701,"time":"2017-06-17T02:38:36.611000Z"}
{"type":"received","order_id":"af396768-dbe9-4f5b-a43a-ea7480f5c1be","order_type":"limit","size":"0.08985400","price":"2447.51000000","side":"sell","client_oid":"a1c6a9c9-6107-496f-a12f-62f01c211ad6","product_id":"BTC-USD","sequence":3342835702,"time":"2017-06-17T02:38:36.619000Z"}
{"type":"open","side":"sell","price":"2447.51000000","order_id":"af396768-dbe9-4f5b-a43a-ea7480f5c1be","remaining_size":"0.08985400","product_id":"BTC-USD","sequence":3342835703,"time":"2017-06-17T02:38:36.619000Z"}
{"type":"done","side":"buy","order_id":"efc87aef-b551-4e7d-b96e-a367ca34a951","reason":"canceled","product_id":"BTC-USD","price":"2435.17000000","remaining_size":"5.00000000","sequence":3342835704,"time":"2017-06-17T02:38:36.632000Z"}
{"type":"done","side":"sell","order_id":"af396768-dbe9-4f5b-a43a-ea7480f5c1be","reason":"canceled","product_id":"BTC-USD","price":"2447.51000000","remaining_size":"0.08985400","sequence":3342835705,"time":"2017-06-17T02:38:36.647000Z"}
{"type":"done","side":"sell","order_id":"f6c08d28-1426-487b-9a69-7445facd0453","reason":"canceled","product_id":"BTC-USD","price":"2447.10000000","remaining_size":"0.10000000","sequence":3342835706,"time":"2017-06-17T02:38:36.650000Z"}
{"type":"done","side":"buy","order_id":"24becf34-705f-4645-af5a-0f768f080ac3","reason":"canceled","product_id":"BTC-USD","price":"2442.79000000","remaining_size":"0.25000000","sequence":3342835707,"time":"2017-06-17T02:38:36.656000Z"}
{"type":"received","order_id":"5bd9e76b-1561-4d4d-b3d2-5f2cb8ef56cd","order_type":"limit","size":"0.20000000","price":"2447.53000000","side":"sell","client_oid":"4fd03593-7f60-4186-b110-e34ea02bdb63","product_id":"BTC-USD","sequence":3342835708,"time":"2017-06-17T02:38:36.663000Z"}
{"type":"open","side":"sell","price":"2447.53000000","order_id":"5bd9e76b-1561-4d4d-b3d2-5f2cb8ef56cd","remaining_size":"0.20000000","product_id":"BTC-USD","sequence":3342835709,"time":"2017-06-17T02:38:36.663000Z"}
{"type":"received","order_id":"e131098b-34a9-47af-8c92-b5ce99c7c08e","order_type":"limit","size":"0.10000000","price":"2447.09000000","side":"sell","client_oid":"287eaf25-66dd-4f70-bca5-5ae9314e5d0f","product_id":"BTC-USD","sequence":3342835710,"time":"2017-06-17T02:38:36.680000Z"}
{"type":"open","side":"sell","price":"2447.09000000","order_id":"e131098b-34a9-47af-8c92-b5ce99c7c08e","remaining_size":"0.10000000","product_id":"BTC-USD","sequence":3342835711,"time":"2017-06-17T02:38:36.680000Z"}
{"type":"done","side":"buy","order_id":"8d1f81ba-a231-4d99-b5df-87108d550f2c","reason":"canceled","product_id":"BTC-USD","price":"2442.99000000","remaining_size":"0.02100000","sequence":3342835712,"time":"2017-06-17T02:38:36.683000Z"}
{"type":"received","order_id":"e0de1f76-279f-466f-a16b-fec04fcb5b29","order_type":"limit","size":"0.08985400","price":"2447.53000000","side":"sell","client_oid":"879b5de1-ac36-4750-8921-3a07a480052d","product_id":"BTC-USD","sequence":3342835713,"time":"2017-06-17T02:38:36.687000Z"}
{"type":"open","side":"sell","price":"2447.53000000","order_id":"e0de1f76-279f-466f-a16b-fec04fcb5b29","remaining_size":"0.08985400","product_id":"BTC-USD","sequence":3342835714,"time":"2017-06-17T02:38:36.687000Z"}
{"type":"done","side":"sell","order_id":"5bd9e76b-1561-4d4d-b3d2-5f2cb8ef56cd","reason":"canceled","product_id":"BTC-USD","price":"2447.53000000","remaining_size":"0.20000000","sequence":3342835715,"time":"2017-06-17T02:38:36.691000Z"}
{"type":"done","side":"sell","order_id":"e0de1f76-279f-466f-a16b-fec04fcb5b29","reason":"canceled","product_id":"BTC-USD","price":"2447.53000000","remaining_size":"0.08985400","sequence":3342835716,"time":"2017-06-17T02:38:36.694000Z"}
{"type":"done","side":"sell","order_id":"e131098b-34a9-47af-8c92-b5ce99c7c08e","reason":"canceled","product_id":"BTC-USD","price":"2447.09000000","remaining_size":"0.10000000","sequence":3342835717,"time":"2017-06-17T02:38:36.694000Z"}
{"type":"received","order_id":"4de5d9c4-7be4-4ec1-b27d-f169cc581c57","order_type":"limit","size":"0.20000000","price":"2447.52000000","side":"sell","client_oid":"d71ee782-532a-4830-ad4f-65d1b8ab65b4","product_id":"BTC-USD","sequence":3342835718,"time":"2017-06-17T02:38:36.701000Z"}
{"type":"open","side":"sell","price":"2447.52000000","order_id":"4de5d9c4-7be4-4ec1-b27d-f169cc581c57","remaining_size":"0.20000000","product_id":"BTC-USD","sequence":3342835719,"time":"2017-06-17T02:38:36.701000Z"}
{"type":"received","order_id":"0e9dca39-1176-4f6f-91b6-a9f2608d26db","order_type":"limit","size":"0.08985400","price":"2447.52000000","side":"sell","client_oid":"7d6a8dda-aa2a-4a99-b4a5-98d0d467eb15","product_id":"BTC-USD","sequence":3342835720,"time":"2017-06-17T02:38:36.707000Z"}
{"type":"open","side":"sell","price":"2447.52000000","order_id":"0e9dca39-1176-4f6f-91b6-a9f2608d26db","remaining_size":"0.08985400","product_id":"BTC-USD","sequence":3342835721,"time":"2017-06-17T02:38:36.707000Z"}
{"type":"done","side":"buy","order_id":"4221a934-5927-42c5-be3b-36406d736272","reason":"canceled","product_id":"BTC-USD","price":"2442.99000000","remaining_size":"0.91068348","sequence":3342835722,"time":"2017-06-17T02:38:36.710000Z"}
{"type":"received","order_id":"dc707bca-f4c4-4377-8acc-6d3bfacbe823","order_type":"limit","size":"0.10000000","price":"2447.08000000","side":"sell","client_oid":"c6e42010-2571-430f-b3cf-69ac4e5607b9","product_id":"BTC-USD","sequence":3342835723,"time":"2017-06-17T02:38:36.717000Z"}
{"type":"open","side":"sell","price":"2447.08000000","order_id":"dc707bca-f4c4-4377-8acc-6d3bfacbe823","remaining_size":"0.10000000","product_id":"BTC-USD","sequence":3342835724,"time":"2017-06-17T02:38:36.717000Z"}
{"type":"done","side":"sell","order_id":"dc707bca-f4c4-4377-8acc-6d3bfacbe823","reason":"canceled","product_id":"BTC-USD","price":"2447.08000000","remaining_size":"0.10000000","sequence":3342835725,"time":"2017-06-17T02:38:36.737000Z"}
{"type":"done","side":"sell","order_id":"0e9dca39-1176-4f6f-91b6-a9f2608d26db","reason":"canceled","product_id":"BTC-USD","price":"2447.52000000","remaining_size":"0.08985400","sequence":3342835726,"time":"2017-06-17T02:38:36.740000Z"}
{"type":"received","order_id":"e0487c56-d6d5-471c-a802-c3f6b8bcfad7","order_type":"limit","size":"0.33852253","price":"2442.99000000","side":"buy","client_oid":"ffd158c5-2d69-470c-8112-140469a52363","product_id":"BTC-USD","sequence":3342835727,"time":"2017-06-17T02:38:36.746000Z"}
{"type":"open","side":"buy","price":"2442.99000000","order_id":"e0487c56-d6d5-471c-a802-c3f6b8bcfad7","remaining_size":"0.33852253","product_id":"BTC-USD","sequence":3342835728,"time":"2017-06-17T02:38:36.746000Z"}
{"type":"received","order_id":"a077d807-9bc5-4f61-a92f-4c150d188df5","order_type":"limit","size":"0.10000000","price":"2447.07000000","side":"sell","client_oid":"b525b98b-de1d-46f5-9a91-23e0d23e432d","product_id":"BTC-USD","sequence":3342835729,"time":"2017-06-17T02:38:36.755000Z"}
{"type":"open","side":"sell","price":"2447.07000000","order_id":"a077d807-9bc5-4f61-a92f-4c150d188df5","remaining_size":"0.10000000","product_id":"BTC-USD","sequence":3342835730,"time":"2017-06-17T02:38:36.755000Z"}
{"type":"received","order_id":"22a62ce6-41b6-4ffa-bc32-4011ead99833","order_type":"limit","size":"0.20000000","price":"2447.51000000","side":"sell","client_oid":"2ffd0f9a-29f4-4514-9c2f-a43fe09f8d0f","product_id":"BTC-USD","sequence":3342835731,"time":"2017-06-17T02:38:36.756000Z"}
{"type":"open","side":"sell","price":"2447.51000000","order_id":"22a62ce6-41b6-4ffa-bc32-4011ead99833","remaining_size":"0.20000000","product_id":"BTC-USD","sequence":3342835732,"time":"2017-06-17T02:38:36.756000Z"}
{"type":"done","side":"sell","order_id":"4de5d9c4-7be4-4ec1-b27d-f169cc581c57","reason":"canceled","product_id":"BTC-USD","price":"2447.52000000","remaining_size":"0.20000000","sequence":3342835733,"time":"2017-06-17T02:38:36.757000Z"}
{"type":"received","order_id":"38a8cae0-216c-4d64-8a24-560179c27f3c","order_type":"limit","size":"0.08985400","price":"2447.51000000","side":"sell","client_oid":"f44435e1-a2a2-47e4-9c18-ed19015010e7","product_id":"BTC-USD","sequence":3342835734,"time":"2017-06-17T02:38:36.760000Z"}
{"type":"open","side":"sell","price":"2447.51000000","order_id":"38a8cae0-216c-4d64-8a24-560179c27f3c","remaining_size":"0.08985400","product_id":"BTC-USD","sequence":3342835735,"time":"2017-06-17T02:38:36.760000Z"}
{"type":"done","side":"sell","order_id":"38a8cae0-216c-4d64-8a24-560179c27f3c","reason":"canceled","product_id":"BTC-USD","price":"2447.51000000","remaining_size":"0.08985400","sequence":3342835736,"time":"2017-06-17T02:38:36.782000Z"}
{"type":"done","side":"sell","order_id":"22a62ce6-41b6-4ffa-bc32-4011ead99833","reason":"canceled","product_id":"BTC-USD","price":"2447.51000000","remaining_size":"0.20000000","sequence":3342835737,"time":"2017-06-17T02:38:36.782000Z"}
{"type":"done","side":"sell","order_id":"a077d807-9bc5-4f61-a92f-4c150d188df5","reason":"canceled","product_id":"BTC-USD","price":"2447.07000000","remaining_size":"0.10000000","sequence":3342835738,"time":"2017-06-17T02:38:36.783000Z"}
{"type":"received","order_id":"36a94602-bb8a-4ea9-acd0-390eb38ba16a","order_type":"limit","size":"0.10000000","price":"2447.06000000","side":"sell","client_oid":"1fd4752e-9a03-4cfc-9dae-e2b810b3b56c","product_id":"BTC-USD","sequence":3342835739,"time":"2017-06-17T02:38:36.791000Z"}
{"type":"open","side":"sell","price":"2447.06000000","order_id":"36a94602-bb8a-4ea9-acd0-390eb38ba16a","remaining_size":"0.10000000","product_id":"BTC-USD","sequence":3342835740,"time":"2017-06-17T02:38:36.791000Z"}
{"type":"received","order_id":"01a33fef-b4e1-43e1-a65b-a5988cc1c846","order_type":"limit","size":"0.08985400","price":"2447.50000000","side":"sell","client_oid":"e9451128-39df-4a9f-972f-bff1a879b239","product_id":"BTC-USD","sequence":3342835741,"time":"2017-06-17T02:38:36.796000Z"}
{"type":"open","side":"sell","price":"2447.50000000","order_id":"01a33fef-b4e1-43e1-a65b-a5988cc1c846","remaining_size":"0.08985400","product_id":"BTC-USD","sequence":3342835742,"time":"2017-06-17T02:38:36.796000Z"}
{"type":"received","order_id":"a7b59b9a-dca8-4f42-9ff1-b19a9e86bd22","order_type":"limit","size":"0.20000000","price":"2447.53000000","side":"sell","client_oid":"cf7c37eb-ee3d-4315-894a-0d7273416c96","product_id":"BTC-USD","sequence":3342835743,"time":"2017-06-17T02:38:36.811000Z"}
{"type":"open","side":"sell","price":"2447.53000000","order_id":"a7b59b9a-dca8-4f42-9ff1-b19a9e86bd22","remaining_size":"0.20000000","product_id":"BTC-USD","sequence":3342835744,"time":"2017-06-17T02:38:36.811000Z"}
{"type":"done","side":"sell","order_id":"36a94602-bb8a-4ea9-acd0-390eb38ba16a","reason":"canceled","product_id":"BTC-USD","price":"2447.06000000","remaining_size":"0.10000000","sequence":3342835745,"time":"2017-06-17T02:38:36.828000Z"}
{"type":"done","side":"sell","order_id":"01a33fef-b4e1-43e1-a65b-a5988cc1c846","reason":"canceled","product_id":"BTC-USD","price":"2447.50000000","remaining_size":"0.08985400","sequence":3342835746,"time":"2017-06-17T02:38:36.829000Z"}
{"type":"done","side":"sell","order_id":"a7b59b9a-dca8-4f42-9ff1-b19a9e86bd22","reason":"canceled","product_id":"BTC-USD","price":"2447.53000000","remaining_size":"0.20000000","sequence":3342835747,"time":"2017-06-17T02:38:36.834000Z"}
{"type":"received","order_id":"985162eb-6623-49c5-9fb7-7664efe61f50","order_type":"limit","size":"0.08985400","price":"2447.52000000","side":"sell","client_oid":"f7663a86-2af1-475a-8d22-2c1066cabd03","product_id":"BTC-USD","sequence":3342835748,"time":"2017-06-17T02:38:36.839000Z"}
{"type":"open","side":"sell","price":"2447.52000000","order_id":"985162eb-6623-49c5-9fb7-7664efe61f50","remaining_size":"0.08985400","product_id":"BTC-USD","sequence":3342835749,"time":"2017-06-17T02:38:36.839000Z"}
{"type":"received","order_id":"c61c0cce-6879-48c1-92d6-fb253a1c755a","order_type":"limit","size":"0.10000000","price":"2447.05000000","side":"sell","client_oid":"c6f6c89c-9a72-401d-b201-8233c3bd6a03","product_id":"BTC-USD","sequence":3342835750,"time":"2017-06-17T02:38:36.844000Z"}
{"type":"open","side":"sell","price":"2447.05000000","order_id":"c61c0cce-6879-48c1-92d6-fb253a1c755a","remaining_size":"0.10000000","product_id":"BTC-USD","sequence":3342835751,"time":"2017-06-17T02:38:36.844000Z"}
{"type":"received","order_id":"94a68437-8724-45a0-adb7-d258e5f15aa0","order_type":"limit","size":"0.20000000","price":"2447.52000000","side":"sell","client_oid":"f082f779-02a1-4ba2-a7c2-3cf239ff1cd8","product_id":"BTC-USD","sequence":3342835752,"time":"2017-06-17T02:38:36.865000Z"}
{"type":"open","side":"sell","price":"2447.52000000","order_id":"94a68437-8724-45a0-adb7-d258e5f15aa0","remaining_size":"0.20000000","product_id":"BTC-USD","sequence":3342835753,"time":"2017-06-17T02:38:36.865000Z"}
{"type":"received","order_id":"69de8aa0-712e-47e4-a218-c7010487ed04","order_type":"limit","size":"0.25000000","price":"2442.77000000","side":"buy","client_oid":"07d5ff07-e753-41cc-9b80-dd00a1017954","product_id":"BTC-USD","sequence":3342835754,"time":"2017-06-17T02:38:36.883000Z"}
{"type":"open","side":"buy","price":"2442.77000000","order_id":"69de8aa0-712e-47e4-a218-c7010487ed04","remaining_size":"0.25000000","product_id":"BTC-USD","sequence":3342835755,"time":"2017-06-17T02:38:36.883000Z"}
{"type":"done","side":"sell","order_id":"c61c0cce-6879-48c1-92d6-fb253a1c755a","reason":"canceled","product_id":"BTC-USD","price":"2447.05000000","remaining_size":"0.10000000","sequence":3342835756,"time":"2017-06-17T02:38:36.886000Z"}
{"type":"received","order_id":"f93c56db-3a36-45fb-817a-d69dbb8864df","order_type":"limit","size":"0.10000000","price":"2447.15000000","side":"sell","client_oid":"06127e00-59ea-4f87-9a89-03eb4414b056","product_id":"BTC-USD","sequence":3342835757,"time":"2017-06-17T02:38:36.890000Z"}
{"type":"open","side":"sell","price":"2447.15000000","order_id":"f93c56db-3a36-45fb-817a-d69dbb8864df","remaining_size":"0.10000000","product_id":"BTC-USD","sequence":3342835758,"time":"2017-06-17T02:38:36.890000Z"}
{"type":"received","order_id":"1535dfc4-6665-4197-be0f-8dc5952879f4","order_type":"limit","size":"0.20000000","price":"2447.53000000","side":"sell","client_oid":"10fed8fa-dc44-4c67-8f40-1f636287038c","product_id":"BTC-USD","sequence":3342835759,"time":"2017-06-17T02:38:36.900000Z"}
{"type":"open","side":"sell","price":"2447.53000000","order_id":"1535dfc4-6665-4197-be0f-8dc5952879f4","remaining_size":"0.20000000","product_id":"BTC-USD","sequence":3342835760,"time":"2017-06-17T02:38:36.900000Z"}
{"type":"done","side":"sell","order_id":"985162eb-6623-49c5-9fb7-7664efe61f50","reason":"canceled","product_id":"BTC-USD","price":"2447.52000000","remaining_size":"0.08985400","sequence":3342835761,"time":"2017-06-17T02:38:36.900000Z"}
{"type":"done","side":"sell","order_id":"94a68437-8724-45a0-adb7-d258e5f15aa0","reason":"canceled","product_id":"BTC-USD","price":"2447.52000000","remaining_size":"0.20000000","sequence":3342835762,"time":"2017-06-17T02:38:36.908000Z"}
{"type":"received","order_id":"47978ae1-9854-4b70-bc1c-033b8a2b2dfc","order_type":"limit","size":"0.08985400","price":"2447.53000000","side":"sell","client_oid":"c8ae17c3-f770-4612-9741-20c0065d808f","product_id":"BTC-USD","sequence":3342835763,"time":"2017-06-17T02:38:36.911000Z"}
{"type":"open","side":"sell","price":"2447.53000000","order_id":"47978ae1-9854-4b70-bc1c-033b8a2b2dfc","remaining_size":"0.08985400","product_id":"BTC-USD","sequence":3342835764,"time":"2017-06-17T02:38:36.911000Z"}
{"type":"done","side":"sell","order_id":"f93c56db-3a36-45fb-817a-d69dbb8864df","reason":"canceled","product_id":"BTC-USD","price":"2447.15000000","remaining_size":"0.10000000","sequence":3342835765,"time":"2017-06-17T02:38:36.922000Z"}
{"type":"done","side":"sell","order_id":"1535dfc4-6665-4197-be0f-8dc5952879f4","reason":"canceled","product_id":"BTC-USD","price":"2447.53000000","remaining_size":"0.20000000","sequence":3342835766,"time":"2017-06-17T02:38:36.925000Z"}
{"type":"done","side":"sell","order_id":"47978ae1-9854-4b70-bc1c-033b8a2b2dfc","reason":"canceled","product_id":"BTC-USD","price":"2447.53000000","remaining_size":"0.08985400","sequence":3342835767,"time":"2017-06-17T02:38:36.930000Z"}
{"type":"received","order_id":"633f088a-a18d-4f76-8b81-cbca400145c5","order_type":"limit","size":"0.08985400","price":"2447.51000000","side":"sell","client_oid":"71f318b5-282a-4c04-87fc-ca5318e37095","product_id":"BTC-USD","sequence":3342835768,"time":"2017-06-17T02:38:36.943000Z"}
{"type":"open","side":"sell","price":"2447.51000000","order_id":"633f088a-a18d-4f76-8b81-cbca400145c5","remaining_size":"0.08985400","product_id":"BTC-USD","sequence":3342835769,"time":"2017-06-17T02:38:36.943000Z"}
{"type":"received","order_id":"e9798767-af0a-4d50-922d-ec932f336f9d","order_type":"limit","size":"0.10000000","price":"2447.14000000","side":"sell","client_oid":"f686661d-7d33-4365-8a13-017c12b8c187","product_id":"BTC-USD","sequence":3342835770,"time":"2017-06-17T02:38:36.962000Z"}
{"type":"open","side":"sell","price":"2447.14000000","order_id":"e9798767-af0a-4d50-922d-ec932f336f9d","remaining_size":"0.10000000","product_id":"BTC-USD","sequence":3342835771,"time":"2017-06-17T02:38:36.962000Z"}
{"type":"done","side":"sell","order_id":"633f088a-a18d-4f76-8b81-cbca400145c5","reason":"canceled","product_id":"BTC-USD","price":"2447.51000000","remaining_size":"0.08985400","sequence":3342835772,"time":"2017-06-17T02:38:36.971000Z"}
{"type":"received","order_id":"9e89752c-1f4f-4bdb-afce-eb1ddbf89c40","order_type":"limit","size":"0.20000000","price":"2448.77000000","side":"sell","client_oid":"06c4deef-fea5-4d99-8d3c-be5e896301f7","product_id":"BTC-USD","sequence":3342835773,"time":"2017-06-17T02:38:36.983000Z"}
{"type":"open","side":"sell","price":"2448.77000000","order_id":"9e89752c-1f4f-4bdb-afce-eb1ddbf89c40","remaining_size":"0.20000000","product_id":"BTC-USD","sequence":3342835774,"time":"2017-06-17T02:38:36.983000Z"}
{"type":"done","side":"sell","order_id":"4f597347-bd76-4aaf-abe4-32f9fc226539","reason":"canceled","product_id":"BTC-USD","price":"2443.59000000","remaining_size":"0.50000000","sequence":3342835775,"time":"2017-06-17T02:38:36.986000Z"}
{"type":"done","side":"sell","order_id":"62514f17-b43b-43dd-8752-d3293ccd21d4","reason":"canceled","product_id":"BTC-USD","price":"2464.03000000","remaining_size":"5.22242500","sequence":3342835776,"time":"2017-06-17T02:38:36.992000Z"}
{"type":"received","order_id":"b14a5a0a-8d58-4dae-a928-56b0ca2323d5","order_type":"limit","size":"0.10000000","price":"2447.15000000","side":"sell","client_oid":"d4b27cc5-88da-4629-86f0-1b130977ba5b","product_id":"BTC-USD","sequence":3342835777,"time":"2017-06-17T02:38:36.996000Z"}
{"type":"open","side":"sell","price":"2447.15000000","order_id":"b14a5a0a-8d58-4dae-a928-56b0ca2323d5","remaining_size":"0.10000000","product_id":"BTC-USD","sequence":3342835778,"time":"2017-06-17T02:38:36.996000Z"}
{"type":"done","side":"buy","order_id":"69de8aa0-712e-47e4-a218-c7010487ed04","reason":"canceled","product_id":"BTC-USD","price":"2442.77000000","remaining_size":"0.25000000","sequence":3342835779,"time":"2017-06-17T02:38:36.999000Z"}
{"type":"done","side":"sell","order_id":"e9798767-af0a-4d50-922d-ec932f336f9d","reason":"canceled","product_id":"BTC-USD","price":"2447.14000000","remaining_size":"0.10000000","sequence":3342835780,"time":"2017-06-17T02:38:37.002000Z"}
{"type":"received","order_id":"3b9b7a03-f5bf-444c-85c1-8793d43fcffa","order_type":"limit","size":"0.25000000","price":"2442.78000000","side":"buy","client_oid":"27168bad-88b1-4bf8-a8b1-72ab3fff33e5","product_id":"BTC-USD","sequence":3342835781,"time":"2017-06-17T02:38:37.015000Z"}
{"type":"open","side":"buy","price":"2442.78000000","order_id":"3b9b7a03-f5bf-444c-85c1-8793d43fcffa","remaining_size":"0.25000000","product_id":"BTC-USD","sequence":3342835782,"time":"2017-06-17T02:38:37.015000Z"}
{"type":"done","side":"sell","order_id":"9e89752c-1f4f-4bdb-afce-eb1ddbf89c40","reason":"canceled","product_id":"BTC-USD","price":"2448.77000000","remaining_size":"0.20000000","sequence":3342835783,"time":"2017-06-17T02:38:37.018000Z"}
{"type":"done","side":"sell","order_id":"b14a5a0a-8d58-4dae-a928-56b0ca2323d5","reason":"canceled","product_id":"BTC-USD","price":"2447.15000000","remaining_size":"0.10000000","sequence":3342835784,"time":"2017-06-17T02:38:37.023000Z"}
{"type":"received","order_id":"45188b18-d586-4231-b599-60b222cf28b9","order_type":"limit","size":"0.20000000","price":"2447.53000000","side":"sell","client_oid":"4373402c-0006-4678-b9f9-c9ae78c1a864","product_id":"BTC-USD","sequence":3342835785,"time":"2017-06-17T02:38:37.027000Z"}
{"type":"open","side":"sell","price":"2447.53000000","order_id":"45188b18-d586-4231-b599-60b222cf28b9","remaining_size":"0.20000000","product_id":"BTC-USD","sequence":3342835786,"time":"2017-06-17T02:38:37.027000Z"}
{"type":"received","order_id":"d065e8df-5cdb-4368-95f6-627336b21760","order_type":"limit","size":"5.19899600","price":"2464.98000000","side":"sell","product_id":"BTC-USD","sequence":3342835787,"time":"2017-06-17T02:38:37.030000Z"}
{"type":"open","side":"sell","price":"2464.98000000","order_id":"d065e8df-5cdb-4368-95f6-627336b21760","remaining_size":"5.19899600","product_id":"BTC-USD","sequence":3342835788,"time":"2017-06-17T02:38:37.030000Z"}
{"type":"received","order_id":"3c745fda-cb33-4a37-a868-fdbfe1091de5","order_type":"limit","size":"0.50000000","price":"2443.55000000","side":"sell","client_oid":"6d207381-9fda-49c8-8975-7e72c7b5531b","product_id":"BTC-USD","sequence":3342835789,"time":"2017-06-17T02:38:37.057000Z"}
{"type":"open","side":"sell","price":"2443.55000000","order_id":"3c745fda-cb33-4a37-a868-fdbfe1091de5","remaining_size":"0.50000000","product_id":"BTC-USD","sequence":3342835790,"time":"2017-06-17T02:38:37.057000Z"}
{"type":"done","side":"sell","order_id":"45188b18-d586-4231-b599-60b222cf28b9","reason":"canceled","product_id":"BTC-USD","price":"2447.53000000","remaining_size":"0.20000000","sequence":3342835791,"time":"2017-06-17T02:38:37.061000Z"}
{"type":"received","order_id":"29a1992b-ba30-450a-b278-03e6a953d2bb","order_type":"limit","size":"0.20000000","price":"2449.17000000","side":"sell","client_oid":"a7f849b2-3a3c-4f98-b929-99c59c877dea","product_id":"BTC-USD","sequence":3342835792,"time":"2017-06-17T02:38:37.161000Z"}
{"type":"open","side":"sell","price":"2449.17000000","order_id":"29a1992b-ba30-450a-b278-03e6a953d2bb","remaining_size":"0.20000000","product_id":"BTC-USD","sequence":3342835793,"time":"2017-06-17T02:38:37.161000Z"}
{"type":"received","order_id":"5b6ee15e-2245-4cec-bd1c-e159bdaa07f2","order_type":"limit","size":"0.10000000","price":"2447.15000000","side":"sell","client_oid":"a99ef37f-920a-4866-b57c-9536856b2408","product_id":"BTC-USD","sequence":3342835794,"time":"2017-06-17T02:38:37.166000Z"}
{"type":"open","side":"sell","price":"2447.15000000","order_id":"5b6ee15e-2245-4cec-bd1c-e159bdaa07f2","remaining_size":"0.10000000","product_id":"BTC-USD","sequence":3342835795,"time":"2017-06-17T02:38:37.166000Z"}
{"type":"done","side":"sell","order_id":"29a1992b-ba30-450a-b278-03e6a953d2bb","reason":"canceled","product_id":"BTC-USD","price":"2449.17000000","remaining_size":"0.20000000","sequence":3342835796,"time":"2017-06-17T02:38:37.170000Z"}
{"type":"done","side":"buy","order_id":"3b9b7a03-f5bf-444c-85c1-8793d43fcffa","reason":"canceled","product_id":"BTC-USD","price":"2442.78000000","remaining_size":"0.25000000","sequence":3342835797,"time":"2017-06-17T02:38:37.173000Z"}
{"type":"done","side":"sell","order_id":"5b6ee15e-2245-4cec-bd1c-e159bdaa07f2","reason":"canceled","product_id":"BTC-USD","price":"2447.15000000","remaining_size":"0.10000000","sequence":3342835798,"time":"2017-06-17T02:38:37.181000Z"}
{"type":"received","order_id":"6120435f-02b2-495c-8563-5af9b3ca6e02","order_type":"limit","size":"0.10000000","price":"2447.14000000","side":"sell","client_oid":"2216d012-2f7b-401e-8765-94b51acd0624","product_id":"BTC-USD","sequence":3342835799,"time":"2017-06-17T02:38:37.191000Z"}
{"type":"open","side":"sell","price":"2447.14000000","order_id":"6120435f-02b2-495c-8563-5af9b3ca6e02","remaining_size":"0.10000000","product_id":"BTC-USD","sequence":3342835800,"time":"2017-06-17T02:38:37.191000Z"}
{"type":"done","side":"sell","order_id":"6120435f-02b2-495c-8563-5af9b3ca6e02","reason":"canceled","product_id":"BTC-USD","price":"2447.14000000","remaining_size":"0.10000000","sequence":3342835801,"time":"2017-06-17T02:38:37.221000Z"}
{"type":"received","order_id":"679812ca-6fec-4b92-8996-68a4da711f73","order_type":"limit","size":"0.10000000","price":"2447.13000000","side":"sell","client_oid":"44fe1b78-15bc-40d9-951c-e4048cfdd804","product_id":"BTC-USD","sequence":3342835802,"time":"2017-06-17T02:38:37.233000Z"}
{"type":"open","side":"sell","price":"2447.13000000","order_id":"679812ca-6fec-4b92-8996-68a4da711f73","remaining_size":"0.10000000","product_id":"BTC-USD","sequence":3342835803,"time":"2017-06-17T02:38:37.233000Z"}
{"type":"done","side":"sell","order_id":"679812ca-6fec-4b92-8996-68a4da711f73","reason":"canceled","product_id":"BTC-USD","price":"2447.13000000","remaining_size":"0.10000000","sequence":3342835804,"time":"2017-06-17T02:38:37.261000Z"}
{"type":"received","order_id":"6ff19333-3c5d-4b65-b696-d370452978b6","order_type":"limit","size":"0.10000000","price":"2447.12000000","side":"sell","client_oid":"87964a87-19f2-46dc-9117-6d3b5bb5e2d9","product_id":"BTC-USD","sequence":3342835805,"time":"2017-06-17T02:38:37.272000Z"}
{"type":"open","side":"sell","price":"2447.12000000","order_id":"6ff19333-3c5d-4b65-b696-d370452978b6","remaining_size":"0.10000000","product_id":"BTC-USD","sequence":3342835806,"time":"2017-06-17T02:38:37.272000Z"}
{"type":"done","side":"sell","order_id":"6ff19333-3c5d-4b65-b696-d370452978b6","reason":"canceled","product_id":"BTC-USD","price":"2447.12000000","remaining_size":"0.10000000","sequence":3342835807,"time":"2017-06-17T02:38:37.306000Z"}
{"type":"received","order_id":"2988df73-1eb0-49ef-9841-e2d97e9bf281","order_type":"limit","size":"0.10000000","price":"2447.11000000","side":"sell","client_oid":"47185c49-fcc2-4b65-9e69-c7fd258fe0c0","product_id":"BTC-USD","sequence":3342835808,"time":"2017-06-17T02:38:37.313000Z"}
{"type":"open","side":"sell","price":"2447.11000000","order_id":"2988df73-1eb0-49ef-9841-e2d97e9bf281","remaining_size":"0.10000000","product_id":"BTC-USD","sequence":3342835809,"time":"2017-06-17T02:38:37.313000Z"}
{"type":"received","order_id":"0c8f943b-4b62-4a4e-ba9d-85cca4e7196e","order_type":"limit","size":"0.20000000","price":"2449.16000000","side":"sell","client_oid":"b138bb8b-63fc-4767-bf75-7d060ecce98f","product_id":"BTC-USD","sequence":3342835810,"time":"2017-06-17T02:38:37.347000Z"}
{"type":"open","side":"sell","price":"2449.16000000","order_id":"0c8f943b-4b62-4a4e-ba9d-85cca4e7196e","remaining_size":"0.20000000","product_id":"BTC-USD","sequence":3342835811,"time":"2017-06-17T02:38:37.347000Z"}
{"type":"done","side":"sell","order_id":"2988df73-1eb0-49ef-9841-e2d97e9bf281","reason":"canceled","product_id":"BTC-USD","price":"2447.11000000","remaining_size":"0.10000000","sequence":3342835812,"time":"2017-06-17T02:38:37.350000Z"}
{"type":"received","order_id":"3c0ff503-2543-4934-8a51-b312ffdf22a7","order_type":"limit","size":"0.10000000","price":"2447.10000000","side":"sell","client_oid":"84a22dc5-5f5a-47ac-9868-07055e11575d","product_id":"BTC-USD","sequence":3342835813,"time":"2017-06-17T02:38:37.365000Z"}
{"type":"open","side":"sell","price":"2447.10000000","order_id":"3c0ff503-2543-4934-8a51-b312ffdf22a7","remaining_size":"0.10000000","product_id":"BTC-USD","sequence":3342835814,"time":"2017-06-17T02:38:37.365000Z"}
{"type":"received","order_id":"e048e77b-c562-4cf0-8034-d57ac8c1584a","order_type":"limit","size":"0.20000000","price":"2449.15000000","side":"sell","client_oid":"b78ca435-7dea-4869-9db3-718aec2f6343","product_id":"BTC-USD","sequence":3342835815,"time":"2017-06-17T02:38:37.377000Z"}
{"type":"open","side":"sell","price":"2449.15000000","order_id":"e048e77b-c562-4cf0-8034-d57ac8c1584a","remaining_size":"0.20000000","product_id":"BTC-USD","sequence":3342835816,"time":"2017-06-17T02:38:37.377000Z"}
{"type":"done","side":"sell","order_id":"0c8f943b-4b62-4a4e-ba9d-85cca4e7196e","reason":"canceled","product_id":"BTC-USD","price":"2449.16000000","remaining_size":"0.20000000","sequence":3342835817,"time":"2017-06-17T02:38:37.388000Z"}
{"type":"done","side":"sell","order_id":"3c0ff503-2543-4934-8a51-b312ffdf22a7","reason":"canceled","product_id":"BTC-USD","price":"2447.10000000","remaining_size":"0.10000000","sequence":3342835818,"time":"2017-06-17T02:38:37.391000Z"}
{"type":"received","order_id":"2e0a0d83-7ff8-4537-bb40-c1cb8c08dd5c","order_type":"limit","size":"0.10000000","price":"2447.09000000","side":"sell","client_oid":"a002b360-56ed-44a7-a072-65bf3ab373e8","product_id":"BTC-USD","sequence":3342835819,"time":"2017-06-17T02:38:37.401000Z"}
{"type":"open","side":"sell","price":"2447.09000000","order_id":"2e0a0d83-7ff8-4537-bb40-c1cb8c08dd5c","remaining_size":"0.10000000","product_id":"BTC-USD","sequence":3342835820,"time":"2017-06-17T02:38:37.401000Z"}
{"type":"done","side":"sell","order_id":"2e0a0d83-7ff8-4537-bb40-c1cb8c08dd5c","reason":"canceled","product_id":"BTC-USD","price":"2447.09000000","remaining_size":"0.10000000","sequence":3342835821,"time":"2017-06-17T02:38:37.406000Z"}
{"type":"done","side":"sell","order_id":"e048e77b-c562-4cf0-8034-d57ac8c1584a","reason":"canceled","product_id":"BTC-USD","price":"2449.15000000","remaining_size":"0.20000000","sequence":3342835822,"time":"2017-06-17T02:38:37.408000Z"}
{"type":"received","order_id":"51e92947-497c-47e2-b21f-82ea05722a35","order_type":"limit","size":"0.10000000","price":"2447.15000000","side":"sell","client_oid":"093982ac-f50a-4334-9349-e2ec3fd185f7","product_id":"BTC-USD","sequence":3342835823,"time":"2017-06-17T02:38:37.416000Z"}
{"type":"open","side":"sell","price":"2447.15000000","order_id":"51e92947-497c-47e2-b21f-82ea05722a35","remaining_size":"0.10000000","product_id":"BTC-USD","sequence":3342835824,"time":"2017-06-17T02:38:37.416000Z"}
{"type":"done","side":"sell","order_id":"51e92947-497c-47e2-b21f-82ea05722a35","reason":"canceled","product_id":"BTC-USD","price":"2447.15000000","remaining_size":"0.10000000","sequence":3342835825,"time":"2017-06-17T02:38:37.448000Z"}
{"type":"received","order_id":"1a2913e2-bc28-4571-befa-4e47fc74924e","order_type":"limit","size":"0.10000000","price":"2447.14000000","side":"sell","client_oid":"78f35eea-c17a-452a-a956-d9e61295e399","product_id":"BTC-USD","sequence":3342835826,"time":"2017-06-17T02:38:37.461000Z"}
{"type":"open","side":"sell","price":"2447.14000000","order_id":"1a2913e2-bc28-4571-befa-4e47fc74924e","remaining_size":"0.10000000","product_id":"BTC-USD","sequence":3342835827,"time":"2017-06-17T02:38:37.461000Z"}
{"type":"received","order_id":"f9d0527f-6f5f-44d8-bcdf-5ba357d3ce4e","order_type":"limit","size":"0.20000000","price":"2447.53000000","side":"sell","client_oid":"99d17d03-5168-46cd-8b14-b531778c9d39","product_id":"BTC-USD","sequence":3342835828,"time":"2017-06-17T02:38:37.474000Z"}
{"type":"open","side":"sell","price":"2447.53000000","order_id":"f9d0527f-6f5f-44d8-bcdf-5ba357d3ce4e","remaining_size":"0.20000000","product_id":"BTC-USD","sequence":3342835829,"time":"2017-06-17T02:38:37.474000Z"}
{"type":"done","side":"sell","order_id":"1a2913e2-bc28-4571-befa-4e47fc74924e","reason":"canceled","product_id":"BTC-USD","price":"2447.14000000","remaining_size":"0.10000000","sequence":3342835830,"time":"2017-06-17T02:38:37.496000Z"}
{"type":"done","side":"sell","order_id":"f9d0527f-6f5f-44d8-bcdf-5ba357d3ce4e","reason":"canceled","product_id":"BTC-USD","price":"2447.53000000","remaining_size":"0.20000000","sequence":3342835831,"time":"2017-06-17T02:38:37.497000Z"}
{"type":"received","order_id":"a9846035-11e1-4658-bfa9-b9cf0b6a5aff","order_type":"limit","size":"0.10000000","price":"2447.13000000","side":"sell","client_oid":"d7e25ebd-20ae-42e6-af25-b66dc26eb292","product_id":"BTC-USD","sequence":3342835832,"time":"2017-06-17T02:38:37.505000Z"}
{"type":"open","side":"sell","price":"2447.13000000","order_id":"a9846035-11e1-4658-bfa9-b9cf0b6a5aff","remaining_size":"0.10000000","product_id":"BTC-USD","sequence":3342835833,"time":"2017-06-17T02:38:37.505000Z"}
{"type":"received","order_id":"f0e9b1ff-4158-4657-be29-334da1dde63c","order_type":"limit","size":"0.20000000","price":"2447.52000000","side":"sell","client_oid":"959db473-5ec2-48f6-bdb4-9e9dfb715971","product_id":"BTC-USD","sequence":3342835834,"time":"2017-06-17T02:38:37.511000Z"}
{"type":"open","side":"sell","price":"2447.52000000","order_id":"f0e9b1ff-4158-4657-be29-334da1dde63c","remaining_size":"0.20000000","product_id":"BTC-USD","sequence":3342835835,"time":"2017-06-17T02:38:37.511000Z"}
{"type":"done","side":"sell","order_id":"f0e9b1ff-4158-4657-be29-334da1dde63c","reason":"canceled","product_id":"BTC-USD","price":"2447.52000000","remaining_size":"0.20000000","sequence":3342835836,"time":"2017-06-17T02:38:37.543000Z"}
{"type":"received","order_id":"7657fe50-5593-4c21-8982-5f23bd7db571","order_type":"limit","size":"0.10000000","price":"2447.12000000","side":"sell","client_oid":"8855d09b-6fb4-47c6-8ebb-f5a43798abbb","product_id":"BTC-USD","sequence":3342835837,"time":"2017-06-17T02:38:37.551000Z"}
{"type":"open","side":"sell","price":"2447.12000000","order_id":"7657fe50-5593-4c21-8982-5f23bd7db571","remaining_size":"0.10000000","product_id":"BTC-USD","sequence":3342835838,"time":"2017-06-17T02:38:37.551000Z"}
{"type":"done","side":"sell","order_id":"a9846035-11e1-4658-bfa9-b9cf0b6a5aff","reason":"canceled","product_id":"BTC-USD","price":"2447.13000000","remaining_size":"0.10000000","sequence":3342835839,"time":"2017-06-17T02:38:37.552000Z"}
{"type":"done","side":"sell","order_id":"7657fe50-5593-4c21-8982-5f23bd7db571","reason":"canceled","product_id":"BTC-USD","price":"2447.12000000","remaining_size":"0.10000000","sequence":3342835840,"time":"2017-06-17T02:38:37.588000Z"}
{"type":"received","order_id":"4a2b3d17-0e5d-4fa2-9d9d-d47fe3cec713","order_type":"limit","size":"0.90000000","price":"2434.05000000","side":"buy","product_id":"BTC-USD","sequence":3342835841,"time":"2017-06-17T02:38:37.596000Z"}
{"type":"open","side":"buy","price":"2434.05000000","order_id":"4a2b3d17-0e5d-4fa2-9d9d-d47fe3cec713","remaining_size":"0.90000000","product_id":"BTC-USD","sequence":3342835842,"time":"2017-06-17T02:38:37.596000Z"}
{"type":"received","order_id":"f14062ae-21f5-44f5-8ddf-0990157ace04","order_type":"limit","size":"0.10000000","price":"2447.15000000","side":"sell","client_oid":"c36534ce-e1fc-4b3b-82c9-3684e546d37f","product_id":"BTC-USD","sequence":3342835843,"time":"2017-06-17T02:38:37.638000Z"}
{"type":"open","side":"sell","price":"2447.15000000","order_id":"f14062ae-21f5-44f5-8ddf-0990157ace04","remaining_size":"0.10000000","product_id":"BTC-USD","sequence":3342835844,"time":"2017-06-17T02:38:37.638000Z"}
{"type":"received","order_id":"dc85cb6b-7bd8-4b64-90f6-c7314dcb2bab","order_type":"limit","size":"0.99000000","price":"2432.62000000","side":"buy","product_id":"BTC-USD","sequence":3342835845,"time":"2017-06-17T02:38:37.656000Z"}
{"type":"open","side":"buy","price":"2432.62000000","order_id":"dc85cb6b-7bd8-4b64-90f6-c7314dcb2bab","remaining_size":"0.99000000","product_id":"BTC-USD","sequence":3342835846,"time":"2017-06-17T02:38:37.656000Z"}
{"type":"done","side":"sell","order_id":"f14062ae-21f5-44f5-8ddf-0990157ace04","reason":"canceled","product_id":"BTC-USD","price":"2447.15000000","remaining_size":"0.10000000","sequence":3342835847,"time":"2017-06-17T02:38:37.669000Z"}
{"type":"received","order_id":"03e04de3-e06a-4bb7-bfb5-70845fe3a3a7","order_type":"limit","size":"0.10000000","price":"2447.14000000","side":"sell","client_oid":"203143fb-6e3e-4845-84b7-7d1ddb479386","product_id":"BTC-USD","sequence":3342835848,"time":"2017-06-17T02:38:37.683000Z"}
{"type":"open","side":"sell","price":"2447.14000000","order_id":"03e04de3-e06a-4bb7-bfb5-70845fe3a3a7","remaining_size":"0.10000000","product_id":"BTC-USD","sequence":3342835849,"time":"2017-06-17T02:38:37.683000Z"}
{"type":"done","side":"sell","order_id":"4c5aa3cf-4c95-4df0-beb5-9cf328091936","reason":"canceled","product_id":"BTC-USD","price":"2506.62000000","remaining_size":"0.55481002","sequence":3342835850,"time":"2017-06-17T02:38:37.706000Z"}
{"type":"done","side":"sell","order_id":"d9928b44-3f24-4801-91dc-7af125363c39","reason":"canceled","product_id":"BTC-USD","price":"2502.83000000","remaining_size":"0.18922657","sequence":3342835851,"time":"2017-06-17T02:38:37.707000Z"}
{"type":"done","side":"buy","order_id":"aca54458-c27e-4dd2-9729-a5ed372c702d","reason":"canceled","product_id":"BTC-USD","price":"2387.23000000","remaining_size":"1.19725898","sequence":3342835852,"time":"2017-06-17T02:38:37.710000Z"}
{"type":"done","side":"sell","order_id":"407e80fc-ef5f-41f2-a786-f408c9cd9101","reason":"canceled","product_id":"BTC-USD","price":"2515.80000000","remaining_size":"1.39903846","sequence":3342835853,"time":"2017-06-17T02:38:37.711000Z"}
{"type":"received","order_id":"96b508a6-ff03-4748-9e84-00f888de8602","order_type":"limit","size":"0.95718725","price":"2386.17000000","side":"buy","client_oid":"10e34b10-5306-11e7-9773-3f851d7e1e98","product_id":"BTC-USD","sequence":3342835854,"time":"2017-06-17T02:38:37.715000Z"}
{"type":"open","side":"buy","price":"2386.17000000","order_id":"96b508a6-ff03-4748-9e84-00f888de8602","remaining_size":"0.95718725","product_id":"BTC-USD","sequence":3342835855,"time":"2017-06-17T02:38:37.715000Z"}
{"type":"received","order_id":"87d62924-c6af-4fbb-aa4c-e62fa67e01ff","order_type":"limit","size":"2.32200204","price":"2366.01000000","side":"buy","client_oid":"10e34b13-5306-11e7-9773-3f851d7e1e98","product_id":"BTC-USD","sequence":3342835856,"time":"2017-06-17T02:38:37.721000Z"}
{"type":"open","side":"buy","price":"2366.01000000","order_id":"87d62924-c6af-4fbb-aa4c-e62fa67e01ff","remaining_size":"2.32200204","product_id":"BTC-USD","sequence":3342835857,"time":"2017-06-17T02:38:37.721000Z"}
{"type":"received","order_id":"ff8a1cd3-97e4-4ea7-9a3f-719b0598668b","order_type":"limit","size":"0.10000000","price":"2447.13000000","side":"sell","client_oid":"e64752a2-7fd5-4b2c-a2e1-74f82a989c24","product_id":"BTC-USD","sequence":3342835858,"time":"2017-06-17T02:38:37.724000Z"}
{"type":"open","side":"sell","price":"2447.13000000","order_id":"ff8a1cd3-97e4-4ea7-9a3f-719b0598668b","remaining_size":"0.10000000","product_id":"BTC-USD","sequence":3342835859,"time":"2017-06-17T02:38:37.724000Z"}
{"type":"received","order_id":"da349c1d-13f0-4dd1-bf5f-d13707baaa07","order_type":"limit","size":"1.20844079","price":"2514.87000000","side":"sell","client_oid":"10e2fcf1-5306-11e7-9773-3f851d7e1e98","product_id":"BTC-USD","sequence":3342835860,"time":"2017-06-17T02:38:37.727000Z"}
{"type":"open","side":"sell","price":"2514.87000000","order_id":"da349c1d-13f0-4dd1-bf5f-d13707baaa07","remaining_size":"1.20844079","product_id":"BTC-USD","sequence":3342835861,"time":"2017-06-17T02:38:37.727000Z"}
{"type":"done","side":"sell","order_id":"03e04de3-e06a-4bb7-bfb5-70845fe3a3a7","reason":"canceled","product_id":"BTC-USD","price":"2447.14000000","remaining_size":"0.10000000","sequence":3342835862,"time":"2017-06-17T02:38:37.728000Z"}
{"type":"done","side":"buy","order_id":"efd25bb1-30ba-4abf-9123-b5fc2085d2ac","reason":"canceled","product_id":"BTC-USD","price":"2383.36000000","remaining_size":"2.05843115","sequence":3342835863,"time":"2017-06-17T02:38:37.728000Z"}
{"type":"done","side":"buy","order_id":"3f9deb43-3806-4ed0-9dd7-035de59de7f4","reason":"canceled","product_id":"BTC-USD","price":"2378.61000000","remaining_size":"2.74959901","sequence":3342835864,"time":"2017-06-17T02:38:37.730000Z"}
{"type":"done","side":"buy","order_id":"35fc80d0-604a-450d-b703-767a51f564b2","reason":"canceled","product_id":"BTC-USD","price":"2366.75000000","remaining_size":"1.83209630","sequence":3342835865,"time":"2017-06-17T02:38:37.732000Z"}
{"type":"received","order_id":"785e2ee3-da80-429f-8b78-455d78478da8","order_type":"limit","size":"0.26664516","price":"2502.05000000","side":"sell","client_oid":"10e2d5e0-5306-11e7-9773-3f851d7e1e98","product_id":"BTC-USD","sequence":3342835866,"time":"2017-06-17T02:38:37.734000Z"}
{"type":"open","side":"sell","price":"2502.05000000","order_id":"785e2ee3-da80-429f-8b78-455d78478da8","remaining_size":"0.26664516","product_id":"BTC-USD","sequence":3342835867,"time":"2017-06-17T02:38:37.734000Z"}
{"type":"received","order_id":"ef496c46-6239-480a-931a-0aa19e43bcd9","order_type":"limit","size":"0.99000000","price":"2431.35000000","side":"buy","product_id":"BTC-USD","sequence":3342835868,"time":"2017-06-17T02:38:37.734000Z"}
{"type":"open","side":"buy","price":"2431.35000000","order_id":"ef496c46-6239-480a-931a-0aa19e43bcd9","remaining_size":"0.99000000","product_id":"BTC-USD","sequence":3342835869,"time":"2017-06-17T02:38:37.734000Z"}
{"type":"done","side":"sell","order_id":"ff8a1cd3-97e4-4ea7-9a3f-719b0598668b","reason":"canceled","product_id":"BTC-USD","price":"2447.13000000","remaining_size":"0.10000000","sequence":3342835870,"time":"2017-06-17T02:38:37.734000Z"}
{"type":"received","order_id":"6239a44c-9c3e-449a-b61c-19b2927aa581","order_type":"limit","size":"2.42960292","price":"2378.10000000","side":"buy","client_oid":"10e34b12-5306-11e7-9773-3f851d7e1e98","product_id":"BTC-USD","sequence":3342835871,"time":"2017-06-17T02:38:37.737000Z"}
{"type":"open","side":"buy","price":"2378.10000000","order_id":"6239a44c-9c3e-449a-b61c-19b2927aa581","remaining_size":"2.42960292","product_id":"BTC-USD","sequence":3342835872,"time":"2017-06-17T02:38:37.737000Z"}
{"type":"received","order_id":"48e9b8ae-28e9-4b15-bc88-04e45b465ced","order_type":"limit","size":"0.53325511","price":"2505.86000000","side":"sell","client_oid":"10e2fcf0-5306-11e7-9773-3f851d7e1e98","product_id":"BTC-USD","sequence":3342835873,"time":"2017-06-17T02:38:37.743000Z"}
{"type":"open","side":"sell","price":"2505.86000000","order_id":"48e9b8ae-28e9-4b15-bc88-04e45b465ced","remaining_size":"0.53325511","product_id":"BTC-USD","sequence":3342835874,"time":"2017-06-17T02:38:37.743000Z"}
{"type":"received","order_id":"c6b82743-11e4-43dd-9f38-3e1d9a7fe1e7","order_type":"limit","size":"1.54972944","price":"2382.57000000","side":"buy","client_oid":"10e34b11-5306-11e7-9773-3f851d7e1e98","product_id":"BTC-USD","sequence":3342835875,"time":"2017-06-17T02:38:37.748000Z"}
{"type":"open","side":"buy","price":"2382.57000000","order_id":"c6b82743-11e4-43dd-9f38-3e1d9a7fe1e7","remaining_size":"1.54972944","product_id":"BTC-USD","sequence":3342835876,"time":"2017-06-17T02:38:37.748000Z"}
{"type":"received","order_id":"14e89939-b6c9-4063-8ad7-a29f86478af8","order_type":"limit","size":"1.38000000","price":"2430.62000000","side":"buy","product_id":"BTC-USD","sequence":3342835877,"time":"2017-06-17T02:38:37.800000Z"}
{"type":"open","side":"buy","price":"2430.62000000","order_id":"14e89939-b6c9-4063-8ad7-a29f86478af8","remaining_size":"1.38000000","product_id":"BTC-USD","sequence":3342835878,"time":"2017-06-17T02:38:37.800000Z"}
{"type":"received","order_id":"fd9907c3-2ac2-4399-b56d-65777132577a","order_type":"limit","size":"0.10000000","price":"2447.15000000","side":"sell","client_oid":"6679b0b4-266f-4296-903e-dd775acb6f8c","product_id":"BTC-USD","sequence":3342835879,"time":"2017-06-17T02:38:37.810000Z"}
{"type":"open","side":"sell","price":"2447.15000000","order_id":"fd9907c3-2ac2-4399-b56d-65777132577a","remaining_size":"0.10000000","product_id":"BTC-USD","sequence":3342835880,"time":"2017-06-17T02:38:37.810000Z"}
{"type":"received","order_id":"603a6c7f-7863-45f7-903c-b5bf42bb8540","order_type":"limit","size":"0.08985400","price":"2449.17000000","side":"sell","client_oid":"444d517e-7c93-427d-b8e7-4ea4e70c7e75","product_id":"BTC-USD","sequence":3342835881,"time":"2017-06-17T02:38:37.815000Z"}
{"type":"open","side":"sell","price":"2449.17000000","order_id":"603a6c7f-7863-45f7-903c-b5bf42bb8540","remaining_size":"0.08985400","product_id":"BTC-USD","sequence":3342835882,"time":"2017-06-17T02:38:37.815000Z"}
{"type":"done","side":"sell","order_id":"603a6c7f-7863-45f7-903c-b5bf42bb8540","reason":"canceled","product_id":"BTC-USD","price":"2449.17000000","remaining_size":"0.08985400","sequence":3342835883,"time":"2017-06-17T02:38:37.856000Z"}
{"type":"received","order_id":"754c35f2-2c54-4e51-8709-4070a6fb67b3","order_type":"limit","size":"0.08985400","price":"2447.53000000","side":"sell","client_oid":"cb5da9a0-7f41-41ca-be7d-2ab40f0cb1e0","product_id":"BTC-USD","sequence":3342835884,"time":"2017-06-17T02:38:37.858000Z"}
{"type":"open","side":"sell","price":"2447.53000000","order_id":"754c35f2-2c54-4e51-8709-4070a6fb67b3","remaining_size":"0.08985400","product_id":"BTC-USD","sequence":3342835885,"time":"2017-06-17T02:38:37.858000Z"}
{"type":"received","order_id":"7baa419c-0abb-4549-aebb-9e602e3af79d","order_type":"limit","size":"0.10000000","price":"2447.14000000","side":"sell","client_oid":"90dc674c-51ad-4ade-b450-537afa5d4f14","product_id":"BTC-USD","sequence":3342835886,"time":"2017-06-17T02:38:37.864000Z"}
{"type":"open","side":"sell","price":"2447.14000000","order_id":"7baa419c-0abb-4549-aebb-9e602e3af79d","remaining_size":"0.10000000","product_id":"BTC-USD","sequence":3342835887,"time":"2017-06-17T02:38:37.864000Z"}
{"type":"done","side":"sell","order_id":"fd9907c3-2ac2-4399-b56d-65777132577a","reason":"canceled","product_id":"BTC-USD","price":"2447.15000000","remaining_size":"0.10000000","sequence":3342835888,"time":"2017-06-17T02:38:37.865000Z"}
{"type":"done","side":"sell","order_id":"7baa419c-0abb-4549-aebb-9e602e3af79d","reason":"canceled","product_id":"BTC-USD","price":"2447.14000000","remaining_size":"0.10000000","sequence":3342835889,"time":"2017-06-17T02:38:37.889000Z"}
{"type":"received","order_id":"61698f19-eefa-4c5c-9834-4c6ce4837c86","order_type":"limit","size":"0.10000000","price":"2447.14000000","side":"sell","client_oid":"d134f322-22cc-4a1c-9e07-37d758b789ea","product_id":"BTC-USD","sequence":3342835890,"time":"2017-06-17T02:38:37.913000Z"}
{"type":"open","side":"sell","price":"2447.14000000","order_id":"61698f19-eefa-4c5c-9834-4c6ce4837c86","remaining_size":"0.10000000","product_id":"BTC-USD","sequence":3342835891,"time":"2017-06-17T02:38:37.913000Z"}
{"type":"received","order_id":"83cba5cf-9bde-41d5-800d-7dcc1276c796","order_type":"limit","size":"0.75000000","price":"2429.97000000","side":"buy","product_id":"BTC-USD","sequence":3342835892,"time":"2017-06-17T02:38:37.915000Z"}
{"type":"open","side":"buy","price":"2429.97000000","order_id":"83cba5cf-9bde-41d5-800d-7dcc1276c796","remaining_size":"0.75000000","product_id":"BTC-USD","sequence":3342835893,"time":"2017-06-17T02:38:37.915000Z"}
{"type":"done","side":"sell","order_id":"754c35f2-2c54-4e51-8709-4070a6fb67b3","reason":"canceled","product_id":"BTC-USD","price":"2447.53000000","remaining_size":"0.08985400","sequence":3342835894,"time":"2017-06-17T02:38:37.921000Z"}
{"type":"received","order_id":"a14bb14f-617c-4fb6-aa75-5deb0833cfbb","order_type":"limit","size":"0.08985400","price":"2447.52000000","side":"sell","client_oid":"fd3532cc-ee7c-4417-9c33-f4db6415394d","product_id":"BTC-USD","sequence":3342835895,"time":"2017-06-17T02:38:37.926000Z"}
{"type":"open","side":"sell","price":"2447.52000000","order_id":"a14bb14f-617c-4fb6-aa75-5deb0833cfbb","remaining_size":"0.08985400","product_id":"BTC-USD","sequence":3342835896,"time":"2017-06-17T02:38:37.926000Z"}
{"type":"done","side":"sell","order_id":"61698f19-eefa-4c5c-9834-4c6ce4837c86","reason":"canceled","product_id":"BTC-USD","price":"2447.14000000","remaining_size":"0.10000000","sequence":3342835897,"time":"2017-06-17T02:38:37.941000Z"}
{"type":"received","order_id":"35af94b5-9056-438e-b0f6-ee3301c93bc3","order_type":"limit","size":"0.10000000","price":"2447.13000000","side":"sell","client_oid":"19fadee1-12ac-4759-8b0c-8335ab9c2da0","product_id":"BTC-USD","sequence":3342835898,"time":"2017-06-17T02:38:37.947000Z"}
{"type":"open","side":"sell","price":"2447.13000000","order_id":"35af94b5-9056-438e-b0f6-ee3301c93bc3","remaining_size":"0.10000000","product_id":"BTC-USD","sequence":3342835899,"time":"2017-06-17T02:38:37.947000Z"}
{"type":"done","side":"sell","order_id":"a14bb14f-617c-4fb6-aa75-5deb0833cfbb","reason":"canceled","product_id":"BTC-USD","price":"2447.52000000","remaining_size":"0.08985400","sequence":3342835900,"time":"2017-06-17T02:38:37.948000Z"}
{"type":"received","order_id":"8b994c6e-c149-4caa-a631-43b481a5df7f","order_type":"limit","size":"0.08985400","price":"2447.53000000","side":"sell","client_oid":"c585b2ac-2906-4b01-b983-fb6977d5ffa2","product_id":"BTC-USD","sequence":3342835901,"time":"2017-06-17T02:38:37.956000Z"}
{"type":"open","side":"sell","price":"2447.53000000","order_id":"8b994c6e-c149-4caa-a631-43b481a5df7f","remaining_size":"0.08985400","product_id":"BTC-USD","sequence":3342835902,"time":"2017-06-17T02:38:37.956000Z"}
{"type":"done","side":"sell","order_id":"8b994c6e-c149-4caa-a631-43b481a5df7f","reason":"canceled","product_id":"BTC-USD","price":"2447.53000000","remaining_size":"0.08985400","sequence":3342835903,"time":"2017-06-17T02:38:37.978000Z"}
{"type":"done","side":"sell","order_id":"35af94b5-9056-438e-b0f6-ee3301c93bc3","reason":"canceled","product_id":"BTC-USD","price":"2447.13000000","remaining_size":"0.10000000","sequence":3342835904,"time":"2017-06-17T02:38:37.997000Z"}
{"type":"received","order_id":"a4d73964-81f1-4f56-a615-f3d27c27e290","order_type":"limit","size":"0.10000000","price":"2447.15000000","side":"sell","client_oid":"540a2d47-57e5-43fc-9450-c256a6ad3f55","product_id":"BTC-USD","sequence":3342835905,"time":"2017-06-17T02:38:38.000000Z"}
{"type":"open","side":"sell","price":"2447.15000000","order_id":"a4d73964-81f1-4f56-a615-f3d27c27e290","remaining_size":"0.10000000","product_id":"BTC-USD","sequence":3342835906,"time":"2017-06-17T02:38:38.000000Z"}
{"type":"done","side":"sell","order_id":"a4d73964-81f1-4f56-a615-f3d27c27e290","reason":"canceled","product_id":"BTC-USD","price":"2447.15000000","remaining_size":"0.10000000","sequence":3342835907,"time":"2017-06-17T02:38:38.021000Z"}
{"type":"received","order_id":"2c57d1cb-7cfd-42ca-b34a-e0f613926479","order_type":"limit","size":"2.45000000","price":"2454.61000000","side":"sell","product_id":"BTC-USD","sequence":3342835908,"time":"2017-06-17T02:38:38.024000Z"}
{"type":"open","side":"sell","price":"2454.61000000","order_id":"2c57d1cb-7cfd-42ca-b34a-e0f613926479","remaining_size":"2.45000000","product_id":"BTC-USD","sequence":3342835909,"time":"2017-06-17T02:38:38.024000Z"}
{"type":"received","order_id":"b2d2388b-32f2-4663-bfd2-c3ef6ec85ac3","order_type":"limit","size":"0.08985400","price":"2447.53000000","side":"sell","client_oid":"c34f0b9e-ec7c-4829-8ea9-482fbbca19c8","product_id":"BTC-USD","sequence":3342835910,"time":"2017-06-17T02:38:38.030000Z"}
{"type":"open","side":"sell","price":"2447.53000000","order_id":"b2d2388b-32f2-4663-bfd2-c3ef6ec85ac3","remaining_size":"0.08985400","product_id":"BTC-USD","sequence":3342835911,"time":"2017-06-17T02:38:38.030000Z"}
{"type":"received","order_id":"3608f37f-fbbe-4213-b52f-e79da16d00ea","order_type":"limit","size":"0.10000000","price":"2447.15000000","side":"sell","client_oid":"f7fdc164-af88-49a0-854d-d128d5c342bf","product_id":"BTC-USD","sequence":3342835912,"time":"2017-06-17T02:38:38.039000Z"}
{"type":"open","side":"sell","price":"2447.15000000","order_id":"3608f37f-fbbe-4213-b52f-e79da16d00ea","remaining_size":"0.10000000","product_id":"BTC-USD","sequence":3342835913,"time":"2017-06-17T02:38:38.039000Z"}
{"type":"done","side":"sell","order_id":"b2d2388b-32f2-4663-bfd2-c3ef6ec85ac3","reason":"canceled","product_id":"BTC-USD","price":"2447.53000000","remaining_size":"0.08985400","sequence":3342835914,"time":"2017-06-17T02:38:38.057000Z"}
{"type":"received","order_id":"641919b4-291f-47fc-a75b-87b54ca031a4","order_type":"limit","size":"0.08985400","price":"2448.77000000","side":"sell","client_oid":"1ad88def-57cb-4b60-b5da-143151ac6300","product_id":"BTC-USD","sequence":3342835915,"time":"2017-06-17T02:38:38.073000Z"}
{"type":"open","side":"sell","price":"2448.77000000","order_id":"641919b4-291f-47fc-a75b-87b54ca031a4","remaining_size":"0.08985400","product_id":"BTC-USD","sequence":3342835916,"time":"2017-06-17T02:38:38.073000Z"}
{"type":"received","order_id":"278f84ad-d12c-4839-a4cb-617c327460bc","order_type":"limit","size":"1.27000000","price":"2454.63000000","side":"sell","product_id":"BTC-USD","sequence":3342835917,"time":"2017-06-17T02:38:38.095000Z"}
{"type":"open","side":"sell","price":"2454.63000000","order_id":"278f84ad-d12c-4839-a4cb-617c327460bc","remaining_size":"1.27000000","product_id":"BTC-USD","sequence":3342835918,"time":"2017-06-17T02:38:38.095000Z"}
{"type":"received","order_id":"259050b0-4082-4ee7-97bf-d0efaa035f3d","order_type":"limit","size":"0.10000000","price":"2447.14000000","side":"sell","client_oid":"2bde3ae0-4f2b-4f46-9d80-080744f54c12","product_id":"BTC-USD","sequence":3342835919,"time":"2017-06-17T02:38:38.100000Z"}
{"type":"open","side":"sell","price":"2447.14000000","order_id":"259050b0-4082-4ee7-97bf-d0efaa035f3d","remaining_size":"0.10000000","product_id":"BTC-USD","sequence":3342835920,"time":"2017-06-17T02:38:38.100000Z"}
{"type":"done","side":"sell","order_id":"3608f37f-fbbe-4213-b52f-e79da16d00ea","reason":"canceled","product_id":"BTC-USD","price":"2447.15000000","remaining_size":"0.10000000","sequence":3342835921,"time":"2017-06-17T02:38:38.103000Z"}
{"type":"received","order_id":"d4e2128e-7564-4c3c-a133-ff8d5e407564","order_type":"limit","size":"0.04000000","price":"2484.71000000","side":"sell","product_id":"BTC-USD","sequence":3342835922,"time":"2017-06-17T02:38:38.105000Z"}
{"type":"open","side":"sell","price":"2484.71000000","order_id":"d4e2128e-7564-4c3c-a133-ff8d5e407564","remaining_size":"0.04000000","product_id":"BTC-USD","sequence":3342835923,"time":"2017-06-17T02:38:38.105000Z"}
{"type":"done","side":"sell","order_id":"641919b4-291f-47fc-a75b-87b54ca031a4","reason":"canceled","product_id":"BTC-USD","price":"2448.77000000","remaining_size":"0.08985400","sequence":3342835924,"time":"2017-06-17T02:38:38.109000Z"}
{"type":"received","order_id":"c0f49dec-5ae0-4b41-92f8-3d119a547391","order_type":"limit","size":"0.08985400","price":"2447.53000000","side":"sell","client_oid":"0850361f-2d74-4f12-9327-082d8dc5b412","product_id":"BTC-USD","sequence":3342835925,"time":"2017-06-17T02:38:38.122000Z"}
{"type":"open","side":"sell","price":"2447.53000000","order_id":"c0f49dec-5ae0-4b41-92f8-3d119a547391","remaining_size":"0.08985400","product_id":"BTC-USD","sequence":3342835926,"time":"2017-06-17T02:38:38.122000Z"}
{"type":"done","side":"sell","order_id":"259050b0-4082-4ee7-97bf-d0efaa035f3d","reason":"canceled","product_id":"BTC-USD","price":"2447.14000000","remaining_size":"0.10000000","sequence":3342835927,"time":"2017-06-17T02:38:38.140000Z"}
{"type":"received","order_id":"21bf3bfe-1597-43f7-9f1c-4930623845ed","order_type":"limit","size":"0.10000000","price":"2447.13000000","side":"sell","client_oid":"415e4a09-5d24-4b97-b7e1-c41fac9800ca","product_id":"BTC-USD","sequence":3342835928,"time":"2017-06-17T02:38:38.154000Z"}
{"type":"open","side":"sell","price":"2447.13000000","order_id":"21bf3bfe-1597-43f7-9f1c-4930623845ed","remaining_size":"0.10000000","product_id":"BTC-USD","sequence":3342835929,"time":"2017-06-17T02:38:38.154000Z"}
{"type":"done","side":"sell","order_id":"c0f49dec-5ae0-4b41-92f8-3d119a547391","reason":"canceled","product_id":"BTC-USD","price":"2447.53000000","remaining_size":"0.08985400","sequence":3342835930,"time":"2017-06-17T02:38:38.156000Z"}
{"type":"received","order_id":"c1e2bf04-c1c5-4311-a5f3-dba8223d2305","order_type":"limit","size":"0.08985400","price":"2448.77000000","side":"sell","client_oid":"acf87d3f-4da7-4f9c-87bd-0e4fec04a1f3","product_id":"BTC-USD","sequence":3342835931,"time":"2017-06-17T02:38:38.166000Z"}
{"type":"open","side":"sell","price":"2448.77000000","order_id":"c1e2bf04-c1c5-4311-a5f3-dba8223d2305","remaining_size":"0.08985400","product_id":"BTC-USD","sequence":3342835932,"time":"2017-06-17T02:38:38.166000Z"}
{"type":"received","order_id":"2c529927-3f9a-476c-82ff-2c738b77a4e0","order_type":"limit","size":"1.28000000","price":"2455.97000000","side":"sell","product_id":"BTC-USD","sequence":3342835933,"time":"2017-06-17T02:38:38.169000Z"}
{"type":"open","side":"sell","price":"2455.97000000","order_id":"2c529927-3f9a-476c-82ff-2c738b77a4e0","remaining_size":"1.28000000","product_id":"BTC-USD","sequence":3342835934,"time":"2017-06-17T02:38:38.169000Z"}
{"type":"done","side":"sell","order_id":"21bf3bfe-1597-43f7-9f1c-4930623845ed","reason":"canceled","product_id":"BTC-USD","price":"2447.13000000","remaining_size":"0.10000000","sequence":3342835935,"time":"2017-06-17T02:38:38.187000Z"}
{"type":"received","order_id":"96706e42-38bd-4100-a25e-69f944f4ad8c","order_type":"limit","size":"0.10000000","price":"2447.12000000","side":"sell","client_oid":"f93c731c-d8b6-4c19-8817-d2fee65693ca","product_id":"BTC-USD","sequence":3342835936,"time":"2017-06-17T02:38:38.196000Z"}
{"type":"open","side":"sell","price":"2447.12000000","order_id":"96706e42-38bd-4100-a25e-69f944f4ad8c","remaining_size":"0.10000000","product_id":"BTC-USD","sequence":3342835937,"time":"2017-06-17T02:38:38.196000Z"}
{"type":"done","side":"sell","order_id":"c1e2bf04-c1c5-4311-a5f3-dba8223d2305","reason":"canceled","product_id":"BTC-USD","price":"2448.77000000","remaining_size":"0.08985400","sequence":3342835938,"time":"2017-06-17T02:38:38.208000Z"}
{"type":"received","order_id":"77dcbf54-b7ae-4b44-b28d-82f6fcaec8ad","order_type":"limit","size":"0.08985400","price":"2447.53000000","side":"sell","client_oid":"733da69d-a2fe-46d8-b11c-becfd8b8e989","product_id":"BTC-USD","sequence":3342835939,"time":"2017-06-17T02:38:38.216000Z"}
{"type":"open","side":"sell","price":"2447.53000000","order_id":"77dcbf54-b7ae-4b44-b28d-82f6fcaec8ad","remaining_size":"0.08985400","product_id":"BTC-USD","sequence":3342835940,"time":"2017-06-17T02:38:38.216000Z"}
{"type":"done","side":"sell","order_id":"96706e42-38bd-4100-a25e-69f944f4ad8c","reason":"canceled","product_id":"BTC-USD","price":"2447.12000000","remaining_size":"0.10000000","sequence":3342835941,"time":"2017-06-17T02:38:38.228000Z"}
{"type":"received","order_id":"a528149f-70e9-4db0-944d-a2b2e6a5860f","order_type":"limit","size":"0.10000000","price":"2447.11000000","side":"sell","client_oid":"80ba932b-18f3-4ffe-82b4-4e53be138e92","product_id":"BTC-USD","sequence":3342835942,"time":"2017-06-17T02:38:38.235000Z"}
{"type":"open","side":"sell","price":"2447.11000000","order_id":"a528149f-70e9-4db0-944d-a2b2e6a5860f","remaining_size":"0.10000000","product_id":"BTC-USD","sequence":3342835943,"time":"2017-06-17T02:38:38.235000Z"}
{"type":"done","side":"sell","order_id":"77dcbf54-b7ae-4b44-b28d-82f6fcaec8ad","reason":"canceled","product_id":"BTC-USD","price":"2447.53000000","remaining_size":"0.08985400","sequence":3342835944,"time":"2017-06-17T02:38:38.252000Z"}
{"type":"received","order_id":"9e445d1f-6f98-4e92-be1d-0d57f0b8e301","order_type":"limit","size":"0.08985400","price":"2448.77000000","side":"sell","client_oid":"768efb68-b478-4796-a342-44c26a96e275","product_id":"BTC-USD","sequence":3342835945,"time":"2017-06-17T02:38:38.263000Z"}
{"type":"open","side":"sell","price":"2448.77000000","order_id":"9e445d1f-6f98-4e92-be1d-0d57f0b8e301","remaining_size":"0.08985400","product_id":"BTC-USD","sequence":3342835946,"time":"2017-06-17T02:38:38.263000Z"}
{"type":"received","order_id":"f2afeb35-a918-492a-9124-fe9f82a722ec","order_type":"limit","size":"0.25000000","price":"2442.77000000","side":"buy","client_oid":"29e3ff8b-9b91-42e0-959b-2a95329ac339","product_id":"BTC-USD","sequence":3342835947,"time":"2017-06-17T02:38:38.266000Z"}
{"type":"open","side":"buy","price":"2442.77000000","order_id":"f2afeb35-a918-492a-9124-fe9f82a722ec","remaining_size":"0.25000000","product_id":"BTC-USD","sequence":3342835948,"time":"2017-06-17T02:38:38.266000Z"}
{"type":"done","side":"sell","order_id":"a528149f-70e9-4db0-944d-a2b2e6a5860f","reason":"canceled","product_id":"BTC-USD","price":"2447.11000000","remaining_size":"0.10000000","sequence":3342835949,"time":"2017-06-17T02:38:38.269000Z"}
{"type":"received","order_id":"a26bb729-21f5-43ea-ba75-334e2e4bfd25","order_type":"limit","size":"0.10000000","price":"2447.10000000","side":"sell","client_oid":"d19a1dd0-f2a2-483a-8923-895966bdc37c","product_id":"BTC-USD","sequence":3342835950,"time":"2017-06-17T02:38:38.288000Z"}
{"type":"open","side":"sell","price":"2447.10000000","order_id":"a26bb729-21f5-43ea-ba75-334e2e4bfd25","remaining_size":"0.10000000","product_id":"BTC-USD","sequence":3342835951,"time":"2017-06-17T02:38:38.288000Z"}
{"type":"done","side":"sell","order_id":"9e445d1f-6f98-4e92-be1d-0d57f0b8e301","reason":"canceled","product_id":"BTC-USD","price":"2448.77000000","remaining_size":"0.08985400","sequence":3342835952,"time":"2017-06-17T02:38:38.297000Z"}
{"type":"received","order_id":"3b485655-abe4-49c2-8cc7-1506ff9b6437","order_type":"limit","size":"0.08985400","price":"2447.53000000","side":"sell","client_oid":"f962d1fb-161a-40fd-9d94-3ed2560acdff","product_id":"BTC-USD","sequence":3342835953,"time":"2017-06-17T02:38:38.305000Z"}
{"type":"open","side":"sell","price":"2447.53000000","order_id":"3b485655-abe4-49c2-8cc7-1506ff9b6437","remaining_size":"0.08985400","product_id":"BTC-USD","sequence":3342835954,"time":"2017-06-17T02:38:38.305000Z"}
{"type":"done","side":"sell","order_id":"a26bb729-21f5-43ea-ba75-334e2e4bfd25","reason":"canceled","product_id":"BTC-USD","price":"2447.10000000","remaining_size":"0.10000000","sequence":3342835955,"time":"2017-06-17T02:38:38.313000Z"}
{"type":"received","order_id":"988f0f45-202d-4c29-aabc-5f4f48d9fa27","order_type":"limit","size":"0.10000000","price":"2447.09000000","side":"sell","client_oid":"ecda4588-9c0c-4c88-b2f0-1754d697dd2b","product_id":"BTC-USD","sequence":3342835956,"time":"2017-06-17T02:38:38.323000Z"}
{"type":"open","side":"sell","price":"2447.09000000","order_id":"988f0f45-202d-4c29-aabc-5f4f48d9fa27","remaining_size":"0.10000000","product_id":"BTC-USD","sequence":3342835957,"time":"2017-06-17T02:38:38.323000Z"}
{"type":"received","order_id":"e86bfd32-7817-4df2-8bcc-38c6969eb93b","order_type":"limit","size":"0.20000000","price":"2448.77000000","side":"sell","client_oid":"523bec44-094a-4a78-a18b-7e1d10a88b99","product_id":"BTC-USD","sequence":3342835958,"time":"2017-06-17T02:38:38.344000Z"}
{"type":"open","side":"sell","price":"2448.77000000","order_id":"e86bfd32-7817-4df2-8bcc-38c6969eb93b","remaining_size":"0.20000000","product_id":"BTC-USD","sequence":3342835959,"time":"2017-06-17T02:38:38.344000Z"}
{"type":"done","side":"sell","order_id":"3b485655-abe4-49c2-8cc7-1506ff9b6437","reason":"canceled","product_id":"BTC-USD","price":"2447.53000000","remaining_size":"0.08985400","sequence":3342835960,"time":"2017-06-17T02:38:38.346000Z"}
{"type":"done","side":"sell","order_id":"e86bfd32-7817-4df2-8bcc-38c6969eb93b","reason":"canceled","product_id":"BTC-USD","price":"2448.77000000","remaining_size":"0.20000000","sequence":3342835961,"time":"2017-06-17T02:38:38.348000Z"}
{"type":"received","order_id":"bfa44c13-515e-4e4d-bcfd-92347f5c47de","order_type":"limit","size":"0.08985400","price":"2448.77000000","side":"sell","client_oid":"745bb630-ef2d-4f4a-be32-5b14c218e1be","product_id":"BTC-USD","sequence":3342835962,"time":"2017-06-17T02:38:38.349000Z"}
{"type":"open","side":"sell","price":"2448.77000000","order_id":"bfa44c13-515e-4e4d-bcfd-92347f5c47de","remaining_size":"0.08985400","product_id":"BTC-USD","sequence":3342835963,"time":"2017-06-17T02:38:38.349000Z"}
{"type":"done","side":"sell","order_id":"988f0f45-202d-4c29-aabc-5f4f48d9fa27","reason":"canceled","product_id":"BTC-USD","price":"2447.09000000","remaining_size":"0.10000000","sequence":3342835964,"time":"2017-06-17T02:38:38.349000Z"}
{"type":"done","side":"buy","order_id":"f2afeb35-a918-492a-9124-fe9f82a722ec","reason":"canceled","product_id":"BTC-USD","price":"2442.77000000","remaining_size":"0.25000000","sequence":3342835965,"time":"2017-06-17T02:38:38.356000Z"}
{"type":"received","order_id":"db5ac5cc-c41c-4b92-83c6-0a7cfd4c5a89","order_type":"limit","size":"0.20000000","price":"2447.53000000","side":"sell","client_oid":"c8e065c0-a729-43a8-82dc-41ae14ab60b7","product_id":"BTC-USD","sequence":3342835966,"time":"2017-06-17T02:38:38.363000Z"}
{"type":"open","side":"sell","price":"2447.53000000","order_id":"db5ac5cc-c41c-4b92-83c6-0a7cfd4c5a89","remaining_size":"0.20000000","product_id":"BTC-USD","sequence":3342835967,"time":"2017-06-17T02:38:38.363000Z"}
{"type":"received","order_id":"cead2dfc-106e-45fd-bf1f-7ce542ac4050","order_type":"limit","size":"0.10000000","price":"2447.08000000","side":"sell","client_oid":"c3b5bd44-6d4b-4780-bb75-d1c35f466611","product_id":"BTC-USD","sequence":3342835968,"time":"2017-06-17T02:38:38.369000Z"}
{"type":"open","side":"sell","price":"2447.08000000","order_id":"cead2dfc-106e-45fd-bf1f-7ce542ac4050","remaining_size":"0.10000000","product_id":"BTC-USD","sequence":3342835969,"time":"2017-06-17T02:38:38.369000Z"}
{"type":"done","side":"sell","order_id":"cead2dfc-106e-45fd-bf1f-7ce542ac4050","reason":"canceled","product_id":"BTC-USD","price":"2447.08000000","remaining_size":"0.10000000","sequence":3342835970,"time":"2017-06-17T02:38:38.375000Z"}
{"type":"done","side":"sell","order_id":"bfa44c13-515e-4e4d-bcfd-92347f5c47de","reason":"canceled","product_id":"BTC-USD","price":"2448.77000000","remaining_size":"0.08985400","sequence":3342835971,"time":"2017-06-17T02:38:38.377000Z"}
{"type":"received","order_id":"2b608dcf-2efb-4250-868e-470ae9496d6f","order_type":"limit","size":"0.08985400","price":"2447.53000000","side":"sell","client_oid":"a2210ac5-950f-4772-b9af-2a267bab59b6","product_id":"BTC-USD","sequence":3342835972,"time":"2017-06-17T02:38:38.393000Z"}
{"type":"open","side":"sell","price":"2447.53000000","order_id":"2b608dcf-2efb-4250-868e-470ae9496d6f","remaining_size":"0.08985400","product_id":"BTC-USD","sequence":3342835973,"time":"2017-06-17T02:38:38.393000Z"}
{"type":"received","order_id":"c978d8b5-0f04-40d2-9c83-f8ced5348dd0","order_type":"limit","size":"0.10000000","price":"2447.07000000","side":"sell","client_oid":"d01c8890-5eb7-40ee-b774-398ebd7a9ab0","product_id":"BTC-USD","sequence":3342835974,"time":"2017-06-17T02:38:38.399000Z"}
{"type":"open","side":"sell","price":"2447.07000000","order_id":"c978d8b5-0f04-40d2-9c83-f8ced5348dd0","remaining_size":"0.10000000","product_id":"BTC-USD","sequence":3342835975,"time":"2017-06-17T02:38:38.399000Z"}
{"type":"done","side":"sell","order_id":"db5ac5cc-c41c-4b92-83c6-0a7cfd4c5a89","reason":"canceled","product_id":"BTC-USD","price":"2447.53000000","remaining_size":"0.20000000","sequence":3342835976,"time":"2017-06-17T02:38:38.401000Z"}
{"type":"received","order_id":"e904f386-9ca7-413a-bdc7-d264d57ed3a1","order_type":"limit","size":"0.20000000","price":"2447.52000000","side":"sell","client_oid":"313e0171-9f23-4658-8253-8958a99ab6a8","product_id":"BTC-USD","sequence":3342835977,"time":"2017-06-17T02:38:38.412000Z"}
{"type":"open","side":"sell","price":"2447.52000000","order_id":"e904f386-9ca7-413a-bdc7-d264d57ed3a1","remaining_size":"0.20000000","product_id":"BTC-USD","sequence":3342835978,"time":"2017-06-17T02:38:38.412000Z"}
{"type":"done","side":"sell","order_id":"c978d8b5-0f04-40d2-9c83-f8ced5348dd0","reason":"canceled","product_id":"BTC-USD","price":"2447.07000000","remaining_size":"0.10000000","sequence":3342835979,"time":"2017-06-17T02:38:38.421000Z"}
{"type":"received","order_id":"4d28bf67-08ac-4baf-a86f-a90250d960ab","order_type":"limit","size":"0.10000000","price":"2447.06000000","side":"sell","client_oid":"723e3e9f-0f88-487b-a855-eadc34a8a645","product_id":"BTC-USD","sequence":3342835980,"time":"2017-06-17T02:38:38.430000Z"}
{"type":"open","side":"sell","price":"2447.06000000","order_id":"4d28bf67-08ac-4baf-a86f-a90250d960ab","remaining_size":"0.10000000","product_id":"BTC-USD","sequence":3342835981,"time":"2017-06-17T02:38:38.430000Z"}
{"type":"received","order_id":"c9960e05-10d2-4b7f-8740-5e143a17fb3a","order_type":"limit","size":"0.08985400","price":"2447.51000000","side":"sell","client_oid":"b925a750-352b-4498-be6b-4a4ae5dd5f37","product_id":"BTC-USD","sequence":3342835982,"time":"2017-06-17T02:38:38.435000Z"}
{"type":"open","side":"sell","price":"2447.51000000","order_id":"c9960e05-10d2-4b7f-8740-5e143a17fb3a","remaining_size":"0.08985400","product_id":"BTC-USD","sequence":3342835983,"time":"2017-06-17T02:38:38.435000Z"}
{"type":"done","side":"sell","order_id":"e904f386-9ca7-413a-bdc7-d264d57ed3a1","reason":"canceled","product_id":"BTC-USD","price":"2447.52000000","remaining_size":"0.20000000","sequence":3342835984,"time":"2017-06-17T02:38:38.440000Z"}
{"type":"received","order_id":"e0c7b888-0df7-4017-87d9-f196b4b58940","order_type":"limit","size":"0.20000000","price":"2447.51000000","side":"sell","client_oid":"c3f6e583-2c65-4f11-bba9-5b37e256f154","product_id":"BTC-USD","sequence":3342835985,"time":"2017-06-17T02:38:38.446000Z"}
{"type":"open","side":"sell","price":"2447.51000000","order_id":"e0c7b888-0df7-4017-87d9-f196b4b58940","remaining_size":"0.20000000","product_id":"BTC-USD","sequence":3342835986,"time":"2017-06-17T02:38:38.446000Z"}
{"type":"done","side":"sell","order_id":"4d28bf67-08ac-4baf-a86f-a90250d960ab","reason":"canceled","product_id":"BTC-USD","price":"2447.06000000","remaining_size":"0.10000000","sequence":3342835987,"time":"2017-06-17T02:38:38.447000Z"}
{"type":"done","side":"sell","order_id":"2b608dcf-2efb-4250-868e-470ae9496d6f","reason":"canceled","product_id":"BTC-USD","price":"2447.53000000","remaining_size":"0.08985400","sequence":3342835988,"time":"2017-06-17T02:38:38.448000Z"}
{"type":"received","order_id":"033f3935-19bf-4b5d-8904-bf41cff425a5","order_type":"limit","size":"0.10000000","price":"2447.15000000","side":"sell","client_oid":"26ba504a-cefd-4a33-bedb-db0020910903","product_id":"BTC-USD","sequence":3342835989,"time":"2017-06-17T02:38:38.471000Z"}
{"type":"open","side":"sell","price":"2447.15000000","order_id":"033f3935-19bf-4b5d-8904-bf41cff425a5","remaining_size":"0.10000000","product_id":"BTC-USD","sequence":3342835990,"time":"2017-06-17T02:38:38.471000Z"}
{"type":"done","side":"sell","order_id":"c9960e05-10d2-4b7f-8740-5e143a17fb3a","reason":"canceled","product_id":"BTC-USD","price":"2447.51000000","remaining_size":"0.08985400","sequence":3342835991,"time":"2017-06-17T02:38:38.475000Z"}
{"type":"done","side":"sell","order_id":"e0c7b888-0df7-4017-87d9-f196b4b58940","reason":"canceled","product_id":"BTC-USD","price":"2447.51000000","remaining_size":"0.20000000","sequence":3342835992,"time":"2017-06-17T02:38:38.478000Z"}
{"type":"done","side":"sell","order_id":"033f3935-19bf-4b5d-8904-bf41cff425a5","reason":"canceled","product_id":"BTC-USD","price":"2447.15000000","remaining_size":"0.10000000","sequence":3342835993,"time":"2017-06-17T02:38:38.481000Z"}
{"type":"received","order_id":"570e0755-0ead-416f-8dc3-229a14b7cb24","order_type":"limit","size":"0.02100000","price":"2441.77000000","side":"buy","product_id":"BTC-USD","sequence":3342835994,"time":"2017-06-17T02:38:38.495000Z"}
{"type":"open","side":"buy","price":"2441.77000000","order_id":"570e0755-0ead-416f-8dc3-229a14b7cb24","remaining_size":"0.02100000","product_id":"BTC-USD","sequence":3342835995,"time":"2017-06-17T02:38:38.495000Z"}
{"type":"received","order_id":"829cf65f-895a-422c-8d9a-85e7d16094f5","order_type":"limit","size":"0.08985400","price":"2449.17000000","side":"sell","client_oid":"3c03e142-9cf5-4beb-b2eb-e0bd5d5dd30e","product_id":"BTC-USD","sequence":3342835996,"time":"2017-06-17T02:38:38.527000Z"}
{"type":"open","side":"sell","price":"2449.17000000","order_id":"829cf65f-895a-422c-8d9a-85e7d16094f5","remaining_size":"0.08985400","product_id":"BTC-USD","sequence":3342835997,"time":"2017-06-17T02:38:38.527000Z"}
{"type":"received","order_id":"5d1f26ac-ce43-4aba-9669-daf574c09b75","order_type":"limit","size":"0.20000000","price":"2449.17000000","side":"sell","client_oid":"f4b67b89-aabc-4378-a7b9-3fc504860283","product_id":"BTC-USD","sequence":3342835998,"time":"2017-06-17T02:38:38.532000Z"}
{"type":"open","side":"sell","price":"2449.17000000","order_id":"5d1f26ac-ce43-4aba-9669-daf574c09b75","remaining_size":"0.20000000","product_id":"BTC-USD","sequence":3342835999,"time":"2017-06-17T02:38:38.532000Z"}
{"type":"received","order_id":"7e120aac-a964-471a-837a-51b2ae83375d","order_type":"limit","size":"0.10000000","price":"2447.15000000","side":"sell","client_oid":"e499679f-a5b3-42ee-b0d4-f08d12446f96","product_id":"BTC-USD","sequence":3342836000,"time":"2017-06-17T02:38:38.537000Z"}
{"type":"open","side":"sell","price":"2447.15000000","order_id":"7e120aac-a964-471a-837a-51b2ae83375d","remaining_size":"0.10000000","product_id":"BTC-USD","sequence":3342836001,"time":"2017-06-17T02:38:38.537000Z"}
{"type":"done","side":"sell","order_id":"829cf65f-895a-422c-8d9a-85e7d16094f5","reason":"canceled","product_id":"BTC-USD","price":"2449.17000000","remaining_size":"0.08985400","sequence":3342836002,"time":"2017-06-17T02:38:38.583000Z"}
{"type":"received","order_id":"d6965cc0-3d55-453f-95d0-83b436dbc9ab","order_type":"limit","size":"0.08985400","price":"2449.16000000","side":"sell","client_oid":"dd628595-bb8a-45c6-9495-5e4f033988f7","product_id":"BTC-USD","sequence":3342836003,"time":"2017-06-17T02:38:38.593000Z"}
{"type":"open","side":"sell","price":"2449.16000000","order_id":"d6965cc0-3d55-453f-95d0-83b436dbc9ab","remaining_size":"0.08985400","product_id":"BTC-USD","sequence":3342836004,"time":"2017-06-17T02:38:38.593000Z"}
{"type":"done","side":"sell","order_id":"5d1f26ac-ce43-4aba-9669-daf574c09b75","reason":"canceled","product_id":"BTC-USD","price":"2449.17000000","remaining_size":"0.20000000","sequence":3342836005,"time":"2017-06-17T02:38:38.594000Z"}
{"type":"received","order_id":"c6f1c9cc-1399-4582-880b-db5083243b75","order_type":"limit","size":"0.25000000","price":"2442.77000000","side":"buy","client_oid":"6f4b6cf4-f268-4c0e-8cff-49bd32522512","product_id":"BTC-USD","sequence":3342836006,"time":"2017-06-17T02:38:38.599000Z"}
{"type":"open","side":"buy","price":"2442.77000000","order_id":"c6f1c9cc-1399-4582-880b-db5083243b75","remaining_size":"0.25000000","product_id":"BTC-USD","sequence":3342836007,"time":"2017-06-17T02:38:38.599000Z"}
{"type":"received","order_id":"433761be-1390-4839-a9d8-4128f6c7b4e9","order_type":"limit","size":"0.20000000","price":"2449.16000000","side":"sell","client_oid":"5f2b41b2-7db9-4c4b-a55e-e3c845cf5f76","product_id":"BTC-USD","sequence":3342836008,"time":"2017-06-17T02:38:38.604000Z"}
{"type":"open","side":"sell","price":"2449.16000000","order_id":"433761be-1390-4839-a9d8-4128f6c7b4e9","remaining_size":"0.20000000","product_id":"BTC-USD","sequence":3342836009,"time":"2017-06-17T02:38:38.604000Z"}
{"type":"received","order_id":"a28fa1cf-d103-4c31-83bc-5c64b630a48d","order_type":"limit","size":"0.10000000","price":"2447.14000000","side":"sell","client_oid":"fffd8824-beab-4863-9174-5b719290bc60","product_id":"BTC-USD","sequence":3342836010,"time":"2017-06-17T02:38:38.610000Z"}
{"type":"open","side":"sell","price":"2447.14000000","order_id":"a28fa1cf-d103-4c31-83bc-5c64b630a48d","remaining_size":"0.10000000","product_id":"BTC-USD","sequence":3342836011,"time":"2017-06-17T02:38:38.610000Z"}
{"type":"done","side":"sell","order_id":"7e120aac-a964-471a-837a-51b2ae83375d","reason":"canceled","product_id":"BTC-USD","price":"2447.15000000","remaining_size":"0.10000000","sequence":3342836012,"time":"2017-06-17T02:38:38.611000Z"}
{"type":"done","side":"sell","order_id":"d6965cc0-3d55-453f-95d0-83b436dbc9ab","reason":"canceled","product_id":"BTC-USD","price":"2449.16000000","remaining_size":"0.08985400","sequence":3342836013,"time":"2017-06-17T02:38:38.627000Z"}
{"type":"done","side":"sell","order_id":"433761be-1390-4839-a9d8-4128f6c7b4e9","reason":"canceled","product_id":"BTC-USD","price":"2449.16000000","remaining_size":"0.20000000","sequence":3342836014,"time":"2017-06-17T02:38:38.630000Z"}
{"type":"done","side":"sell","order_id":"a28fa1cf-d103-4c31-83bc-5c64b630a48d","reason":"canceled","product_id":"BTC-USD","price":"2447.14000000","remaining_size":"0.10000000","sequence":3342836015,"time":"2017-06-17T02:38:38.637000Z"}
{"type":"received","order_id":"35ae0838-3d90-4a1a-aced-fbf1d7ffd848","order_type":"limit","size":"0.08985400","price":"2447.53000000","side":"sell","client_oid":"e902cfd9-3b33-4a10-a8fc-72c75c4c035e","product_id":"BTC-USD","sequence":3342836016,"time":"2017-06-17T02:38:38.639000Z"}
{"type":"open","side":"sell","price":"2447.53000000","order_id":"35ae0838-3d90-4a1a-aced-fbf1d7ffd848","remaining_size":"0.08985400","product_id":"BTC-USD","sequence":3342836017,"time":"2017-06-17T02:38:38.639000Z"}
{"type":"done","side":"buy","order_id":"570e0755-0ead-416f-8dc3-229a14b7cb24","reason":"canceled","product_id":"BTC-USD","price":"2441.77000000","remaining_size":"0.02100000","sequence":3342836018,"time":"2017-06-17T02:38:38.642000Z"}
{"type":"received","order_id":"29ad7e92-5bc9-4476-98a3-3c1c419f7581","order_type":"limit","size":"0.10000000","price":"2447.13000000","side":"sell","client_oid":"aa1c0a75-0259-4f7a-96ae-42e09ea84d58","product_id":"BTC-USD","sequence":3342836019,"time":"2017-06-17T02:38:38.653000Z"}
{"type":"open","side":"sell","price":"2447.13000000","order_id":"29ad7e92-5bc9-4476-98a3-3c1c419f7581","remaining_size":"0.10000000","product_id":"BTC-USD","sequence":3342836020,"time":"2017-06-17T02:38:38.653000Z"}
{"type":"done","side":"sell","order_id":"2c529927-3f9a-476c-82ff-2c738b77a4e0","reason":"canceled","product_id":"BTC-USD","price":"2455.97000000","remaining_size":"1.28000000","sequence":3342836021,"time":"2017-06-17T02:38:38.667000Z"}
{"type":"received","order_id":"991cf357-32c0-4134-a6a2-86c1c58ee7a0","order_type":"limit","size":"0.20000000","price":"2448.77000000","side":"sell","client_oid":"51bb89c5-faf8-44f4-85c0-04c656503232","product_id":"BTC-USD","sequence":3342836022,"time":"2017-06-17T02:38:38.681000Z"}
{"type":"open","side":"sell","price":"2448.77000000","order_id":"991cf357-32c0-4134-a6a2-86c1c58ee7a0","remaining_size":"0.20000000","product_id":"BTC-USD","sequence":3342836023,"time":"2017-06-17T02:38:38.681000Z"}
{"type":"done","side":"sell","order_id":"29ad7e92-5bc9-4476-98a3-3c1c419f7581","reason":"canceled","product_id":"BTC-USD","price":"2447.13000000","remaining_size":"0.10000000","sequence":3342836024,"time":"2017-06-17T02:38:38.681000Z"}
{"type":"done","side":"sell","order_id":"35ae0838-3d90-4a1a-aced-fbf1d7ffd848","reason":"canceled","product_id":"BTC-USD","price":"2447.53000000","remaining_size":"0.08985400","sequence":3342836025,"time":"2017-06-17T02:38:38.682000Z"}
{"type":"done","side":"sell","order_id":"991cf357-32c0-4134-a6a2-86c1c58ee7a0","reason":"canceled","product_id":"BTC-USD","price":"2448.77000000","remaining_size":"0.20000000","sequence":3342836026,"time":"2017-06-17T02:38:38.685000Z"}
{"type":"received","order_id":"d20f40c2-dd5b-4658-a11b-e3496d6ebf3b","order_type":"limit","size":"0.08985400","price":"2448.77000000","side":"sell","client_oid":"a61ad019-8d7c-424d-b8e9-a6397ac8b320","product_id":"BTC-USD","sequence":3342836027,"time":"2017-06-17T02:38:38.694000Z"}
{"type":"open","side":"sell","price":"2448.77000000","order_id":"d20f40c2-dd5b-4658-a11b-e3496d6ebf3b","remaining_size":"0.08985400","product_id":"BTC-USD","sequence":3342836028,"time":"2017-06-17T02:38:38.694000Z"}
{"type":"received","order_id":"a4907773-f94d-4deb-8606-bb7247c2db6d","order_type":"limit","size":"0.20000000","price":"2447.53000000","side":"sell","client_oid":"544fe4c2-46f2-463e-8ef9-2746001c8e06","product_id":"BTC-USD","sequence":3342836029,"time":"2017-06-17T02:38:38.699000Z"}
{"type":"open","side":"sell","price":"2447.53000000","order_id":"a4907773-f94d-4deb-8606-bb7247c2db6d","remaining_size":"0.20000000","product_id":"BTC-USD","sequence":3342836030,"time":"2017-06-17T02:38:38.699000Z"}
{"type":"received","order_id":"ba0bfe90-ed43-4082-b63f-b70853670455","order_type":"limit","size":"0.10000000","price":"2447.12000000","side":"sell","client_oid":"b91ad080-1c6a-444f-8f00-b578dfecf574","product_id":"BTC-USD","sequence":3342836031,"time":"2017-06-17T02:38:38.704000Z"}
{"type":"open","side":"sell","price":"2447.12000000","order_id":"ba0bfe90-ed43-4082-b63f-b70853670455","remaining_size":"0.10000000","product_id":"BTC-USD","sequence":3342836032,"time":"2017-06-17T02:38:38.704000Z"}
{"type":"done","side":"buy","order_id":"c6f1c9cc-1399-4582-880b-db5083243b75","reason":"canceled","product_id":"BTC-USD","price":"2442.77000000","remaining_size":"0.25000000","sequence":3342836033,"time":"2017-06-17T02:38:38.708000Z"}
{"type":"done","side":"sell","order_id":"d20f40c2-dd5b-4658-a11b-e3496d6ebf3b","reason":"canceled","product_id":"BTC-USD","price":"2448.77000000","remaining_size":"0.08985400","sequence":3342836034,"time":"2017-06-17T02:38:38.712000Z"}
{"type":"done","side":"sell","order_id":"ba0bfe90-ed43-4082-b63f-b70853670455","reason":"canceled","product_id":"BTC-USD","price":"2447.12000000","remaining_size":"0.10000000","sequence":3342836035,"time":"2017-06-17T02:38:38.730000Z"}
{"type":"done","side":"sell","order_id":"a4907773-f94d-4deb-8606-bb7247c2db6d","reason":"canceled","product_id":"BTC-USD","price":"2447.53000000","remaining_size":"0.20000000","sequence":3342836036,"time":"2017-06-17T02:38:38.736000Z"}
{"type":"received","order_id":"1c9174fe-0eb3-46ed-9b34-35bf0e0cb622","order_type":"limit","size":"0.10000000","price":"2447.11000000","side":"sell","client_oid":"e5560a45-0635-45da-8561-9f88ba27109e","product_id":"BTC-USD","sequence":3342836037,"time":"2017-06-17T02:38:38.741000Z"}
{"type":"open","side":"sell","price":"2447.11000000","order_id":"1c9174fe-0eb3-46ed-9b34-35bf0e0cb622","remaining_size":"0.10000000","product_id":"BTC-USD","sequence":3342836038,"time":"2017-06-17T02:38:38.741000Z"}
{"type":"received","order_id":"340a2542-3d71-41a4-85e4-b03d832b7a4f","order_type":"limit","size":"0.20000000","price":"2447.52000000","side":"sell","client_oid":"61640e6a-b65e-4d35-a0be-ec578b61175e","product_id":"BTC-USD","sequence":3342836039,"time":"2017-06-17T02:38:38.752000Z"}
{"type":"open","side":"sell","price":"2447.52000000","order_id":"340a2542-3d71-41a4-85e4-b03d832b7a4f","remaining_size":"0.20000000","product_id":"BTC-USD","sequence":3342836040,"time":"2017-06-17T02:38:38.752000Z"}
{"type":"received","order_id":"42f09f8c-0def-4e4f-a15c-d86d490ffb1a","order_type":"limit","size":"0.08985400","price":"2447.52000000","side":"sell","client_oid":"a88aed90-e902-420e-b10b-299fcbd12e98","product_id":"BTC-USD","sequence":3342836041,"time":"2017-06-17T02:38:38.763000Z"}
{"type":"open","side":"sell","price":"2447.52000000","order_id":"42f09f8c-0def-4e4f-a15c-d86d490ffb1a","remaining_size":"0.08985400","product_id":"BTC-USD","sequence":3342836042,"time":"2017-06-17T02:38:38.763000Z"}
{"type":"received","order_id":"204c8f6c-d206-435b-a316-a6a9df5b2a77","order_type":"limit","size":"0.25000000","price":"2442.78000000","side":"buy","client_oid":"23145f07-2346-4d12-b82e-697dd63eab0c","product_id":"BTC-USD","sequence":3342836043,"time":"2017-06-17T02:38:38.768000Z"}
{"type":"open","side":"buy","price":"2442.78000000","order_id":"204c8f6c-d206-435b-a316-a6a9df5b2a77","remaining_size":"0.25000000","product_id":"BTC-USD","sequence":3342836044,"time":"2017-06-17T02:38:38.768000Z"}
{"type":"done","side":"sell","order_id":"1c9174fe-0eb3-46ed-9b34-35bf0e0cb622","reason":"canceled","product_id":"BTC-USD","price":"2447.11000000","remaining_size":"0.10000000","sequence":3342836045,"time":"2017-06-17T02:38:38.773000Z"}
{"type":"received","order_id":"ca5c1d92-4f34-4c9c-90fe-17c18c7a6f7f","order_type":"limit","size":"0.10000000","price":"2447.10000000","side":"sell","client_oid":"4a771394-6bf5-4e4d-934c-878cc5dc64ff","product_id":"BTC-USD","sequence":3342836046,"time":"2017-06-17T02:38:38.784000Z"}
{"type":"open","side":"sell","price":"2447.10000000","order_id":"ca5c1d92-4f34-4c9c-90fe-17c18c7a6f7f","remaining_size":"0.10000000","product_id":"BTC-USD","sequence":3342836047,"time":"2017-06-17T02:38:38.784000Z"}
{"type":"done","side":"sell","order_id":"278f84ad-d12c-4839-a4cb-617c327460bc","reason":"canceled","product_id":"BTC-USD","price":"2454.63000000","remaining_size":"1.27000000","sequence":3342836048,"time":"2017-06-17T02:38:38.790000Z"}
{"type":"received","order_id":"fcce4586-0ce7-4855-bba8-576d61297391","order_type":"limit","size":"0.20000000","price":"2447.51000000","side":"sell","client_oid":"bd6e7122-1a39-4c60-9676-60501c9ebfc7","product_id":"BTC-USD","sequence":3342836049,"time":"2017-06-17T02:38:38.802000Z"}
{"type":"open","side":"sell","price":"2447.51000000","order_id":"fcce4586-0ce7-4855-bba8-576d61297391","remaining_size":"0.20000000","product_id":"BTC-USD","sequence":3342836050,"time":"2017-06-17T02:38:38.802000Z"}
{"type":"done","side":"sell","order_id":"340a2542-3d71-41a4-85e4-b03d832b7a4f","reason":"canceled","product_id":"BTC-USD","price":"2447.52000000","remaining_size":"0.20000000","sequence":3342836051,"time":"2017-06-17T02:38:38.802000Z"}
{"type":"done","side":"sell","order_id":"42f09f8c-0def-4e4f-a15c-d86d490ffb1a","reason":"canceled","product_id":"BTC-USD","price":"2447.52000000","remaining_size":"0.08985400","sequence":3342836052,"time":"2017-06-17T02:38:38.804000Z"}
{"type":"received","order_id":"bf8697f3-3ec4-4ab4-a302-b11778fe2652","order_type":"limit","size":"0.08985400","price":"2447.51000000","side":"sell","client_oid":"574b5c6d-14c2-43e1-814b-bf4a03042d9c","product_id":"BTC-USD","sequence":3342836053,"time":"2017-06-17T02:38:38.812000Z"}
{"type":"open","side":"sell","price":"2447.51000000","order_id":"bf8697f3-3ec4-4ab4-a302-b11778fe2652","remaining_size":"0.08985400","product_id":"BTC-USD","sequence":3342836054,"time":"2017-06-17T02:38:38.812000Z"}
{"type":"done","side":"sell","order_id":"ca5c1d92-4f34-4c9c-90fe-17c18c7a6f7f","reason":"canceled","product_id":"BTC-USD","price":"2447.10000000","remaining_size":"0.10000000","sequence":3342836055,"time":"2017-06-17T02:38:38.813000Z"}
{"type":"done","side":"buy","order_id":"204c8f6c-d206-435b-a316-a6a9df5b2a77","reason":"canceled","product_id":"BTC-USD","price":"2442.78000000","remaining_size":"0.25000000","sequence":3342836056,"time":"2017-06-17T02:38:38.817000Z"}
{"type":"done","side":"sell","order_id":"fcce4586-0ce7-4855-bba8-576d61297391","reason":"canceled","product_id":"BTC-USD","price":"2447.51000000","remaining_size":"0.20000000","sequence":3342836057,"time":"2017-06-17T02:38:38.829000Z"}
{"type":"received","order_id":"1fcf96b3-de15-49a5-86d8-ab8ae199ef69","order_type":"limit","size":"0.10000000","price":"2447.15000000","side":"sell","client_oid":"c8bfc545-3d22-494b-96dd-559c6aef47ce","product_id":"BTC-USD","sequence":3342836058,"time":"2017-06-17T02:38:38.829000Z"}
{"type":"open","side":"sell","price":"2447.15000000","order_id":"1fcf96b3-de15-49a5-86d8-ab8ae199ef69","remaining_size":"0.10000000","product_id":"BTC-USD","sequence":3342836059,"time":"2017-06-17T02:38:38.829000Z"}
{"type":"done","side":"sell","order_id":"2c57d1cb-7cfd-42ca-b34a-e0f613926479","reason":"canceled","product_id":"BTC-USD","price":"2454.61000000","remaining_size":"2.45000000","sequence":3342836060,"time":"2017-06-17T02:38:38.831000Z"}
{"type":"done","side":"sell","order_id":"bf8697f3-3ec4-4ab4-a302-b11778fe2652","reason":"canceled","product_id":"BTC-USD","price":"2447.51000000","remaining_size":"0.08985400","sequence":3342836061,"time":"2017-06-17T02:38:38.841000Z"}
{"type":"received","order_id":"dc2fc272-f926-440b-8303-b010d7387772","order_type":"limit","size":"0.08985400","price":"2447.50000000","side":"sell","client_oid":"295a85d9-f76f-484c-9b17-8b7170060daf","product_id":"BTC-USD","sequence":3342836062,"time":"2017-06-17T02:38:38.851000Z"}
{"type":"open","side":"sell","price":"2447.50000000","order_id":"dc2fc272-f926-440b-8303-b010d7387772","remaining_size":"0.08985400","product_id":"BTC-USD","sequence":3342836063,"time":"2017-06-17T02:38:38.851000Z"}
{"type":"done","side":"sell","order_id":"dc2fc272-f926-440b-8303-b010d7387772","reason":"canceled","product_id":"BTC-USD","price":"2447.50000000","remaining_size":"0.08985400","sequence":3342836064,"time":"2017-06-17T02:38:38.862000Z"}
{"type":"done","side":"sell","order_id":"1fcf96b3-de15-49a5-86d8-ab8ae199ef69","reason":"canceled","product_id":"BTC-USD","price":"2447.15000000","remaining_size":"0.10000000","sequence":3342836065,"time":"2017-06-17T02:38:38.863000Z"}
{"type":"done","side":"buy","order_id":"bd9aa2ff-005b-45b7-962c-414dc3c43911","reason":"canceled","product_id":"BTC-USD","price":"2442.39000000","remaining_size":"0.50000000","sequence":3342836066,"time":"2017-06-17T02:38:38.864000Z"}
{"type":"done","side":"buy","order_id":"83cba5cf-9bde-41d5-800d-7dcc1276c796","reason":"canceled","product_id":"BTC-USD","price":"2429.97000000","remaining_size":"0.75000000","sequence":3342836067,"time":"2017-06-17T02:38:38.889000Z"}
{"type":"done","side":"sell","order_id":"d065e8df-5cdb-4368-95f6-627336b21760","reason":"canceled","product_id":"BTC-USD","price":"2464.98000000","remaining_size":"5.19899600","sequence":3342836068,"time":"2017-06-17T02:38:38.894000Z"}
{"type":"done","side":"sell","order_id":"3c745fda-cb33-4a37-a868-fdbfe1091de5","reason":"canceled","product_id":"BTC-USD","price":"2443.55000000","remaining_size":"0.50000000","sequence":3342836069,"time":"2017-06-17T02:38:38.904000Z"}
{"type":"received","order_id":"a0fbece7-e23f-47a6-b58b-ccc07c04a9c5","order_type":"limit","size":"4.84143500","price":"2469.47000000","side":"sell","product_id":"BTC-USD","sequence":3342836070,"time":"2017-06-17T02:38:38.905000Z"}
{"type":"open","side":"sell","price":"2469.47000000","order_id":"a0fbece7-e23f-47a6-b58b-ccc07c04a9c5","remaining_size":"4.84143500","product_id":"BTC-USD","sequence":3342836071,"time":"2017-06-17T02:38:38.905000Z"}
{"type":"done","side":"buy","order_id":"14e89939-b6c9-4063-8ad7-a29f86478af8","reason":"canceled","product_id":"BTC-USD","price":"2430.62000000","remaining_size":"1.38000000","sequence":3342836072,"time":"2017-06-17T02:38:38.932000Z"}
{"type":"received","order_id":"ce5ac288-5032-4690-a663-9283d9e44721","order_type":"limit","size":"0.25000000","price":"2442.77000000","side":"buy","client_oid":"7f60ae40-0378-4ca9-bd87-a8e66c842fc6","product_id":"BTC-USD","sequence":3342836073,"time":"2017-06-17T02:38:38.957000Z"}
{"type":"open","side":"buy","price":"2442.77000000","order_id":"ce5ac288-5032-4690-a663-9283d9e44721","remaining_size":"0.25000000","product_id":"BTC-USD","sequence":3342836074,"time":"2017-06-17T02:38:38.957000Z"}
{"type":"done","side":"buy","order_id":"ef496c46-6239-480a-931a-0aa19e43bcd9","reason":"canceled","product_id":"BTC-USD","price":"2431.35000000","remaining_size":"0.99000000","sequence":3342836075,"time":"2017-06-17T02:38:38.979000Z"}
{"type":"done","side":"buy","order_id":"dc85cb6b-7bd8-4b64-90f6-c7314dcb2bab","reason":"canceled","product_id":"BTC-USD","price":"2432.62000000","remaining_size":"0.99000000","sequence":3342836076,"time":"2017-06-17T02:38:39.019000Z"}
{"type":"received","order_id":"212e5542-5bae-4296-b348-3c6245438e22","order_type":"limit","size":"0.50000000","price":"2443.56000000","side":"sell","client_oid":"09d4780a-1e8f-4f78-b447-eee896455232","product_id":"BTC-USD","sequence":3342836077,"time":"2017-06-17T02:38:39.045000Z"}
{"type":"open","side":"sell","price":"2443.56000000","order_id":"212e5542-5bae-4296-b348-3c6245438e22","remaining_size":"0.50000000","product_id":"BTC-USD","sequence":3342836078,"time":"2017-06-17T02:38:39.045000Z"}
{"type":"done","side":"buy","order_id":"4a2b3d17-0e5d-4fa2-9d9d-d47fe3cec713","reason":"canceled","product_id":"BTC-USD","price":"2434.05000000","remaining_size":"0.90000000","sequence":3342836079,"time":"2017-06-17T02:38:39.057000Z"}
{"type":"done","side":"buy","order_id":"ce5ac288-5032-4690-a663-9283d9e44721","reason":"canceled","product_id":"BTC-USD","price":"2442.77000000","remaining_size":"0.25000000","sequence":3342836080,"time":"2017-06-17T02:38:39.069000Z"}
{"type":"received","order_id":"5311f3e7-44cc-4c3d-934f-0830c04d29e4","order_type":"limit","size":"3.69065628","price":"2443.00000000","side":"sell","client_oid":"688212a5-21d6-4826-d0a6-c30cd1c57c7d","product_id":"BTC-USD","sequence":3342836081,"time":"2017-06-17T02:38:39.142000Z"}
{"type":"open","side":"sell","price":"2443.00000000","order_id":"5311f3e7-44cc-4c3d-934f-0830c04d29e4","remaining_size":"3.69065628","product_id":"BTC-USD","sequence":3342836082,"time":"2017-06-17T02:38:39.142000Z"}
{"type":"done","side":"sell","order_id":"212e5542-5bae-4296-b348-3c6245438e22","reason":"canceled","product_id":"BTC-USD","price":"2443.56000000","remaining_size":"0.50000000","sequence":3342836083,"time":"2017-06-17T02:38:39.218000Z"}
{"type":"received","order_id":"f3c25eb7-9b18-4752-9aa3-4f51b4b8c769","order_type":"limit","size":"0.08985400","price":"2449.17000000","side":"sell","client_oid":"4f931083-47d4-498f-907e-8954fb07e0ea","product_id":"BTC-USD","sequence":3342836084,"time":"2017-06-17T02:38:39.342000Z"}
{"type":"open","side":"sell","price":"2449.17000000","order_id":"f3c25eb7-9b18-4752-9aa3-4f51b4b8c769","remaining_size":"0.08985400","product_id":"BTC-USD","sequence":3342836085,"time":"2017-06-17T02:38:39.342000Z"}
{"type":"received","order_id":"2a24708a-059c-4b53-a8bd-86bb1df00d69","order_type":"limit","size":"0.10000000","price":"2447.15000000","side":"sell","client_oid":"8a93a91c-8280-4116-a08b-620a2954917b","product_id":"BTC-USD","sequence":3342836086,"time":"2017-06-17T02:38:39.345000Z"}
{"type":"open","side":"sell","price":"2447.15000000","order_id":"2a24708a-059c-4b53-a8bd-86bb1df00d69","remaining_size":"0.10000000","product_id":"BTC-USD","sequence":3342836087,"time":"2017-06-17T02:38:39.345000Z"}
{"type":"received","order_id":"248a7e3b-4d22-48a3-b7c1-9f7a1b3398a4","order_type":"limit","size":"0.50000000","price":"2443.50000000","side":"sell","client_oid":"cd5a4845-8a91-4fb9-bc5c-89e6459f723a","product_id":"BTC-USD","sequence":3342836088,"time":"2017-06-17T02:38:39.363000Z"}
{"type":"open","side":"sell","price":"2443.50000000","order_id":"248a7e3b-4d22-48a3-b7c1-9f7a1b3398a4","remaining_size":"0.50000000","product_id":"BTC-USD","sequence":3342836089,"time":"2017-06-17T02:38:39.363000Z"}
{"type":"received","order_id":"b042c46b-1769-4ca0-9c8d-1755a53a0574","order_type":"limit","size":"0.25000000","price":"2442.77000000","side":"buy","client_oid":"6e22ec6f-4c0c-46ed-9562-3bcfc49c2beb","product_id":"BTC-USD","sequence":3342836090,"time":"2017-06-17T02:38:39.377000Z"}
{"type":"open","side":"buy","price":"2442.77000000","order_id":"b042c46b-1769-4ca0-9c8d-1755a53a0574","remaining_size":"0.25000000","product_id":"BTC-USD","sequence":3342836091,"time":"2017-06-17T02:38:39.377000Z"}
{"type":"done","side":"sell","order_id":"2a24708a-059c-4b53-a8bd-86bb1df00d69","reason":"canceled","product_id":"BTC-USD","price":"2447.15000000","remaining_size":"0.10000000","sequence":3342836092,"time":"2017-06-17T02:38:39.388000Z"}
{"type":"received","order_id":"6091675d-1dcb-40d6-a6d9-f245d7a9242b","order_type":"limit","size":"0.10000000","price":"2447.14000000","side":"sell","client_oid":"b071c0c6-f355-4e89-bdab-3d3d0ad17a9c","product_id":"BTC-USD","sequence":3342836093,"time":"2017-06-17T02:38:39.392000Z"}
{"type":"open","side":"sell","price":"2447.14000000","order_id":"6091675d-1dcb-40d6-a6d9-f245d7a9242b","remaining_size":"0.10000000","product_id":"BTC-USD","sequence":3342836094,"time":"2017-06-17T02:38:39.392000Z"}
{"type":"received","order_id":"0def3076-e99d-4253-8d16-d8f5664865c6","order_type":"limit","size":"0.08985400","price":"2447.53000000","side":"sell","client_oid":"1e121ee1-d6c6-4840-91c9-eb1e04132ded","product_id":"BTC-USD","sequence":3342836095,"time":"2017-06-17T02:38:39.398000Z"}
{"type":"open","side":"sell","price":"2447.53000000","order_id":"0def3076-e99d-4253-8d16-d8f5664865c6","remaining_size":"0.08985400","product_id":"BTC-USD","sequence":3342836096,"time":"2017-06-17T02:38:39.398000Z"}
{"type":"done","side":"sell","order_id":"f3c25eb7-9b18-4752-9aa3-4f51b4b8c769","reason":"canceled","product_id":"BTC-USD","price":"2449.17000000","remaining_size":"0.08985400","sequence":3342836097,"time":"2017-06-17T02:38:39.399000Z"}
{"type":"done","side":"sell","order_id":"0def3076-e99d-4253-8d16-d8f5664865c6","reason":"canceled","product_id":"BTC-USD","price":"2447.53000000","remaining_size":"0.08985400","sequence":3342836098,"time":"2017-06-17T02:38:39.437000Z"}
{"type":"received","order_id":"e241afcc-6d50-4e6a-a50b-84cb618b70ef","order_type":"limit","size":"0.10000000","price":"2447.13000000","side":"sell","client_oid":"3bc4dea6-7818-4613-992b-00edfafcfae9","product_id":"BTC-USD","sequence":3342836099,"time":"2017-06-17T02:38:39.443000Z"}
{"type":"open","side":"sell","price":"2447.13000000","order_id":"e241afcc-6d50-4e6a-a50b-84cb618b70ef","remaining_size":"0.10000000","product_id":"BTC-USD","sequence":3342836100,"time":"2017-06-17T02:38:39.443000Z"}
{"type":"done","side":"sell","order_id":"6091675d-1dcb-40d6-a6d9-f245d7a9242b","reason":"canceled","product_id":"BTC-USD","price":"2447.14000000","remaining_size":"0.10000000","sequence":3342836101,"time":"2017-06-17T02:38:39.446000Z"}
{"type":"received","order_id":"af655125-4cb6-41f0-a57e-cd6d2d5a6657","order_type":"limit","size":"0.08985400","price":"2447.53000000","side":"sell","client_oid":"a5c34d7b-0324-48b6-9333-1d662e0dfe8a","product_id":"BTC-USD","sequence":3342836102,"time":"2017-06-17T02:38:39.450000Z"}
{"type":"open","side":"sell","price":"2447.53000000","order_id":"af655125-4cb6-41f0-a57e-cd6d2d5a6657","remaining_size":"0.08985400","product_id":"BTC-USD","sequence":3342836103,"time":"2017-06-17T02:38:39.450000Z"}
{"type":"done","side":"buy","order_id":"b042c46b-1769-4ca0-9c8d-1755a53a0574","reason":"canceled","product_id":"BTC-USD","price":"2442.77000000","remaining_size":"0.25000000","sequence":3342836104,"time":"2017-06-17T02:38:39.463000Z"}
{"type":"done","side":"sell","order_id":"e241afcc-6d50-4e6a-a50b-84cb618b70ef","reason":"canceled","product_id":"BTC-USD","price":"2447.13000000","remaining_size":"0.10000000","sequence":3342836105,"time":"2017-06-17T02:38:39.479000Z"}
{"type":"received","order_id":"f7092131-3f0c-45e5-94e1-915e4ab2ed87","order_type":"limit","size":"0.25000000","price":"2442.78000000","side":"buy","client_oid":"10d3b4e3-6fba-422b-b22c-89cf505ee3e1","product_id":"BTC-USD","sequence":3342836106,"time":"2017-06-17T02:38:39.491000Z"}
{"type":"open","side":"buy","price":"2442.78000000","order_id":"f7092131-3f0c-45e5-94e1-915e4ab2ed87","remaining_size":"0.25000000","product_id":"BTC-USD","sequence":3342836107,"time":"2017-06-17T02:38:39.491000Z"}
{"type":"done","side":"sell","order_id":"af655125-4cb6-41f0-a57e-cd6d2d5a6657","reason":"canceled","product_id":"BTC-USD","price":"2447.53000000","remaining_size":"0.08985400","sequence":3342836108,"time":"2017-06-17T02:38:39.495000Z"}
{"type":"received","order_id":"b65cd3b3-382d-4339-83ac-54d84bb4fca5","order_type":"limit","size":"0.08985400","price":"2448.77000000","side":"sell","client_oid":"ad9e345a-8a9b-4344-a6f8-def50462e065","product_id":"BTC-USD","sequence":3342836109,"time":"2017-06-17T02:38:39.532000Z"}
{"type":"open","side":"sell","price":"2448.77000000","order_id":"b65cd3b3-382d-4339-83ac-54d84bb4fca5","remaining_size":"0.08985400","product_id":"BTC-USD","sequence":3342836110,"time":"2017-06-17T02:38:39.532000Z"}
{"type":"received","order_id":"b83fb6b9-bb2e-43c3-b78a-2d0755f73772","order_type":"limit","size":"0.10000000","price":"2447.15000000","side":"sell","client_oid":"d60f49e9-07b2-44a4-a12d-d14c0d64fec4","product_id":"BTC-USD","sequence":3342836111,"time":"2017-06-17T02:38:39.555000Z"}
{"type":"open","side":"sell","price":"2447.15000000","order_id":"b83fb6b9-bb2e-43c3-b78a-2d0755f73772","remaining_size":"0.10000000","product_id":"BTC-USD","sequence":3342836112,"time":"2017-06-17T02:38:39.555000Z"}
{"type":"done","side":"sell","order_id":"b65cd3b3-382d-4339-83ac-54d84bb4fca5","reason":"canceled","product_id":"BTC-USD","price":"2448.77000000","remaining_size":"0.08985400","sequence":3342836113,"time":"2017-06-17T02:38:39.556000Z"}
{"type":"received","order_id":"35d8a648-48cb-4022-94f2-de22cbf74594","order_type":"limit","size":"0.08985400","price":"2449.17000000","side":"sell","client_oid":"814807ef-f1ca-4e4f-a107-c120cb709bf2","product_id":"BTC-USD","sequence":3342836114,"time":"2017-06-17T02:38:39.560000Z"}
{"type":"open","side":"sell","price":"2449.17000000","order_id":"35d8a648-48cb-4022-94f2-de22cbf74594","remaining_size":"0.08985400","product_id":"BTC-USD","sequence":3342836115,"time":"2017-06-17T02:38:39.560000Z"}
{"type":"done","side":"sell","order_id":"35d8a648-48cb-4022-94f2-de22cbf74594","reason":"canceled","product_id":"BTC-USD","price":"2449.17000000","remaining_size":"0.08985400","sequence":3342836116,"time":"2017-06-17T02:38:39.577000Z"}
{"type":"done","side":"buy","order_id":"f7092131-3f0c-45e5-94e1-915e4ab2ed87","reason":"canceled","product_id":"BTC-USD","price":"2442.78000000","remaining_size":"0.25000000","sequence":3342836117,"time":"2017-06-17T02:38:39.578000Z"}
{"type":"done","side":"sell","order_id":"b83fb6b9-bb2e-43c3-b78a-2d0755f73772","reason":"canceled","product_id":"BTC-USD","price":"2447.15000000","remaining_size":"0.10000000","sequence":3342836118,"time":"2017-06-17T02:38:39.578000Z"}
{"type":"received","order_id":"fb73b8b5-b0ce-4708-adf1-179678be27a5","order_type":"limit","size":"0.10000000","price":"2447.14000000","side":"sell","client_oid":"e4c2a8ae-a808-46f5-8edb-455c1f8057d7","product_id":"BTC-USD","sequence":3342836119,"time":"2017-06-17T02:38:39.590000Z"}
{"type":"open","side":"sell","price":"2447.14000000","order_id":"fb73b8b5-b0ce-4708-adf1-179678be27a5","remaining_size":"0.10000000","product_id":"BTC-USD","sequence":3342836120,"time":"2017-06-17T02:38:39.590000Z"}
{"type":"received","order_id":"133c433d-8b39-4618-bfdd-4eaec0d3e606","order_type":"limit","size":"0.08985400","price":"2447.53000000","side":"sell","client_oid":"839c4c92-f987-42d6-8d8e-bbd64d0db058","product_id":"BTC-USD","sequence":3342836121,"time":"2017-06-17T02:38:39.596000Z"}
{"type":"open","side":"sell","price":"2447.53000000","order_id":"133c433d-8b39-4618-bfdd-4eaec0d3e606","remaining_size":"0.08985400","product_id":"BTC-USD","sequence":3342836122,"time":"2017-06-17T02:38:39.596000Z"}
{"type":"done","side":"sell","order_id":"fb73b8b5-b0ce-4708-adf1-179678be27a5","reason":"canceled","product_id":"BTC-USD","price":"2447.14000000","remaining_size":"0.10000000","sequence":3342836123,"time":"2017-06-17T02:38:39.620000Z"}
{"type":"received","order_id":"88164224-3580-47aa-b511-926bb4800b52","order_type":"limit","size":"0.10000000","price":"2447.13000000","side":"sell","client_oid":"a14cd3e6-d4f4-4e36-8167-28950fbae48b","product_id":"BTC-USD","sequence":3342836124,"time":"2017-06-17T02:38:39.635000Z"}
{"type":"open","side":"sell","price":"2447.13000000","order_id":"88164224-3580-47aa-b511-926bb4800b52","remaining_size":"0.10000000","product_id":"BTC-USD","sequence":3342836125,"time":"2017-06-17T02:38:39.635000Z"}
{"type":"done","side":"sell","order_id":"133c433d-8b39-4618-bfdd-4eaec0d3e606","reason":"canceled","product_id":"BTC-USD","price":"2447.53000000","remaining_size":"0.08985400","sequence":3342836126,"time":"2017-06-17T02:38:39.635000Z"}
{"type":"done","side":"sell","order_id":"88164224-3580-47aa-b511-926bb4800b52","reason":"canceled","product_id":"BTC-USD","price":"2447.13000000","remaining_size":"0.10000000","sequence":3342836127,"time":"2017-06-17T02:38:39.639000Z"}
{"type":"received","order_id":"9e6b2cf0-8882-49af-9f8d-abc701dd1580","order_type":"limit","size":"0.08985400","price":"2448.77000000","side":"sell","client_oid":"f420cef2-f776-4b2f-bf6a-598ab0aee920","product_id":"BTC-USD","sequence":3342836128,"time":"2017-06-17T02:38:39.645000Z"}
{"type":"open","side":"sell","price":"2448.77000000","order_id":"9e6b2cf0-8882-49af-9f8d-abc701dd1580","remaining_size":"0.08985400","product_id":"BTC-USD","sequence":3342836129,"time":"2017-06-17T02:38:39.645000Z"}
{"type":"received","order_id":"05e9ab2e-6427-47a9-8727-72a97ba8d7a0","order_type":"limit","size":"0.10000000","price":"2447.15000000","side":"sell","client_oid":"2a7ef8df-5d15-4cc7-9244-caa7e8fcde06","product_id":"BTC-USD","sequence":3342836130,"time":"2017-06-17T02:38:39.650000Z"}
{"type":"open","side":"sell","price":"2447.15000000","order_id":"05e9ab2e-6427-47a9-8727-72a97ba8d7a0","remaining_size":"0.10000000","product_id":"BTC-USD","sequence":3342836131,"time":"2017-06-17T02:38:39.650000Z"}
{"type":"done","side":"sell","order_id":"9e6b2cf0-8882-49af-9f8d-abc701dd1580","reason":"canceled","product_id":"BTC-USD","price":"2448.77000000","remaining_size":"0.08985400","sequence":3342836132,"time":"2017-06-17T02:38:39.699000Z"}
{"type":"received","order_id":"c9380da0-b344-463c-a46d-b53944a53a84","order_type":"limit","size":"0.08985400","price":"2447.53000000","side":"sell","client_oid":"45c32500-ac73-4a43-abd3-a224860b8187","product_id":"BTC-USD","sequence":3342836133,"time":"2017-06-17T02:38:39.702000Z"}
{"type":"open","side":"sell","price":"2447.53000000","order_id":"c9380da0-b344-463c-a46d-b53944a53a84","remaining_size":"0.08985400","product_id":"BTC-USD","sequence":3342836134,"time":"2017-06-17T02:38:39.702000Z"}
{"type":"done","side":"sell","order_id":"05e9ab2e-6427-47a9-8727-72a97ba8d7a0","reason":"canceled","product_id":"BTC-USD","price":"2447.15000000","remaining_size":"0.10000000","sequence":3342836135,"time":"2017-06-17T02:38:39.702000Z"}
{"type":"received","order_id":"1883c1ea-6866-4436-9a50-dcac5d6fc4ea","order_type":"limit","size":"0.10000000","price":"2447.14000000","side":"sell","client_oid":"c701b8d5-b59a-48da-8e4a-937d532aea25","product_id":"BTC-USD","sequence":3342836136,"time":"2017-06-17T02:38:39.710000Z"}
{"type":"open","side":"sell","price":"2447.14000000","order_id":"1883c1ea-6866-4436-9a50-dcac5d6fc4ea","remaining_size":"0.10000000","product_id":"BTC-USD","sequence":3342836137,"time":"2017-06-17T02:38:39.710000Z"}
{"type":"done","side":"sell","order_id":"c9380da0-b344-463c-a46d-b53944a53a84","reason":"canceled","product_id":"BTC-USD","price":"2447.53000000","remaining_size":"0.08985400","sequence":3342836138,"time":"2017-06-17T02:38:39.721000Z"}
{"type":"done","side":"sell","order_id":"1883c1ea-6866-4436-9a50-dcac5d6fc4ea","reason":"canceled","product_id":"BTC-USD","price":"2447.14000000","remaining_size":"0.10000000","sequence":3342836139,"time":"2017-06-17T02:38:39.727000Z"}
{"type":"received","order_id":"d22747c5-a918-40b3-b875-1448b74ec81b","order_type":"limit","size":"0.10000000","price":"2447.15000000","side":"sell","client_oid":"bfcfe778-62a6-4f4c-930c-2ba7e6cc50c3","product_id":"BTC-USD","sequence":3342836140,"time":"2017-06-17T02:38:39.746000Z"}
{"type":"open","side":"sell","price":"2447.15000000","order_id":"d22747c5-a918-40b3-b875-1448b74ec81b","remaining_size":"0.10000000","product_id":"BTC-USD","sequence":3342836141,"time":"2017-06-17T02:38:39.746000Z"}
{"type":"received","order_id":"2f483306-89fe-4076-ab49-c44809ac1867","order_type":"limit","size":"0.10000000","price":"2447.14000000","side":"sell","client_oid":"ddcdfd96-9d1f-48c1-996e-97182db68196","product_id":"BTC-USD","sequence":3342836142,"time":"2017-06-17T02:38:39.781000Z"}
{"type":"open","side":"sell","price":"2447.14000000","order_id":"2f483306-89fe-4076-ab49-c44809ac1867","remaining_size":"0.10000000","product_id":"BTC-USD","sequence":3342836143,"time":"2017-06-17T02:38:39.781000Z"}
{"type":"done","side":"sell","order_id":"2f483306-89fe-4076-ab49-c44809ac1867","reason":"canceled","product_id":"BTC-USD","price":"2447.14000000","remaining_size":"0.10000000","sequence":3342836144,"time":"2017-06-17T02:38:39.787000Z"}
{"type":"done","side":"sell","order_id":"d22747c5-a918-40b3-b875-1448b74ec81b","reason":"canceled","product_id":"BTC-USD","price":"2447.15000000","remaining_size":"0.10000000","sequence":3342836145,"time":"2017-06-17T02:38:39.788000Z"}
{"type":"received","order_id":"e439ada9-f5e2-4752-bf14-c35d7f0ba317","order_type":"limit","size":"0.08985400","price":"2449.17000000","side":"sell","client_oid":"a5dc0d7a-3a69-43dd-8f46-9484dbccefc7","product_id":"BTC-USD","sequence":3342836146,"time":"2017-06-17T02:38:39.790000Z"}
{"type":"open","side":"sell","price":"2449.17000000","order_id":"e439ada9-f5e2-4752-bf14-c35d7f0ba317","remaining_size":"0.08985400","product_id":"BTC-USD","sequence":3342836147,"time":"2017-06-17T02:38:39.790000Z"}
{"type":"received","order_id":"15e532e0-251b-43a1-a25d-c3188fa0c6db","order_type":"limit","size":"0.20000000","price":"2447.53000000","side":"sell","client_oid":"04bb3ee8-72d9-4492-98de-65cebff68bef","product_id":"BTC-USD","sequence":3342836148,"time":"2017-06-17T02:38:39.824000Z"}
{"type":"open","side":"sell","price":"2447.53000000","order_id":"15e532e0-251b-43a1-a25d-c3188fa0c6db","remaining_size":"0.20000000","product_id":"BTC-USD","sequence":3342836149,"time":"2017-06-17T02:38:39.824000Z"}
{"type":"done","side":"sell","order_id":"e439ada9-f5e2-4752-bf14-c35d7f0ba317","reason":"canceled","product_id":"BTC-USD","price":"2449.17000000","remaining_size":"0.08985400","sequence":3342836150,"time":"2017-06-17T02:38:39.835000Z"}
{"type":"done","side":"sell","order_id":"15e532e0-251b-43a1-a25d-c3188fa0c6db","reason":"canceled","product_id":"BTC-USD","price":"2447.53000000","remaining_size":"0.20000000","sequence":3342836151,"time":"2017-06-17T02:38:39.837000Z"}
