{"type":"received","order_id":"7ac17f85-d805-4da4-bb07-951ab911e073","order_type":"limit","size":"0.10000000","price":"2447.15000000","side":"sell","client_oid":"c1f40869-7a06-450c-84bc-7627802fc233","product_id":"BTC-USD","sequence":3342834812,"time":"2017-06-17T02:38:28.512000Z"}
{"type":"open","side":"sell","price":"2447.15000000","order_id":"7ac17f85-d805-4da4-bb07-951ab911e073","remaining_size":"0.10000000","product_id":"BTC-USD","sequence":3342834813,"time":"2017-06-17T02:38:28.512000Z"}
{"type":"done","side":"sell","order_id":"87aae6f5-efd9-4531-bdca-badd85f9c137","reason":"canceled","product_id":"BTC-USD","price":"2448.77000000","remaining_size":"0.08985400","sequence":3342834814,"time":"2017-06-17T02:38:28.547000Z"}
{"type":"received","order_id":"eb171c4b-4100-4a26-a43c-22961b6a6e50","order_type":"limit","size":"0.08985400","price":"2447.53000000","side":"sell","client_oid":"74c3feb1-5439-4261-a983-752253fd43c7","product_id":"BTC-USD","sequence":3342834815,"time":"2017-06-17T02:38:28.552000Z"}
{"type":"open","side":"sell","price":"2447.53000000","order_id":"eb171c4b-4100-4a26-a43c-22961b6a6e50","remaining_size":"0.08985400","product_id":"BTC-USD","sequence":3342834816,"time":"2017-06-17T02:38:28.552000Z"}
{"type":"done","side":"sell","order_id":"7ac17f85-d805-4da4-bb07-951ab911e073","reason":"canceled","product_id":"BTC-USD","price":"2447.15000000","remaining_size":"0.10000000","sequence":3342834817,"time":"2017-06-17T02:38:28.553000Z"}
{"type":"done","side":"sell","order_id":"e9ee4656-1d1d-4976-af56-b74f35c09c03","reason":"canceled","product_id":"BTC-USD","price":"2447.53000000","remaining_size":"0.20000000","sequence":3342834818,"time":"2017-06-17T02:38:28.558000Z"}
{"type":"received","order_id":"2177c27d-bac8-4b29-8bca-027d3433c1b5","order_type":"limit","size":"0.10000000","price":"2447.14000000","side":"sell","client_oid":"6a7a71c7-5243-4248-be43-39d837328021","product_id":"BTC-USD","sequence":3342834819,"time":"2017-06-17T02:38:28.562000Z"}
{"type":"open","side":"sell","price":"2447.14000000","order_id":"2177c27d-bac8-4b29-8bca-027d3433c1b5","remaining_size":"0.10000000","product_id":"BTC-USD","sequence":3342834820,"time":"2017-06-17T02:38:28.562000Z"}
{"type":"received","order_id":"1eb270c4-acbf-4215-b795-55af87d34177","order_type":"limit","size":"0.20000000","price":"2447.52000000","side":"sell","client_oid":"283fe625-4c55-4335-8f6f-aa740aec84c0","product_id":"BTC-USD","sequence":3342834821,"time":"2017-06-17T02:38:28.567000Z"}
{"type":"open","side":"sell","price":"2447.52000000","order_id":"1eb270c4-acbf-4215-b795-55af87d34177","remaining_size":"0.20000000","product_id":"BTC-USD","sequence":3342834822,"time":"2017-06-17T02:38:28.567000Z"}
{"type":"received","order_id":"c2d4652f-fb6d-41f4-a4c2-9cb0a7f45d9d","order_type":"limit","size":"1.08000000","price":"2435.36000000","side":"buy","product_id":"BTC-USD","sequence":3342834823,"time":"2017-06-17T02:38:28.569000Z"}
{"type":"open","side":"buy","price":"2435.36000000","order_id":"c2d4652f-fb6d-41f4-a4c2-9cb0a7f45d9d","remaining_size":"1.08000000","product_id":"BTC-USD","sequence":3342834824,"time":"2017-06-17T02:38:28.569000Z"}
{"type":"done","side":"sell","order_id":"eb171c4b-4100-4a26-a43c-22961b6a6e50","reason":"canceled","product_id":"BTC-USD","price":"2447.53000000","remaining_size":"0.08985400","sequence":3342834825,"time":"2017-06-17T02:38:28.590000Z"}
{"type":"done","side":"sell","order_id":"1eb270c4-acbf-4215-b795-55af87d34177","reason":"canceled","product_id":"BTC-USD","price":"2447.52000000","remaining_size":"0.20000000","sequence":3342834826,"time":"2017-06-17T02:38:28.593000Z"}
{"type":"received","order_id":"5b172688-a64d-4bfd-8e8a-dbac1676f98b","order_type":"limit","size":"0.08985400","price":"2447.51000000","side":"sell","client_oid":"ea3f6839-0266-4c45-bbf8-5b7575b48fdd","product_id":"BTC-USD","sequence":3342834827,"time":"2017-06-17T02:38:28.600000Z"}
{"type":"open","side":"sell","price":"2447.51000000","order_id":"5b172688-a64d-4bfd-8e8a-dbac1676f98b","remaining_size":"0.08985400","product_id":"BTC-USD","sequence":3342834828,"time":"2017-06-17T02:38:28.600000Z"}
{"type":"received","order_id":"50ca6189-2938-441b-8451-2633ec7013a9","order_type":"limit","size":"0.20000000","price":"2447.51000000","side":"sell","client_oid":"d48b2a96-40c4-4bbc-a7c4-c928817ca6fd","product_id":"BTC-USD","sequence":3342834829,"time":"2017-06-17T02:38:28.607000Z"}
{"type":"open","side":"sell","price":"2447.51000000","order_id":"50ca6189-2938-441b-8451-2633ec7013a9","remaining_size":"0.20000000","product_id":"BTC-USD","sequence":3342834830,"time":"2017-06-17T02:38:28.607000Z"}
{"type":"done","side":"sell","order_id":"2177c27d-bac8-4b29-8bca-027d3433c1b5","reason":"canceled","product_id":"BTC-USD","price":"2447.14000000","remaining_size":"0.10000000","sequence":3342834831,"time":"2017-06-17T02:38:28.627000Z"}
{"type":"received","order_id":"92937ca7-fb36-4ea1-ac37-c4be3ef30480","order_type":"limit","size":"0.20000000","price":"2447.50000000","side":"sell","client_oid":"b8c6d691-9369-4c4e-b0c6-e6a8405ba07a","product_id":"BTC-USD","sequence":3342834832,"time":"2017-06-17T02:38:28.645000Z"}
{"type":"open","side":"sell","price":"2447.50000000","order_id":"92937ca7-fb36-4ea1-ac37-c4be3ef30480","remaining_size":"0.20000000","product_id":"BTC-USD","sequence":3342834833,"time":"2017-06-17T02:38:28.645000Z"}
{"type":"done","side":"sell","order_id":"50ca6189-2938-441b-8451-2633ec7013a9","reason":"canceled","product_id":"BTC-USD","price":"2447.51000000","remaining_size":"0.20000000","sequence":3342834834,"time":"2017-06-17T02:38:28.646000Z"}
{"type":"received","order_id":"945b1f0b-40da-4c59-b186-83551297b234","order_type":"limit","size":"0.08985400","price":"2447.50000000","side":"sell","client_oid":"4e4e7e77-326e-4ec9-8863-7112201802a5","product_id":"BTC-USD","sequence":3342834835,"time":"2017-06-17T02:38:28.650000Z"}
{"type":"open","side":"sell","price":"2447.50000000","order_id":"945b1f0b-40da-4c59-b186-83551297b234","remaining_size":"0.08985400","product_id":"BTC-USD","sequence":3342834836,"time":"2017-06-17T02:38:28.650000Z"}
{"type":"received","order_id":"1eb7eac4-97ee-4592-b437-09c848efa0ea","order_type":"limit","size":"3.92000000","price":"2435.17000000","side":"buy","product_id":"BTC-USD","sequence":3342834837,"time":"2017-06-17T02:38:28.653000Z"}
{"type":"open","side":"buy","price":"2435.17000000","order_id":"1eb7eac4-97ee-4592-b437-09c848efa0ea","remaining_size":"3.92000000","product_id":"BTC-USD","sequence":3342834838,"time":"2017-06-17T02:38:28.653000Z"}
{"type":"received","order_id":"5edf66fe-1da5-433e-b0db-fd50ea6a25d7","order_type":"limit","size":"0.10000000","price":"2447.13000000","side":"sell","client_oid":"b5d72bd3-ad28-46bd-afe8-464c3255cc47","product_id":"BTC-USD","sequence":3342834839,"time":"2017-06-17T02:38:28.655000Z"}
{"type":"open","side":"sell","price":"2447.13000000","order_id":"5edf66fe-1da5-433e-b0db-fd50ea6a25d7","remaining_size":"0.10000000","product_id":"BTC-USD","sequence":3342834840,"time":"2017-06-17T02:38:28.655000Z"}
{"type":"done","side":"sell","order_id":"5b172688-a64d-4bfd-8e8a-dbac1676f98b","reason":"canceled","product_id":"BTC-USD","price":"2447.51000000","remaining_size":"0.08985400","sequence":3342834841,"time":"2017-06-17T02:38:28.656000Z"}
{"type":"done","side":"sell","order_id":"945b1f0b-40da-4c59-b186-83551297b234","reason":"canceled","product_id":"BTC-USD","price":"2447.50000000","remaining_size":"0.08985400","sequence":3342834842,"time":"2017-06-17T02:38:28.670000Z"}
{"type":"done","side":"sell","order_id":"5edf66fe-1da5-433e-b0db-fd50ea6a25d7","reason":"canceled","product_id":"BTC-USD","price":"2447.13000000","remaining_size":"0.10000000","sequence":3342834843,"time":"2017-06-17T02:38:28.685000Z"}
{"type":"received","order_id":"6c065775-f058-4f3a-812c-a9330fc452c7","order_type":"limit","size":"0.10000000","price":"2447.15000000","side":"sell","client_oid":"3b902487-6b59-4a8a-afda-0517547941ad","product_id":"BTC-USD","sequence":3342834844,"time":"2017-06-17T02:38:28.697000Z"}
{"type":"open","side":"sell","price":"2447.15000000","order_id":"6c065775-f058-4f3a-812c-a9330fc452c7","remaining_size":"0.10000000","product_id":"BTC-USD","sequence":3342834845,"time":"2017-06-17T02:38:28.697000Z"}
{"type":"done","side":"sell","order_id":"92937ca7-fb36-4ea1-ac37-c4be3ef30480","reason":"canceled","product_id":"BTC-USD","price":"2447.50000000","remaining_size":"0.20000000","sequence":3342834846,"time":"2017-06-17T02:38:28.700000Z"}
{"type":"received","order_id":"66a594ae-ac6e-4e76-99f7-a834e31f0088","order_type":"limit","size":"0.08985400","price":"2447.49000000","side":"sell","client_oid":"5d4f0dab-94f1-4f99-bf05-e3b7400075b7","product_id":"BTC-USD","sequence":3342834847,"time":"2017-06-17T02:38:28.712000Z"}
{"type":"open","side":"sell","price":"2447.49000000","order_id":"66a594ae-ac6e-4e76-99f7-a834e31f0088","remaining_size":"0.08985400","product_id":"BTC-USD","sequence":3342834848,"time":"2017-06-17T02:38:28.712000Z"}
{"type":"done","side":"sell","order_id":"6c065775-f058-4f3a-812c-a9330fc452c7","reason":"canceled","product_id":"BTC-USD","price":"2447.15000000","remaining_size":"0.10000000","sequence":3342834849,"time":"2017-06-17T02:38:28.733000Z"}
{"type":"done","side":"sell","order_id":"66a594ae-ac6e-4e76-99f7-a834e31f0088","reason":"canceled","product_id":"BTC-USD","price":"2447.49000000","remaining_size":"0.08985400","sequence":3342834850,"time":"2017-06-17T02:38:28.736000Z"}
{"type":"received","order_id":"f00a5252-1840-4bbe-9e66-01582ef861dd","order_type":"limit","size":"0.10000000","price":"2447.14000000","side":"sell","client_oid":"fd6998ee-46eb-454f-9d51-b504326ca569","product_id":"BTC-USD","sequence":3342834851,"time":"2017-06-17T02:38:28.742000Z"}
{"type":"open","side":"sell","price":"2447.14000000","order_id":"f00a5252-1840-4bbe-9e66-01582ef861dd","remaining_size":"0.10000000","product_id":"BTC-USD","sequence":3342834852,"time":"2017-06-17T02:38:28.742000Z"}
{"type":"received","order_id":"2da42ffe-ffa3-4cf7-abea-5e45e23da37b","order_type":"limit","size":"0.08985400","price":"2447.53000000","side":"sell","client_oid":"97f6ee1c-f916-4d62-8fb0-fbf3edeed898","product_id":"BTC-USD","sequence":3342834853,"time":"2017-06-17T02:38:28.749000Z"}
{"type":"open","side":"sell","price":"2447.53000000","order_id":"2da42ffe-ffa3-4cf7-abea-5e45e23da37b","remaining_size":"0.08985400","product_id":"BTC-USD","sequence":3342834854,"time":"2017-06-17T02:38:28.749000Z"}
{"type":"received","order_id":"6f892d11-0a6a-41cc-b5aa-1796fad04063","order_type":"limit","size":"0.20000000","price":"2447.53000000","side":"sell","client_oid":"e1a96436-8fc3-4b30-be74-e323ccf4dc41","product_id":"BTC-USD","sequence":3342834855,"time":"2017-06-17T02:38:28.765000Z"}
{"type":"open","side":"sell","price":"2447.53000000","order_id":"6f892d11-0a6a-41cc-b5aa-1796fad04063","remaining_size":"0.20000000","product_id":"BTC-USD","sequence":3342834856,"time":"2017-06-17T02:38:28.765000Z"}
{"type":"received","order_id":"ce92e500-48dc-4868-a104-b927b64caf46","order_type":"limit","size":"0.10000000","price":"2447.13000000","side":"sell","client_oid":"c7bddad3-c8cd-4bbe-bf1f-2f5ddb587eb8","product_id":"BTC-USD","sequence":3342834857,"time":"2017-06-17T02:38:28.801000Z"}
{"type":"open","side":"sell","price":"2447.13000000","order_id":"ce92e500-48dc-4868-a104-b927b64caf46","remaining_size":"0.10000000","product_id":"BTC-USD","sequence":3342834858,"time":"2017-06-17T02:38:28.801000Z"}
{"type":"received","order_id":"39d5d882-a2fd-4076-b992-ccebe2d541ba","order_type":"limit","size":"0.20000000","price":"2447.52000000","side":"sell","client_oid":"5f60fb78-f67d-4513-a270-858ffea427f0","product_id":"BTC-USD","sequence":3342834859,"time":"2017-06-17T02:38:28.803000Z"}
{"type":"open","side":"sell","price":"2447.52000000","order_id":"39d5d882-a2fd-4076-b992-ccebe2d541ba","remaining_size":"0.20000000","product_id":"BTC-USD","sequence":3342834860,"time":"2017-06-17T02:38:28.803000Z"}
{"type":"received","order_id":"0195b255-7b7c-4d0d-9761-27fa41d7d581","order_type":"limit","size":"0.08985400","price":"2447.52000000","side":"sell","client_oid":"0fa9459b-9824-445b-8607-ef9e2379c4bf","product_id":"BTC-USD","sequence":3342834861,"time":"2017-06-17T02:38:28.803000Z"}
{"type":"open","side":"sell","price":"2447.52000000","order_id":"0195b255-7b7c-4d0d-9761-27fa41d7d581","remaining_size":"0.08985400","product_id":"BTC-USD","sequence":3342834862,"time":"2017-06-17T02:38:28.803000Z"}
{"type":"done","side":"sell","order_id":"f00a5252-1840-4bbe-9e66-01582ef861dd","reason":"canceled","product_id":"BTC-USD","price":"2447.14000000","remaining_size":"0.10000000","sequence":3342834863,"time":"2017-06-17T02:38:28.804000Z"}
{"type":"done","side":"sell","order_id":"2da42ffe-ffa3-4cf7-abea-5e45e23da37b","reason":"canceled","product_id":"BTC-USD","price":"2447.53000000","remaining_size":"0.08985400","sequence":3342834864,"time":"2017-06-17T02:38:28.805000Z"}
{"type":"done","side":"sell","order_id":"6f892d11-0a6a-41cc-b5aa-1796fad04063","reason":"canceled","product_id":"BTC-USD","price":"2447.53000000","remaining_size":"0.20000000","sequence":3342834865,"time":"2017-06-17T02:38:28.806000Z"}
{"type":"done","side":"sell","order_id":"ce92e500-48dc-4868-a104-b927b64caf46","reason":"canceled","product_id":"BTC-USD","price":"2447.13000000","remaining_size":"0.10000000","sequence":3342834866,"time":"2017-06-17T02:38:28.827000Z"}
{"type":"done","side":"sell","order_id":"0195b255-7b7c-4d0d-9761-27fa41d7d581","reason":"canceled","product_id":"BTC-USD","price":"2447.52000000","remaining_size":"0.08985400","sequence":3342834867,"time":"2017-06-17T02:38:28.844000Z"}
{"type":"done","side":"sell","order_id":"39d5d882-a2fd-4076-b992-ccebe2d541ba","reason":"canceled","product_id":"BTC-USD","price":"2447.52000000","remaining_size":"0.20000000","sequence":3342834868,"time":"2017-06-17T02:38:28.846000Z"}
{"type":"received","order_id":"d345f3c9-4adc-48ca-8f7e-b0f032b15154","order_type":"limit","size":"0.08985400","price":"2447.51000000","side":"sell","client_oid":"808d95fc-2f4b-497d-a8d3-f22d8b801d53","product_id":"BTC-USD","sequence":3342834869,"time":"2017-06-17T02:38:28.865000Z"}
{"type":"open","side":"sell","price":"2447.51000000","order_id":"d345f3c9-4adc-48ca-8f7e-b0f032b15154","remaining_size":"0.08985400","product_id":"BTC-USD","sequence":3342834870,"time":"2017-06-17T02:38:28.865000Z"}
{"type":"received","order_id":"2c6af93b-28f8-45f7-84ed-7a10738771fc","order_type":"limit","size":"0.10000000","price":"2447.15000000","side":"sell","client_oid":"1a8c3bc5-8094-42f3-8cb9-0e4fe40b1df4","product_id":"BTC-USD","sequence":3342834871,"time":"2017-06-17T02:38:28.877000Z"}
{"type":"open","side":"sell","price":"2447.15000000","order_id":"2c6af93b-28f8-45f7-84ed-7a10738771fc","remaining_size":"0.10000000","product_id":"BTC-USD","sequence":3342834872,"time":"2017-06-17T02:38:28.877000Z"}
{"type":"done","side":"sell","order_id":"d345f3c9-4adc-48ca-8f7e-b0f032b15154","reason":"canceled","product_id":"BTC-USD","price":"2447.51000000","remaining_size":"0.08985400","sequence":3342834873,"time":"2017-06-17T02:38:28.878000Z"}
{"type":"received","order_id":"f2abcc1c-bfa0-4db5-90be-90670b0cf5d9","order_type":"limit","size":"0.08985400","price":"2449.17000000","side":"sell","client_oid":"03547a13-c2f7-4ec5-b1d8-16f1c658efef","product_id":"BTC-USD","sequence":3342834874,"time":"2017-06-17T02:38:28.884000Z"}
{"type":"open","side":"sell","price":"2449.17000000","order_id":"f2abcc1c-bfa0-4db5-90be-90670b0cf5d9","remaining_size":"0.08985400","product_id":"BTC-USD","sequence":3342834875,"time":"2017-06-17T02:38:28.884000Z"}
{"type":"done","side":"sell","order_id":"2c6af93b-28f8-45f7-84ed-7a10738771fc","reason":"canceled","product_id":"BTC-USD","price":"2447.15000000","remaining_size":"0.10000000","sequence":3342834876,"time":"2017-06-17T02:38:28.889000Z"}
{"type":"received","order_id":"d1078b05-91e3-48eb-b6fa-decd6faebb68","order_type":"limit","size":"0.20000000","price":"2448.77000000","side":"sell","client_oid":"1d777e2e-fb92-479e-aeff-355fc10fb4bd","product_id":"BTC-USD","sequence":3342834877,"time":"2017-06-17T02:38:28.904000Z"}
{"type":"open","side":"sell","price":"2448.77000000","order_id":"d1078b05-91e3-48eb-b6fa-decd6faebb68","remaining_size":"0.20000000","product_id":"BTC-USD","sequence":3342834878,"time":"2017-06-17T02:38:28.904000Z"}
{"type":"received","order_id":"bb548dc3-4099-441f-aca7-23db9d85d91b","order_type":"limit","size":"0.10000000","price":"2447.14000000","side":"sell","client_oid":"759b18b2-10c3-4973-857f-4862d6d5573e","product_id":"BTC-USD","sequence":3342834879,"time":"2017-06-17T02:38:28.911000Z"}
{"type":"open","side":"sell","price":"2447.14000000","order_id":"bb548dc3-4099-441f-aca7-23db9d85d91b","remaining_size":"0.10000000","product_id":"BTC-USD","sequence":3342834880,"time":"2017-06-17T02:38:28.911000Z"}
{"type":"done","side":"sell","order_id":"f2abcc1c-bfa0-4db5-90be-90670b0cf5d9","reason":"canceled","product_id":"BTC-USD","price":"2449.17000000","remaining_size":"0.08985400","sequence":3342834881,"time":"2017-06-17T02:38:28.921000Z"}
{"type":"done","side":"sell","order_id":"bb548dc3-4099-441f-aca7-23db9d85d91b","reason":"canceled","product_id":"BTC-USD","price":"2447.14000000","remaining_size":"0.10000000","sequence":3342834882,"time":"2017-06-17T02:38:28.933000Z"}
{"type":"done","side":"sell","order_id":"d1078b05-91e3-48eb-b6fa-decd6faebb68","reason":"canceled","product_id":"BTC-USD","price":"2448.77000000","remaining_size":"0.20000000","sequence":3342834883,"time":"2017-06-17T02:38:28.935000Z"}
{"type":"received","order_id":"6b9d7fe4-00fb-499d-a13e-b7a5c488a36c","order_type":"limit","size":"0.10000000","price":"2447.13000000","side":"sell","client_oid":"fb97076d-4aff-4f28-9cb1-bb5cba4a17c9","product_id":"BTC-USD","sequence":3342834884,"time":"2017-06-17T02:38:28.947000Z"}
{"type":"open","side":"sell","price":"2447.13000000","order_id":"6b9d7fe4-00fb-499d-a13e-b7a5c488a36c","remaining_size":"0.10000000","product_id":"BTC-USD","sequence":3342834885,"time":"2017-06-17T02:38:28.947000Z"}
{"type":"received","order_id":"ecb2dca8-8ed4-4985-9229-81e6dd350c02","order_type":"limit","size":"23.69797322","price":"2426.01000000","side":"buy","product_id":"BTC-USD","sequence":3342834886,"time":"2017-06-17T02:38:28.962000Z"}
{"type":"open","side":"buy","price":"2426.01000000","order_id":"ecb2dca8-8ed4-4985-9229-81e6dd350c02","remaining_size":"23.69797322","product_id":"BTC-USD","sequence":3342834887,"time":"2017-06-17T02:38:28.962000Z"}
{"type":"done","side":"sell","order_id":"6b9d7fe4-00fb-499d-a13e-b7a5c488a36c","reason":"canceled","product_id":"BTC-USD","price":"2447.13000000","remaining_size":"0.10000000","sequence":3342834888,"time":"2017-06-17T02:38:28.977000Z"}
{"type":"received","order_id":"753cf122-fb8c-4515-b9e3-904f7d46577e","order_type":"limit","size":"0.10000000","price":"2447.12000000","side":"sell","client_oid":"de0dcb65-0281-47d6-973e-32d88563f73d","product_id":"BTC-USD","sequence":3342834889,"time":"2017-06-17T02:38:28.987000Z"}
{"type":"open","side":"sell","price":"2447.12000000","order_id":"753cf122-fb8c-4515-b9e3-904f7d46577e","remaining_size":"0.10000000","product_id":"BTC-USD","sequence":3342834890,"time":"2017-06-17T02:38:28.987000Z"}
{"type":"done","side":"buy","order_id":"2da81499-890b-4abb-834a-0fa3b4d35f92","reason":"canceled","product_id":"BTC-USD","price":"2427.26000000","remaining_size":"23.68535715","sequence":3342834891,"time":"2017-06-17T02:38:28.994000Z"}
{"type":"done","side":"buy","order_id":"1eb7eac4-97ee-4592-b437-09c848efa0ea","reason":"canceled","product_id":"BTC-USD","price":"2435.17000000","remaining_size":"3.92000000","sequence":3342834892,"time":"2017-06-17T02:38:29.008000Z"}
{"type":"done","side":"sell","order_id":"753cf122-fb8c-4515-b9e3-904f7d46577e","reason":"canceled","product_id":"BTC-USD","price":"2447.12000000","remaining_size":"0.10000000","sequence":3342834893,"time":"2017-06-17T02:38:29.021000Z"}
{"type":"done","side":"buy","order_id":"406bb99d-d263-4e6b-8fa6-9aeb87abf86b","reason":"canceled","product_id":"BTC-USD","price":"2442.38000000","remaining_size":"0.02100000","sequence":3342834894,"time":"2017-06-17T02:38:29.026000Z"}
{"type":"received","order_id":"7eadad7b-eb89-42a8-b356-0f9e70db8215","order_type":"limit","size":"0.10000000","price":"2447.11000000","side":"sell","client_oid":"bc39f393-c9cd-4ea2-8390-a7d4c69d983c","product_id":"BTC-USD","sequence":3342834895,"time":"2017-06-17T02:38:29.039000Z"}
{"type":"open","side":"sell","price":"2447.11000000","order_id":"7eadad7b-eb89-42a8-b356-0f9e70db8215","remaining_size":"0.10000000","product_id":"BTC-USD","sequence":3342834896,"time":"2017-06-17T02:38:29.039000Z"}
{"type":"done","side":"buy","order_id":"c2d4652f-fb6d-41f4-a4c2-9cb0a7f45d9d","reason":"canceled","product_id":"BTC-USD","price":"2435.36000000","remaining_size":"1.08000000","sequence":3342834897,"time":"2017-06-17T02:38:29.050000Z"}
{"type":"done","side":"sell","order_id":"7eadad7b-eb89-42a8-b356-0f9e70db8215","reason":"canceled","product_id":"BTC-USD","price":"2447.11000000","remaining_size":"0.10000000","sequence":3342834898,"time":"2017-06-17T02:38:29.072000Z"}
{"type":"received","order_id":"374dbc8a-fe3f-4c0c-974e-27a489948bcb","order_type":"limit","size":"0.10000000","price":"2447.10000000","side":"sell","client_oid":"6a793728-2301-4643-99c0-f0b560705117","product_id":"BTC-USD","sequence":3342834899,"time":"2017-06-17T02:38:29.075000Z"}
{"type":"open","side":"sell","price":"2447.10000000","order_id":"374dbc8a-fe3f-4c0c-974e-27a489948bcb","remaining_size":"0.10000000","product_id":"BTC-USD","sequence":3342834900,"time":"2017-06-17T02:38:29.075000Z"}
{"type":"received","order_id":"31484eb0-25bb-4513-a813-355cc87b3db0","order_type":"limit","size":"0.25000000","price":"2442.77000000","side":"buy","client_oid":"b23bee74-2193-4eb1-aa3f-5dea9bb8e662","product_id":"BTC-USD","sequence":3342834901,"time":"2017-06-17T02:38:29.082000Z"}
{"type":"open","side":"buy","price":"2442.77000000","order_id":"31484eb0-25bb-4513-a813-355cc87b3db0","remaining_size":"0.25000000","product_id":"BTC-USD","sequence":3342834902,"time":"2017-06-17T02:38:29.082000Z"}
{"type":"done","side":"sell","order_id":"374dbc8a-fe3f-4c0c-974e-27a489948bcb","reason":"canceled","product_id":"BTC-USD","price":"2447.10000000","remaining_size":"0.10000000","sequence":3342834903,"time":"2017-06-17T02:38:29.118000Z"}
{"type":"received","order_id":"d45d6d35-16ef-42ea-bdb0-995ef6055b00","order_type":"limit","size":"0.10000000","price":"2447.09000000","side":"sell","client_oid":"83e2b1ff-0265-4f94-bada-a255ca5be284","product_id":"BTC-USD","sequence":3342834904,"time":"2017-06-17T02:38:29.125000Z"}
{"type":"open","side":"sell","price":"2447.09000000","order_id":"d45d6d35-16ef-42ea-bdb0-995ef6055b00","remaining_size":"0.10000000","product_id":"BTC-USD","sequence":3342834905,"time":"2017-06-17T02:38:29.125000Z"}
{"type":"done","side":"sell","order_id":"d45d6d35-16ef-42ea-bdb0-995ef6055b00","reason":"canceled","product_id":"BTC-USD","price":"2447.09000000","remaining_size":"0.10000000","sequence":3342834906,"time":"2017-06-17T02:38:29.159000Z"}
{"type":"done","side":"buy","order_id":"31484eb0-25bb-4513-a813-355cc87b3db0","reason":"canceled","product_id":"BTC-USD","price":"2442.77000000","remaining_size":"0.25000000","sequence":3342834907,"time":"2017-06-17T02:38:29.173000Z"}
{"type":"received","order_id":"cf2ddff3-5343-48da-a9e7-8700b7a134ee","order_type":"limit","size":"0.10000000","price":"2447.08000000","side":"sell","client_oid":"d765a5d9-f36a-4a21-b703-a91265f738b4","product_id":"BTC-USD","sequence":3342834908,"time":"2017-06-17T02:38:29.174000Z"}
{"type":"open","side":"sell","price":"2447.08000000","order_id":"cf2ddff3-5343-48da-a9e7-8700b7a134ee","remaining_size":"0.10000000","product_id":"BTC-USD","sequence":3342834909,"time":"2017-06-17T02:38:29.174000Z"}
{"type":"done","side":"sell","order_id":"cf2ddff3-5343-48da-a9e7-8700b7a134ee","reason":"canceled","product_id":"BTC-USD","price":"2447.08000000","remaining_size":"0.10000000","sequence":3342834910,"time":"2017-06-17T02:38:29.205000Z"}
{"type":"received","order_id":"79fa30c6-5940-47b3-b0e5-03e7e2c35440","order_type":"limit","size":"0.10000000","price":"2447.07000000","side":"sell","client_oid":"8563217a-c872-4932-8f70-686d744fdb23","product_id":"BTC-USD","sequence":3342834911,"time":"2017-06-17T02:38:29.214000Z"}
{"type":"open","side":"sell","price":"2447.07000000","order_id":"79fa30c6-5940-47b3-b0e5-03e7e2c35440","remaining_size":"0.10000000","product_id":"BTC-USD","sequence":3342834912,"time":"2017-06-17T02:38:29.214000Z"}
{"type":"done","side":"sell","order_id":"79fa30c6-5940-47b3-b0e5-03e7e2c35440","reason":"canceled","product_id":"BTC-USD","price":"2447.07000000","remaining_size":"0.10000000","sequence":3342834913,"time":"2017-06-17T02:38:29.255000Z"}
{"type":"received","order_id":"55113e9b-037a-4adb-b824-9cd4d2efaad1","order_type":"limit","size":"0.10000000","price":"2447.06000000","side":"sell","client_oid":"699db2f3-080a-4ede-a6de-7a24279de4ed","product_id":"BTC-USD","sequence":3342834914,"time":"2017-06-17T02:38:29.267000Z"}
{"type":"open","side":"sell","price":"2447.06000000","order_id":"55113e9b-037a-4adb-b824-9cd4d2efaad1","remaining_size":"0.10000000","product_id":"BTC-USD","sequence":3342834915,"time":"2017-06-17T02:38:29.267000Z"}
{"type":"done","side":"sell","order_id":"55113e9b-037a-4adb-b824-9cd4d2efaad1","reason":"canceled","product_id":"BTC-USD","price":"2447.06000000","remaining_size":"0.10000000","sequence":3342834916,"time":"2017-06-17T02:38:29.297000Z"}
{"type":"received","order_id":"dc111bb2-b964-42bc-b165-468688791ba4","order_type":"limit","size":"0.10000000","price":"2447.05000000","side":"sell","client_oid":"5e418836-a1eb-4209-8d17-afd9fcf551c7","product_id":"BTC-USD","sequence":3342834917,"time":"2017-06-17T02:38:29.306000Z"}
{"type":"open","side":"sell","price":"2447.05000000","order_id":"dc111bb2-b964-42bc-b165-468688791ba4","remaining_size":"0.10000000","product_id":"BTC-USD","sequence":3342834918,"time":"2017-06-17T02:38:29.306000Z"}
{"type":"received","order_id":"3ebdae04-51fd-4fd3-ae97-167473d32f68","order_type":"limit","size":"0.20000000","price":"2449.17000000","side":"sell","client_oid":"a5bac4ab-a4bd-44f0-ab47-4794ef9bef53","product_id":"BTC-USD","sequence":3342834919,"time":"2017-06-17T02:38:29.322000Z"}
{"type":"open","side":"sell","price":"2449.17000000","order_id":"3ebdae04-51fd-4fd3-ae97-167473d32f68","remaining_size":"0.20000000","product_id":"BTC-USD","sequence":3342834920,"time":"2017-06-17T02:38:29.322000Z"}
{"type":"done","side":"sell","order_id":"dc111bb2-b964-42bc-b165-468688791ba4","reason":"canceled","product_id":"BTC-USD","price":"2447.05000000","remaining_size":"0.10000000","sequence":3342834921,"time":"2017-06-17T02:38:29.337000Z"}
{"type":"received","order_id":"b83f0fa2-f1b2-4279-8be8-c1b0b116ddf6","order_type":"limit","size":"0.10000000","price":"2447.15000000","side":"sell","client_oid":"ba10d524-b680-4f29-a4e2-72c35bf5f5d5","product_id":"BTC-USD","sequence":3342834922,"time":"2017-06-17T02:38:29.352000Z"}
{"type":"open","side":"sell","price":"2447.15000000","order_id":"b83f0fa2-f1b2-4279-8be8-c1b0b116ddf6","remaining_size":"0.10000000","product_id":"BTC-USD","sequence":3342834923,"time":"2017-06-17T02:38:29.352000Z"}
{"type":"done","side":"sell","order_id":"3ebdae04-51fd-4fd3-ae97-167473d32f68","reason":"canceled","product_id":"BTC-USD","price":"2449.17000000","remaining_size":"0.20000000","sequence":3342834924,"time":"2017-06-17T02:38:29.353000Z"}
{"type":"received","order_id":"4b16a3cd-eaba-41d8-8712-4227df484cde","order_type":"limit","size":"0.08985400","price":"2449.17000000","side":"sell","client_oid":"883941be-fab3-4015-b174-9faaadae1bb1","product_id":"BTC-USD","sequence":3342834925,"time":"2017-06-17T02:38:29.358000Z"}
{"type":"open","side":"sell","price":"2449.17000000","order_id":"4b16a3cd-eaba-41d8-8712-4227df484cde","remaining_size":"0.08985400","product_id":"BTC-USD","sequence":3342834926,"time":"2017-06-17T02:38:29.358000Z"}
{"type":"done","side":"sell","order_id":"4b16a3cd-eaba-41d8-8712-4227df484cde","reason":"canceled","product_id":"BTC-USD","price":"2449.17000000","remaining_size":"0.08985400","sequence":3342834927,"time":"2017-06-17T02:38:29.377000Z"}
{"type":"received","order_id":"06e3c25f-2acf-4ec0-9c57-c78fcf18739b","order_type":"limit","size":"0.08985400","price":"2447.53000000","side":"sell","client_oid":"ea38f4cd-452e-4b24-a210-cd7f2fde2fbd","product_id":"BTC-USD","sequence":3342834928,"time":"2017-06-17T02:38:29.384000Z"}
{"type":"open","side":"sell","price":"2447.53000000","order_id":"06e3c25f-2acf-4ec0-9c57-c78fcf18739b","remaining_size":"0.08985400","product_id":"BTC-USD","sequence":3342834929,"time":"2017-06-17T02:38:29.384000Z"}
{"type":"received","order_id":"9822a031-5bd9-4ab8-9fa0-e75ffc187f8f","order_type":"limit","size":"0.10000000","price":"2447.14000000","side":"sell","client_oid":"ee19acac-9bd0-437b-8e53-a456ecc89612","product_id":"BTC-USD","sequence":3342834930,"time":"2017-06-17T02:38:29.410000Z"}
{"type":"open","side":"sell","price":"2447.14000000","order_id":"9822a031-5bd9-4ab8-9fa0-e75ffc187f8f","remaining_size":"0.10000000","product_id":"BTC-USD","sequence":3342834931,"time":"2017-06-17T02:38:29.410000Z"}
{"type":"done","side":"sell","order_id":"b83f0fa2-f1b2-4279-8be8-c1b0b116ddf6","reason":"canceled","product_id":"BTC-USD","price":"2447.15000000","remaining_size":"0.10000000","sequence":3342834932,"time":"2017-06-17T02:38:29.413000Z"}
{"type":"done","side":"sell","order_id":"9822a031-5bd9-4ab8-9fa0-e75ffc187f8f","reason":"canceled","product_id":"BTC-USD","price":"2447.14000000","remaining_size":"0.10000000","sequence":3342834933,"time":"2017-06-17T02:38:29.415000Z"}
{"type":"done","side":"sell","order_id":"06e3c25f-2acf-4ec0-9c57-c78fcf18739b","reason":"canceled","product_id":"BTC-USD","price":"2447.53000000","remaining_size":"0.08985400","sequence":3342834934,"time":"2017-06-17T02:38:29.418000Z"}
{"type":"received","order_id":"9f32fdfb-596b-4e42-828e-b56a4628c754","order_type":"limit","size":"0.10000000","price":"2447.13000000","side":"sell","client_oid":"4b81912d-f290-43a9-b634-afe9c4ee0018","product_id":"BTC-USD","sequence":3342834935,"time":"2017-06-17T02:38:29.442000Z"}
{"type":"open","side":"sell","price":"2447.13000000","order_id":"9f32fdfb-596b-4e42-828e-b56a4628c754","remaining_size":"0.10000000","product_id":"BTC-USD","sequence":3342834936,"time":"2017-06-17T02:38:29.442000Z"}
{"type":"done","side":"sell","order_id":"9f32fdfb-596b-4e42-828e-b56a4628c754","reason":"canceled","product_id":"BTC-USD","price":"2447.13000000","remaining_size":"0.10000000","sequence":3342834937,"time":"2017-06-17T02:38:29.461000Z"}
{"type":"received","order_id":"0393d87f-ad44-4997-ac47-e68a5c90ce44","order_type":"limit","size":"0.10000000","price":"2447.12000000","side":"sell","client_oid":"8043479f-6e9c-4a72-810c-b314d14dee8e","product_id":"BTC-USD","sequence":3342834938,"time":"2017-06-17T02:38:29.485000Z"}
{"type":"open","side":"sell","price":"2447.12000000","order_id":"0393d87f-ad44-4997-ac47-e68a5c90ce44","remaining_size":"0.10000000","product_id":"BTC-USD","sequence":3342834939,"time":"2017-06-17T02:38:29.485000Z"}
{"type":"done","side":"sell","order_id":"0393d87f-ad44-4997-ac47-e68a5c90ce44","reason":"canceled","product_id":"BTC-USD","price":"2447.12000000","remaining_size":"0.10000000","sequence":3342834940,"time":"2017-06-17T02:38:29.505000Z"}
{"type":"received","order_id":"81083721-440d-482c-8b4f-cd0eae911722","order_type":"limit","size":"0.20000000","price":"2447.53000000","side":"sell","client_oid":"e735a2db-750f-49fc-9446-93e54c2df715","product_id":"BTC-USD","sequence":3342834941,"time":"2017-06-17T02:38:29.530000Z"}
{"type":"open","side":"sell","price":"2447.53000000","order_id":"81083721-440d-482c-8b4f-cd0eae911722","remaining_size":"0.20000000","product_id":"BTC-USD","sequence":3342834942,"time":"2017-06-17T02:38:29.530000Z"}
{"type":"received","order_id":"4fb5557c-7fb8-426f-9c20-481f114eb666","order_type":"limit","size":"0.08985400","price":"2447.52000000","side":"sell","client_oid":"6d75c89f-d4c7-4277-a603-527aad55a837","product_id":"BTC-USD","sequence":3342834943,"time":"2017-06-17T02:38:29.543000Z"}
{"type":"open","side":"sell","price":"2447.52000000","order_id":"4fb5557c-7fb8-426f-9c20-481f114eb666","remaining_size":"0.08985400","product_id":"BTC-USD","sequence":3342834944,"time":"2017-06-17T02:38:29.543000Z"}
{"type":"received","order_id":"5dac7d61-55c1-4f33-8a41-ab6e2a502684","order_type":"limit","size":"0.10000000","price":"2447.11000000","side":"sell","client_oid":"49056d09-fe16-4c38-9911-6f61b93e45ea","product_id":"BTC-USD","sequence":3342834945,"time":"2017-06-17T02:38:29.552000Z"}
{"type":"open","side":"sell","price":"2447.11000000","order_id":"5dac7d61-55c1-4f33-8a41-ab6e2a502684","remaining_size":"0.10000000","product_id":"BTC-USD","sequence":3342834946,"time":"2017-06-17T02:38:29.552000Z"}
{"type":"done","side":"sell","order_id":"4fb5557c-7fb8-426f-9c20-481f114eb666","reason":"canceled","product_id":"BTC-USD","price":"2447.52000000","remaining_size":"0.08985400","sequence":3342834947,"time":"2017-06-17T02:38:29.553000Z"}
{"type":"done","side":"sell","order_id":"81083721-440d-482c-8b4f-cd0eae911722","reason":"canceled","product_id":"BTC-USD","price":"2447.53000000","remaining_size":"0.20000000","sequence":3342834948,"time":"2017-06-17T02:38:29.555000Z"}
{"type":"done","side":"sell","order_id":"5dac7d61-55c1-4f33-8a41-ab6e2a502684","reason":"canceled","product_id":"BTC-USD","price":"2447.11000000","remaining_size":"0.10000000","sequence":3342834949,"time":"2017-06-17T02:38:29.557000Z"}
{"type":"received","order_id":"a6c610c6-3018-4296-bf07-8686265d2f53","order_type":"limit","size":"0.08985400","price":"2447.53000000","side":"sell","client_oid":"accf89c6-dbd3-4af1-880e-c9912f2365c8","product_id":"BTC-USD","sequence":3342834950,"time":"2017-06-17T02:38:29.567000Z"}
{"type":"open","side":"sell","price":"2447.53000000","order_id":"a6c610c6-3018-4296-bf07-8686265d2f53","remaining_size":"0.08985400","product_id":"BTC-USD","sequence":3342834951,"time":"2017-06-17T02:38:29.567000Z"}
{"type":"received","order_id":"9cc3cc01-d680-49f7-8245-2fdd09b05c3a","order_type":"limit","size":"0.10000000","price":"2447.15000000","side":"sell","client_oid":"01b9cba4-0f52-4a44-ada4-cc10cd83a8f6","product_id":"BTC-USD","sequence":3342834952,"time":"2017-06-17T02:38:29.576000Z"}
{"type":"open","side":"sell","price":"2447.15000000","order_id":"9cc3cc01-d680-49f7-8245-2fdd09b05c3a","remaining_size":"0.10000000","product_id":"BTC-USD","sequence":3342834953,"time":"2017-06-17T02:38:29.576000Z"}
{"type":"done","side":"sell","order_id":"9cc3cc01-d680-49f7-8245-2fdd09b05c3a","reason":"canceled","product_id":"BTC-USD","price":"2447.15000000","remaining_size":"0.10000000","sequence":3342834954,"time":"2017-06-17T02:38:29.597000Z"}
{"type":"done","side":"sell","order_id":"a6c610c6-3018-4296-bf07-8686265d2f53","reason":"canceled","product_id":"BTC-USD","price":"2447.53000000","remaining_size":"0.08985400","sequence":3342834955,"time":"2017-06-17T02:38:29.603000Z"}
{"type":"received","order_id":"43a4f8cb-adfe-4e9e-88f1-d6b1e352effd","order_type":"limit","size":"0.10000000","price":"2447.14000000","side":"sell","client_oid":"d9fe5788-bf66-4c1b-8d84-6056450753dd","product_id":"BTC-USD","sequence":3342834956,"time":"2017-06-17T02:38:29.607000Z"}
{"type":"open","side":"sell","price":"2447.14000000","order_id":"43a4f8cb-adfe-4e9e-88f1-d6b1e352effd","remaining_size":"0.10000000","product_id":"BTC-USD","sequence":3342834957,"time":"2017-06-17T02:38:29.607000Z"}
{"type":"done","side":"sell","order_id":"43a4f8cb-adfe-4e9e-88f1-d6b1e352effd","reason":"canceled","product_id":"BTC-USD","price":"2447.14000000","remaining_size":"0.10000000","sequence":3342834958,"time":"2017-06-17T02:38:29.640000Z"}
{"type":"received","order_id":"253ddb5c-fe12-4910-a9e7-b616efb5c556","order_type":"limit","size":"0.10000000","price":"2447.13000000","side":"sell","client_oid":"4af2c8c4-9e6c-4e90-897c-89470e92fc76","product_id":"BTC-USD","sequence":3342834959,"time":"2017-06-17T02:38:29.650000Z"}
{"type":"open","side":"sell","price":"2447.13000000","order_id":"253ddb5c-fe12-4910-a9e7-b616efb5c556","remaining_size":"0.10000000","product_id":"BTC-USD","sequence":3342834960,"time":"2017-06-17T02:38:29.650000Z"}
{"type":"received","order_id":"1a7b5e67-eab4-4f1c-922c-e47381fd893b","order_type":"limit","size":"0.25000000","price":"2442.77000000","side":"buy","client_oid":"765b96a4-2dd5-4ab7-a9bb-96e7ce35d201","product_id":"BTC-USD","sequence":3342834961,"time":"2017-06-17T02:38:29.670000Z"}
{"type":"open","side":"buy","price":"2442.77000000","order_id":"1a7b5e67-eab4-4f1c-922c-e47381fd893b","remaining_size":"0.25000000","product_id":"BTC-USD","sequence":3342834962,"time":"2017-06-17T02:38:29.670000Z"}
{"type":"done","side":"sell","order_id":"253ddb5c-fe12-4910-a9e7-b616efb5c556","reason":"canceled","product_id":"BTC-USD","price":"2447.13000000","remaining_size":"0.10000000","sequence":3342834963,"time":"2017-06-17T02:38:29.683000Z"}
{"type":"received","order_id":"40bfcb6f-41ee-4f8d-a303-888606c87e92","order_type":"limit","size":"0.10000000","price":"2447.12000000","side":"sell","client_oid":"46448aff-56ae-42f6-af96-88d022afdae5","product_id":"BTC-USD","sequence":3342834964,"time":"2017-06-17T02:38:29.692000Z"}
{"type":"open","side":"sell","price":"2447.12000000","order_id":"40bfcb6f-41ee-4f8d-a303-888606c87e92","remaining_size":"0.10000000","product_id":"BTC-USD","sequence":3342834965,"time":"2017-06-17T02:38:29.692000Z"}
{"type":"done","side":"sell","order_id":"40bfcb6f-41ee-4f8d-a303-888606c87e92","reason":"canceled","product_id":"BTC-USD","price":"2447.12000000","remaining_size":"0.10000000","sequence":3342834966,"time":"2017-06-17T02:38:29.725000Z"}
{"type":"received","order_id":"24603766-a745-40f6-89d5-0c90ef4bbd0e","order_type":"limit","size":"0.10000000","price":"2447.11000000","side":"sell","client_oid":"1c9b3c28-cbb2-4bdf-a599-b849bb296249","product_id":"BTC-USD","sequence":3342834967,"time":"2017-06-17T02:38:29.734000Z"}
{"type":"open","side":"sell","price":"2447.11000000","order_id":"24603766-a745-40f6-89d5-0c90ef4bbd0e","remaining_size":"0.10000000","product_id":"BTC-USD","sequence":3342834968,"time":"2017-06-17T02:38:29.734000Z"}
{"type":"done","side":"sell","order_id":"24603766-a745-40f6-89d5-0c90ef4bbd0e","reason":"canceled","product_id":"BTC-USD","price":"2447.11000000","remaining_size":"0.10000000","sequence":3342834969,"time":"2017-06-17T02:38:29.768000Z"}
{"type":"done","side":"buy","order_id":"1a7b5e67-eab4-4f1c-922c-e47381fd893b","reason":"canceled","product_id":"BTC-USD","price":"2442.77000000","remaining_size":"0.25000000","sequence":3342834970,"time":"2017-06-17T02:38:29.775000Z"}
{"type":"received","order_id":"bf00e062-dc58-49f1-ab73-e171f6ac28fb","order_type":"limit","size":"0.10000000","price":"2447.10000000","side":"sell","client_oid":"fcc64d07-edbc-40c0-8d71-c63f23c6588a","product_id":"BTC-USD","sequence":3342834971,"time":"2017-06-17T02:38:29.782000Z"}
{"type":"open","side":"sell","price":"2447.10000000","order_id":"bf00e062-dc58-49f1-ab73-e171f6ac28fb","remaining_size":"0.10000000","product_id":"BTC-USD","sequence":3342834972,"time":"2017-06-17T02:38:29.782000Z"}
{"type":"done","side":"sell","order_id":"bf00e062-dc58-49f1-ab73-e171f6ac28fb","reason":"canceled","product_id":"BTC-USD","price":"2447.10000000","remaining_size":"0.10000000","sequence":3342834973,"time":"2017-06-17T02:38:29.813000Z"}
{"type":"received","order_id":"194a3b2c-0614-4005-9b19-1c241672e7f9","order_type":"limit","size":"0.10000000","price":"2447.09000000","side":"sell","client_oid":"1181c0fb-6803-44b7-b3bc-2343932b604d","product_id":"BTC-USD","sequence":3342834974,"time":"2017-06-17T02:38:29.828000Z"}
{"type":"open","side":"sell","price":"2447.09000000","order_id":"194a3b2c-0614-4005-9b19-1c241672e7f9","remaining_size":"0.10000000","product_id":"BTC-USD","sequence":3342834975,"time":"2017-06-17T02:38:29.828000Z"}
{"type":"done","side":"sell","order_id":"194a3b2c-0614-4005-9b19-1c241672e7f9","reason":"canceled","product_id":"BTC-USD","price":"2447.09000000","remaining_size":"0.10000000","sequence":3342834976,"time":"2017-06-17T02:38:29.857000Z"}
{"type":"received","order_id":"153243ff-795d-4ae0-bb37-e205c813de36","order_type":"limit","size":"0.10000000","price":"2447.08000000","side":"sell","client_oid":"e94a8e50-8173-467c-a4c7-320ef05a6130","product_id":"BTC-USD","sequence":3342834977,"time":"2017-06-17T02:38:29.884000Z"}
{"type":"open","side":"sell","price":"2447.08000000","order_id":"153243ff-795d-4ae0-bb37-e205c813de36","remaining_size":"0.10000000","product_id":"BTC-USD","sequence":3342834978,"time":"2017-06-17T02:38:29.884000Z"}
{"type":"received","order_id":"4e723a9d-d615-48f5-94c0-75535445e0cc","order_type":"market","size":"0.03000000","side":"buy","funds":"73.2900000000000000","product_id":"BTC-USD","sequence":3342834979,"time":"2017-06-17T02:38:29.890000Z"}
{"type":"match","trade_id":16934579,"maker_order_id":"9ba3d7f4-87d1-4a9e-9e1a-f636c6e0a55a","taker_order_id":"4e723a9d-d615-48f5-94c0-75535445e0cc","side":"sell","size":"0.03000000","price":"2443.00000000","product_id":"BTC-USD","sequence":3342834980,"time":"2017-06-17T02:38:29.890000Z"}
{"type":"done","side":"buy","order_id":"4e723a9d-d615-48f5-94c0-75535445e0cc","reason":"filled","product_id":"BTC-USD","remaining_size":"0.00000000","sequence":3342834981,"time":"2017-06-17T02:38:29.890000Z"}
{"type":"done","side":"sell","order_id":"153243ff-795d-4ae0-bb37-e205c813de36","reason":"canceled","product_id":"BTC-USD","price":"2447.08000000","remaining_size":"0.10000000","sequence":3342834982,"time":"2017-06-17T02:38:29.901000Z"}
{"type":"received","order_id":"a56317d7-cd3c-423c-9b7e-e723e08a54bd","order_type":"limit","size":"0.25000000","price":"2442.77000000","side":"buy","client_oid":"b70fe20f-780e-43d4-9b55-89b7e901cbbc","product_id":"BTC-USD","sequence":3342834983,"time":"2017-06-17T02:38:29.908000Z"}
{"type":"open","side":"buy","price":"2442.77000000","order_id":"a56317d7-cd3c-423c-9b7e-e723e08a54bd","remaining_size":"0.25000000","product_id":"BTC-USD","sequence":3342834984,"time":"2017-06-17T02:38:29.908000Z"}
{"type":"received","order_id":"bcf3f485-1b11-484c-8d78-c7e4cc4a2f5a","order_type":"limit","size":"0.02100000","price":"2442.37000000","side":"buy","product_id":"BTC-USD","sequence":3342834985,"time":"2017-06-17T02:38:29.909000Z"}
{"type":"open","side":"buy","price":"2442.37000000","order_id":"bcf3f485-1b11-484c-8d78-c7e4cc4a2f5a","remaining_size":"0.02100000","product_id":"BTC-USD","sequence":3342834986,"time":"2017-06-17T02:38:29.909000Z"}
{"type":"received","order_id":"0fd35942-98ae-4308-8098-83db9d8be45b","order_type":"limit","size":"0.10000000","price":"2447.07000000","side":"sell","client_oid":"d915b19b-5454-4de8-b075-ccc82316a386","product_id":"BTC-USD","sequence":3342834987,"time":"2017-06-17T02:38:29.913000Z"}
{"type":"open","side":"sell","price":"2447.07000000","order_id":"0fd35942-98ae-4308-8098-83db9d8be45b","remaining_size":"0.10000000","product_id":"BTC-USD","sequence":3342834988,"time":"2017-06-17T02:38:29.913000Z"}
{"type":"done","side":"sell","order_id":"ca5418e1-9af4-4fd4-9d78-b277bd4a11fd","reason":"canceled","product_id":"BTC-USD","price":"2443.93000000","remaining_size":"0.50000000","sequence":3342834989,"time":"2017-06-17T02:38:29.938000Z"}
{"type":"done","side":"sell","order_id":"0fd35942-98ae-4308-8098-83db9d8be45b","reason":"canceled","product_id":"BTC-USD","price":"2447.07000000","remaining_size":"0.10000000","sequence":3342834990,"time":"2017-06-17T02:38:29.946000Z"}
{"type":"received","order_id":"899a021c-8f76-486b-a176-2bbf0cb74359","order_type":"limit","size":"0.10000000","price":"2447.06000000","side":"sell","client_oid":"cd255993-7220-4bab-85c9-c07a6161aa1f","product_id":"BTC-USD","sequence":3342834991,"time":"2017-06-17T02:38:29.959000Z"}
{"type":"open","side":"sell","price":"2447.06000000","order_id":"899a021c-8f76-486b-a176-2bbf0cb74359","remaining_size":"0.10000000","product_id":"BTC-USD","sequence":3342834992,"time":"2017-06-17T02:38:29.959000Z"}
{"type":"done","side":"sell","order_id":"899a021c-8f76-486b-a176-2bbf0cb74359","reason":"canceled","product_id":"BTC-USD","price":"2447.06000000","remaining_size":"0.10000000","sequence":3342834993,"time":"2017-06-17T02:38:29.995000Z"}
{"type":"received","order_id":"2adc9b64-4322-481a-9532-be8e60cf8b80","order_type":"limit","size":"0.10000000","price":"2447.05000000","side":"sell","client_oid":"55dce634-fef3-43fa-97f9-64f2193f91b3","product_id":"BTC-USD","sequence":3342834994,"time":"2017-06-17T02:38:30.005000Z"}
{"type":"open","side":"sell","price":"2447.05000000","order_id":"2adc9b64-4322-481a-9532-be8e60cf8b80","remaining_size":"0.10000000","product_id":"BTC-USD","sequence":3342834995,"time":"2017-06-17T02:38:30.005000Z"}
{"type":"done","side":"buy","order_id":"a56317d7-cd3c-423c-9b7e-e723e08a54bd","reason":"canceled","product_id":"BTC-USD","price":"2442.77000000","remaining_size":"0.25000000","sequence":3342834996,"time":"2017-06-17T02:38:30.024000Z"}
{"type":"done","side":"sell","order_id":"2adc9b64-4322-481a-9532-be8e60cf8b80","reason":"canceled","product_id":"BTC-USD","price":"2447.05000000","remaining_size":"0.10000000","sequence":3342834997,"time":"2017-06-17T02:38:30.037000Z"}
{"type":"received","order_id":"7e9e1ce8-e8d0-494d-b6b1-befa6df12b83","order_type":"limit","size":"0.10000000","price":"2447.04000000","side":"sell","client_oid":"61803a06-ace6-4f6d-8310-9e7f5264d345","product_id":"BTC-USD","sequence":3342834998,"time":"2017-06-17T02:38:30.045000Z"}
{"type":"open","side":"sell","price":"2447.04000000","order_id":"7e9e1ce8-e8d0-494d-b6b1-befa6df12b83","remaining_size":"0.10000000","product_id":"BTC-USD","sequence":3342834999,"time":"2017-06-17T02:38:30.045000Z"}
{"type":"received","order_id":"8e95732e-77d6-4bfb-9b0b-390d7d5e3876","order_type":"limit","size":"0.50000000","price":"2443.91000000","side":"sell","client_oid":"417a691f-1aa8-4187-a8a5-c9b9162cbc2f","product_id":"BTC-USD","sequence":3342835000,"time":"2017-06-17T02:38:30.075000Z"}
{"type":"open","side":"sell","price":"2443.91000000","order_id":"8e95732e-77d6-4bfb-9b0b-390d7d5e3876","remaining_size":"0.50000000","product_id":"BTC-USD","sequence":3342835001,"time":"2017-06-17T02:38:30.075000Z"}
{"type":"done","side":"sell","order_id":"7e9e1ce8-e8d0-494d-b6b1-befa6df12b83","reason":"canceled","product_id":"BTC-USD","price":"2447.04000000","remaining_size":"0.10000000","sequence":3342835002,"time":"2017-06-17T02:38:30.080000Z"}
{"type":"received","order_id":"85235b2e-a8e9-4037-b419-fd3cf6d5d844","order_type":"limit","size":"0.10000000","price":"2447.03000000","side":"sell","client_oid":"4c26fc86-e3e5-450c-8509-04dcdc54c466","product_id":"BTC-USD","sequence":3342835003,"time":"2017-06-17T02:38:30.093000Z"}
{"type":"open","side":"sell","price":"2447.03000000","order_id":"85235b2e-a8e9-4037-b419-fd3cf6d5d844","remaining_size":"0.10000000","product_id":"BTC-USD","sequence":3342835004,"time":"2017-06-17T02:38:30.093000Z"}
{"type":"done","side":"sell","order_id":"85235b2e-a8e9-4037-b419-fd3cf6d5d844","reason":"canceled","product_id":"BTC-USD","price":"2447.03000000","remaining_size":"0.10000000","sequence":3342835005,"time":"2017-06-17T02:38:30.127000Z"}
{"type":"received","order_id":"e97671df-568f-4627-a0ea-b8d38f141e04","order_type":"limit","size":"0.10000000","price":"2447.02000000","side":"sell","client_oid":"e97c0a20-ae64-4bb2-8c2a-39e23e671b3e","product_id":"BTC-USD","sequence":3342835006,"time":"2017-06-17T02:38:30.134000Z"}
{"type":"open","side":"sell","price":"2447.02000000","order_id":"e97671df-568f-4627-a0ea-b8d38f141e04","remaining_size":"0.10000000","product_id":"BTC-USD","sequence":3342835007,"time":"2017-06-17T02:38:30.134000Z"}
{"type":"done","side":"sell","order_id":"e97671df-568f-4627-a0ea-b8d38f141e04","reason":"canceled","product_id":"BTC-USD","price":"2447.02000000","remaining_size":"0.10000000","sequence":3342835008,"time":"2017-06-17T02:38:30.169000Z"}
{"type":"received","order_id":"1501f209-52ad-4d6f-a524-3a26fde6abf0","order_type":"limit","size":"0.10000000","price":"2447.01000000","side":"sell","client_oid":"f19a3eba-47ee-458c-bf46-ac351280af55","product_id":"BTC-USD","sequence":3342835009,"time":"2017-06-17T02:38:30.180000Z"}
{"type":"open","side":"sell","price":"2447.01000000","order_id":"1501f209-52ad-4d6f-a524-3a26fde6abf0","remaining_size":"0.10000000","product_id":"BTC-USD","sequence":3342835010,"time":"2017-06-17T02:38:30.180000Z"}
{"type":"done","side":"sell","order_id":"8e95732e-77d6-4bfb-9b0b-390d7d5e3876","reason":"canceled","product_id":"BTC-USD","price":"2443.91000000","remaining_size":"0.50000000","sequence":3342835011,"time":"2017-06-17T02:38:30.181000Z"}
{"type":"done","side":"sell","order_id":"1501f209-52ad-4d6f-a524-3a26fde6abf0","reason":"canceled","product_id":"BTC-USD","price":"2447.01000000","remaining_size":"0.10000000","sequence":3342835012,"time":"2017-06-17T02:38:30.213000Z"}
{"type":"received","order_id":"ad40a1de-9a51-4372-b533-1c129976c48e","order_type":"limit","size":"0.10000000","price":"2447.00000000","side":"sell","client_oid":"9299fab2-fcaf-479d-8fb8-4d83ac0dd968","product_id":"BTC-USD","sequence":3342835013,"time":"2017-06-17T02:38:30.225000Z"}
{"type":"open","side":"sell","price":"2447.00000000","order_id":"ad40a1de-9a51-4372-b533-1c129976c48e","remaining_size":"0.10000000","product_id":"BTC-USD","sequence":3342835014,"time":"2017-06-17T02:38:30.225000Z"}
{"type":"received","order_id":"96784be2-dc9f-4706-b6f1-c71fe672e6cb","order_type":"limit","size":"0.25000000","price":"2442.77000000","side":"buy","client_oid":"6c046699-1d0e-43ef-894b-8e34880028e2","product_id":"BTC-USD","sequence":3342835015,"time":"2017-06-17T02:38:30.244000Z"}
{"type":"open","side":"buy","price":"2442.77000000","order_id":"96784be2-dc9f-4706-b6f1-c71fe672e6cb","remaining_size":"0.25000000","product_id":"BTC-USD","sequence":3342835016,"time":"2017-06-17T02:38:30.244000Z"}
{"type":"done","side":"sell","order_id":"ad40a1de-9a51-4372-b533-1c129976c48e","reason":"canceled","product_id":"BTC-USD","price":"2447.00000000","remaining_size":"0.10000000","sequence":3342835017,"time":"2017-06-17T02:38:30.257000Z"}
{"type":"received","order_id":"f6134304-9bc4-45b4-aac5-26863eac7c49","order_type":"limit","size":"0.10000000","price":"2446.99000000","side":"sell","client_oid":"ee6e3363-a5f9-43ef-860f-5280eaa3754b","product_id":"BTC-USD","sequence":3342835018,"time":"2017-06-17T02:38:30.275000Z"}
{"type":"open","side":"sell","price":"2446.99000000","order_id":"f6134304-9bc4-45b4-aac5-26863eac7c49","remaining_size":"0.10000000","product_id":"BTC-USD","sequence":3342835019,"time":"2017-06-17T02:38:30.275000Z"}
{"type":"done","side":"sell","order_id":"f6134304-9bc4-45b4-aac5-26863eac7c49","reason":"canceled","product_id":"BTC-USD","price":"2446.99000000","remaining_size":"0.10000000","sequence":3342835020,"time":"2017-06-17T02:38:30.296000Z"}
{"type":"received","order_id":"1ce3401d-ecbd-4035-887d-af585c4d74af","order_type":"limit","size":"0.50000000","price":"2443.82000000","side":"sell","client_oid":"9f4c5379-1df0-411b-aec2-c5fed605d621","product_id":"BTC-USD","sequence":3342835021,"time":"2017-06-17T02:38:30.302000Z"}
{"type":"open","side":"sell","price":"2443.82000000","order_id":"1ce3401d-ecbd-4035-887d-af585c4d74af","remaining_size":"0.50000000","product_id":"BTC-USD","sequence":3342835022,"time":"2017-06-17T02:38:30.302000Z"}
{"type":"received","order_id":"539d50b1-832f-4949-9195-f1f536530ae3","order_type":"limit","size":"0.10000000","price":"2446.98000000","side":"sell","client_oid":"f88cfa1c-e578-4800-9b1e-ad234444420a","product_id":"BTC-USD","sequence":3342835023,"time":"2017-06-17T02:38:30.306000Z"}
{"type":"open","side":"sell","price":"2446.98000000","order_id":"539d50b1-832f-4949-9195-f1f536530ae3","remaining_size":"0.10000000","product_id":"BTC-USD","sequence":3342835024,"time":"2017-06-17T02:38:30.306000Z"}
{"type":"done","side":"sell","order_id":"539d50b1-832f-4949-9195-f1f536530ae3","reason":"canceled","product_id":"BTC-USD","price":"2446.98000000","remaining_size":"0.10000000","sequence":3342835025,"time":"2017-06-17T02:38:30.335000Z"}
{"type":"received","order_id":"1846210f-fabc-4d0d-adcd-7c08d554d292","order_type":"limit","size":"0.10000000","price":"2447.15000000","side":"sell","client_oid":"cdc62b15-e89f-4760-8ec3-de2f0d094895","product_id":"BTC-USD","sequence":3342835026,"time":"2017-06-17T02:38:30.352000Z"}
{"type":"open","side":"sell","price":"2447.15000000","order_id":"1846210f-fabc-4d0d-adcd-7c08d554d292","remaining_size":"0.10000000","product_id":"BTC-USD","sequence":3342835027,"time":"2017-06-17T02:38:30.352000Z"}
{"type":"done","side":"sell","order_id":"1846210f-fabc-4d0d-adcd-7c08d554d292","reason":"canceled","product_id":"BTC-USD","price":"2447.15000000","remaining_size":"0.10000000","sequence":3342835028,"time":"2017-06-17T02:38:30.360000Z"}
{"type":"received","order_id":"14e7f9e0-18ba-47e4-a0a2-131e6a5ead69","order_type":"limit","size":"0.20000000","price":"2447.53000000","side":"sell","client_oid":"79d50f95-bac8-4851-853c-f073949aa3f5","product_id":"BTC-USD","sequence":3342835029,"time":"2017-06-17T02:38:30.361000Z"}
{"type":"open","side":"sell","price":"2447.53000000","order_id":"14e7f9e0-18ba-47e4-a0a2-131e6a5ead69","remaining_size":"0.20000000","product_id":"BTC-USD","sequence":3342835030,"time":"2017-06-17T02:38:30.361000Z"}
{"type":"done","side":"buy","order_id":"96784be2-dc9f-4706-b6f1-c71fe672e6cb","reason":"canceled","product_id":"BTC-USD","price":"2442.77000000","remaining_size":"0.25000000","sequence":3342835031,"time":"2017-06-17T02:38:30.362000Z"}
{"type":"received","order_id":"eb14532a-cb8b-4ddc-9449-fe19750a3e60","order_type":"limit","size":"0.08985400","price":"2447.53000000","side":"sell","client_oid":"122fd13d-3244-4cf5-8f82-d91632cb7c07","product_id":"BTC-USD","sequence":3342835032,"time":"2017-06-17T02:38:30.364000Z"}
{"type":"open","side":"sell","price":"2447.53000000","order_id":"eb14532a-cb8b-4ddc-9449-fe19750a3e60","remaining_size":"0.08985400","product_id":"BTC-USD","sequence":3342835033,"time":"2017-06-17T02:38:30.364000Z"}
{"type":"received","order_id":"b93fce6e-ca67-43fa-b955-1ee1f36785fa","order_type":"limit","size":"0.50000000","price":"2442.62000000","side":"buy","client_oid":"a81d3faf-4e77-40f3-8d65-193401f2ecfe","product_id":"BTC-USD","sequence":3342835034,"time":"2017-06-17T02:38:30.373000Z"}
{"type":"open","side":"buy","price":"2442.62000000","order_id":"b93fce6e-ca67-43fa-b955-1ee1f36785fa","remaining_size":"0.50000000","product_id":"BTC-USD","sequence":3342835035,"time":"2017-06-17T02:38:30.373000Z"}
{"type":"done","side":"sell","order_id":"eb14532a-cb8b-4ddc-9449-fe19750a3e60","reason":"canceled","product_id":"BTC-USD","price":"2447.53000000","remaining_size":"0.08985400","sequence":3342835036,"time":"2017-06-17T02:38:30.376000Z"}
{"type":"received","order_id":"037e42ab-3677-4d98-85a9-e56522135ad0","order_type":"limit","size":"0.10000000","price":"2447.15000000","side":"sell","client_oid":"0533204e-7999-443b-b567-705915a70795","product_id":"BTC-USD","sequence":3342835037,"time":"2017-06-17T02:38:30.387000Z"}
{"type":"open","side":"sell","price":"2447.15000000","order_id":"037e42ab-3677-4d98-85a9-e56522135ad0","remaining_size":"0.10000000","product_id":"BTC-USD","sequence":3342835038,"time":"2017-06-17T02:38:30.387000Z"}
{"type":"done","side":"sell","order_id":"14e7f9e0-18ba-47e4-a0a2-131e6a5ead69","reason":"canceled","product_id":"BTC-USD","price":"2447.53000000","remaining_size":"0.20000000","sequence":3342835039,"time":"2017-06-17T02:38:30.388000Z"}
{"type":"received","order_id":"9e7d486c-3fa7-40ef-99a1-e845206b1ef1","order_type":"limit","size":"0.08985400","price":"2449.17000000","side":"sell","client_oid":"1a8d4ce3-6cc4-4491-bcdc-5cb7d064e529","product_id":"BTC-USD","sequence":3342835040,"time":"2017-06-17T02:38:30.400000Z"}
{"type":"open","side":"sell","price":"2449.17000000","order_id":"9e7d486c-3fa7-40ef-99a1-e845206b1ef1","remaining_size":"0.08985400","product_id":"BTC-USD","sequence":3342835041,"time":"2017-06-17T02:38:30.400000Z"}
{"type":"received","order_id":"56d68dfa-1589-4af5-be16-77f46d1110f8","order_type":"limit","size":"0.20000000","price":"2449.17000000","side":"sell","client_oid":"a08e0cc9-a24c-4f97-a774-83114050bef4","product_id":"BTC-USD","sequence":3342835042,"time":"2017-06-17T02:38:30.416000Z"}
{"type":"open","side":"sell","price":"2449.17000000","order_id":"56d68dfa-1589-4af5-be16-77f46d1110f8","remaining_size":"0.20000000","product_id":"BTC-USD","sequence":3342835043,"time":"2017-06-17T02:38:30.416000Z"}
{"type":"done","side":"sell","order_id":"037e42ab-3677-4d98-85a9-e56522135ad0","reason":"canceled","product_id":"BTC-USD","price":"2447.15000000","remaining_size":"0.10000000","sequence":3342835044,"time":"2017-06-17T02:38:30.419000Z"}
{"type":"done","side":"sell","order_id":"9e7d486c-3fa7-40ef-99a1-e845206b1ef1","reason":"canceled","product_id":"BTC-USD","price":"2449.17000000","remaining_size":"0.08985400","sequence":3342835045,"time":"2017-06-17T02:38:30.421000Z"}
{"type":"done","side":"sell","order_id":"56d68dfa-1589-4af5-be16-77f46d1110f8","reason":"canceled","product_id":"BTC-USD","price":"2449.17000000","remaining_size":"0.20000000","sequence":3342835046,"time":"2017-06-17T02:38:30.422000Z"}
{"type":"received","order_id":"b4273405-cc6e-424f-adf2-300f8bbb6554","order_type":"limit","size":"0.10000000","price":"2447.14000000","side":"sell","client_oid":"b292e3f5-527b-407a-a519-4977b6384409","product_id":"BTC-USD","sequence":3342835047,"time":"2017-06-17T02:38:30.427000Z"}
{"type":"open","side":"sell","price":"2447.14000000","order_id":"b4273405-cc6e-424f-adf2-300f8bbb6554","remaining_size":"0.10000000","product_id":"BTC-USD","sequence":3342835048,"time":"2017-06-17T02:38:30.427000Z"}
{"type":"received","order_id":"88432edb-b8c8-47c8-973b-30d19ebe35ac","order_type":"limit","size":"0.08985400","price":"2447.53000000","side":"sell","client_oid":"acb63bd9-46ce-4777-992c-36b8cfea8d9b","product_id":"BTC-USD","sequence":3342835049,"time":"2017-06-17T02:38:30.433000Z"}
{"type":"open","side":"sell","price":"2447.53000000","order_id":"88432edb-b8c8-47c8-973b-30d19ebe35ac","remaining_size":"0.08985400","product_id":"BTC-USD","sequence":3342835050,"time":"2017-06-17T02:38:30.433000Z"}
{"type":"done","side":"sell","order_id":"b4273405-cc6e-424f-adf2-300f8bbb6554","reason":"canceled","product_id":"BTC-USD","price":"2447.14000000","remaining_size":"0.10000000","sequence":3342835051,"time":"2017-06-17T02:38:30.465000Z"}
{"type":"done","side":"sell","order_id":"88432edb-b8c8-47c8-973b-30d19ebe35ac","reason":"canceled","product_id":"BTC-USD","price":"2447.53000000","remaining_size":"0.08985400","sequence":3342835052,"time":"2017-06-17T02:38:30.473000Z"}
{"type":"received","order_id":"33936797-47bb-4dfb-8d64-e4328e470e4a","order_type":"limit","size":"0.10000000","price":"2447.13000000","side":"sell","client_oid":"7fda352c-869d-4b33-b477-5e90b396b003","product_id":"BTC-USD","sequence":3342835053,"time":"2017-06-17T02:38:30.474000Z"}
{"type":"open","side":"sell","price":"2447.13000000","order_id":"33936797-47bb-4dfb-8d64-e4328e470e4a","remaining_size":"0.10000000","product_id":"BTC-USD","sequence":3342835054,"time":"2017-06-17T02:38:30.474000Z"}
{"type":"received","order_id":"7e63a8b7-a94f-4cf1-badb-9e5b8272e7d7","order_type":"limit","size":"0.25000000","price":"2442.77000000","side":"buy","client_oid":"f897750a-13fa-43b0-aab5-e377293cc971","product_id":"BTC-USD","sequence":3342835055,"time":"2017-06-17T02:38:30.480000Z"}
{"type":"open","side":"buy","price":"2442.77000000","order_id":"7e63a8b7-a94f-4cf1-badb-9e5b8272e7d7","remaining_size":"0.25000000","product_id":"BTC-USD","sequence":3342835056,"time":"2017-06-17T02:38:30.480000Z"}
{"type":"received","order_id":"3b672134-b56d-4704-80da-35de805c7374","order_type":"limit","size":"0.08985400","price":"2448.77000000","side":"sell","client_oid":"2e11a583-82e0-4e50-a1e0-fdf3d895be19","product_id":"BTC-USD","sequence":3342835057,"time":"2017-06-17T02:38:30.481000Z"}
{"type":"open","side":"sell","price":"2448.77000000","order_id":"3b672134-b56d-4704-80da-35de805c7374","remaining_size":"0.08985400","product_id":"BTC-USD","sequence":3342835058,"time":"2017-06-17T02:38:30.481000Z"}
{"type":"done","side":"sell","order_id":"33936797-47bb-4dfb-8d64-e4328e470e4a","reason":"canceled","product_id":"BTC-USD","price":"2447.13000000","remaining_size":"0.10000000","sequence":3342835059,"time":"2017-06-17T02:38:30.509000Z"}
{"type":"received","order_id":"d4c042f1-7e9f-48d0-952c-f1fe03198fc6","order_type":"limit","size":"0.10000000","price":"2447.12000000","side":"sell","client_oid":"53ddb322-7e07-4ada-9cdc-dd8ce6b65f37","product_id":"BTC-USD","sequence":3342835060,"time":"2017-06-17T02:38:30.518000Z"}
{"type":"open","side":"sell","price":"2447.12000000","order_id":"d4c042f1-7e9f-48d0-952c-f1fe03198fc6","remaining_size":"0.10000000","product_id":"BTC-USD","sequence":3342835061,"time":"2017-06-17T02:38:30.518000Z"}
{"type":"done","side":"sell","order_id":"3b672134-b56d-4704-80da-35de805c7374","reason":"canceled","product_id":"BTC-USD","price":"2448.77000000","remaining_size":"0.08985400","sequence":3342835062,"time":"2017-06-17T02:38:30.534000Z"}
{"type":"done","side":"sell","order_id":"d4c042f1-7e9f-48d0-952c-f1fe03198fc6","reason":"canceled","product_id":"BTC-USD","price":"2447.12000000","remaining_size":"0.10000000","sequence":3342835063,"time":"2017-06-17T02:38:30.551000Z"}
{"type":"received","order_id":"36ad2a80-10fb-4d50-bc0c-78638ddfd78f","order_type":"limit","size":"0.08985400","price":"2447.53000000","side":"sell","client_oid":"762c3caf-ec0d-4262-ac1d-9cc6b53662d4","product_id":"BTC-USD","sequence":3342835064,"time":"2017-06-17T02:38:30.555000Z"}
{"type":"open","side":"sell","price":"2447.53000000","order_id":"36ad2a80-10fb-4d50-bc0c-78638ddfd78f","remaining_size":"0.08985400","product_id":"BTC-USD","sequence":3342835065,"time":"2017-06-17T02:38:30.555000Z"}
{"type":"received","order_id":"89bbbec2-130c-4eb4-8728-5dccf2c2731c","order_type":"limit","size":"0.10000000","price":"2447.11000000","side":"sell","client_oid":"4f2c7e17-8c60-44ef-8607-17ef1bc61d27","product_id":"BTC-USD","sequence":3342835066,"time":"2017-06-17T02:38:30.561000Z"}
{"type":"open","side":"sell","price":"2447.11000000","order_id":"89bbbec2-130c-4eb4-8728-5dccf2c2731c","remaining_size":"0.10000000","product_id":"BTC-USD","sequence":3342835067,"time":"2017-06-17T02:38:30.561000Z"}
{"type":"done","side":"sell","order_id":"89bbbec2-130c-4eb4-8728-5dccf2c2731c","reason":"canceled","product_id":"BTC-USD","price":"2447.11000000","remaining_size":"0.10000000","sequence":3342835068,"time":"2017-06-17T02:38:30.593000Z"}
{"type":"done","side":"sell","order_id":"36ad2a80-10fb-4d50-bc0c-78638ddfd78f","reason":"canceled","product_id":"BTC-USD","price":"2447.53000000","remaining_size":"0.08985400","sequence":3342835069,"time":"2017-06-17T02:38:30.600000Z"}
{"type":"done","side":"buy","order_id":"7e63a8b7-a94f-4cf1-badb-9e5b8272e7d7","reason":"canceled","product_id":"BTC-USD","price":"2442.77000000","remaining_size":"0.25000000","sequence":3342835070,"time":"2017-06-17T02:38:30.600000Z"}
{"type":"received","order_id":"a58d7db7-fd17-4e5d-a489-f0cf0661ec96","order_type":"limit","size":"0.10000000","price":"2447.10000000","side":"sell","client_oid":"ea309ad3-ec3f-4977-ab9a-6bfeec621843","product_id":"BTC-USD","sequence":3342835071,"time":"2017-06-17T02:38:30.614000Z"}
{"type":"open","side":"sell","price":"2447.10000000","order_id":"a58d7db7-fd17-4e5d-a489-f0cf0661ec96","remaining_size":"0.10000000","product_id":"BTC-USD","sequence":3342835072,"time":"2017-06-17T02:38:30.614000Z"}
{"type":"received","order_id":"193aaf89-6da8-4f1e-ba4e-328ec274cc88","order_type":"limit","size":"0.08985400","price":"2448.77000000","side":"sell","client_oid":"c56b0949-aa79-40ea-8a41-79f057733c3d","product_id":"BTC-USD","sequence":3342835073,"time":"2017-06-17T02:38:30.625000Z"}
{"type":"open","side":"sell","price":"2448.77000000","order_id":"193aaf89-6da8-4f1e-ba4e-328ec274cc88","remaining_size":"0.08985400","product_id":"BTC-USD","sequence":3342835074,"time":"2017-06-17T02:38:30.625000Z"}
{"type":"done","side":"sell","order_id":"a58d7db7-fd17-4e5d-a489-f0cf0661ec96","reason":"canceled","product_id":"BTC-USD","price":"2447.10000000","remaining_size":"0.10000000","sequence":3342835075,"time":"2017-06-17T02:38:30.637000Z"}
{"type":"received","order_id":"17fe742d-01a3-494c-9dab-1d387495d126","order_type":"limit","size":"0.25000000","price":"2442.78000000","side":"buy","client_oid":"f6dee791-bf67-4ca1-bd3b-3c9501558dc8","product_id":"BTC-USD","sequence":3342835076,"time":"2017-06-17T02:38:30.644000Z"}
{"type":"open","side":"buy","price":"2442.78000000","order_id":"17fe742d-01a3-494c-9dab-1d387495d126","remaining_size":"0.25000000","product_id":"BTC-USD","sequence":3342835077,"time":"2017-06-17T02:38:30.644000Z"}
{"type":"received","order_id":"a44a29e6-2c15-46b2-849a-7a9bba8ab567","order_type":"limit","size":"0.10000000","price":"2447.09000000","side":"sell","client_oid":"6637da4a-9513-45cb-9d19-a6f890d0e9c7","product_id":"BTC-USD","sequence":3342835078,"time":"2017-06-17T02:38:30.647000Z"}
{"type":"open","side":"sell","price":"2447.09000000","order_id":"a44a29e6-2c15-46b2-849a-7a9bba8ab567","remaining_size":"0.10000000","product_id":"BTC-USD","sequence":3342835079,"time":"2017-06-17T02:38:30.647000Z"}
{"type":"done","side":"sell","order_id":"193aaf89-6da8-4f1e-ba4e-328ec274cc88","reason":"canceled","product_id":"BTC-USD","price":"2448.77000000","remaining_size":"0.08985400","sequence":3342835080,"time":"2017-06-17T02:38:30.657000Z"}
{"type":"received","order_id":"5b8bcda3-3c71-4404-af81-d3de80fe98ab","order_type":"limit","size":"0.08985400","price":"2447.53000000","side":"sell","client_oid":"0ab5b48a-ea3f-4d67-93ae-139fbcf978e9","product_id":"BTC-USD","sequence":3342835081,"time":"2017-06-17T02:38:30.666000Z"}
{"type":"open","side":"sell","price":"2447.53000000","order_id":"5b8bcda3-3c71-4404-af81-d3de80fe98ab","remaining_size":"0.08985400","product_id":"BTC-USD","sequence":3342835082,"time":"2017-06-17T02:38:30.666000Z"}
{"type":"done","side":"buy","order_id":"29582f03-1a90-4f25-8082-2d7a8e46577f","reason":"canceled","product_id":"BTC-USD","price":"2442.99000000","remaining_size":"0.46484897","sequence":3342835083,"time":"2017-06-17T02:38:30.670000Z"}
{"type":"done","side":"sell","order_id":"a44a29e6-2c15-46b2-849a-7a9bba8ab567","reason":"canceled","product_id":"BTC-USD","price":"2447.09000000","remaining_size":"0.10000000","sequence":3342835084,"time":"2017-06-17T02:38:30.680000Z"}
{"type":"received","order_id":"0ab8845b-9173-43ba-b0b9-a8accb0d963d","order_type":"limit","size":"0.10000000","price":"2447.08000000","side":"sell","client_oid":"9cd9c79e-a126-4335-9c81-f857e5697bb3","product_id":"BTC-USD","sequence":3342835085,"time":"2017-06-17T02:38:30.690000Z"}
{"type":"open","side":"sell","price":"2447.08000000","order_id":"0ab8845b-9173-43ba-b0b9-a8accb0d963d","remaining_size":"0.10000000","product_id":"BTC-USD","sequence":3342835086,"time":"2017-06-17T02:38:30.690000Z"}
{"type":"done","side":"buy","order_id":"17fe742d-01a3-494c-9dab-1d387495d126","reason":"canceled","product_id":"BTC-USD","price":"2442.78000000","remaining_size":"0.25000000","sequence":3342835087,"time":"2017-06-17T02:38:30.713000Z"}
{"type":"done","side":"sell","order_id":"5b8bcda3-3c71-4404-af81-d3de80fe98ab","reason":"canceled","product_id":"BTC-USD","price":"2447.53000000","remaining_size":"0.08985400","sequence":3342835088,"time":"2017-06-17T02:38:30.713000Z"}
{"type":"received","order_id":"5c710d09-4279-43a1-8ec6-b9e4fb8500b9","order_type":"limit","size":"0.08985400","price":"2448.77000000","side":"sell","client_oid":"1fc5dbfa-a198-461f-b38a-4ac4a5390fd2","product_id":"BTC-USD","sequence":3342835089,"time":"2017-06-17T02:38:30.714000Z"}
{"type":"open","side":"sell","price":"2448.77000000","order_id":"5c710d09-4279-43a1-8ec6-b9e4fb8500b9","remaining_size":"0.08985400","product_id":"BTC-USD","sequence":3342835090,"time":"2017-06-17T02:38:30.714000Z"}
{"type":"done","side":"sell","order_id":"0ab8845b-9173-43ba-b0b9-a8accb0d963d","reason":"canceled","product_id":"BTC-USD","price":"2447.08000000","remaining_size":"0.10000000","sequence":3342835091,"time":"2017-06-17T02:38:30.721000Z"}
{"type":"received","order_id":"f0f753d9-2150-4095-96dd-66684e56db46","order_type":"limit","size":"0.10000000","price":"2447.07000000","side":"sell","client_oid":"b527f208-17d6-4944-b3bd-e76b97e4ab92","product_id":"BTC-USD","sequence":3342835092,"time":"2017-06-17T02:38:30.949000Z"}
{"type":"open","side":"sell","price":"2447.07000000","order_id":"f0f753d9-2150-4095-96dd-66684e56db46","remaining_size":"0.10000000","product_id":"BTC-USD","sequence":3342835093,"time":"2017-06-17T02:38:30.949000Z"}
{"type":"received","order_id":"4221a934-5927-42c5-be3b-36406d736272","order_type":"limit","size":"0.91068348","price":"2442.99000000","side":"buy","client_oid":"b946fe4b-03c6-46fa-8aca-df10b1de7ad6","product_id":"BTC-USD","sequence":3342835094,"time":"2017-06-17T02:38:30.950000Z"}
{"type":"open","side":"buy","price":"2442.99000000","order_id":"4221a934-5927-42c5-be3b-36406d736272","remaining_size":"0.91068348","product_id":"BTC-USD","sequence":3342835095,"time":"2017-06-17T02:38:30.950000Z"}
{"type":"done","side":"sell","order_id":"f0f753d9-2150-4095-96dd-66684e56db46","reason":"canceled","product_id":"BTC-USD","price":"2447.07000000","remaining_size":"0.10000000","sequence":3342835096,"time":"2017-06-17T02:38:30.954000Z"}
{"type":"received","order_id":"201349c5-41dc-4bb8-8d78-a3466c6f229f","order_type":"limit","size":"0.20000000","price":"2448.77000000","side":"sell","client_oid":"ce73cfd1-d678-4417-a666-bd447f07524e","product_id":"BTC-USD","sequence":3342835097,"time":"2017-06-17T02:38:30.961000Z"}
{"type":"open","side":"sell","price":"2448.77000000","order_id":"201349c5-41dc-4bb8-8d78-a3466c6f229f","remaining_size":"0.20000000","product_id":"BTC-USD","sequence":3342835098,"time":"2017-06-17T02:38:30.961000Z"}
{"type":"done","side":"sell","order_id":"201349c5-41dc-4bb8-8d78-a3466c6f229f","reason":"canceled","product_id":"BTC-USD","price":"2448.77000000","remaining_size":"0.20000000","sequence":3342835099,"time":"2017-06-17T02:38:30.965000Z"}
{"type":"received","order_id":"d6a9f16d-0cdb-4e86-930a-0fa3f15e0288","order_type":"limit","size":"0.10000000","price":"2447.15000000","side":"sell","client_oid":"dc34e552-8975-4319-ab58-025d2c842016","product_id":"BTC-USD","sequence":3342835100,"time":"2017-06-17T02:38:30.968000Z"}
{"type":"open","side":"sell","price":"2447.15000000","order_id":"d6a9f16d-0cdb-4e86-930a-0fa3f15e0288","remaining_size":"0.10000000","product_id":"BTC-USD","sequence":3342835101,"time":"2017-06-17T02:38:30.968000Z"}
{"type":"done","side":"sell","order_id":"5c710d09-4279-43a1-8ec6-b9e4fb8500b9","reason":"canceled","product_id":"BTC-USD","price":"2448.77000000","remaining_size":"0.08985400","sequence":3342835102,"time":"2017-06-17T02:38:30.968000Z"}
{"type":"received","order_id":"37c3dfe0-9b64-422b-aa10-36b450d2cfdd","order_type":"limit","size":"0.08985400","price":"2447.53000000","side":"sell","client_oid":"ebee3461-9f69-4ab7-a544-cd978fbefbf8","product_id":"BTC-USD","sequence":3342835103,"time":"2017-06-17T02:38:30.979000Z"}
{"type":"open","side":"sell","price":"2447.53000000","order_id":"37c3dfe0-9b64-422b-aa10-36b450d2cfdd","remaining_size":"0.08985400","product_id":"BTC-USD","sequence":3342835104,"time":"2017-06-17T02:38:30.979000Z"}
{"type":"done","side":"sell","order_id":"d6a9f16d-0cdb-4e86-930a-0fa3f15e0288","reason":"canceled","product_id":"BTC-USD","price":"2447.15000000","remaining_size":"0.10000000","sequence":3342835105,"time":"2017-06-17T02:38:31.007000Z"}
{"type":"done","side":"sell","order_id":"37c3dfe0-9b64-422b-aa10-36b450d2cfdd","reason":"canceled","product_id":"BTC-USD","price":"2447.53000000","remaining_size":"0.08985400","sequence":3342835106,"time":"2017-06-17T02:38:31.013000Z"}
{"type":"received","order_id":"50936713-e457-46e4-bf4a-3265f3f5fcb3","order_type":"limit","size":"0.10000000","price":"2447.14000000","side":"sell","client_oid":"69bc5e7e-c69d-4dff-95a3-72ec899fd038","product_id":"BTC-USD","sequence":3342835107,"time":"2017-06-17T02:38:31.016000Z"}
{"type":"open","side":"sell","price":"2447.14000000","order_id":"50936713-e457-46e4-bf4a-3265f3f5fcb3","remaining_size":"0.10000000","product_id":"BTC-USD","sequence":3342835108,"time":"2017-06-17T02:38:31.016000Z"}
{"type":"received","order_id":"a8cb2373-3ad5-4e2c-949b-6bfe92341925","order_type":"limit","size":"0.08985400","price":"2448.77000000","side":"sell","client_oid":"3c0e84b2-2a36-48b1-b322-32a39e791260","product_id":"BTC-USD","sequence":3342835109,"time":"2017-06-17T02:38:31.024000Z"}
{"type":"open","side":"sell","price":"2448.77000000","order_id":"a8cb2373-3ad5-4e2c-949b-6bfe92341925","remaining_size":"0.08985400","product_id":"BTC-USD","sequence":3342835110,"time":"2017-06-17T02:38:31.024000Z"}
{"type":"done","side":"sell","order_id":"50936713-e457-46e4-bf4a-3265f3f5fcb3","reason":"canceled","product_id":"BTC-USD","price":"2447.14000000","remaining_size":"0.10000000","sequence":3342835111,"time":"2017-06-17T02:38:31.044000Z"}
{"type":"received","order_id":"87e490c4-272c-4552-bf7a-67cb4847ea70","order_type":"limit","size":"0.10000000","price":"2447.13000000","side":"sell","client_oid":"a6213b9a-2d14-441a-9495-3aad93cf5761","product_id":"BTC-USD","sequence":3342835112,"time":"2017-06-17T02:38:31.066000Z"}
{"type":"open","side":"sell","price":"2447.13000000","order_id":"87e490c4-272c-4552-bf7a-67cb4847ea70","remaining_size":"0.10000000","product_id":"BTC-USD","sequence":3342835113,"time":"2017-06-17T02:38:31.066000Z"}
{"type":"done","side":"sell","order_id":"a8cb2373-3ad5-4e2c-949b-6bfe92341925","reason":"canceled","product_id":"BTC-USD","price":"2448.77000000","remaining_size":"0.08985400","sequence":3342835114,"time":"2017-06-17T02:38:31.076000Z"}
{"type":"received","order_id":"b81f042a-3f47-4bc6-98a6-fe3f79604524","order_type":"limit","size":"0.08985400","price":"2447.53000000","side":"sell","client_oid":"a537116c-8dcf-4b18-9da5-7fb9c93c41a1","product_id":"BTC-USD","sequence":3342835115,"time":"2017-06-17T02:38:31.088000Z"}
{"type":"open","side":"sell","price":"2447.53000000","order_id":"b81f042a-3f47-4bc6-98a6-fe3f79604524","remaining_size":"0.08985400","product_id":"BTC-USD","sequence":3342835116,"time":"2017-06-17T02:38:31.088000Z"}
{"type":"done","side":"sell","order_id":"87e490c4-272c-4552-bf7a-67cb4847ea70","reason":"canceled","product_id":"BTC-USD","price":"2447.13000000","remaining_size":"0.10000000","sequence":3342835117,"time":"2017-06-17T02:38:31.089000Z"}
{"type":"received","order_id":"af2cb935-9b0d-4d9f-b2ba-01ea517d1bac","order_type":"limit","size":"0.10000000","price":"2447.12000000","side":"sell","client_oid":"5d053d1b-178d-4d1d-9345-c118b5304675","product_id":"BTC-USD","sequence":3342835118,"time":"2017-06-17T02:38:31.097000Z"}
{"type":"open","side":"sell","price":"2447.12000000","order_id":"af2cb935-9b0d-4d9f-b2ba-01ea517d1bac","remaining_size":"0.10000000","product_id":"BTC-USD","sequence":3342835119,"time":"2017-06-17T02:38:31.097000Z"}
{"type":"done","side":"sell","order_id":"af2cb935-9b0d-4d9f-b2ba-01ea517d1bac","reason":"canceled","product_id":"BTC-USD","price":"2447.12000000","remaining_size":"0.10000000","sequence":3342835120,"time":"2017-06-17T02:38:31.132000Z"}
{"type":"done","side":"sell","order_id":"b81f042a-3f47-4bc6-98a6-fe3f79604524","reason":"canceled","product_id":"BTC-USD","price":"2447.53000000","remaining_size":"0.08985400","sequence":3342835121,"time":"2017-06-17T02:38:31.141000Z"}
{"type":"received","order_id":"f9629023-d167-4045-9b6d-af99d7cbb83e","order_type":"limit","size":"0.10000000","price":"2447.11000000","side":"sell","client_oid":"0199f6a7-8d84-4957-99a5-1405c242d443","product_id":"BTC-USD","sequence":3342835122,"time":"2017-06-17T02:38:31.169000Z"}
{"type":"open","side":"sell","price":"2447.11000000","order_id":"f9629023-d167-4045-9b6d-af99d7cbb83e","remaining_size":"0.10000000","product_id":"BTC-USD","sequence":3342835123,"time":"2017-06-17T02:38:31.169000Z"}
{"type":"received","order_id":"cf9d580b-5bcb-4df1-bb73-4dd7af358f3a","order_type":"limit","size":"0.08985400","price":"2448.77000000","side":"sell","client_oid":"ff81f6e7-6bc2-4605-aeaf-c2b80b8e5d20","product_id":"BTC-USD","sequence":3342835124,"time":"2017-06-17T02:38:31.183000Z"}
{"type":"open","side":"sell","price":"2448.77000000","order_id":"cf9d580b-5bcb-4df1-bb73-4dd7af358f3a","remaining_size":"0.08985400","product_id":"BTC-USD","sequence":3342835125,"time":"2017-06-17T02:38:31.183000Z"}
{"type":"done","side":"sell","order_id":"f9629023-d167-4045-9b6d-af99d7cbb83e","reason":"canceled","product_id":"BTC-USD","price":"2447.11000000","remaining_size":"0.10000000","sequence":3342835126,"time":"2017-06-17T02:38:31.185000Z"}
{"type":"received","order_id":"a63e5d01-4165-4d1d-88aa-3072da26ad9e","order_type":"limit","size":"0.10000000","price":"2447.10000000","side":"sell","client_oid":"1eea418d-495e-4f7a-b226-46f23c953224","product_id":"BTC-USD","sequence":3342835127,"time":"2017-06-17T02:38:31.199000Z"}
{"type":"open","side":"sell","price":"2447.10000000","order_id":"a63e5d01-4165-4d1d-88aa-3072da26ad9e","remaining_size":"0.10000000","product_id":"BTC-USD","sequence":3342835128,"time":"2017-06-17T02:38:31.199000Z"}
{"type":"done","side":"sell","order_id":"cf9d580b-5bcb-4df1-bb73-4dd7af358f3a","reason":"canceled","product_id":"BTC-USD","price":"2448.77000000","remaining_size":"0.08985400","sequence":3342835129,"time":"2017-06-17T02:38:31.213000Z"}
{"type":"received","order_id":"9a81ca5f-502e-4de1-a3d0-075f1ff31597","order_type":"limit","size":"0.08985400","price":"2447.53000000","side":"sell","client_oid":"571fdb44-b37b-4cae-817a-d5fd4357bf56","product_id":"BTC-USD","sequence":3342835130,"time":"2017-06-17T02:38:31.221000Z"}
{"type":"open","side":"sell","price":"2447.53000000","order_id":"9a81ca5f-502e-4de1-a3d0-075f1ff31597","remaining_size":"0.08985400","product_id":"BTC-USD","sequence":3342835131,"time":"2017-06-17T02:38:31.221000Z"}
{"type":"done","side":"sell","order_id":"a63e5d01-4165-4d1d-88aa-3072da26ad9e","reason":"canceled","product_id":"BTC-USD","price":"2447.10000000","remaining_size":"0.10000000","sequence":3342835132,"time":"2017-06-17T02:38:31.237000Z"}
{"type":"received","order_id":"67db6dd3-a5d6-48a9-acd1-7b55147bb89d","order_type":"limit","size":"0.10000000","price":"2447.09000000","side":"sell","client_oid":"c806a735-bbe6-4e52-9286-75c5c3df0d42","product_id":"BTC-USD","sequence":3342835133,"time":"2017-06-17T02:38:31.240000Z"}
{"type":"open","side":"sell","price":"2447.09000000","order_id":"67db6dd3-a5d6-48a9-acd1-7b55147bb89d","remaining_size":"0.10000000","product_id":"BTC-USD","sequence":3342835134,"time":"2017-06-17T02:38:31.240000Z"}
{"type":"done","side":"sell","order_id":"9a81ca5f-502e-4de1-a3d0-075f1ff31597","reason":"canceled","product_id":"BTC-USD","price":"2447.53000000","remaining_size":"0.08985400","sequence":3342835135,"time":"2017-06-17T02:38:31.256000Z"}
{"type":"received","order_id":"1059f1f8-d80a-48d0-8bec-33134aabea86","order_type":"limit","size":"0.08985400","price":"2448.77000000","side":"sell","client_oid":"b643995b-37f8-4b69-ac2e-dbffa0efe5ce","product_id":"BTC-USD","sequence":3342835136,"time":"2017-06-17T02:38:31.277000Z"}
{"type":"open","side":"sell","price":"2448.77000000","order_id":"1059f1f8-d80a-48d0-8bec-33134aabea86","remaining_size":"0.08985400","product_id":"BTC-USD","sequence":3342835137,"time":"2017-06-17T02:38:31.277000Z"}
{"type":"done","side":"sell","order_id":"67db6dd3-a5d6-48a9-acd1-7b55147bb89d","reason":"canceled","product_id":"BTC-USD","price":"2447.09000000","remaining_size":"0.10000000","sequence":3342835138,"time":"2017-06-17T02:38:31.281000Z"}
{"type":"received","order_id":"7a200371-a7e3-4fa8-baa8-583199a6b9b2","order_type":"limit","size":"0.10000000","price":"2447.08000000","side":"sell","client_oid":"55467e9f-8527-4ea2-81a6-66af49c5790e","product_id":"BTC-USD","sequence":3342835139,"time":"2017-06-17T02:38:31.300000Z"}
{"type":"open","side":"sell","price":"2447.08000000","order_id":"7a200371-a7e3-4fa8-baa8-583199a6b9b2","remaining_size":"0.10000000","product_id":"BTC-USD","sequence":3342835140,"time":"2017-06-17T02:38:31.300000Z"}
{"type":"done","side":"sell","order_id":"1059f1f8-d80a-48d0-8bec-33134aabea86","reason":"canceled","product_id":"BTC-USD","price":"2448.77000000","remaining_size":"0.08985400","sequence":3342835141,"time":"2017-06-17T02:38:31.309000Z"}
{"type":"received","order_id":"0ae85b6e-1dcf-4fb7-8cee-cc101d5e73d7","order_type":"limit","size":"0.08985400","price":"2447.53000000","side":"sell","client_oid":"387490a6-c663-4343-8875-b631daa20f3c","product_id":"BTC-USD","sequence":3342835142,"time":"2017-06-17T02:38:31.319000Z"}
{"type":"open","side":"sell","price":"2447.53000000","order_id":"0ae85b6e-1dcf-4fb7-8cee-cc101d5e73d7","remaining_size":"0.08985400","product_id":"BTC-USD","sequence":3342835143,"time":"2017-06-17T02:38:31.319000Z"}
{"type":"received","order_id":"0ee503d7-af2e-43aa-b512-a0bb3356cf73","order_type":"limit","size":"0.20000000","price":"2447.53000000","side":"sell","client_oid":"f6be35e9-9b97-48cb-8204-d3ce904a3203","product_id":"BTC-USD","sequence":3342835144,"time":"2017-06-17T02:38:31.340000Z"}
{"type":"open","side":"sell","price":"2447.53000000","order_id":"0ee503d7-af2e-43aa-b512-a0bb3356cf73","remaining_size":"0.20000000","product_id":"BTC-USD","sequence":3342835145,"time":"2017-06-17T02:38:31.340000Z"}
{"type":"done","side":"sell","order_id":"7a200371-a7e3-4fa8-baa8-583199a6b9b2","reason":"canceled","product_id":"BTC-USD","price":"2447.08000000","remaining_size":"0.10000000","sequence":3342835146,"time":"2017-06-17T02:38:31.341000Z"}
{"type":"received","order_id":"cfc6592c-4b26-4e38-881b-7a2d175bb53d","order_type":"limit","size":"0.10000000","price":"2447.07000000","side":"sell","client_oid":"c9f20942-d62a-48bd-86fc-c0b547f3ba8b","product_id":"BTC-USD","sequence":3342835147,"time":"2017-06-17T02:38:31.346000Z"}
{"type":"open","side":"sell","price":"2447.07000000","order_id":"cfc6592c-4b26-4e38-881b-7a2d175bb53d","remaining_size":"0.10000000","product_id":"BTC-USD","sequence":3342835148,"time":"2017-06-17T02:38:31.346000Z"}
{"type":"done","side":"sell","order_id":"0ae85b6e-1dcf-4fb7-8cee-cc101d5e73d7","reason":"canceled","product_id":"BTC-USD","price":"2447.53000000","remaining_size":"0.08985400","sequence":3342835149,"time":"2017-06-17T02:38:31.356000Z"}
{"type":"done","side":"sell","order_id":"cfc6592c-4b26-4e38-881b-7a2d175bb53d","reason":"canceled","product_id":"BTC-USD","price":"2447.07000000","remaining_size":"0.10000000","sequence":3342835150,"time":"2017-06-17T02:38:31.358000Z"}
{"type":"received","order_id":"c9ba5bb3-4689-4fc3-abdd-56aac8957c25","order_type":"limit","size":"0.08985400","price":"2447.52000000","side":"sell","client_oid":"24b4a75b-e7a5-46c9-ac2d-0e203432e84f","product_id":"BTC-USD","sequence":3342835151,"time":"2017-06-17T02:38:31.370000Z"}
{"type":"open","side":"sell","price":"2447.52000000","order_id":"c9ba5bb3-4689-4fc3-abdd-56aac8957c25","remaining_size":"0.08985400","product_id":"BTC-USD","sequence":3342835152,"time":"2017-06-17T02:38:31.370000Z"}
{"type":"received","order_id":"d0b88e04-0a03-4230-86b8-0232d70ddef2","order_type":"limit","size":"0.20000000","price":"2447.52000000","side":"sell","client_oid":"8963b9d3-7066-4a79-aa2c-b0847c6fd152","product_id":"BTC-USD","sequence":3342835153,"time":"2017-06-17T02:38:31.375000Z"}
{"type":"open","side":"sell","price":"2447.52000000","order_id":"d0b88e04-0a03-4230-86b8-0232d70ddef2","remaining_size":"0.20000000","product_id":"BTC-USD","sequence":3342835154,"time":"2017-06-17T02:38:31.375000Z"}
{"type":"done","side":"sell","order_id":"0ee503d7-af2e-43aa-b512-a0bb3356cf73","reason":"canceled","product_id":"BTC-USD","price":"2447.53000000","remaining_size":"0.20000000","sequence":3342835155,"time":"2017-06-17T02:38:31.375000Z"}
{"type":"done","side":"sell","order_id":"c9ba5bb3-4689-4fc3-abdd-56aac8957c25","reason":"canceled","product_id":"BTC-USD","price":"2447.52000000","remaining_size":"0.08985400","sequence":3342835156,"time":"2017-06-17T02:38:31.392000Z"}
{"type":"received","order_id":"2dcc335d-83bd-47a9-8700-5b7133833db4","order_type":"limit","size":"0.10000000","price":"2447.06000000","side":"sell","client_oid":"97b82aec-928b-4ea3-bd93-d5c476eeac59","product_id":"BTC-USD","sequence":3342835157,"time":"2017-06-17T02:38:31.396000Z"}
{"type":"open","side":"sell","price":"2447.06000000","order_id":"2dcc335d-83bd-47a9-8700-5b7133833db4","remaining_size":"0.10000000","product_id":"BTC-USD","sequence":3342835158,"time":"2017-06-17T02:38:31.396000Z"}
{"type":"received","order_id":"bd50a53e-9b0e-4100-bc1a-1d822adf8989","order_type":"limit","size":"0.08985400","price":"2447.53000000","side":"sell","client_oid":"7fcf833e-afa0-41d0-836a-769f0a135bae","product_id":"BTC-USD","sequence":3342835159,"time":"2017-06-17T02:38:31.411000Z"}
{"type":"open","side":"sell","price":"2447.53000000","order_id":"bd50a53e-9b0e-4100-bc1a-1d822adf8989","remaining_size":"0.08985400","product_id":"BTC-USD","sequence":3342835160,"time":"2017-06-17T02:38:31.411000Z"}
{"type":"done","side":"sell","order_id":"d0b88e04-0a03-4230-86b8-0232d70ddef2","reason":"canceled","product_id":"BTC-USD","price":"2447.52000000","remaining_size":"0.20000000","sequence":3342835161,"time":"2017-06-17T02:38:31.413000Z"}
{"type":"done","side":"sell","order_id":"2dcc335d-83bd-47a9-8700-5b7133833db4","reason":"canceled","product_id":"BTC-USD","price":"2447.06000000","remaining_size":"0.10000000","sequence":3342835162,"time":"2017-06-17T02:38:31.416000Z"}
{"type":"received","order_id":"c5436913-cce0-4cdb-8e92-88fbbd074ca8","order_type":"limit","size":"0.10000000","price":"2447.15000000","side":"sell","client_oid":"5cc77139-ebb5-44b5-8826-94886837971e","product_id":"BTC-USD","sequence":3342835163,"time":"2017-06-17T02:38:31.434000Z"}
{"type":"open","side":"sell","price":"2447.15000000","order_id":"c5436913-cce0-4cdb-8e92-88fbbd074ca8","remaining_size":"0.10000000","product_id":"BTC-USD","sequence":3342835164,"time":"2017-06-17T02:38:31.434000Z"}
{"type":"received","order_id":"eb49d2b5-2fe9-431b-8293-e542fdacc6c8","order_type":"limit","size":"0.90000000","price":"2434.05000000","side":"buy","product_id":"BTC-USD","sequence":3342835165,"time":"2017-06-17T02:38:31.451000Z"}
{"type":"open","side":"buy","price":"2434.05000000","order_id":"eb49d2b5-2fe9-431b-8293-e542fdacc6c8","remaining_size":"0.90000000","product_id":"BTC-USD","sequence":3342835166,"time":"2017-06-17T02:38:31.451000Z"}
{"type":"received","order_id":"0d970136-95d4-4e31-a5e6-f33301f04462","order_type":"limit","size":"0.20000000","price":"2447.53000000","side":"sell","client_oid":"c70ed9db-c6b9-4610-830f-4694dc624f19","product_id":"BTC-USD","sequence":3342835167,"time":"2017-06-17T02:38:31.462000Z"}
{"type":"open","side":"sell","price":"2447.53000000","order_id":"0d970136-95d4-4e31-a5e6-f33301f04462","remaining_size":"0.20000000","product_id":"BTC-USD","sequence":3342835168,"time":"2017-06-17T02:38:31.462000Z"}
{"type":"done","side":"sell","order_id":"bd50a53e-9b0e-4100-bc1a-1d822adf8989","reason":"canceled","product_id":"BTC-USD","price":"2447.53000000","remaining_size":"0.08985400","sequence":3342835169,"time":"2017-06-17T02:38:31.467000Z"}
{"type":"done","side":"sell","order_id":"0d970136-95d4-4e31-a5e6-f33301f04462","reason":"canceled","product_id":"BTC-USD","price":"2447.53000000","remaining_size":"0.20000000","sequence":3342835170,"time":"2017-06-17T02:38:31.477000Z"}
{"type":"received","order_id":"923f3cd0-f1ed-44a0-910a-907abd4e867a","order_type":"limit","size":"0.08985400","price":"2447.51000000","side":"sell","client_oid":"65be489e-841a-4089-94ea-4a0f87fe9977","product_id":"BTC-USD","sequence":3342835171,"time":"2017-06-17T02:38:31.478000Z"}
{"type":"open","side":"sell","price":"2447.51000000","order_id":"923f3cd0-f1ed-44a0-910a-907abd4e867a","remaining_size":"0.08985400","product_id":"BTC-USD","sequence":3342835172,"time":"2017-06-17T02:38:31.478000Z"}
{"type":"received","order_id":"a34d7d44-a233-4c73-8124-e5f59a677c14","order_type":"limit","size":"0.20000000","price":"2447.52000000","side":"sell","client_oid":"2aa6cd69-0f5d-42f9-a180-3828fe22aafb","product_id":"BTC-USD","sequence":3342835173,"time":"2017-06-17T02:38:31.495000Z"}
{"type":"open","side":"sell","price":"2447.52000000","order_id":"a34d7d44-a233-4c73-8124-e5f59a677c14","remaining_size":"0.20000000","product_id":"BTC-USD","sequence":3342835174,"time":"2017-06-17T02:38:31.495000Z"}
{"type":"done","side":"sell","order_id":"c5436913-cce0-4cdb-8e92-88fbbd074ca8","reason":"canceled","product_id":"BTC-USD","price":"2447.15000000","remaining_size":"0.10000000","sequence":3342835175,"time":"2017-06-17T02:38:31.495000Z"}
{"type":"received","order_id":"a884808f-0ba7-4bee-a19c-6a6f28de9548","order_type":"limit","size":"0.10000000","price":"2447.14000000","side":"sell","client_oid":"77f17502-8f8b-4e33-9ee9-1e28e4c9c29e","product_id":"BTC-USD","sequence":3342835176,"time":"2017-06-17T02:38:31.508000Z"}
{"type":"open","side":"sell","price":"2447.14000000","order_id":"a884808f-0ba7-4bee-a19c-6a6f28de9548","remaining_size":"0.10000000","product_id":"BTC-USD","sequence":3342835177,"time":"2017-06-17T02:38:31.508000Z"}
{"type":"done","side":"sell","order_id":"a884808f-0ba7-4bee-a19c-6a6f28de9548","reason":"canceled","product_id":"BTC-USD","price":"2447.14000000","remaining_size":"0.10000000","sequence":3342835178,"time":"2017-06-17T02:38:31.521000Z"}
{"type":"done","side":"sell","order_id":"a34d7d44-a233-4c73-8124-e5f59a677c14","reason":"canceled","product_id":"BTC-USD","price":"2447.52000000","remaining_size":"0.20000000","sequence":3342835179,"time":"2017-06-17T02:38:31.530000Z"}
{"type":"received","order_id":"db59ee4e-6fca-462b-b0ea-64054b786d99","order_type":"limit","size":"0.99000000","price":"2432.62000000","side":"buy","product_id":"BTC-USD","sequence":3342835180,"time":"2017-06-17T02:38:31.532000Z"}
{"type":"open","side":"buy","price":"2432.62000000","order_id":"db59ee4e-6fca-462b-b0ea-64054b786d99","remaining_size":"0.99000000","product_id":"BTC-USD","sequence":3342835181,"time":"2017-06-17T02:38:31.532000Z"}
{"type":"received","order_id":"69888d27-5b49-46e3-a2e7-0c096a240b7c","order_type":"limit","size":"0.20000000","price":"2447.51000000","side":"sell","client_oid":"069b17a9-8055-4cbc-b371-e5b62882372d","product_id":"BTC-USD","sequence":3342835182,"time":"2017-06-17T02:38:31.552000Z"}
{"type":"open","side":"sell","price":"2447.51000000","order_id":"69888d27-5b49-46e3-a2e7-0c096a240b7c","remaining_size":"0.20000000","product_id":"BTC-USD","sequence":3342835183,"time":"2017-06-17T02:38:31.552000Z"}
{"type":"done","side":"sell","order_id":"923f3cd0-f1ed-44a0-910a-907abd4e867a","reason":"canceled","product_id":"BTC-USD","price":"2447.51000000","remaining_size":"0.08985400","sequence":3342835184,"time":"2017-06-17T02:38:31.552000Z"}
{"type":"received","order_id":"e2b5aa1b-1f4f-4330-ae8c-8ed4d4bd9e01","order_type":"limit","size":"0.08985400","price":"2448.77000000","side":"sell","client_oid":"80b227b6-3b2d-4de2-9360-6d395ff9c45f","product_id":"BTC-USD","sequence":3342835185,"time":"2017-06-17T02:38:31.569000Z"}
{"type":"open","side":"sell","price":"2448.77000000","order_id":"e2b5aa1b-1f4f-4330-ae8c-8ed4d4bd9e01","remaining_size":"0.08985400","product_id":"BTC-USD","sequence":3342835186,"time":"2017-06-17T02:38:31.569000Z"}
{"type":"received","order_id":"60cbec4f-815d-471c-bb44-52698309baff","order_type":"limit","size":"0.10000000","price":"2447.13000000","side":"sell","client_oid":"967b702a-51d7-4d8c-8715-23f68ba0c38a","product_id":"BTC-USD","sequence":3342835187,"time":"2017-06-17T02:38:31.576000Z"}
{"type":"open","side":"sell","price":"2447.13000000","order_id":"60cbec4f-815d-471c-bb44-52698309baff","remaining_size":"0.10000000","product_id":"BTC-USD","sequence":3342835188,"time":"2017-06-17T02:38:31.576000Z"}
{"type":"done","side":"sell","order_id":"69888d27-5b49-46e3-a2e7-0c096a240b7c","reason":"canceled","product_id":"BTC-USD","price":"2447.51000000","remaining_size":"0.20000000","sequence":3342835189,"time":"2017-06-17T02:38:31.580000Z"}
{"type":"received","order_id":"6d13d5fd-ea89-4406-96ad-619ff37ae7d6","order_type":"limit","size":"0.20000000","price":"2447.53000000","side":"sell","client_oid":"eaacc30e-db0a-4069-a596-f65c93d02253","product_id":"BTC-USD","sequence":3342835190,"time":"2017-06-17T02:38:31.587000Z"}
{"type":"open","side":"sell","price":"2447.53000000","order_id":"6d13d5fd-ea89-4406-96ad-619ff37ae7d6","remaining_size":"0.20000000","product_id":"BTC-USD","sequence":3342835191,"time":"2017-06-17T02:38:31.587000Z"}
{"type":"done","side":"sell","order_id":"e2b5aa1b-1f4f-4330-ae8c-8ed4d4bd9e01","reason":"canceled","product_id":"BTC-USD","price":"2448.77000000","remaining_size":"0.08985400","sequence":3342835192,"time":"2017-06-17T02:38:31.589000Z"}
{"type":"done","side":"sell","order_id":"6d13d5fd-ea89-4406-96ad-619ff37ae7d6","reason":"canceled","product_id":"BTC-USD","price":"2447.53000000","remaining_size":"0.20000000","sequence":3342835193,"time":"2017-06-17T02:38:31.621000Z"}
{"type":"received","order_id":"829ed923-0fcf-47a9-84a7-7f09ae7e4607","order_type":"limit","size":"0.10000000","price":"2447.12000000","side":"sell","client_oid":"6f132e99-0f8a-446f-bb6e-28cf198c2428","product_id":"BTC-USD","sequence":3342835194,"time":"2017-06-17T02:38:31.624000Z"}
{"type":"open","side":"sell","price":"2447.12000000","order_id":"829ed923-0fcf-47a9-84a7-7f09ae7e4607","remaining_size":"0.10000000","product_id":"BTC-USD","sequence":3342835195,"time":"2017-06-17T02:38:31.624000Z"}
{"type":"received","order_id":"50ab83af-e123-4d93-b007-1b407a012ea0","order_type":"limit","size":"0.99000000","price":"2431.35000000","side":"buy","product_id":"BTC-USD","sequence":3342835196,"time":"2017-06-17T02:38:31.626000Z"}
{"type":"open","side":"buy","price":"2431.35000000","order_id":"50ab83af-e123-4d93-b007-1b407a012ea0","remaining_size":"0.99000000","product_id":"BTC-USD","sequence":3342835197,"time":"2017-06-17T02:38:31.626000Z"}
{"type":"done","side":"sell","order_id":"60cbec4f-815d-471c-bb44-52698309baff","reason":"canceled","product_id":"BTC-USD","price":"2447.13000000","remaining_size":"0.10000000","sequence":3342835198,"time":"2017-06-17T02:38:31.627000Z"}
{"type":"done","side":"sell","order_id":"829ed923-0fcf-47a9-84a7-7f09ae7e4607","reason":"canceled","product_id":"BTC-USD","price":"2447.12000000","remaining_size":"0.10000000","sequence":3342835199,"time":"2017-06-17T02:38:31.633000Z"}
{"type":"received","order_id":"0cc9eed0-4b83-48ef-b8b8-db0520526b5c","order_type":"limit","size":"0.10000000","price":"2447.15000000","side":"sell","client_oid":"04d5e3bf-5c94-4b2f-b2f3-5c6c1d5027f0","product_id":"BTC-USD","sequence":3342835200,"time":"2017-06-17T02:38:31.683000Z"}
{"type":"open","side":"sell","price":"2447.15000000","order_id":"0cc9eed0-4b83-48ef-b8b8-db0520526b5c","remaining_size":"0.10000000","product_id":"BTC-USD","sequence":3342835201,"time":"2017-06-17T02:38:31.683000Z"}
{"type":"done","side":"sell","order_id":"0cc9eed0-4b83-48ef-b8b8-db0520526b5c","reason":"canceled","product_id":"BTC-USD","price":"2447.15000000","remaining_size":"0.10000000","sequence":3342835202,"time":"2017-06-17T02:38:31.698000Z"}
{"type":"received","order_id":"0111f719-50c2-4649-8880-e7dd5de22d4f","order_type":"limit","size":"0.10000000","price":"2447.14000000","side":"sell","client_oid":"ea1dc082-d74b-4628-937b-81ff89eeea26","product_id":"BTC-USD","sequence":3342835203,"time":"2017-06-17T02:38:31.706000Z"}
{"type":"open","side":"sell","price":"2447.14000000","order_id":"0111f719-50c2-4649-8880-e7dd5de22d4f","remaining_size":"0.10000000","product_id":"BTC-USD","sequence":3342835204,"time":"2017-06-17T02:38:31.706000Z"}
{"type":"received","order_id":"605c6bf9-405d-4285-ba92-2c9c860f4c22","order_type":"limit","size":"1.38000000","price":"2430.62000000","side":"buy","product_id":"BTC-USD","sequence":3342835205,"time":"2017-06-17T02:38:31.712000Z"}
{"type":"open","side":"buy","price":"2430.62000000","order_id":"605c6bf9-405d-4285-ba92-2c9c860f4c22","remaining_size":"1.38000000","product_id":"BTC-USD","sequence":3342835206,"time":"2017-06-17T02:38:31.712000Z"}
{"type":"done","side":"sell","order_id":"0111f719-50c2-4649-8880-e7dd5de22d4f","reason":"canceled","product_id":"BTC-USD","price":"2447.14000000","remaining_size":"0.10000000","sequence":3342835207,"time":"2017-06-17T02:38:31.741000Z"}
{"type":"received","order_id":"aa157c3f-d16e-4c9c-93a2-19062c9803bb","order_type":"limit","size":"0.75000000","price":"2429.97000000","side":"buy","product_id":"BTC-USD","sequence":3342835208,"time":"2017-06-17T02:38:31.768000Z"}
{"type":"open","side":"buy","price":"2429.97000000","order_id":"aa157c3f-d16e-4c9c-93a2-19062c9803bb","remaining_size":"0.75000000","product_id":"BTC-USD","sequence":3342835209,"time":"2017-06-17T02:38:31.768000Z"}
{"type":"received","order_id":"07e7f6d7-b200-4ea1-bebc-bf4e3ae9b29b","order_type":"limit","size":"0.10000000","price":"2447.13000000","side":"sell","client_oid":"9032c8e3-40eb-4d1c-9f82-22a9f1e0f308","product_id":"BTC-USD","sequence":3342835210,"time":"2017-06-17T02:38:31.771000Z"}
{"type":"open","side":"sell","price":"2447.13000000","order_id":"07e7f6d7-b200-4ea1-bebc-bf4e3ae9b29b","remaining_size":"0.10000000","product_id":"BTC-USD","sequence":3342835211,"time":"2017-06-17T02:38:31.771000Z"}
{"type":"done","side":"sell","order_id":"07e7f6d7-b200-4ea1-bebc-bf4e3ae9b29b","reason":"canceled","product_id":"BTC-USD","price":"2447.13000000","remaining_size":"0.10000000","sequence":3342835212,"time":"2017-06-17T02:38:31.787000Z"}
{"type":"received","order_id":"55c98835-fb33-4750-a628-4ffce13fa4e6","order_type":"limit","size":"0.10000000","price":"2443.00000000","side":"sell","client_oid":"037f1628-ed30-4def-befe-ba3b95aadb44","product_id":"BTC-USD","sequence":3342835213,"time":"2017-06-17T02:38:31.797000Z"}
{"type":"open","side":"sell","price":"2443.00000000","order_id":"55c98835-fb33-4750-a628-4ffce13fa4e6","remaining_size":"0.10000000","product_id":"BTC-USD","sequence":3342835214,"time":"2017-06-17T02:38:31.797000Z"}
{"type":"received","order_id":"38037bd7-7b7c-4ee8-95a9-22824dd33929","order_type":"limit","size":"0.10000000","price":"2447.15000000","side":"sell","client_oid":"6602bf30-769b-4ac7-91fe-a1bec35959a2","product_id":"BTC-USD","sequence":3342835215,"time":"2017-06-17T02:38:31.799000Z"}
{"type":"open","side":"sell","price":"2447.15000000","order_id":"38037bd7-7b7c-4ee8-95a9-22824dd33929","remaining_size":"0.10000000","product_id":"BTC-USD","sequence":3342835216,"time":"2017-06-17T02:38:31.799000Z"}
{"type":"done","side":"sell","order_id":"38037bd7-7b7c-4ee8-95a9-22824dd33929","reason":"canceled","product_id":"BTC-USD","price":"2447.15000000","remaining_size":"0.10000000","sequence":3342835217,"time":"2017-06-17T02:38:31.829000Z"}
{"type":"received","order_id":"a1e7f37f-b498-4b84-a325-c2f4804f5576","order_type":"limit","size":"0.10000000","price":"2447.14000000","side":"sell","client_oid":"2d88b154-5c8a-49a5-b2d8-51c527e33123","product_id":"BTC-USD","sequence":3342835218,"time":"2017-06-17T02:38:31.844000Z"}
{"type":"open","side":"sell","price":"2447.14000000","order_id":"a1e7f37f-b498-4b84-a325-c2f4804f5576","remaining_size":"0.10000000","product_id":"BTC-USD","sequence":3342835219,"time":"2017-06-17T02:38:31.844000Z"}
{"type":"done","side":"sell","order_id":"a1e7f37f-b498-4b84-a325-c2f4804f5576","reason":"canceled","product_id":"BTC-USD","price":"2447.14000000","remaining_size":"0.10000000","sequence":3342835220,"time":"2017-06-17T02:38:31.873000Z"}
{"type":"received","order_id":"b2463beb-dc30-458d-bedf-18ed230fee04","order_type":"limit","size":"2.45000000","price":"2454.61000000","side":"sell","product_id":"BTC-USD","sequence":3342835221,"time":"2017-06-17T02:38:31.880000Z"}
{"type":"open","side":"sell","price":"2454.61000000","order_id":"b2463beb-dc30-458d-bedf-18ed230fee04","remaining_size":"2.45000000","product_id":"BTC-USD","sequence":3342835222,"time":"2017-06-17T02:38:31.880000Z"}
{"type":"received","order_id":"ec310ebb-5f28-48f3-bbf6-ede189402682","order_type":"limit","size":"0.10000000","price":"2447.13000000","side":"sell","client_oid":"def7c740-911d-4008-986e-b52124d60e6f","product_id":"BTC-USD","sequence":3342835223,"time":"2017-06-17T02:38:31.882000Z"}
{"type":"open","side":"sell","price":"2447.13000000","order_id":"ec310ebb-5f28-48f3-bbf6-ede189402682","remaining_size":"0.10000000","product_id":"BTC-USD","sequence":3342835224,"time":"2017-06-17T02:38:31.882000Z"}
{"type":"done","side":"sell","order_id":"ec310ebb-5f28-48f3-bbf6-ede189402682","reason":"canceled","product_id":"BTC-USD","price":"2447.13000000","remaining_size":"0.10000000","sequence":3342835225,"time":"2017-06-17T02:38:31.917000Z"}
{"type":"received","order_id":"f053775b-3366-4d1a-8fb7-fa0111244e82","order_type":"limit","size":"0.10000000","price":"2447.12000000","side":"sell","client_oid":"44f62060-ed8e-4317-8575-3a5d3621aee2","product_id":"BTC-USD","sequence":3342835226,"time":"2017-06-17T02:38:31.927000Z"}
{"type":"open","side":"sell","price":"2447.12000000","order_id":"f053775b-3366-4d1a-8fb7-fa0111244e82","remaining_size":"0.10000000","product_id":"BTC-USD","sequence":3342835227,"time":"2017-06-17T02:38:31.927000Z"}
{"type":"received","order_id":"3679f0d7-2031-40d2-a547-f4ce677209c1","order_type":"limit","size":"1.27000000","price":"2454.63000000","side":"sell","product_id":"BTC-USD","sequence":3342835228,"time":"2017-06-17T02:38:31.957000Z"}
{"type":"open","side":"sell","price":"2454.63000000","order_id":"3679f0d7-2031-40d2-a547-f4ce677209c1","remaining_size":"1.27000000","product_id":"BTC-USD","sequence":3342835229,"time":"2017-06-17T02:38:31.957000Z"}
{"type":"done","side":"sell","order_id":"f053775b-3366-4d1a-8fb7-fa0111244e82","reason":"canceled","product_id":"BTC-USD","price":"2447.12000000","remaining_size":"0.10000000","sequence":3342835230,"time":"2017-06-17T02:38:31.963000Z"}
{"type":"received","order_id":"adc081f5-c888-480c-ba3f-f53f755c9948","order_type":"limit","size":"0.10000000","price":"2447.11000000","side":"sell","client_oid":"c4b00817-1ce6-4a44-b6eb-3a34c7e966ad","product_id":"BTC-USD","sequence":3342835231,"time":"2017-06-17T02:38:31.972000Z"}
{"type":"open","side":"sell","price":"2447.11000000","order_id":"adc081f5-c888-480c-ba3f-f53f755c9948","remaining_size":"0.10000000","product_id":"BTC-USD","sequence":3342835232,"time":"2017-06-17T02:38:31.972000Z"}
{"type":"done","side":"sell","order_id":"adc081f5-c888-480c-ba3f-f53f755c9948","reason":"canceled","product_id":"BTC-USD","price":"2447.11000000","remaining_size":"0.10000000","sequence":3342835233,"time":"2017-06-17T02:38:32.008000Z"}
{"type":"received","order_id":"d042263f-f6fc-4ae1-be71-676156495116","order_type":"limit","size":"0.10000000","price":"2447.10000000","side":"sell","client_oid":"99007555-5702-47c2-8c61-60a8d25efdec","product_id":"BTC-USD","sequence":3342835234,"time":"2017-06-17T02:38:32.019000Z"}
{"type":"open","side":"sell","price":"2447.10000000","order_id":"d042263f-f6fc-4ae1-be71-676156495116","remaining_size":"0.10000000","product_id":"BTC-USD","sequence":3342835235,"time":"2017-06-17T02:38:32.019000Z"}
{"type":"received","order_id":"45c1f21a-e39d-4e5b-bcfe-ff751bdbea1f","order_type":"limit","size":"1.28000000","price":"2455.97000000","side":"sell","product_id":"BTC-USD","sequence":3342835236,"time":"2017-06-17T02:38:32.023000Z"}
{"type":"open","side":"sell","price":"2455.97000000","order_id":"45c1f21a-e39d-4e5b-bcfe-ff751bdbea1f","remaining_size":"1.28000000","product_id":"BTC-USD","sequence":3342835237,"time":"2017-06-17T02:38:32.023000Z"}
{"type":"received","order_id":"189aa6fb-22d0-491d-811c-9bbd8da50e05","order_type":"limit","size":"0.02100000","price":"2442.17000000","side":"buy","product_id":"BTC-USD","sequence":3342835238,"time":"2017-06-17T02:38:32.036000Z"}
{"type":"open","side":"buy","price":"2442.17000000","order_id":"189aa6fb-22d0-491d-811c-9bbd8da50e05","remaining_size":"0.02100000","product_id":"BTC-USD","sequence":3342835239,"time":"2017-06-17T02:38:32.036000Z"}
{"type":"done","side":"sell","order_id":"d042263f-f6fc-4ae1-be71-676156495116","reason":"canceled","product_id":"BTC-USD","price":"2447.10000000","remaining_size":"0.10000000","sequence":3342835240,"time":"2017-06-17T02:38:32.055000Z"}
{"type":"received","order_id":"d18114fc-2c3e-4972-b98f-c5c171b4e46e","order_type":"limit","size":"0.10000000","price":"2447.09000000","side":"sell","client_oid":"b9964411-868b-44e4-aed1-2581aa8d031b","product_id":"BTC-USD","sequence":3342835241,"time":"2017-06-17T02:38:32.067000Z"}
{"type":"open","side":"sell","price":"2447.09000000","order_id":"d18114fc-2c3e-4972-b98f-c5c171b4e46e","remaining_size":"0.10000000","product_id":"BTC-USD","sequence":3342835242,"time":"2017-06-17T02:38:32.067000Z"}
{"type":"done","side":"sell","order_id":"d18114fc-2c3e-4972-b98f-c5c171b4e46e","reason":"canceled","product_id":"BTC-USD","price":"2447.09000000","remaining_size":"0.10000000","sequence":3342835243,"time":"2017-06-17T02:38:32.097000Z"}
{"type":"received","order_id":"ac1d4fb4-8f50-4227-be61-e3a6373283bc","order_type":"limit","size":"0.10000000","price":"2447.08000000","side":"sell","client_oid":"1e5ab560-d5e0-4aea-956e-f3c38be89aa4","product_id":"BTC-USD","sequence":3342835244,"time":"2017-06-17T02:38:32.111000Z"}
{"type":"open","side":"sell","price":"2447.08000000","order_id":"ac1d4fb4-8f50-4227-be61-e3a6373283bc","remaining_size":"0.10000000","product_id":"BTC-USD","sequence":3342835245,"time":"2017-06-17T02:38:32.111000Z"}
{"type":"done","side":"sell","order_id":"ac1d4fb4-8f50-4227-be61-e3a6373283bc","reason":"canceled","product_id":"BTC-USD","price":"2447.08000000","remaining_size":"0.10000000","sequence":3342835246,"time":"2017-06-17T02:38:32.142000Z"}
{"type":"received","order_id":"b544f60b-1274-4bfe-ab3e-f584a5a15618","order_type":"limit","size":"0.10000000","price":"2447.07000000","side":"sell","client_oid":"0c97e380-4adc-4f07-a1a1-83519e76d2d4","product_id":"BTC-USD","sequence":3342835247,"time":"2017-06-17T02:38:32.154000Z"}
{"type":"open","side":"sell","price":"2447.07000000","order_id":"b544f60b-1274-4bfe-ab3e-f584a5a15618","remaining_size":"0.10000000","product_id":"BTC-USD","sequence":3342835248,"time":"2017-06-17T02:38:32.154000Z"}
{"type":"received","order_id":"280e8895-89b5-4da3-a4a5-e96e0c2cbfd9","order_type":"limit","size":"0.25000000","price":"2442.77000000","side":"buy","client_oid":"cc1092fc-29f1-4bce-bb9d-9c8467684c27","product_id":"BTC-USD","sequence":3342835249,"time":"2017-06-17T02:38:32.160000Z"}
{"type":"open","side":"buy","price":"2442.77000000","order_id":"280e8895-89b5-4da3-a4a5-e96e0c2cbfd9","remaining_size":"0.25000000","product_id":"BTC-USD","sequence":3342835250,"time":"2017-06-17T02:38:32.160000Z"}
{"type":"received","order_id":"ed86b68d-a824-411b-8d07-795f40b138f3","order_type":"limit","size":"0.10000000","price":"2447.06000000","side":"sell","client_oid":"7208a623-a86f-49ac-9f2f-eb619a2d5a5a","product_id":"BTC-USD","sequence":3342835251,"time":"2017-06-17T02:38:32.196000Z"}
{"type":"open","side":"sell","price":"2447.06000000","order_id":"ed86b68d-a824-411b-8d07-795f40b138f3","remaining_size":"0.10000000","product_id":"BTC-USD","sequence":3342835252,"time":"2017-06-17T02:38:32.196000Z"}
{"type":"done","side":"sell","order_id":"ed86b68d-a824-411b-8d07-795f40b138f3","reason":"canceled","product_id":"BTC-USD","price":"2447.06000000","remaining_size":"0.10000000","sequence":3342835253,"time":"2017-06-17T02:38:32.200000Z"}
{"type":"done","side":"sell","order_id":"b544f60b-1274-4bfe-ab3e-f584a5a15618","reason":"canceled","product_id":"BTC-USD","price":"2447.07000000","remaining_size":"0.10000000","sequence":3342835254,"time":"2017-06-17T02:38:32.206000Z"}
{"type":"received","order_id":"fd20bf9d-b8b5-4bbe-9c91-9cfd7d43a788","order_type":"limit","size":"0.10000000","price":"2447.15000000","side":"sell","client_oid":"e484f02f-1459-41fd-80ab-f66ada701b3e","product_id":"BTC-USD","sequence":3342835255,"time":"2017-06-17T02:38:32.256000Z"}
{"type":"open","side":"sell","price":"2447.15000000","order_id":"fd20bf9d-b8b5-4bbe-9c91-9cfd7d43a788","remaining_size":"0.10000000","product_id":"BTC-USD","sequence":3342835256,"time":"2017-06-17T02:38:32.256000Z"}
{"type":"done","side":"buy","order_id":"280e8895-89b5-4da3-a4a5-e96e0c2cbfd9","reason":"canceled","product_id":"BTC-USD","price":"2442.77000000","remaining_size":"0.25000000","sequence":3342835257,"time":"2017-06-17T02:38:32.263000Z"}
{"type":"done","side":"sell","order_id":"fd20bf9d-b8b5-4bbe-9c91-9cfd7d43a788","reason":"canceled","product_id":"BTC-USD","price":"2447.15000000","remaining_size":"0.10000000","sequence":3342835258,"time":"2017-06-17T02:38:32.265000Z"}
{"type":"received","order_id":"23cdf802-61c0-4786-9e23-2f2d75942b86","order_type":"limit","size":"0.10000000","price":"2447.14000000","side":"sell","client_oid":"819298f0-3930-4118-b3b7-19f7eb2a88cb","product_id":"BTC-USD","sequence":3342835259,"time":"2017-06-17T02:38:32.276000Z"}
{"type":"open","side":"sell","price":"2447.14000000","order_id":"23cdf802-61c0-4786-9e23-2f2d75942b86","remaining_size":"0.10000000","product_id":"BTC-USD","sequence":3342835260,"time":"2017-06-17T02:38:32.276000Z"}
{"type":"received","order_id":"c04c369d-f7a8-44f9-9584-41f5046dd215","order_type":"limit","size":"0.10000000","price":"2447.13000000","side":"sell","client_oid":"65ad3b85-7efb-4351-a17e-ce495d1ed1f9","product_id":"BTC-USD","sequence":3342835261,"time":"2017-06-17T02:38:32.345000Z"}
{"type":"open","side":"sell","price":"2447.13000000","order_id":"c04c369d-f7a8-44f9-9584-41f5046dd215","remaining_size":"0.10000000","product_id":"BTC-USD","sequence":3342835262,"time":"2017-06-17T02:38:32.345000Z"}
{"type":"done","side":"sell","order_id":"23cdf802-61c0-4786-9e23-2f2d75942b86","reason":"canceled","product_id":"BTC-USD","price":"2447.14000000","remaining_size":"0.10000000","sequence":3342835263,"time":"2017-06-17T02:38:32.346000Z"}
{"type":"received","order_id":"e2a61b79-d3a4-45b4-acfc-1e794bdccf75","order_type":"limit","size":"0.20000000","price":"2447.53000000","side":"sell","client_oid":"9c1dca81-2ebf-457f-80a5-7a9e323cece1","product_id":"BTC-USD","sequence":3342835264,"time":"2017-06-17T02:38:32.365000Z"}
{"type":"open","side":"sell","price":"2447.53000000","order_id":"e2a61b79-d3a4-45b4-acfc-1e794bdccf75","remaining_size":"0.20000000","product_id":"BTC-USD","sequence":3342835265,"time":"2017-06-17T02:38:32.365000Z"}
{"type":"received","order_id":"d6f28a13-2f50-4195-aa1f-7a799845c97c","order_type":"limit","size":"0.08985400","price":"2447.53000000","side":"sell","client_oid":"822b6ac7-b91f-4b42-8dd9-5f8a589ee6c7","product_id":"BTC-USD","sequence":3342835266,"time":"2017-06-17T02:38:32.374000Z"}
{"type":"open","side":"sell","price":"2447.53000000","order_id":"d6f28a13-2f50-4195-aa1f-7a799845c97c","remaining_size":"0.08985400","product_id":"BTC-USD","sequence":3342835267,"time":"2017-06-17T02:38:32.374000Z"}
{"type":"done","side":"sell","order_id":"c04c369d-f7a8-44f9-9584-41f5046dd215","reason":"canceled","product_id":"BTC-USD","price":"2447.13000000","remaining_size":"0.10000000","sequence":3342835268,"time":"2017-06-17T02:38:32.400000Z"}
{"type":"done","side":"sell","order_id":"d6f28a13-2f50-4195-aa1f-7a799845c97c","reason":"canceled","product_id":"BTC-USD","price":"2447.53000000","remaining_size":"0.08985400","sequence":3342835269,"time":"2017-06-17T02:38:32.404000Z"}
{"type":"received","order_id":"7f095096-8dd6-458c-b23a-e5a44a922f87","order_type":"limit","size":"0.08985400","price":"2447.52000000","side":"sell","client_oid":"9f114cdb-f866-4df1-b6c8-67c16ea84647","product_id":"BTC-USD","sequence":3342835270,"time":"2017-06-17T02:38:32.413000Z"}
{"type":"open","side":"sell","price":"2447.52000000","order_id":"7f095096-8dd6-458c-b23a-e5a44a922f87","remaining_size":"0.08985400","product_id":"BTC-USD","sequence":3342835271,"time":"2017-06-17T02:38:32.413000Z"}
{"type":"done","side":"sell","order_id":"e2a61b79-d3a4-45b4-acfc-1e794bdccf75","reason":"canceled","product_id":"BTC-USD","price":"2447.53000000","remaining_size":"0.20000000","sequence":3342835272,"time":"2017-06-17T02:38:32.413000Z"}
{"type":"received","order_id":"2e2b77e1-d763-453a-8cc9-1425daceca7c","order_type":"limit","size":"0.20000000","price":"2447.52000000","side":"sell","client_oid":"2a955fa4-e3ef-4e4f-a855-8359865069ed","product_id":"BTC-USD","sequence":3342835273,"time":"2017-06-17T02:38:32.418000Z"}
{"type":"open","side":"sell","price":"2447.52000000","order_id":"2e2b77e1-d763-453a-8cc9-1425daceca7c","remaining_size":"0.20000000","product_id":"BTC-USD","sequence":3342835274,"time":"2017-06-17T02:38:32.418000Z"}
{"type":"done","side":"sell","order_id":"2e2b77e1-d763-453a-8cc9-1425daceca7c","reason":"canceled","product_id":"BTC-USD","price":"2447.52000000","remaining_size":"0.20000000","sequence":3342835275,"time":"2017-06-17T02:38:32.444000Z"}
{"type":"done","side":"sell","order_id":"7f095096-8dd6-458c-b23a-e5a44a922f87","reason":"canceled","product_id":"BTC-USD","price":"2447.52000000","remaining_size":"0.08985400","sequence":3342835276,"time":"2017-06-17T02:38:32.449000Z"}
{"type":"received","order_id":"3bbc81ca-6e54-4480-88f2-ab7607adc351","order_type":"limit","size":"0.10000000","price":"2447.15000000","side":"sell","client_oid":"ed345bc3-757a-4b59-95da-ff8f2355cad4","product_id":"BTC-USD","sequence":3342835277,"time":"2017-06-17T02:38:32.452000Z"}
{"type":"open","side":"sell","price":"2447.15000000","order_id":"3bbc81ca-6e54-4480-88f2-ab7607adc351","remaining_size":"0.10000000","product_id":"BTC-USD","sequence":3342835278,"time":"2017-06-17T02:38:32.452000Z"}
{"type":"received","order_id":"9fbc29b3-19fb-4fc6-abb6-1324f2d7a323","order_type":"limit","size":"0.20000000","price":"2447.51000000","side":"sell","client_oid":"c3aff7a2-1949-47c9-b8ce-ad9340ee6d07","product_id":"BTC-USD","sequence":3342835279,"time":"2017-06-17T02:38:32.472000Z"}
{"type":"open","side":"sell","price":"2447.51000000","order_id":"9fbc29b3-19fb-4fc6-abb6-1324f2d7a323","remaining_size":"0.20000000","product_id":"BTC-USD","sequence":3342835280,"time":"2017-06-17T02:38:32.472000Z"}
{"type":"received","order_id":"2f9244d5-83d1-41ed-9594-a63ca656f72f","order_type":"limit","size":"1.56270438","price":"2442.99000000","side":"sell","product_id":"BTC-USD","sequence":3342835281,"time":"2017-06-17T02:38:32.478000Z"}
{"type":"match","trade_id":16934580,"maker_order_id":"d7412797-194d-4ce6-9c4f-ded678c4a2c8","taker_order_id":"2f9244d5-83d1-41ed-9594-a63ca656f72f","side":"buy","size":"1.56270438","price":"2442.99000000","product_id":"BTC-USD","sequence":3342835282,"time":"2017-06-17T02:38:32.478000Z"}
{"type":"done","side":"sell","order_id":"2f9244d5-83d1-41ed-9594-a63ca656f72f","reason":"filled","product_id":"BTC-USD","price":"2442.99000000","remaining_size":"0.00000000","sequence":3342835283,"time":"2017-06-17T02:38:32.478000Z"}
{"type":"done","side":"sell","order_id":"9fbc29b3-19fb-4fc6-abb6-1324f2d7a323","reason":"canceled","product_id":"BTC-USD","price":"2447.51000000","remaining_size":"0.20000000","sequence":3342835284,"time":"2017-06-17T02:38:32.497000Z"}
{"type":"done","side":"sell","order_id":"3bbc81ca-6e54-4480-88f2-ab7607adc351","reason":"canceled","product_id":"BTC-USD","price":"2447.15000000","remaining_size":"0.10000000","sequence":3342835285,"time":"2017-06-17T02:38:32.500000Z"}
{"type":"received","order_id":"93c44845-2e69-41b4-8747-882b1eb723aa","order_type":"limit","size":"0.08985400","price":"2447.51000000","side":"sell","client_oid":"c6e54a8c-e556-43be-b7f4-009514cbec96","product_id":"BTC-USD","sequence":3342835286,"time":"2017-06-17T02:38:32.502000Z"}
{"type":"open","side":"sell","price":"2447.51000000","order_id":"93c44845-2e69-41b4-8747-882b1eb723aa","remaining_size":"0.08985400","product_id":"BTC-USD","sequence":3342835287,"time":"2017-06-17T02:38:32.502000Z"}
{"type":"done","side":"buy","order_id":"b93fce6e-ca67-43fa-b955-1ee1f36785fa","reason":"canceled","product_id":"BTC-USD","price":"2442.62000000","remaining_size":"0.50000000","sequence":3342835288,"time":"2017-06-17T02:38:32.504000Z"}
{"type":"received","order_id":"225f6948-eac4-44e8-91e9-e93dcba98d2f","order_type":"limit","size":"0.10000000","price":"2447.14000000","side":"sell","client_oid":"ff54278e-72cf-4ce9-8b2d-7b6fb1c595d7","product_id":"BTC-USD","sequence":3342835289,"time":"2017-06-17T02:38:32.507000Z"}
{"type":"open","side":"sell","price":"2447.14000000","order_id":"225f6948-eac4-44e8-91e9-e93dcba98d2f","remaining_size":"0.10000000","product_id":"BTC-USD","sequence":3342835290,"time":"2017-06-17T02:38:32.507000Z"}
{"type":"received","order_id":"9e8d56d2-5702-4c9b-81cf-b6f867cf6ea1","order_type":"limit","size":"0.20000000","price":"2447.50000000","side":"sell","client_oid":"368c9e2b-4323-45e6-afd5-8765f2b7bbd0","product_id":"BTC-USD","sequence":3342835291,"time":"2017-06-17T02:38:32.516000Z"}
{"type":"open","side":"sell","price":"2447.50000000","order_id":"9e8d56d2-5702-4c9b-81cf-b6f867cf6ea1","remaining_size":"0.20000000","product_id":"BTC-USD","sequence":3342835292,"time":"2017-06-17T02:38:32.516000Z"}
{"type":"done","side":"sell","order_id":"1ce3401d-ecbd-4035-887d-af585c4d74af","reason":"canceled","product_id":"BTC-USD","price":"2443.82000000","remaining_size":"0.50000000","sequence":3342835293,"time":"2017-06-17T02:38:32.520000Z"}
{"type":"done","side":"sell","order_id":"225f6948-eac4-44e8-91e9-e93dcba98d2f","reason":"canceled","product_id":"BTC-USD","price":"2447.14000000","remaining_size":"0.10000000","sequence":3342835294,"time":"2017-06-17T02:38:32.539000Z"}
{"type":"done","side":"sell","order_id":"9e8d56d2-5702-4c9b-81cf-b6f867cf6ea1","reason":"canceled","product_id":"BTC-USD","price":"2447.50000000","remaining_size":"0.20000000","sequence":3342835295,"time":"2017-06-17T02:38:32.546000Z"}
{"type":"received","order_id":"d8773d45-2fc7-479d-ab04-277f71c3a76d","order_type":"limit","size":"0.10000000","price":"2447.13000000","side":"sell","client_oid":"4664910a-3384-4003-b077-9eb614c9f30a","product_id":"BTC-USD","sequence":3342835296,"time":"2017-06-17T02:38:32.576000Z"}
{"type":"open","side":"sell","price":"2447.13000000","order_id":"d8773d45-2fc7-479d-ab04-277f71c3a76d","remaining_size":"0.10000000","product_id":"BTC-USD","sequence":3342835297,"time":"2017-06-17T02:38:32.576000Z"}
{"type":"done","side":"sell","order_id":"93c44845-2e69-41b4-8747-882b1eb723aa","reason":"canceled","product_id":"BTC-USD","price":"2447.51000000","remaining_size":"0.08985400","sequence":3342835298,"time":"2017-06-17T02:38:32.577000Z"}
{"type":"received","order_id":"2445ee41-a227-4aa9-bfd0-b06d138558dc","order_type":"limit","size":"0.08985400","price":"2447.49000000","side":"sell","client_oid":"2271f24c-dba9-4414-a7da-c865efc6a24b","product_id":"BTC-USD","sequence":3342835299,"time":"2017-06-17T02:38:32.582000Z"}
{"type":"open","side":"sell","price":"2447.49000000","order_id":"2445ee41-a227-4aa9-bfd0-b06d138558dc","remaining_size":"0.08985400","product_id":"BTC-USD","sequence":3342835300,"time":"2017-06-17T02:38:32.582000Z"}
{"type":"received","order_id":"1b51cc11-6ee2-4218-9521-ff600e432199","order_type":"limit","size":"0.20000000","price":"2447.49000000","side":"sell","client_oid":"056ed492-0046-4cd6-b6eb-950fc7e2b28b","product_id":"BTC-USD","sequence":3342835301,"time":"2017-06-17T02:38:32.589000Z"}
{"type":"open","side":"sell","price":"2447.49000000","order_id":"1b51cc11-6ee2-4218-9521-ff600e432199","remaining_size":"0.20000000","product_id":"BTC-USD","sequence":3342835302,"time":"2017-06-17T02:38:32.589000Z"}
{"type":"done","side":"sell","order_id":"2445ee41-a227-4aa9-bfd0-b06d138558dc","reason":"canceled","product_id":"BTC-USD","price":"2447.49000000","remaining_size":"0.08985400","sequence":3342835303,"time":"2017-06-17T02:38:32.589000Z"}
{"type":"done","side":"sell","order_id":"1b51cc11-6ee2-4218-9521-ff600e432199","reason":"canceled","product_id":"BTC-USD","price":"2447.49000000","remaining_size":"0.20000000","sequence":3342835304,"time":"2017-06-17T02:38:32.593000Z"}
{"type":"received","order_id":"e7b9d629-c644-4419-a599-f898a2e1baea","order_type":"limit","size":"0.10000000","price":"2447.12000000","side":"sell","client_oid":"7b938ca2-48bd-407e-905d-40ee55404020","product_id":"BTC-USD","sequence":3342835305,"time":"2017-06-17T02:38:32.608000Z"}
{"type":"open","side":"sell","price":"2447.12000000","order_id":"e7b9d629-c644-4419-a599-f898a2e1baea","remaining_size":"0.10000000","product_id":"BTC-USD","sequence":3342835306,"time":"2017-06-17T02:38:32.608000Z"}
{"type":"done","side":"sell","order_id":"d8773d45-2fc7-479d-ab04-277f71c3a76d","reason":"canceled","product_id":"BTC-USD","price":"2447.13000000","remaining_size":"0.10000000","sequence":3342835307,"time":"2017-06-17T02:38:32.608000Z"}
{"type":"received","order_id":"125a088d-9535-4d63-b4ed-8ec11d275bf6","order_type":"limit","size":"0.20000000","price":"2447.53000000","side":"sell","client_oid":"adc250b2-6a11-484f-b84c-5df9e9db6144","product_id":"BTC-USD","sequence":3342835308,"time":"2017-06-17T02:38:32.614000Z"}
{"type":"open","side":"sell","price":"2447.53000000","order_id":"125a088d-9535-4d63-b4ed-8ec11d275bf6","remaining_size":"0.20000000","product_id":"BTC-USD","sequence":3342835309,"time":"2017-06-17T02:38:32.614000Z"}
{"type":"received","order_id":"3e5a87c2-8d10-40af-ab6e-1b30858d8080","order_type":"limit","size":"0.25000000","price":"2442.77000000","side":"buy","client_oid":"86db594c-6fa4-44b3-b2eb-7f832caa38ca","product_id":"BTC-USD","sequence":3342835310,"time":"2017-06-17T02:38:32.622000Z"}
{"type":"open","side":"buy","price":"2442.77000000","order_id":"3e5a87c2-8d10-40af-ab6e-1b30858d8080","remaining_size":"0.25000000","product_id":"BTC-USD","sequence":3342835311,"time":"2017-06-17T02:38:32.622000Z"}
{"type":"done","side":"sell","order_id":"e7b9d629-c644-4419-a599-f898a2e1baea","reason":"canceled","product_id":"BTC-USD","price":"2447.12000000","remaining_size":"0.10000000","sequence":3342835312,"time":"2017-06-17T02:38:32.633000Z"}
{"type":"received","order_id":"89a2db07-ccef-42dd-9798-fb5133634fce","order_type":"limit","size":"0.08985400","price":"2447.52000000","side":"sell","client_oid":"50ed52b8-e202-47f4-82e8-cfe705426094","product_id":"BTC-USD","sequence":3342835313,"time":"2017-06-17T02:38:32.644000Z"}
{"type":"open","side":"sell","price":"2447.52000000","order_id":"89a2db07-ccef-42dd-9798-fb5133634fce","remaining_size":"0.08985400","product_id":"BTC-USD","sequence":3342835314,"time":"2017-06-17T02:38:32.644000Z"}
{"type":"done","side":"sell","order_id":"45c1f21a-e39d-4e5b-bcfe-ff751bdbea1f","reason":"canceled","product_id":"BTC-USD","price":"2455.97000000","remaining_size":"1.28000000","sequence":3342835315,"time":"2017-06-17T02:38:32.648000Z"}
{"type":"done","side":"sell","order_id":"125a088d-9535-4d63-b4ed-8ec11d275bf6","reason":"canceled","product_id":"BTC-USD","price":"2447.53000000","remaining_size":"0.20000000","sequence":3342835316,"time":"2017-06-17T02:38:32.652000Z"}
{"type":"done","side":"sell","order_id":"89a2db07-ccef-42dd-9798-fb5133634fce","reason":"canceled","product_id":"BTC-USD","price":"2447.52000000","remaining_size":"0.08985400","sequence":3342835317,"time":"2017-06-17T02:38:32.677000Z"}
{"type":"received","order_id":"31677033-f5e2-43fd-8153-674f92cae501","order_type":"limit","size":"0.10000000","price":"2447.11000000","side":"sell","client_oid":"54c78769-b324-4d89-b252-17dfce679d81","product_id":"BTC-USD","sequence":3342835318,"time":"2017-06-17T02:38:32.697000Z"}
{"type":"open","side":"sell","price":"2447.11000000","order_id":"31677033-f5e2-43fd-8153-674f92cae501","remaining_size":"0.10000000","product_id":"BTC-USD","sequence":3342835319,"time":"2017-06-17T02:38:32.697000Z"}
{"type":"done","side":"sell","order_id":"3679f0d7-2031-40d2-a547-f4ce677209c1","reason":"canceled","product_id":"BTC-USD","price":"2454.63000000","remaining_size":"1.27000000","sequence":3342835320,"time":"2017-06-17T02:38:32.699000Z"}
{"type":"done","side":"sell","order_id":"31677033-f5e2-43fd-8153-674f92cae501","reason":"canceled","product_id":"BTC-USD","price":"2447.11000000","remaining_size":"0.10000000","sequence":3342835321,"time":"2017-06-17T02:38:32.701000Z"}
{"type":"received","order_id":"01e3bc16-08ad-485b-8b84-78d2c7fc2f3f","order_type":"limit","size":"0.50000000","price":"2443.61000000","side":"sell","client_oid":"0ec378db-66a4-434f-9d18-2217d97d09a2","product_id":"BTC-USD","sequence":3342835322,"time":"2017-06-17T02:38:32.712000Z"}
{"type":"open","side":"sell","price":"2443.61000000","order_id":"01e3bc16-08ad-485b-8b84-78d2c7fc2f3f","remaining_size":"0.50000000","product_id":"BTC-USD","sequence":3342835323,"time":"2017-06-17T02:38:32.712000Z"}
{"type":"done","side":"buy","order_id":"3e5a87c2-8d10-40af-ab6e-1b30858d8080","reason":"canceled","product_id":"BTC-USD","price":"2442.77000000","remaining_size":"0.25000000","sequence":3342835324,"time":"2017-06-17T02:38:32.713000Z"}
{"type":"received","order_id":"c07103b2-0348-4378-9f6d-51ccf22c945b","order_type":"limit","size":"0.20000000","price":"2447.52000000","side":"sell","client_oid":"4a72cfb5-dfdb-436b-98f5-3bfe2335dd1b","product_id":"BTC-USD","sequence":3342835325,"time":"2017-06-17T02:38:32.716000Z"}
{"type":"open","side":"sell","price":"2447.52000000","order_id":"c07103b2-0348-4378-9f6d-51ccf22c945b","remaining_size":"0.20000000","product_id":"BTC-USD","sequence":3342835326,"time":"2017-06-17T02:38:32.716000Z"}
{"type":"done","side":"sell","order_id":"c07103b2-0348-4378-9f6d-51ccf22c945b","reason":"canceled","product_id":"BTC-USD","price":"2447.52000000","remaining_size":"0.20000000","sequence":3342835327,"time":"2017-06-17T02:38:32.720000Z"}
{"type":"received","order_id":"66d3edbc-9607-436b-a976-d20bc977372f","order_type":"limit","size":"0.08985400","price":"2448.77000000","side":"sell","client_oid":"5e2a6f8a-51d3-4778-8e5b-d281fcf044f5","product_id":"BTC-USD","sequence":3342835328,"time":"2017-06-17T02:38:32.724000Z"}
{"type":"open","side":"sell","price":"2448.77000000","order_id":"66d3edbc-9607-436b-a976-d20bc977372f","remaining_size":"0.08985400","product_id":"BTC-USD","sequence":3342835329,"time":"2017-06-17T02:38:32.724000Z"}
{"type":"received","order_id":"27b780f9-61c5-481d-af5b-5a4a1611dfba","order_type":"limit","size":"0.10000000","price":"2447.15000000","side":"sell","client_oid":"9cfe1459-c596-4b85-bedb-2b774657688d","product_id":"BTC-USD","sequence":3342835330,"time":"2017-06-17T02:38:32.729000Z"}
{"type":"open","side":"sell","price":"2447.15000000","order_id":"27b780f9-61c5-481d-af5b-5a4a1611dfba","remaining_size":"0.10000000","product_id":"BTC-USD","sequence":3342835331,"time":"2017-06-17T02:38:32.729000Z"}
{"type":"done","side":"sell","order_id":"66d3edbc-9607-436b-a976-d20bc977372f","reason":"canceled","product_id":"BTC-USD","price":"2448.77000000","remaining_size":"0.08985400","sequence":3342835332,"time":"2017-06-17T02:38:32.730000Z"}
{"type":"received","order_id":"a24d7b51-17c0-4179-801c-7b3ac8f0b64f","order_type":"limit","size":"0.20000000","price":"2449.17000000","side":"sell","client_oid":"4f2de74c-4d2f-46aa-9af9-f83a773984ea","product_id":"BTC-USD","sequence":3342835333,"time":"2017-06-17T02:38:32.737000Z"}
{"type":"open","side":"sell","price":"2449.17000000","order_id":"a24d7b51-17c0-4179-801c-7b3ac8f0b64f","remaining_size":"0.20000000","product_id":"BTC-USD","sequence":3342835334,"time":"2017-06-17T02:38:32.737000Z"}
{"type":"received","order_id":"c692b06c-1c05-4027-a8d8-a2e01552283e","order_type":"limit","size":"0.08985400","price":"2447.53000000","side":"sell","client_oid":"8e26d90b-c84b-4e52-8857-496f74566680","product_id":"BTC-USD","sequence":3342835335,"time":"2017-06-17T02:38:32.742000Z"}
{"type":"open","side":"sell","price":"2447.53000000","order_id":"c692b06c-1c05-4027-a8d8-a2e01552283e","remaining_size":"0.08985400","product_id":"BTC-USD","sequence":3342835336,"time":"2017-06-17T02:38:32.742000Z"}
{"type":"done","side":"sell","order_id":"b2463beb-dc30-458d-bedf-18ed230fee04","reason":"canceled","product_id":"BTC-USD","price":"2454.61000000","remaining_size":"2.45000000","sequence":3342835337,"time":"2017-06-17T02:38:32.745000Z"}
{"type":"done","side":"sell","order_id":"27b780f9-61c5-481d-af5b-5a4a1611dfba","reason":"canceled","product_id":"BTC-USD","price":"2447.15000000","remaining_size":"0.10000000","sequence":3342835338,"time":"2017-06-17T02:38:32.752000Z"}
{"type":"done","side":"sell","order_id":"a24d7b51-17c0-4179-801c-7b3ac8f0b64f","reason":"canceled","product_id":"BTC-USD","price":"2449.17000000","remaining_size":"0.20000000","sequence":3342835339,"time":"2017-06-17T02:38:32.761000Z"}
{"type":"done","side":"sell","order_id":"c692b06c-1c05-4027-a8d8-a2e01552283e","reason":"canceled","product_id":"BTC-USD","price":"2447.53000000","remaining_size":"0.08985400","sequence":3342835340,"time":"2017-06-17T02:38:32.775000Z"}
{"type":"received","order_id":"e589a68f-fe31-4006-ae81-1b302c16b007","order_type":"limit","size":"0.10000000","price":"2447.14000000","side":"sell","client_oid":"c9d03228-a8e0-4136-b2ca-e7cd8a796a79","product_id":"BTC-USD","sequence":3342835341,"time":"2017-06-17T02:38:32.781000Z"}
{"type":"open","side":"sell","price":"2447.14000000","order_id":"e589a68f-fe31-4006-ae81-1b302c16b007","remaining_size":"0.10000000","product_id":"BTC-USD","sequence":3342835342,"time":"2017-06-17T02:38:32.781000Z"}
{"type":"received","order_id":"b6974a97-d40b-4177-aed3-df10c5d93ee2","order_type":"limit","size":"0.08985400","price":"2448.77000000","side":"sell","client_oid":"85efb19f-1dc9-46ea-a175-976ccb90fe3e","product_id":"BTC-USD","sequence":3342835343,"time":"2017-06-17T02:38:32.792000Z"}
{"type":"open","side":"sell","price":"2448.77000000","order_id":"b6974a97-d40b-4177-aed3-df10c5d93ee2","remaining_size":"0.08985400","product_id":"BTC-USD","sequence":3342835344,"time":"2017-06-17T02:38:32.792000Z"}
{"type":"received","order_id":"f668099e-e530-49a4-9eb8-cf469c311cc8","order_type":"limit","size":"0.20000000","price":"2447.53000000","side":"sell","client_oid":"2733a6bf-e13a-47ec-ac60-3e2eecae7c3e","product_id":"BTC-USD","sequence":3342835345,"time":"2017-06-17T02:38:32.815000Z"}
{"type":"open","side":"sell","price":"2447.53000000","order_id":"f668099e-e530-49a4-9eb8-cf469c311cc8","remaining_size":"0.20000000","product_id":"BTC-USD","sequence":3342835346,"time":"2017-06-17T02:38:32.815000Z"}
{"type":"done","side":"sell","order_id":"e589a68f-fe31-4006-ae81-1b302c16b007","reason":"canceled","product_id":"BTC-USD","price":"2447.14000000","remaining_size":"0.10000000","sequence":3342835347,"time":"2017-06-17T02:38:32.824000Z"}
{"type":"received","order_id":"26448f31-dd6b-43e6-891a-6f907ea77254","order_type":"limit","size":"0.10000000","price":"2447.15000000","side":"sell","client_oid":"1be70325-2cd3-49cf-aa64-bd26d403719d","product_id":"BTC-USD","sequence":3342835348,"time":"2017-06-17T02:38:32.828000Z"}
{"type":"open","side":"sell","price":"2447.15000000","order_id":"26448f31-dd6b-43e6-891a-6f907ea77254","remaining_size":"0.10000000","product_id":"BTC-USD","sequence":3342835349,"time":"2017-06-17T02:38:32.828000Z"}
{"type":"done","side":"sell","order_id":"b6974a97-d40b-4177-aed3-df10c5d93ee2","reason":"canceled","product_id":"BTC-USD","price":"2448.77000000","remaining_size":"0.08985400","sequence":3342835350,"time":"2017-06-17T02:38:32.832000Z"}
{"type":"done","side":"sell","order_id":"f668099e-e530-49a4-9eb8-cf469c311cc8","reason":"canceled","product_id":"BTC-USD","price":"2447.53000000","remaining_size":"0.20000000","sequence":3342835351,"time":"2017-06-17T02:38:32.833000Z"}
{"type":"done","side":"sell","order_id":"26448f31-dd6b-43e6-891a-6f907ea77254","reason":"canceled","product_id":"BTC-USD","price":"2447.15000000","remaining_size":"0.10000000","sequence":3342835352,"time":"2017-06-17T02:38:32.835000Z"}
{"type":"done","side":"buy","order_id":"aa157c3f-d16e-4c9c-93a2-19062c9803bb","reason":"canceled","product_id":"BTC-USD","price":"2429.97000000","remaining_size":"0.75000000","sequence":3342835353,"time":"2017-06-17T02:38:32.892000Z"}
{"type":"received","order_id":"cb7e77eb-87ea-44fa-b329-5171ea99a603","order_type":"limit","size":"0.10000000","price":"2447.15000000","side":"sell","client_oid":"7041f519-36d5-4323-a6ab-511d48972630","product_id":"BTC-USD","sequence":3342835354,"time":"2017-06-17T02:38:32.898000Z"}
{"type":"open","side":"sell","price":"2447.15000000","order_id":"cb7e77eb-87ea-44fa-b329-5171ea99a603","remaining_size":"0.10000000","product_id":"BTC-USD","sequence":3342835355,"time":"2017-06-17T02:38:32.898000Z"}
{"type":"done","side":"sell","order_id":"cb7e77eb-87ea-44fa-b329-5171ea99a603","reason":"canceled","product_id":"BTC-USD","price":"2447.15000000","remaining_size":"0.10000000","sequence":3342835356,"time":"2017-06-17T02:38:32.906000Z"}
{"type":"received","order_id":"9d76d79d-1014-4389-bfcd-8f852dbdd4b4","order_type":"limit","size":"0.10000000","price":"2447.14000000","side":"sell","client_oid":"04d2e093-f1cd-402c-a583-7653cc121906","product_id":"BTC-USD","sequence":3342835357,"time":"2017-06-17T02:38:32.915000Z"}
{"type":"open","side":"sell","price":"2447.14000000","order_id":"9d76d79d-1014-4389-bfcd-8f852dbdd4b4","remaining_size":"0.10000000","product_id":"BTC-USD","sequence":3342835358,"time":"2017-06-17T02:38:32.915000Z"}
{"type":"done","side":"buy","order_id":"605c6bf9-405d-4285-ba92-2c9c860f4c22","reason":"canceled","product_id":"BTC-USD","price":"2430.62000000","remaining_size":"1.38000000","sequence":3342835359,"time":"2017-06-17T02:38:32.941000Z"}
{"type":"done","side":"sell","order_id":"9d76d79d-1014-4389-bfcd-8f852dbdd4b4","reason":"canceled","product_id":"BTC-USD","price":"2447.14000000","remaining_size":"0.10000000","sequence":3342835360,"time":"2017-06-17T02:38:32.950000Z"}
{"type":"received","order_id":"08304d25-b15d-474e-a962-2abc0e32e166","order_type":"limit","size":"0.10000000","price":"2447.13000000","side":"sell","client_oid":"1988c611-c9aa-4b5a-bf07-ea8c47522a2e","product_id":"BTC-USD","sequence":3342835361,"time":"2017-06-17T02:38:32.957000Z"}
{"type":"open","side":"sell","price":"2447.13000000","order_id":"08304d25-b15d-474e-a962-2abc0e32e166","remaining_size":"0.10000000","product_id":"BTC-USD","sequence":3342835362,"time":"2017-06-17T02:38:32.957000Z"}
{"type":"received","order_id":"cce46876-d785-4a8d-93da-e4f7cd2d8c82","order_type":"limit","size":"0.25000000","price":"2442.77000000","side":"buy","client_oid":"97ea1a15-5874-4ae6-b662-431ca10eb345","product_id":"BTC-USD","sequence":3342835363,"time":"2017-06-17T02:38:32.957000Z"}
{"type":"open","side":"buy","price":"2442.77000000","order_id":"cce46876-d785-4a8d-93da-e4f7cd2d8c82","remaining_size":"0.25000000","product_id":"BTC-USD","sequence":3342835364,"time":"2017-06-17T02:38:32.957000Z"}
{"type":"done","side":"buy","order_id":"50ab83af-e123-4d93-b007-1b407a012ea0","reason":"canceled","product_id":"BTC-USD","price":"2431.35000000","remaining_size":"0.99000000","sequence":3342835365,"time":"2017-06-17T02:38:32.994000Z"}
{"type":"done","side":"sell","order_id":"08304d25-b15d-474e-a962-2abc0e32e166","reason":"canceled","product_id":"BTC-USD","price":"2447.13000000","remaining_size":"0.10000000","sequence":3342835366,"time":"2017-06-17T02:38:32.995000Z"}
{"type":"received","order_id":"d7daf64c-ae25-4f1b-9045-e682597d480b","order_type":"limit","size":"0.10000000","price":"2447.12000000","side":"sell","client_oid":"131fe328-92ae-4fd2-9c79-ee384863e362","product_id":"BTC-USD","sequence":3342835367,"time":"2017-06-17T02:38:33.003000Z"}
{"type":"open","side":"sell","price":"2447.12000000","order_id":"d7daf64c-ae25-4f1b-9045-e682597d480b","remaining_size":"0.10000000","product_id":"BTC-USD","sequence":3342835368,"time":"2017-06-17T02:38:33.003000Z"}
{"type":"done","side":"sell","order_id":"d7daf64c-ae25-4f1b-9045-e682597d480b","reason":"canceled","product_id":"BTC-USD","price":"2447.12000000","remaining_size":"0.10000000","sequence":3342835369,"time":"2017-06-17T02:38:33.037000Z"}
{"type":"done","side":"buy","order_id":"cce46876-d785-4a8d-93da-e4f7cd2d8c82","reason":"canceled","product_id":"BTC-USD","price":"2442.77000000","remaining_size":"0.25000000","sequence":3342835370,"time":"2017-06-17T02:38:33.044000Z"}
{"type":"received","order_id":"70df3b25-7b11-4e63-85c9-13480adc7f1e","order_type":"limit","size":"0.10000000","price":"2447.11000000","side":"sell","client_oid":"d287f1cb-f3c7-4f9d-b987-f8ac9f3df55d","product_id":"BTC-USD","sequence":3342835371,"time":"2017-06-17T02:38:33.045000Z"}
{"type":"open","side":"sell","price":"2447.11000000","order_id":"70df3b25-7b11-4e63-85c9-13480adc7f1e","remaining_size":"0.10000000","product_id":"BTC-USD","sequence":3342835372,"time":"2017-06-17T02:38:33.045000Z"}
{"type":"done","side":"buy","order_id":"db59ee4e-6fca-462b-b0ea-64054b786d99","reason":"canceled","product_id":"BTC-USD","price":"2432.62000000","remaining_size":"0.99000000","sequence":3342835373,"time":"2017-06-17T02:38:33.057000Z"}
{"type":"received","order_id":"0b22b8e3-dbfd-405b-8656-9805abe0ee43","order_type":"limit","size":"0.10000000","price":"2447.10000000","side":"sell","client_oid":"81ee08fd-e695-4175-8387-04085e0a0890","product_id":"BTC-USD","sequence":3342835374,"time":"2017-06-17T02:38:33.111000Z"}
{"type":"open","side":"sell","price":"2447.10000000","order_id":"0b22b8e3-dbfd-405b-8656-9805abe0ee43","remaining_size":"0.10000000","product_id":"BTC-USD","sequence":3342835375,"time":"2017-06-17T02:38:33.111000Z"}
{"type":"done","side":"sell","order_id":"70df3b25-7b11-4e63-85c9-13480adc7f1e","reason":"canceled","product_id":"BTC-USD","price":"2447.11000000","remaining_size":"0.10000000","sequence":3342835376,"time":"2017-06-17T02:38:33.112000Z"}
{"type":"done","side":"buy","order_id":"eb49d2b5-2fe9-431b-8293-e542fdacc6c8","reason":"canceled","product_id":"BTC-USD","price":"2434.05000000","remaining_size":"0.90000000","sequence":3342835377,"time":"2017-06-17T02:38:33.127000Z"}
{"type":"done","side":"sell","order_id":"0b22b8e3-dbfd-405b-8656-9805abe0ee43","reason":"canceled","product_id":"BTC-USD","price":"2447.10000000","remaining_size":"0.10000000","sequence":3342835378,"time":"2017-06-17T02:38:33.145000Z"}
{"type":"received","order_id":"7098ab91-f5f2-49c4-85dc-4990d167fa28","order_type":"limit","size":"0.10000000","price":"2447.09000000","side":"sell","client_oid":"b4435dac-70b6-49ad-835b-14eed0738f3b","product_id":"BTC-USD","sequence":3342835379,"time":"2017-06-17T02:38:33.164000Z"}
{"type":"open","side":"sell","price":"2447.09000000","order_id":"7098ab91-f5f2-49c4-85dc-4990d167fa28","remaining_size":"0.10000000","product_id":"BTC-USD","sequence":3342835380,"time":"2017-06-17T02:38:33.164000Z"}
{"type":"done","side":"sell","order_id":"7098ab91-f5f2-49c4-85dc-4990d167fa28","reason":"canceled","product_id":"BTC-USD","price":"2447.09000000","remaining_size":"0.10000000","sequence":3342835381,"time":"2017-06-17T02:38:33.170000Z"}
{"type":"received","order_id":"0d65d03e-f3bb-4107-8aaf-f8c409ce6d8f","order_type":"limit","size":"0.10000000","price":"2447.15000000","side":"sell","client_oid":"785568e2-2033-4b18-9545-d68c0c6e6b9b","product_id":"BTC-USD","sequence":3342835382,"time":"2017-06-17T02:38:33.180000Z"}
{"type":"open","side":"sell","price":"2447.15000000","order_id":"0d65d03e-f3bb-4107-8aaf-f8c409ce6d8f","remaining_size":"0.10000000","product_id":"BTC-USD","sequence":3342835383,"time":"2017-06-17T02:38:33.180000Z"}
{"type":"received","order_id":"894a01fc-0761-47cf-91d5-41260696131d","order_type":"limit","size":"0.25000000","price":"2442.77000000","side":"buy","client_oid":"f3d514e9-52af-47bf-94fe-8e9f40a51cfe","product_id":"BTC-USD","sequence":3342835384,"time":"2017-06-17T02:38:33.197000Z"}
{"type":"open","side":"buy","price":"2442.77000000","order_id":"894a01fc-0761-47cf-91d5-41260696131d","remaining_size":"0.25000000","product_id":"BTC-USD","sequence":3342835385,"time":"2017-06-17T02:38:33.197000Z"}
{"type":"done","side":"sell","order_id":"0d65d03e-f3bb-4107-8aaf-f8c409ce6d8f","reason":"canceled","product_id":"BTC-USD","price":"2447.15000000","remaining_size":"0.10000000","sequence":3342835386,"time":"2017-06-17T02:38:33.212000Z"}
{"type":"received","order_id":"8cfaee2a-2f8f-4ede-be20-dad6601d3057","order_type":"limit","size":"0.10000000","price":"2447.14000000","side":"sell","client_oid":"9ece04b2-74f2-4cc3-b6db-602114d31710","product_id":"BTC-USD","sequence":3342835387,"time":"2017-06-17T02:38:33.221000Z"}
{"type":"open","side":"sell","price":"2447.14000000","order_id":"8cfaee2a-2f8f-4ede-be20-dad6601d3057","remaining_size":"0.10000000","product_id":"BTC-USD","sequence":3342835388,"time":"2017-06-17T02:38:33.221000Z"}
{"type":"done","side":"sell","order_id":"8cfaee2a-2f8f-4ede-be20-dad6601d3057","reason":"canceled","product_id":"BTC-USD","price":"2447.14000000","remaining_size":"0.10000000","sequence":3342835389,"time":"2017-06-17T02:38:33.257000Z"}
{"type":"received","order_id":"81569770-9564-48d1-a38b-4eadf9f9ebb4","order_type":"limit","size":"0.10000000","price":"2447.13000000","side":"sell","client_oid":"9fd0eef8-4fba-4222-b284-d6866e0fef9d","product_id":"BTC-USD","sequence":3342835390,"time":"2017-06-17T02:38:33.266000Z"}
{"type":"open","side":"sell","price":"2447.13000000","order_id":"81569770-9564-48d1-a38b-4eadf9f9ebb4","remaining_size":"0.10000000","product_id":"BTC-USD","sequence":3342835391,"time":"2017-06-17T02:38:33.266000Z"}
{"type":"done","side":"sell","order_id":"81569770-9564-48d1-a38b-4eadf9f9ebb4","reason":"canceled","product_id":"BTC-USD","price":"2447.13000000","remaining_size":"0.10000000","sequence":3342835392,"time":"2017-06-17T02:38:33.301000Z"}
{"type":"done","side":"buy","order_id":"894a01fc-0761-47cf-91d5-41260696131d","reason":"canceled","product_id":"BTC-USD","price":"2442.77000000","remaining_size":"0.25000000","sequence":3342835393,"time":"2017-06-17T02:38:33.308000Z"}
{"type":"received","order_id":"aced802f-7ea4-4fc7-b1ec-b963c7847c9c","order_type":"limit","size":"0.10000000","price":"2447.12000000","side":"sell","client_oid":"17ea00b9-24ed-4d3a-b654-d1dd04be59fe","product_id":"BTC-USD","sequence":3342835394,"time":"2017-06-17T02:38:33.309000Z"}
{"type":"open","side":"sell","price":"2447.12000000","order_id":"aced802f-7ea4-4fc7-b1ec-b963c7847c9c","remaining_size":"0.10000000","product_id":"BTC-USD","sequence":3342835395,"time":"2017-06-17T02:38:33.309000Z"}
{"type":"done","side":"sell","order_id":"aced802f-7ea4-4fc7-b1ec-b963c7847c9c","reason":"canceled","product_id":"BTC-USD","price":"2447.12000000","remaining_size":"0.10000000","sequence":3342835396,"time":"2017-06-17T02:38:33.342000Z"}
{"type":"received","order_id":"4e04c976-b7bc-4c93-842f-4dc4ab302862","order_type":"limit","size":"0.20000000","price":"2449.17000000","side":"sell","client_oid":"c7eee553-f3a5-43a2-9ab7-58c0c0f50515","product_id":"BTC-USD","sequence":3342835397,"time":"2017-06-17T02:38:33.346000Z"}
{"type":"open","side":"sell","price":"2449.17000000","order_id":"4e04c976-b7bc-4c93-842f-4dc4ab302862","remaining_size":"0.20000000","product_id":"BTC-USD","sequence":3342835398,"time":"2017-06-17T02:38:33.346000Z"}
{"type":"received","order_id":"49c9ee31-f1d4-4e52-a8d0-c1ab7fcc209b","order_type":"limit","size":"0.10000000","price":"2447.11000000","side":"sell","client_oid":"3850371b-bf30-4433-a471-4f8591688ef2","product_id":"BTC-USD","sequence":3342835399,"time":"2017-06-17T02:38:33.355000Z"}
{"type":"open","side":"sell","price":"2447.11000000","order_id":"49c9ee31-f1d4-4e52-a8d0-c1ab7fcc209b","remaining_size":"0.10000000","product_id":"BTC-USD","sequence":3342835400,"time":"2017-06-17T02:38:33.355000Z"}
{"type":"received","order_id":"a411224f-db29-4277-905a-a7e0e2ea6154","order_type":"limit","size":"0.20000000","price":"2449.16000000","side":"sell","client_oid":"d4066b2e-bbc7-4eeb-be4c-ffbb5c2d057e","product_id":"BTC-USD","sequence":3342835401,"time":"2017-06-17T02:38:33.373000Z"}
{"type":"open","side":"sell","price":"2449.16000000","order_id":"a411224f-db29-4277-905a-a7e0e2ea6154","remaining_size":"0.20000000","product_id":"BTC-USD","sequence":3342835402,"time":"2017-06-17T02:38:33.373000Z"}
{"type":"done","side":"sell","order_id":"4e04c976-b7bc-4c93-842f-4dc4ab302862","reason":"canceled","product_id":"BTC-USD","price":"2449.17000000","remaining_size":"0.20000000","sequence":3342835403,"time":"2017-06-17T02:38:33.374000Z"}
{"type":"received","order_id":"a5911609-1347-437b-94c2-f3df7a06b1ae","order_type":"limit","size":"0.10000000","price":"2447.10000000","side":"sell","client_oid":"141ae7e8-3a2f-4fd9-b8f2-6bb7b2282698","product_id":"BTC-USD","sequence":3342835404,"time":"2017-06-17T02:38:33.416000Z"}
{"type":"open","side":"sell","price":"2447.10000000","order_id":"a5911609-1347-437b-94c2-f3df7a06b1ae","remaining_size":"0.10000000","product_id":"BTC-USD","sequence":3342835405,"time":"2017-06-17T02:38:33.416000Z"}
{"type":"done","side":"sell","order_id":"a5911609-1347-437b-94c2-f3df7a06b1ae","reason":"canceled","product_id":"BTC-USD","price":"2447.10000000","remaining_size":"0.10000000","sequence":3342835406,"time":"2017-06-17T02:38:33.433000Z"}
{"type":"done","side":"sell","order_id":"a411224f-db29-4277-905a-a7e0e2ea6154","reason":"canceled","product_id":"BTC-USD","price":"2449.16000000","remaining_size":"0.20000000","sequence":3342835407,"time":"2017-06-17T02:38:33.563000Z"}
{"type":"received","order_id":"ff55803c-facc-4b89-85ff-486be2642fcf","order_type":"limit","size":"0.20000000","price":"2447.53000000","side":"sell","client_oid":"83eb8836-95aa-45c0-aa5a-f1f997cd1eb1","product_id":"BTC-USD","sequence":3342835408,"time":"2017-06-17T02:38:33.593000Z"}
{"type":"open","side":"sell","price":"2447.53000000","order_id":"ff55803c-facc-4b89-85ff-486be2642fcf","remaining_size":"0.20000000","product_id":"BTC-USD","sequence":3342835409,"time":"2017-06-17T02:38:33.593000Z"}
{"type":"done","side":"sell","order_id":"49c9ee31-f1d4-4e52-a8d0-c1ab7fcc209b","reason":"canceled","product_id":"BTC-USD","price":"2447.11000000","remaining_size":"0.10000000","sequence":3342835410,"time":"2017-06-17T02:38:33.624000Z"}
{"type":"received","order_id":"8e9e7d4a-135b-46f9-b0ff-910db01a7fb3","order_type":"limit","size":"0.10000000","price":"2447.10000000","side":"sell","client_oid":"7f7be518-862c-4ca6-8425-f46925c30f59","product_id":"BTC-USD","sequence":3342835411,"time":"2017-06-17T02:38:33.647000Z"}
{"type":"open","side":"sell","price":"2447.10000000","order_id":"8e9e7d4a-135b-46f9-b0ff-910db01a7fb3","remaining_size":"0.10000000","product_id":"BTC-USD","sequence":3342835412,"time":"2017-06-17T02:38:33.647000Z"}
{"type":"received","order_id":"d56b315c-62ee-4ef5-8cef-0eeee064c07c","order_type":"limit","size":"0.20000000","price":"2447.52000000","side":"sell","client_oid":"3580f73d-3154-4a74-91a3-15dd0cd37e96","product_id":"BTC-USD","sequence":3342835413,"time":"2017-06-17T02:38:33.654000Z"}
{"type":"open","side":"sell","price":"2447.52000000","order_id":"d56b315c-62ee-4ef5-8cef-0eeee064c07c","remaining_size":"0.20000000","product_id":"BTC-USD","sequence":3342835414,"time":"2017-06-17T02:38:33.654000Z"}
{"type":"done","side":"sell","order_id":"ff55803c-facc-4b89-85ff-486be2642fcf","reason":"canceled","product_id":"BTC-USD","price":"2447.53000000","remaining_size":"0.20000000","sequence":3342835415,"time":"2017-06-17T02:38:33.655000Z"}
{"type":"done","side":"sell","order_id":"e356c790-d2fe-4d79-98bf-b099afaecfd7","reason":"canceled","product_id":"BTC-USD","price":"2517.65000000","remaining_size":"0.71000000","sequence":3342835416,"time":"2017-06-17T02:38:33.660000Z"}
{"type":"done","side":"sell","order_id":"8e9e7d4a-135b-46f9-b0ff-910db01a7fb3","reason":"canceled","product_id":"BTC-USD","price":"2447.10000000","remaining_size":"0.10000000","sequence":3342835417,"time":"2017-06-17T02:38:33.680000Z"}
{"type":"received","order_id":"224ab22a-a88d-4d46-abaa-a6083af813e6","order_type":"limit","size":"0.10000000","price":"2447.15000000","side":"sell","client_oid":"f186b711-5178-4098-8d42-9a42ad10610a","product_id":"BTC-USD","sequence":3342835418,"time":"2017-06-17T02:38:33.751000Z"}
{"type":"open","side":"sell","price":"2447.15000000","order_id":"224ab22a-a88d-4d46-abaa-a6083af813e6","remaining_size":"0.10000000","product_id":"BTC-USD","sequence":3342835419,"time":"2017-06-17T02:38:33.751000Z"}
{"type":"done","side":"sell","order_id":"d56b315c-62ee-4ef5-8cef-0eeee064c07c","reason":"canceled","product_id":"BTC-USD","price":"2447.52000000","remaining_size":"0.20000000","sequence":3342835420,"time":"2017-06-17T02:38:33.752000Z"}
{"type":"received","order_id":"8f6aad29-8abf-480c-979f-b47814d91965","order_type":"limit","size":"0.25000000","price":"2442.77000000","side":"buy","client_oid":"e897768b-dc2c-44d6-af9d-51dba066d96f","product_id":"BTC-USD","sequence":3342835421,"time":"2017-06-17T02:38:33.776000Z"}
{"type":"open","side":"buy","price":"2442.77000000","order_id":"8f6aad29-8abf-480c-979f-b47814d91965","remaining_size":"0.25000000","product_id":"BTC-USD","sequence":3342835422,"time":"2017-06-17T02:38:33.776000Z"}
{"type":"received","order_id":"95ca7101-471e-480e-a04d-ac32143c9056","order_type":"limit","size":"0.10000000","price":"2447.14000000","side":"sell","client_oid":"d15aa074-eaa5-4c31-a3cf-881e079d239d","product_id":"BTC-USD","sequence":3342835423,"time":"2017-06-17T02:38:33.788000Z"}
{"type":"open","side":"sell","price":"2447.14000000","order_id":"95ca7101-471e-480e-a04d-ac32143c9056","remaining_size":"0.10000000","product_id":"BTC-USD","sequence":3342835424,"time":"2017-06-17T02:38:33.788000Z"}
{"type":"done","side":"sell","order_id":"224ab22a-a88d-4d46-abaa-a6083af813e6","reason":"canceled","product_id":"BTC-USD","price":"2447.15000000","remaining_size":"0.10000000","sequence":3342835425,"time":"2017-06-17T02:38:33.799000Z"}
{"type":"done","side":"sell","order_id":"95ca7101-471e-480e-a04d-ac32143c9056","reason":"canceled","product_id":"BTC-USD","price":"2447.14000000","remaining_size":"0.10000000","sequence":3342835426,"time":"2017-06-17T02:38:33.843000Z"}
{"type":"done","side":"buy","order_id":"8f6aad29-8abf-480c-979f-b47814d91965","reason":"canceled","product_id":"BTC-USD","price":"2442.77000000","remaining_size":"0.25000000","sequence":3342835427,"time":"2017-06-17T02:38:33.876000Z"}
{"type":"received","order_id":"f19584c4-87ef-4462-a275-45bb1f2c0cbf","order_type":"limit","size":"0.08985400","price":"2447.53000000","side":"sell","client_oid":"05da64dd-4039-4f57-89cc-515a48cd11e0","product_id":"BTC-USD","sequence":3342835428,"time":"2017-06-17T02:38:33.877000Z"}
{"type":"open","side":"sell","price":"2447.53000000","order_id":"f19584c4-87ef-4462-a275-45bb1f2c0cbf","remaining_size":"0.08985400","product_id":"BTC-USD","sequence":3342835429,"time":"2017-06-17T02:38:33.877000Z"}
{"type":"received","order_id":"c485b1a4-56ec-4d61-a33b-43e2b098d1c1","order_type":"limit","size":"0.25000000","price":"2442.78000000","side":"buy","client_oid":"4c2658ee-a332-44b7-a60a-bc5b65268aff","product_id":"BTC-USD","sequence":3342835430,"time":"2017-06-17T02:38:33.891000Z"}
{"type":"open","side":"buy","price":"2442.78000000","order_id":"c485b1a4-56ec-4d61-a33b-43e2b098d1c1","remaining_size":"0.25000000","product_id":"BTC-USD","sequence":3342835431,"time":"2017-06-17T02:38:33.891000Z"}
{"type":"received","order_id":"dfd5ff5d-0ce3-4250-a6f7-89310f9028ad","order_type":"limit","size":"0.10000000","price":"2447.15000000","side":"sell","client_oid":"6e8ffe72-157f-4bb7-b1f3-1ff3e91ba180","product_id":"BTC-USD","sequence":3342835432,"time":"2017-06-17T02:38:33.897000Z"}
{"type":"open","side":"sell","price":"2447.15000000","order_id":"dfd5ff5d-0ce3-4250-a6f7-89310f9028ad","remaining_size":"0.10000000","product_id":"BTC-USD","sequence":3342835433,"time":"2017-06-17T02:38:33.897000Z"}
{"type":"done","side":"sell","order_id":"f19584c4-87ef-4462-a275-45bb1f2c0cbf","reason":"canceled","product_id":"BTC-USD","price":"2447.53000000","remaining_size":"0.08985400","sequence":3342835434,"time":"2017-06-17T02:38:33.919000Z"}
{"type":"received","order_id":"ec7ed1ef-5bc5-4e6c-b943-26317f9d316a","order_type":"limit","size":"0.08985400","price":"2448.77000000","side":"sell","client_oid":"d5bc3fb6-bc8d-48b9-85fb-d4c4f22b6737","product_id":"BTC-USD","sequence":3342835435,"time":"2017-06-17T02:38:33.944000Z"}
{"type":"open","side":"sell","price":"2448.77000000","order_id":"ec7ed1ef-5bc5-4e6c-b943-26317f9d316a","remaining_size":"0.08985400","product_id":"BTC-USD","sequence":3342835436,"time":"2017-06-17T02:38:33.944000Z"}
{"type":"done","side":"sell","order_id":"ec7ed1ef-5bc5-4e6c-b943-26317f9d316a","reason":"canceled","product_id":"BTC-USD","price":"2448.77000000","remaining_size":"0.08985400","sequence":3342835437,"time":"2017-06-17T02:38:33.959000Z"}
{"type":"received","order_id":"2c7227fe-dea9-4448-9d9c-8c21e773c4f1","order_type":"limit","size":"0.10000000","price":"2447.14000000","side":"sell","client_oid":"d424af58-647a-4b7b-b57f-e19514fa05fa","product_id":"BTC-USD","sequence":3342835438,"time":"2017-06-17T02:38:33.963000Z"}
{"type":"open","side":"sell","price":"2447.14000000","order_id":"2c7227fe-dea9-4448-9d9c-8c21e773c4f1","remaining_size":"0.10000000","product_id":"BTC-USD","sequence":3342835439,"time":"2017-06-17T02:38:33.963000Z"}
{"type":"done","side":"buy","order_id":"c485b1a4-56ec-4d61-a33b-43e2b098d1c1","reason":"canceled","product_id":"BTC-USD","price":"2442.78000000","remaining_size":"0.25000000","sequence":3342835440,"time":"2017-06-17T02:38:33.965000Z"}
{"type":"done","side":"sell","order_id":"dfd5ff5d-0ce3-4250-a6f7-89310f9028ad","reason":"canceled","product_id":"BTC-USD","price":"2447.15000000","remaining_size":"0.10000000","sequence":3342835441,"time":"2017-06-17T02:38:33.966000Z"}
{"type":"received","order_id":"ca3040f5-b0bc-4386-8887-6864320fe16f","order_type":"limit","size":"0.08985400","price":"2447.53000000","side":"sell","client_oid":"14ae2b25-dfa3-43e8-887a-8c0ae72186d1","product_id":"BTC-USD","sequence":3342835442,"time":"2017-06-17T02:38:33.970000Z"}
{"type":"open","side":"sell","price":"2447.53000000","order_id":"ca3040f5-b0bc-4386-8887-6864320fe16f","remaining_size":"0.08985400","product_id":"BTC-USD","sequence":3342835443,"time":"2017-06-17T02:38:33.970000Z"}
{"type":"received","order_id":"868d1f94-2b5e-47fd-92cf-2850c3e54220","order_type":"limit","size":"0.73000000","price":"2449.19000000","side":"sell","client_oid":"07b3c499-c6ee-7635-512a-c5cc32214894","product_id":"BTC-USD","sequence":3342835444,"time":"2017-06-17T02:38:33.974000Z"}
{"type":"open","side":"sell","price":"2449.19000000","order_id":"868d1f94-2b5e-47fd-92cf-2850c3e54220","remaining_size":"0.73000000","product_id":"BTC-USD","sequence":3342835445,"time":"2017-06-17T02:38:33.974000Z"}
{"type":"received","order_id":"b1e20dc6-93a9-4b2c-b261-570182bd176c","order_type":"limit","size":"0.20000000","price":"2447.53000000","side":"sell","client_oid":"7b9537c2-a923-4640-a4ff-dcb6203c0caf","product_id":"BTC-USD","sequence":3342835446,"time":"2017-06-17T02:38:34.004000Z"}
{"type":"open","side":"sell","price":"2447.53000000","order_id":"b1e20dc6-93a9-4b2c-b261-570182bd176c","remaining_size":"0.20000000","product_id":"BTC-USD","sequence":3342835447,"time":"2017-06-17T02:38:34.004000Z"}
{"type":"done","side":"sell","order_id":"2c7227fe-dea9-4448-9d9c-8c21e773c4f1","reason":"canceled","product_id":"BTC-USD","price":"2447.14000000","remaining_size":"0.10000000","sequence":3342835448,"time":"2017-06-17T02:38:34.005000Z"}
{"type":"done","side":"sell","order_id":"ca3040f5-b0bc-4386-8887-6864320fe16f","reason":"canceled","product_id":"BTC-USD","price":"2447.53000000","remaining_size":"0.08985400","sequence":3342835449,"time":"2017-06-17T02:38:34.014000Z"}
{"type":"received","order_id":"3782139e-8624-4911-9217-933d7e37eb5d","order_type":"limit","size":"0.20000000","price":"2447.52000000","side":"sell","client_oid":"328439e7-31b5-4c5a-9d42-7b0ee48aabc2","product_id":"BTC-USD","sequence":3342835450,"time":"2017-06-17T02:38:34.024000Z"}
{"type":"open","side":"sell","price":"2447.52000000","order_id":"3782139e-8624-4911-9217-933d7e37eb5d","remaining_size":"0.20000000","product_id":"BTC-USD","sequence":3342835451,"time":"2017-06-17T02:38:34.024000Z"}
{"type":"done","side":"sell","order_id":"3782139e-8624-4911-9217-933d7e37eb5d","reason":"canceled","product_id":"BTC-USD","price":"2447.52000000","remaining_size":"0.20000000","sequence":3342835452,"time":"2017-06-17T02:38:34.056000Z"}
{"type":"received","order_id":"0040394a-45d5-4e2d-bd28-215cf4348dc4","order_type":"limit","size":"0.10000000","price":"2447.15000000","side":"sell","client_oid":"55c6d884-c186-45ea-8b4f-5a1407897e1a","product_id":"BTC-USD","sequence":3342835453,"time":"2017-06-17T02:38:34.059000Z"}
{"type":"open","side":"sell","price":"2447.15000000","order_id":"0040394a-45d5-4e2d-bd28-215cf4348dc4","remaining_size":"0.10000000","product_id":"BTC-USD","sequence":3342835454,"time":"2017-06-17T02:38:34.059000Z"}
{"type":"received","order_id":"602f931a-b403-4b60-a222-bc9373aa3c8a","order_type":"limit","size":"0.08985400","price":"2447.52000000","side":"sell","client_oid":"b24a0171-8d1f-4091-a1a6-61cf0a141573","product_id":"BTC-USD","sequence":3342835455,"time":"2017-06-17T02:38:34.063000Z"}
{"type":"open","side":"sell","price":"2447.52000000","order_id":"602f931a-b403-4b60-a222-bc9373aa3c8a","remaining_size":"0.08985400","product_id":"BTC-USD","sequence":3342835456,"time":"2017-06-17T02:38:34.063000Z"}
{"type":"done","side":"sell","order_id":"b1e20dc6-93a9-4b2c-b261-570182bd176c","reason":"canceled","product_id":"BTC-USD","price":"2447.53000000","remaining_size":"0.20000000","sequence":3342835457,"time":"2017-06-17T02:38:34.064000Z"}
{"type":"done","side":"sell","order_id":"602f931a-b403-4b60-a222-bc9373aa3c8a","reason":"canceled","product_id":"BTC-USD","price":"2447.52000000","remaining_size":"0.08985400","sequence":3342835458,"time":"2017-06-17T02:38:34.100000Z"}
{"type":"done","side":"sell","order_id":"0040394a-45d5-4e2d-bd28-215cf4348dc4","reason":"canceled","product_id":"BTC-USD","price":"2447.15000000","remaining_size":"0.10000000","sequence":3342835459,"time":"2017-06-17T02:38:34.107000Z"}
{"type":"received","order_id":"087287a1-7209-4ffe-b64f-72360e41238c","order_type":"limit","size":"0.10000000","price":"2447.14000000","side":"sell","client_oid":"9f3a9045-6ce5-420f-9a8e-66629366c8d2","product_id":"BTC-USD","sequence":3342835460,"time":"2017-06-17T02:38:34.118000Z"}
{"type":"open","side":"sell","price":"2447.14000000","order_id":"087287a1-7209-4ffe-b64f-72360e41238c","remaining_size":"0.10000000","product_id":"BTC-USD","sequence":3342835461,"time":"2017-06-17T02:38:34.118000Z"}
{"type":"received","order_id":"69142d50-f524-4af4-96ab-4c8d65420a64","order_type":"limit","size":"0.08985400","price":"2447.53000000","side":"sell","client_oid":"77320888-464e-4f62-9a7a-4905b839e21c","product_id":"BTC-USD","sequence":3342835462,"time":"2017-06-17T02:38:34.135000Z"}
{"type":"open","side":"sell","price":"2447.53000000","order_id":"69142d50-f524-4af4-96ab-4c8d65420a64","remaining_size":"0.08985400","product_id":"BTC-USD","sequence":3342835463,"time":"2017-06-17T02:38:34.135000Z"}
{"type":"done","side":"sell","order_id":"087287a1-7209-4ffe-b64f-72360e41238c","reason":"canceled","product_id":"BTC-USD","price":"2447.14000000","remaining_size":"0.10000000","sequence":3342835464,"time":"2017-06-17T02:38:34.162000Z"}
{"type":"received","order_id":"5ac4ce80-e65d-4216-adb1-3756b1c409ed","order_type":"limit","size":"0.20000000","price":"2447.53000000","side":"sell","client_oid":"5fc86b4b-4b50-4dc6-a13f-ad183b4d3eff","product_id":"BTC-USD","sequence":3342835465,"time":"2017-06-17T02:38:34.163000Z"}
{"type":"open","side":"sell","price":"2447.53000000","order_id":"5ac4ce80-e65d-4216-adb1-3756b1c409ed","remaining_size":"0.20000000","product_id":"BTC-USD","sequence":3342835466,"time":"2017-06-17T02:38:34.163000Z"}
{"type":"received","order_id":"9da5a0ef-adf5-4fd9-a5bb-8164bbb760f3","order_type":"limit","size":"0.02100000","price":"2441.97000000","side":"buy","product_id":"BTC-USD","sequence":3342835467,"time":"2017-06-17T02:38:34.175000Z"}
{"type":"open","side":"buy","price":"2441.97000000","order_id":"9da5a0ef-adf5-4fd9-a5bb-8164bbb760f3","remaining_size":"0.02100000","product_id":"BTC-USD","sequence":3342835468,"time":"2017-06-17T02:38:34.175000Z"}
{"type":"done","side":"sell","order_id":"69142d50-f524-4af4-96ab-4c8d65420a64","reason":"canceled","product_id":"BTC-USD","price":"2447.53000000","remaining_size":"0.08985400","sequence":3342835469,"time":"2017-06-17T02:38:34.181000Z"}
{"type":"received","order_id":"63723498-4b18-4852-900d-3de87479bf23","order_type":"limit","size":"0.08985400","price":"2448.77000000","side":"sell","client_oid":"3d767525-e2d1-4d4a-b7d1-1c6df8cd06f4","product_id":"BTC-USD","sequence":3342835470,"time":"2017-06-17T02:38:34.194000Z"}
{"type":"open","side":"sell","price":"2448.77000000","order_id":"63723498-4b18-4852-900d-3de87479bf23","remaining_size":"0.08985400","product_id":"BTC-USD","sequence":3342835471,"time":"2017-06-17T02:38:34.194000Z"}
{"type":"done","side":"sell","order_id":"5ac4ce80-e65d-4216-adb1-3756b1c409ed","reason":"canceled","product_id":"BTC-USD","price":"2447.53000000","remaining_size":"0.20000000","sequence":3342835472,"time":"2017-06-17T02:38:34.195000Z"}
{"type":"received","order_id":"bc2d2c48-9b5e-4a7f-8390-25d55eab8323","order_type":"limit","size":"0.20000000","price":"2448.77000000","side":"sell","client_oid":"89fd8882-4b90-48d5-b2ca-ff61b9621e40","product_id":"BTC-USD","sequence":3342835473,"time":"2017-06-17T02:38:34.210000Z"}
{"type":"open","side":"sell","price":"2448.77000000","order_id":"bc2d2c48-9b5e-4a7f-8390-25d55eab8323","remaining_size":"0.20000000","product_id":"BTC-USD","sequence":3342835474,"time":"2017-06-17T02:38:34.210000Z"}
{"type":"received","order_id":"65a38393-a8f5-4b95-8147-79f5f0bbd9f0","order_type":"limit","size":"0.10000000","price":"2447.15000000","side":"sell","client_oid":"628b9ea9-84df-4518-ad46-c408618631e2","product_id":"BTC-USD","sequence":3342835475,"time":"2017-06-17T02:38:34.216000Z"}
{"type":"open","side":"sell","price":"2447.15000000","order_id":"65a38393-a8f5-4b95-8147-79f5f0bbd9f0","remaining_size":"0.10000000","product_id":"BTC-USD","sequence":3342835476,"time":"2017-06-17T02:38:34.216000Z"}
{"type":"done","side":"sell","order_id":"63723498-4b18-4852-900d-3de87479bf23","reason":"canceled","product_id":"BTC-USD","price":"2448.77000000","remaining_size":"0.08985400","sequence":3342835477,"time":"2017-06-17T02:38:34.223000Z"}
{"type":"received","order_id":"eb33d121-b764-4af7-b78a-01b429cffa06","order_type":"limit","size":"0.08985400","price":"2448.76000000","side":"sell","client_oid":"dce52a0c-5ed7-4da2-a1ca-710761cda2b3","product_id":"BTC-USD","sequence":3342835478,"time":"2017-06-17T02:38:34.232000Z"}
{"type":"open","side":"sell","price":"2448.76000000","order_id":"eb33d121-b764-4af7-b78a-01b429cffa06","remaining_size":"0.08985400","product_id":"BTC-USD","sequence":3342835479,"time":"2017-06-17T02:38:34.232000Z"}
{"type":"received","order_id":"951f4e3c-d0d4-4ec1-b454-5a99e3c74f58","order_type":"limit","size":"0.20000000","price":"2447.53000000","side":"sell","client_oid":"2e68974d-f026-464d-a4de-ee0d96fc1358","product_id":"BTC-USD","sequence":3342835480,"time":"2017-06-17T02:38:34.238000Z"}
{"type":"open","side":"sell","price":"2447.53000000","order_id":"951f4e3c-d0d4-4ec1-b454-5a99e3c74f58","remaining_size":"0.20000000","product_id":"BTC-USD","sequence":3342835481,"time":"2017-06-17T02:38:34.238000Z"}
{"type":"done","side":"sell","order_id":"bc2d2c48-9b5e-4a7f-8390-25d55eab8323","reason":"canceled","product_id":"BTC-USD","price":"2448.77000000","remaining_size":"0.20000000","sequence":3342835482,"time":"2017-06-17T02:38:34.239000Z"}
{"type":"done","side":"sell","order_id":"65a38393-a8f5-4b95-8147-79f5f0bbd9f0","reason":"canceled","product_id":"BTC-USD","price":"2447.15000000","remaining_size":"0.10000000","sequence":3342835483,"time":"2017-06-17T02:38:34.259000Z"}
{"type":"done","side":"sell","order_id":"eb33d121-b764-4af7-b78a-01b429cffa06","reason":"canceled","product_id":"BTC-USD","price":"2448.76000000","remaining_size":"0.08985400","sequence":3342835484,"time":"2017-06-17T02:38:34.269000Z"}
{"type":"done","side":"sell","order_id":"951f4e3c-d0d4-4ec1-b454-5a99e3c74f58","reason":"canceled","product_id":"BTC-USD","price":"2447.53000000","remaining_size":"0.20000000","sequence":3342835485,"time":"2017-06-17T02:38:34.279000Z"}
{"type":"done","side":"sell","order_id":"01e3bc16-08ad-485b-8b84-78d2c7fc2f3f","reason":"canceled","product_id":"BTC-USD","price":"2443.61000000","remaining_size":"0.50000000","sequence":3342835486,"time":"2017-06-17T02:38:34.315000Z"}
{"type":"received","order_id":"96afbe47-ff24-4939-847a-093a45a477d8","order_type":"limit","size":"0.10000000","price":"2447.15000000","side":"sell","client_oid":"4174e075-4fa9-4be3-816d-99d211bdcd90","product_id":"BTC-USD","sequence":3342835487,"time":"2017-06-17T02:38:34.327000Z"}
{"type":"open","side":"sell","price":"2447.15000000","order_id":"96afbe47-ff24-4939-847a-093a45a477d8","remaining_size":"0.10000000","product_id":"BTC-USD","sequence":3342835488,"time":"2017-06-17T02:38:34.327000Z"}
{"type":"done","side":"sell","order_id":"96afbe47-ff24-4939-847a-093a45a477d8","reason":"canceled","product_id":"BTC-USD","price":"2447.15000000","remaining_size":"0.10000000","sequence":3342835489,"time":"2017-06-17T02:38:34.365000Z"}
{"type":"received","order_id":"5a29a1d2-08fb-43ed-8b1c-5faf2335d562","order_type":"limit","size":"0.10000000","price":"2447.14000000","side":"sell","client_oid":"3bec279f-b560-4f9e-91e6-bd4abb30b107","product_id":"BTC-USD","sequence":3342835490,"time":"2017-06-17T02:38:34.378000Z"}
{"type":"open","side":"sell","price":"2447.14000000","order_id":"5a29a1d2-08fb-43ed-8b1c-5faf2335d562","remaining_size":"0.10000000","product_id":"BTC-USD","sequence":3342835491,"time":"2017-06-17T02:38:34.378000Z"}
{"type":"done","side":"sell","order_id":"5a29a1d2-08fb-43ed-8b1c-5faf2335d562","reason":"canceled","product_id":"BTC-USD","price":"2447.14000000","remaining_size":"0.10000000","sequence":3342835492,"time":"2017-06-17T02:38:34.409000Z"}
{"type":"received","order_id":"0c43d4f7-8634-4209-aa62-9cb3fcfbc610","order_type":"limit","size":"0.08985400","price":"2447.53000000","side":"sell","client_oid":"24904d61-c569-49e1-9be1-55a9f8b46628","product_id":"BTC-USD","sequence":3342835493,"time":"2017-06-17T02:38:34.422000Z"}
{"type":"open","side":"sell","price":"2447.53000000","order_id":"0c43d4f7-8634-4209-aa62-9cb3fcfbc610","remaining_size":"0.08985400","product_id":"BTC-USD","sequence":3342835494,"time":"2017-06-17T02:38:34.422000Z"}
{"type":"received","order_id":"97dedc18-1e65-4306-8dc6-b0a12229715d","order_type":"limit","size":"0.10000000","price":"2447.13000000","side":"sell","client_oid":"0871a46c-fb60-46a3-b5d3-cc589347c15d","product_id":"BTC-USD","sequence":3342835495,"time":"2017-06-17T02:38:34.429000Z"}
{"type":"open","side":"sell","price":"2447.13000000","order_id":"97dedc18-1e65-4306-8dc6-b0a12229715d","remaining_size":"0.10000000","product_id":"BTC-USD","sequence":3342835496,"time":"2017-06-17T02:38:34.429000Z"}
{"type":"received","order_id":"4f597347-bd76-4aaf-abe4-32f9fc226539","order_type":"limit","size":"0.50000000","price":"2443.59000000","side":"sell","client_oid":"371cd50d-3b88-4581-9b18-b37fb779641b","product_id":"BTC-USD","sequence":3342835497,"time":"2017-06-17T02:38:34.451000Z"}
{"type":"open","side":"sell","price":"2443.59000000","order_id":"4f597347-bd76-4aaf-abe4-32f9fc226539","remaining_size":"0.50000000","product_id":"BTC-USD","sequence":3342835498,"time":"2017-06-17T02:38:34.451000Z"}
{"type":"done","side":"sell","order_id":"97dedc18-1e65-4306-8dc6-b0a12229715d","reason":"canceled","product_id":"BTC-USD","price":"2447.13000000","remaining_size":"0.10000000","sequence":3342835499,"time":"2017-06-17T02:38:34.469000Z"}
{"type":"received","order_id":"d6fa316f-423b-4f11-a3be-76c2a22958db","order_type":"limit","size":"0.10000000","price":"2447.12000000","side":"sell","client_oid":"6c4154d3-aaa8-4824-8f05-34e20c89c9e8","product_id":"BTC-USD","sequence":3342835500,"time":"2017-06-17T02:38:34.478000Z"}
{"type":"open","side":"sell","price":"2447.12000000","order_id":"d6fa316f-423b-4f11-a3be-76c2a22958db","remaining_size":"0.10000000","product_id":"BTC-USD","sequence":3342835501,"time":"2017-06-17T02:38:34.478000Z"}
{"type":"done","side":"sell","order_id":"0c43d4f7-8634-4209-aa62-9cb3fcfbc610","reason":"canceled","product_id":"BTC-USD","price":"2447.53000000","remaining_size":"0.08985400","sequence":3342835502,"time":"2017-06-17T02:38:34.486000Z"}
{"type":"received","order_id":"1edabce9-36e2-4997-90c0-0f3f4fe2c10d","order_type":"limit","size":"0.08985400","price":"2448.77000000","side":"sell","client_oid":"4731f92f-8b63-439a-8eff-1ddcba28444d","product_id":"BTC-USD","sequence":3342835503,"time":"2017-06-17T02:38:34.490000Z"}
{"type":"open","side":"sell","price":"2448.77000000","order_id":"1edabce9-36e2-4997-90c0-0f3f4fe2c10d","remaining_size":"0.08985400","product_id":"BTC-USD","sequence":3342835504,"time":"2017-06-17T02:38:34.490000Z"}
{"type":"received","order_id":"fea03e99-7d98-4a60-9562-cdfcd36820b6","order_type":"limit","size":"0.10000000","price":"2447.11000000","side":"sell","client_oid":"9eb6aaac-4696-4a91-a320-3cc32004fcd9","product_id":"BTC-USD","sequence":3342835505,"time":"2017-06-17T02:38:34.512000Z"}
{"type":"open","side":"sell","price":"2447.11000000","order_id":"fea03e99-7d98-4a60-9562-cdfcd36820b6","remaining_size":"0.10000000","product_id":"BTC-USD","sequence":3342835506,"time":"2017-06-17T02:38:34.512000Z"}
{"type":"done","side":"sell","order_id":"d6fa316f-423b-4f11-a3be-76c2a22958db","reason":"canceled","product_id":"BTC-USD","price":"2447.12000000","remaining_size":"0.10000000","sequence":3342835507,"time":"2017-06-17T02:38:34.514000Z"}
{"type":"done","side":"sell","order_id":"1edabce9-36e2-4997-90c0-0f3f4fe2c10d","reason":"canceled","product_id":"BTC-USD","price":"2448.77000000","remaining_size":"0.08985400","sequence":3342835508,"time":"2017-06-17T02:38:34.520000Z"}
{"type":"done","side":"sell","order_id":"fea03e99-7d98-4a60-9562-cdfcd36820b6","reason":"canceled","product_id":"BTC-USD","price":"2447.11000000","remaining_size":"0.10000000","sequence":3342835509,"time":"2017-06-17T02:38:34.546000Z"}
{"type":"received","order_id":"624516bb-385c-487d-801d-c40149a2afc2","order_type":"limit","size":"0.08985400","price":"2447.53000000","side":"sell","client_oid":"ce0fbf6d-3104-4495-8f8e-bcfff9507b71","product_id":"BTC-USD","sequence":3342835510,"time":"2017-06-17T02:38:34.551000Z"}
{"type":"open","side":"sell","price":"2447.53000000","order_id":"624516bb-385c-487d-801d-c40149a2afc2","remaining_size":"0.08985400","product_id":"BTC-USD","sequence":3342835511,"time":"2017-06-17T02:38:34.551000Z"}
{"type":"done","side":"sell","order_id":"624516bb-385c-487d-801d-c40149a2afc2","reason":"canceled","product_id":"BTC-USD","price":"2447.53000000","remaining_size":"0.08985400","sequence":3342835512,"time":"2017-06-17T02:38:34.582000Z"}
{"type":"received","order_id":"9bab13a1-a46c-43a1-8a4d-24c79ad5718d","order_type":"limit","size":"0.10000000","price":"2447.10000000","side":"sell","client_oid":"c5168b3e-c742-444d-89c4-5ffea3095547","product_id":"BTC-USD","sequence":3342835513,"time":"2017-06-17T02:38:34.586000Z"}
{"type":"open","side":"sell","price":"2447.10000000","order_id":"9bab13a1-a46c-43a1-8a4d-24c79ad5718d","remaining_size":"0.10000000","product_id":"BTC-USD","sequence":3342835514,"time":"2017-06-17T02:38:34.586000Z"}
{"type":"done","side":"sell","order_id":"9bab13a1-a46c-43a1-8a4d-24c79ad5718d","reason":"canceled","product_id":"BTC-USD","price":"2447.10000000","remaining_size":"0.10000000","sequence":3342835515,"time":"2017-06-17T02:38:34.592000Z"}
{"type":"received","order_id":"2fa6843a-1395-43e9-8822-846a73080253","order_type":"limit","size":"0.08985400","price":"2448.77000000","side":"sell","client_oid":"2fcc4d97-8ec2-459c-920d-5dfbb8dc167c","product_id":"BTC-USD","sequence":3342835516,"time":"2017-06-17T02:38:34.597000Z"}
{"type":"open","side":"sell","price":"2448.77000000","order_id":"2fa6843a-1395-43e9-8822-846a73080253","remaining_size":"0.08985400","product_id":"BTC-USD","sequence":3342835517,"time":"2017-06-17T02:38:34.597000Z"}
{"type":"received","order_id":"0c9d962d-042b-4e60-a338-78d0baee2e48","order_type":"limit","size":"0.10000000","price":"2447.15000000","side":"sell","client_oid":"66773481-6c61-4f7a-918e-cd7de9abc32d","product_id":"BTC-USD","sequence":3342835518,"time":"2017-06-17T02:38:34.603000Z"}
{"type":"open","side":"sell","price":"2447.15000000","order_id":"0c9d962d-042b-4e60-a338-78d0baee2e48","remaining_size":"0.10000000","product_id":"BTC-USD","sequence":3342835519,"time":"2017-06-17T02:38:34.603000Z"}
{"type":"done","side":"sell","order_id":"2fa6843a-1395-43e9-8822-846a73080253","reason":"canceled","product_id":"BTC-USD","price":"2448.77000000","remaining_size":"0.08985400","sequence":3342835520,"time":"2017-06-17T02:38:34.624000Z"}
{"type":"done","side":"sell","order_id":"0c9d962d-042b-4e60-a338-78d0baee2e48","reason":"canceled","product_id":"BTC-USD","price":"2447.15000000","remaining_size":"0.10000000","sequence":3342835521,"time":"2017-06-17T02:38:34.633000Z"}
{"type":"received","order_id":"762d6500-2c25-4224-a3e3-0aca9f1e1e15","order_type":"limit","size":"0.08985400","price":"2447.53000000","side":"sell","client_oid":"bcc9c37f-6515-449a-a605-4695f3d40b46","product_id":"BTC-USD","sequence":3342835522,"time":"2017-06-17T02:38:34.635000Z"}
{"type":"open","side":"sell","price":"2447.53000000","order_id":"762d6500-2c25-4224-a3e3-0aca9f1e1e15","remaining_size":"0.08985400","product_id":"BTC-USD","sequence":3342835523,"time":"2017-06-17T02:38:34.635000Z"}
{"type":"received","order_id":"9e5743c9-1d55-4a64-9754-9526f860a6cf","order_type":"limit","size":"0.10000000","price":"2447.14000000","side":"sell","client_oid":"23310746-1561-4b3c-958d-c9710e06f780","product_id":"BTC-USD","sequence":3342835524,"time":"2017-06-17T02:38:34.647000Z"}
{"type":"open","side":"sell","price":"2447.14000000","order_id":"9e5743c9-1d55-4a64-9754-9526f860a6cf","remaining_size":"0.10000000","product_id":"BTC-USD","sequence":3342835525,"time":"2017-06-17T02:38:34.647000Z"}
{"type":"done","side":"sell","order_id":"9e5743c9-1d55-4a64-9754-9526f860a6cf","reason":"canceled","product_id":"BTC-USD","price":"2447.14000000","remaining_size":"0.10000000","sequence":3342835526,"time":"2017-06-17T02:38:34.683000Z"}
{"type":"done","side":"sell","order_id":"762d6500-2c25-4224-a3e3-0aca9f1e1e15","reason":"canceled","product_id":"BTC-USD","price":"2447.53000000","remaining_size":"0.08985400","sequence":3342835527,"time":"2017-06-17T02:38:34.692000Z"}
{"type":"received","order_id":"75ff9d8b-de98-4598-b9c3-f6e920bd2f79","order_type":"limit","size":"0.10000000","price":"2447.13000000","side":"sell","client_oid":"f48fb624-5505-4440-8d46-e3f6c073e6dd","product_id":"BTC-USD","sequence":3342835528,"time":"2017-06-17T02:38:34.700000Z"}
{"type":"open","side":"sell","price":"2447.13000000","order_id":"75ff9d8b-de98-4598-b9c3-f6e920bd2f79","remaining_size":"0.10000000","product_id":"BTC-USD","sequence":3342835529,"time":"2017-06-17T02:38:34.700000Z"}
{"type":"received","order_id":"1293ed94-33e5-467b-af7d-1a10b7ae75bd","order_type":"limit","size":"0.08985400","price":"2448.77000000","side":"sell","client_oid":"cb81ac05-3be8-43e7-b34a-f9be69fab485","product_id":"BTC-USD","sequence":3342835530,"time":"2017-06-17T02:38:34.708000Z"}
{"type":"open","side":"sell","price":"2448.77000000","order_id":"1293ed94-33e5-467b-af7d-1a10b7ae75bd","remaining_size":"0.08985400","product_id":"BTC-USD","sequence":3342835531,"time":"2017-06-17T02:38:34.708000Z"}
{"type":"done","side":"sell","order_id":"75ff9d8b-de98-4598-b9c3-f6e920bd2f79","reason":"canceled","product_id":"BTC-USD","price":"2447.13000000","remaining_size":"0.10000000","sequence":3342835532,"time":"2017-06-17T02:38:34.725000Z"}
{"type":"received","order_id":"1f712bd8-634c-4961-ace0-4efd18b5fad7","order_type":"limit","size":"0.10000000","price":"2447.12000000","side":"sell","client_oid":"627629c4-bafd-4cac-b027-178bfc5da613","product_id":"BTC-USD","sequence":3342835533,"time":"2017-06-17T02:38:34.737000Z"}
{"type":"open","side":"sell","price":"2447.12000000","order_id":"1f712bd8-634c-4961-ace0-4efd18b5fad7","remaining_size":"0.10000000","product_id":"BTC-USD","sequence":3342835534,"time":"2017-06-17T02:38:34.737000Z"}
{"type":"done","side":"sell","order_id":"1293ed94-33e5-467b-af7d-1a10b7ae75bd","reason":"canceled","product_id":"BTC-USD","price":"2448.77000000","remaining_size":"0.08985400","sequence":3342835535,"time":"2017-06-17T02:38:34.745000Z"}
{"type":"done","side":"sell","order_id":"1f712bd8-634c-4961-ace0-4efd18b5fad7","reason":"canceled","product_id":"BTC-USD","price":"2447.12000000","remaining_size":"0.10000000","sequence":3342835536,"time":"2017-06-17T02:38:34.768000Z"}
{"type":"received","order_id":"8a0ad646-3c18-4610-a35e-5c641300b342","order_type":"limit","size":"0.08985400","price":"2447.53000000","side":"sell","client_oid":"e48d4a13-68eb-4044-b9e9-07b6aede4355","product_id":"BTC-USD","sequence":3342835537,"time":"2017-06-17T02:38:34.780000Z"}
{"type":"open","side":"sell","price":"2447.53000000","order_id":"8a0ad646-3c18-4610-a35e-5c641300b342","remaining_size":"0.08985400","product_id":"BTC-USD","sequence":3342835538,"time":"2017-06-17T02:38:34.780000Z"}
{"type":"done","side":"sell","order_id":"8a0ad646-3c18-4610-a35e-5c641300b342","reason":"canceled","product_id":"BTC-USD","price":"2447.53000000","remaining_size":"0.08985400","sequence":3342835539,"time":"2017-06-17T02:38:34.792000Z"}
{"type":"received","order_id":"8da8bf16-6fb9-49a9-b30c-4f245b4273c0","order_type":"limit","size":"0.10000000","price":"2447.11000000","side":"sell","client_oid":"5f255bc9-d48d-43ad-95d3-d323d854c14f","product_id":"BTC-USD","sequence":3342835540,"time":"2017-06-17T02:38:34.798000Z"}
{"type":"open","side":"sell","price":"2447.11000000","order_id":"8da8bf16-6fb9-49a9-b30c-4f245b4273c0","remaining_size":"0.10000000","product_id":"BTC-USD","sequence":3342835541,"time":"2017-06-17T02:38:34.798000Z"}
{"type":"received","order_id":"9199fe04-658a-41ac-a7cd-bd67bb9a117a","order_type":"limit","size":"0.08985400","price":"2448.77000000","side":"sell","client_oid":"12a6cd3c-596c-4e47-a44d-4cb8e758f1e7","product_id":"BTC-USD","sequence":3342835542,"time":"2017-06-17T02:38:34.812000Z"}
{"type":"open","side":"sell","price":"2448.77000000","order_id":"9199fe04-658a-41ac-a7cd-bd67bb9a117a","remaining_size":"0.08985400","product_id":"BTC-USD","sequence":3342835543,"time":"2017-06-17T02:38:34.812000Z"}
{"type":"received","order_id":"7f5673a2-9c79-4aa6-8245-0fcbb6407418","order_type":"limit","size":"0.20000000","price":"2449.17000000","side":"sell","client_oid":"0bb097e9-7597-417a-a28c-fdac99400c7d","product_id":"BTC-USD","sequence":3342835544,"time":"2017-06-17T02:38:34.823000Z"}
{"type":"open","side":"sell","price":"2449.17000000","order_id":"7f5673a2-9c79-4aa6-8245-0fcbb6407418","remaining_size":"0.20000000","product_id":"BTC-USD","sequence":3342835545,"time":"2017-06-17T02:38:34.823000Z"}
{"type":"done","side":"sell","order_id":"7f5673a2-9c79-4aa6-8245-0fcbb6407418","reason":"canceled","product_id":"BTC-USD","price":"2449.17000000","remaining_size":"0.20000000","sequence":3342835546,"time":"2017-06-17T02:38:34.829000Z"}
{"type":"received","order_id":"3141c4d8-07c6-43f8-8e69-e55179740572","order_type":"limit","size":"0.10000000","price":"2447.10000000","side":"sell","client_oid":"36335a91-0ee3-4215-969f-8a99acee4979","product_id":"BTC-USD","sequence":3342835547,"time":"2017-06-17T02:38:34.837000Z"}
{"type":"open","side":"sell","price":"2447.10000000","order_id":"3141c4d8-07c6-43f8-8e69-e55179740572","remaining_size":"0.10000000","product_id":"BTC-USD","sequence":3342835548,"time":"2017-06-17T02:38:34.837000Z"}
{"type":"done","side":"sell","order_id":"8da8bf16-6fb9-49a9-b30c-4f245b4273c0","reason":"canceled","product_id":"BTC-USD","price":"2447.11000000","remaining_size":"0.10000000","sequence":3342835549,"time":"2017-06-17T02:38:34.840000Z"}
{"type":"done","side":"sell","order_id":"9199fe04-658a-41ac-a7cd-bd67bb9a117a","reason":"canceled","product_id":"BTC-USD","price":"2448.77000000","remaining_size":"0.08985400","sequence":3342835550,"time":"2017-06-17T02:38:34.842000Z"}
{"type":"received","order_id":"a44db07c-e7c0-48a3-98b2-bd72c9d364b0","order_type":"limit","size":"0.08985400","price":"2447.53000000","side":"sell","client_oid":"4fa34ff4-0fad-4d86-864c-3c9ea3ea8578","product_id":"BTC-USD","sequence":3342835551,"time":"2017-06-17T02:38:34.855000Z"}
{"type":"open","side":"sell","price":"2447.53000000","order_id":"a44db07c-e7c0-48a3-98b2-bd72c9d364b0","remaining_size":"0.08985400","product_id":"BTC-USD","sequence":3342835552,"time":"2017-06-17T02:38:34.855000Z"}
{"type":"received","order_id":"001dd91a-375a-4738-8c67-33f8357f77e1","order_type":"limit","size":"0.20000000","price":"2447.53000000","side":"sell","client_oid":"ce97822a-ea0e-4eb1-8a0b-d8f8a6696364","product_id":"BTC-USD","sequence":3342835553,"time":"2017-06-17T02:38:34.862000Z"}
{"type":"open","side":"sell","price":"2447.53000000","order_id":"001dd91a-375a-4738-8c67-33f8357f77e1","remaining_size":"0.20000000","product_id":"BTC-USD","sequence":3342835554,"time":"2017-06-17T02:38:34.862000Z"}
{"type":"done","side":"sell","order_id":"3141c4d8-07c6-43f8-8e69-e55179740572","reason":"canceled","product_id":"BTC-USD","price":"2447.10000000","remaining_size":"0.10000000","sequence":3342835555,"time":"2017-06-17T02:38:34.872000Z"}
{"type":"done","side":"sell","order_id":"001dd91a-375a-4738-8c67-33f8357f77e1","reason":"canceled","product_id":"BTC-USD","price":"2447.53000000","remaining_size":"0.20000000","sequence":3342835556,"time":"2017-06-17T02:38:34.879000Z"}
{"type":"received","order_id":"efc87aef-b551-4e7d-b96e-a367ca34a951","order_type":"limit","size":"5.00000000","price":"2435.17000000","side":"buy","product_id":"BTC-USD","sequence":3342835557,"time":"2017-06-17T02:38:34.883000Z"}
{"type":"open","side":"buy","price":"2435.17000000","order_id":"efc87aef-b551-4e7d-b96e-a367ca34a951","remaining_size":"5.00000000","product_id":"BTC-USD","sequence":3342835558,"time":"2017-06-17T02:38:34.883000Z"}
{"type":"done","side":"sell","order_id":"a44db07c-e7c0-48a3-98b2-bd72c9d364b0","reason":"canceled","product_id":"BTC-USD","price":"2447.53000000","remaining_size":"0.08985400","sequence":3342835559,"time":"2017-06-17T02:38:34.885000Z"}
{"type":"received","order_id":"a2f53e85-d4fb-4a83-8db7-658a11daa457","order_type":"limit","size":"0.10000000","price":"2447.09000000","side":"sell","client_oid":"1447fb6e-9c85-48cf-a1a5-e6a3e11e1284","product_id":"BTC-USD","sequence":3342835560,"time":"2017-06-17T02:38:34.897000Z"}
{"type":"open","side":"sell","price":"2447.09000000","order_id":"a2f53e85-d4fb-4a83-8db7-658a11daa457","remaining_size":"0.10000000","product_id":"BTC-USD","sequence":3342835561,"time":"2017-06-17T02:38:34.897000Z"}
{"type":"received","order_id":"44b15c04-3470-47d7-afcc-818e47f8f129","order_type":"limit","size":"0.08985400","price":"2447.52000000","side":"sell","client_oid":"c3ef31f1-50f7-4e4f-a4a8-c84e944c5318","product_id":"BTC-USD","sequence":3342835562,"time":"2017-06-17T02:38:34.909000Z"}
{"type":"open","side":"sell","price":"2447.52000000","order_id":"44b15c04-3470-47d7-afcc-818e47f8f129","remaining_size":"0.08985400","product_id":"BTC-USD","sequence":3342835563,"time":"2017-06-17T02:38:34.909000Z"}
{"type":"done","side":"sell","order_id":"a2f53e85-d4fb-4a83-8db7-658a11daa457","reason":"canceled","product_id":"BTC-USD","price":"2447.09000000","remaining_size":"0.10000000","sequence":3342835564,"time":"2017-06-17T02:38:34.922000Z"}
{"type":"done","side":"sell","order_id":"44b15c04-3470-47d7-afcc-818e47f8f129","reason":"canceled","product_id":"BTC-USD","price":"2447.52000000","remaining_size":"0.08985400","sequence":3342835565,"time":"2017-06-17T02:38:34.926000Z"}
{"type":"received","order_id":"94ea7c38-8583-4168-9494-8b600f831c1d","order_type":"limit","size":"0.10000000","price":"2447.08000000","side":"sell","client_oid":"9d2df8df-323d-49b6-9ccc-149aa5a2c069","product_id":"BTC-USD","sequence":3342835566,"time":"2017-06-17T02:38:34.935000Z"}
{"type":"open","side":"sell","price":"2447.08000000","order_id":"94ea7c38-8583-4168-9494-8b600f831c1d","remaining_size":"0.10000000","product_id":"BTC-USD","sequence":3342835567,"time":"2017-06-17T02:38:34.935000Z"}
{"type":"received","order_id":"a5f4f2e0-7ff7-4929-a91a-00088acac6c9","order_type":"limit","size":"0.08985400","price":"2447.53000000","side":"sell","client_oid":"b71a45a7-424b-473e-83d6-1ee7de29ba44","product_id":"BTC-USD","sequence":3342835568,"time":"2017-06-17T02:38:34.945000Z"}
{"type":"open","side":"sell","price":"2447.53000000","order_id":"a5f4f2e0-7ff7-4929-a91a-00088acac6c9","remaining_size":"0.08985400","product_id":"BTC-USD","sequence":3342835569,"time":"2017-06-17T02:38:34.945000Z"}
{"type":"done","side":"sell","order_id":"94ea7c38-8583-4168-9494-8b600f831c1d","reason":"canceled","product_id":"BTC-USD","price":"2447.08000000","remaining_size":"0.10000000","sequence":3342835570,"time":"2017-06-17T02:38:34.964000Z"}
{"type":"received","order_id":"f146ced9-f132-4bc1-99a3-8d8e4f282630","order_type":"limit","size":"0.10000000","price":"2447.15000000","side":"sell","client_oid":"df3b0ba3-0e07-4b31-885e-d2e7e3ef1ef2","product_id":"BTC-USD","sequence":3342835571,"time":"2017-06-17T02:38:34.983000Z"}
{"type":"open","side":"sell","price":"2447.15000000","order_id":"f146ced9-f132-4bc1-99a3-8d8e4f282630","remaining_size":"0.10000000","product_id":"BTC-USD","sequence":3342835572,"time":"2017-06-17T02:38:34.983000Z"}
{"type":"done","side":"sell","order_id":"f146ced9-f132-4bc1-99a3-8d8e4f282630","reason":"canceled","product_id":"BTC-USD","price":"2447.15000000","remaining_size":"0.10000000","sequence":3342835573,"time":"2017-06-17T02:38:35.009000Z"}
{"type":"done","side":"sell","order_id":"a5f4f2e0-7ff7-4929-a91a-00088acac6c9","reason":"canceled","product_id":"BTC-USD","price":"2447.53000000","remaining_size":"0.08985400","sequence":3342835574,"time":"2017-06-17T02:38:35.017000Z"}
{"type":"received","order_id":"6069fef9-ba10-4ad4-a269-b8a997a36bd1","order_type":"limit","size":"0.10000000","price":"2447.07000000","side":"sell","client_oid":"e8d9ac7c-6de1-49bd-baf6-acba118223a6","product_id":"BTC-USD","sequence":3342835575,"time":"2017-06-17T02:38:35.043000Z"}
{"type":"open","side":"sell","price":"2447.07000000","order_id":"6069fef9-ba10-4ad4-a269-b8a997a36bd1","remaining_size":"0.10000000","product_id":"BTC-USD","sequence":3342835576,"time":"2017-06-17T02:38:35.043000Z"}
{"type":"done","side":"sell","order_id":"6069fef9-ba10-4ad4-a269-b8a997a36bd1","reason":"canceled","product_id":"BTC-USD","price":"2447.07000000","remaining_size":"0.10000000","sequence":3342835577,"time":"2017-06-17T02:38:35.053000Z"}
{"type":"received","order_id":"06042d49-c9f1-4af0-93d8-4bd37678eaa1","order_type":"limit","size":"0.10000000","price":"2447.14000000","side":"sell","client_oid":"bcf0ec09-1941-46a9-9c75-129b635e17d0","product_id":"BTC-USD","sequence":3342835578,"time":"2017-06-17T02:38:35.064000Z"}
{"type":"open","side":"sell","price":"2447.14000000","order_id":"06042d49-c9f1-4af0-93d8-4bd37678eaa1","remaining_size":"0.10000000","product_id":"BTC-USD","sequence":3342835579,"time":"2017-06-17T02:38:35.064000Z"}
{"type":"done","side":"sell","order_id":"06042d49-c9f1-4af0-93d8-4bd37678eaa1","reason":"canceled","product_id":"BTC-USD","price":"2447.14000000","remaining_size":"0.10000000","sequence":3342835580,"time":"2017-06-17T02:38:35.100000Z"}
{"type":"received","order_id":"51aea2d3-2da0-4291-a0f0-c80c47cdd291","order_type":"limit","size":"0.10000000","price":"2447.15000000","side":"sell","client_oid":"ae93ac23-ec51-42ef-a772-8c831cf52073","product_id":"BTC-USD","sequence":3342835581,"time":"2017-06-17T02:38:35.111000Z"}
{"type":"open","side":"sell","price":"2447.15000000","order_id":"51aea2d3-2da0-4291-a0f0-c80c47cdd291","remaining_size":"0.10000000","product_id":"BTC-USD","sequence":3342835582,"time":"2017-06-17T02:38:35.111000Z"}
{"type":"done","side":"sell","order_id":"51aea2d3-2da0-4291-a0f0-c80c47cdd291","reason":"canceled","product_id":"BTC-USD","price":"2447.15000000","remaining_size":"0.10000000","sequence":3342835583,"time":"2017-06-17T02:38:35.145000Z"}
{"type":"received","order_id":"169b2bc6-eff9-44c8-bc16-e261ea6e29d4","order_type":"limit","size":"0.10000000","price":"2447.14000000","side":"sell","client_oid":"024da13f-9d72-4027-8896-df13649e0c61","product_id":"BTC-USD","sequence":3342835584,"time":"2017-06-17T02:38:35.160000Z"}
{"type":"open","side":"sell","price":"2447.14000000","order_id":"169b2bc6-eff9-44c8-bc16-e261ea6e29d4","remaining_size":"0.10000000","product_id":"BTC-USD","sequence":3342835585,"time":"2017-06-17T02:38:35.160000Z"}
{"type":"received","order_id":"fe23e4d5-b261-4d5d-9482-5bffdeb79607","order_type":"limit","size":"0.01170000","price":"2449.55000000","side":"sell","client_oid":"c68f68de-fb69-413e-ba4f-75ce8fd1f2ee","product_id":"BTC-USD","sequence":3342835586,"time":"2017-06-17T02:38:35.168000Z"}
{"type":"open","side":"sell","price":"2449.55000000","order_id":"fe23e4d5-b261-4d5d-9482-5bffdeb79607","remaining_size":"0.01170000","product_id":"BTC-USD","sequence":3342835587,"time":"2017-06-17T02:38:35.168000Z"}
{"type":"done","side":"sell","order_id":"169b2bc6-eff9-44c8-bc16-e261ea6e29d4","reason":"canceled","product_id":"BTC-USD","price":"2447.14000000","remaining_size":"0.10000000","sequence":3342835588,"time":"2017-06-17T02:38:35.192000Z"}
{"type":"received","order_id":"beb6c6c2-f176-41ea-b7e8-c545c2816e02","order_type":"limit","size":"0.10000000","price":"2447.13000000","side":"sell","client_oid":"b4ff0c22-856c-48f3-bd96-f245e1bf33d2","product_id":"BTC-USD","sequence":3342835589,"time":"2017-06-17T02:38:35.206000Z"}
{"type":"open","side":"sell","price":"2447.13000000","order_id":"beb6c6c2-f176-41ea-b7e8-c545c2816e02","remaining_size":"0.10000000","product_id":"BTC-USD","sequence":3342835590,"time":"2017-06-17T02:38:35.206000Z"}
{"type":"done","side":"sell","order_id":"beb6c6c2-f176-41ea-b7e8-c545c2816e02","reason":"canceled","product_id":"BTC-USD","price":"2447.13000000","remaining_size":"0.10000000","sequence":3342835591,"time":"2017-06-17T02:38:35.236000Z"}
{"type":"received","order_id":"280169a5-b2d3-44e0-b7b3-6f15a0eb21a8","order_type":"limit","size":"0.10000000","price":"2447.12000000","side":"sell","client_oid":"ea51123b-cb14-43e2-936a-e1dae7f9dc07","product_id":"BTC-USD","sequence":3342835592,"time":"2017-06-17T02:38:35.263000Z"}
{"type":"open","side":"sell","price":"2447.12000000","order_id":"280169a5-b2d3-44e0-b7b3-6f15a0eb21a8","remaining_size":"0.10000000","product_id":"BTC-USD","sequence":3342835593,"time":"2017-06-17T02:38:35.263000Z"}
{"type":"done","side":"sell","order_id":"280169a5-b2d3-44e0-b7b3-6f15a0eb21a8","reason":"canceled","product_id":"BTC-USD","price":"2447.12000000","remaining_size":"0.10000000","sequence":3342835594,"time":"2017-06-17T02:38:35.301000Z"}
{"type":"received","order_id":"8c4571e1-cf84-4b8b-aca3-23e85eb5c662","order_type":"limit","size":"0.10000000","price":"2447.11000000","side":"sell","client_oid":"e7a1ce00-9133-464a-a1df-95644124d208","product_id":"BTC-USD","sequence":3342835595,"time":"2017-06-17T02:38:35.311000Z"}
{"type":"open","side":"sell","price":"2447.11000000","order_id":"8c4571e1-cf84-4b8b-aca3-23e85eb5c662","remaining_size":"0.10000000","product_id":"BTC-USD","sequence":3342835596,"time":"2017-06-17T02:38:35.311000Z"}
{"type":"received","order_id":"610b0796-9f2e-441e-acba-8676194497da","order_type":"limit","size":"0.08985400","price":"2449.17000000","side":"sell","client_oid":"e2c6e5e7-12e1-4005-8c7e-0f6eb1aa54b4","product_id":"BTC-USD","sequence":3342835597,"time":"2017-06-17T02:38:35.320000Z"}
{"type":"open","side":"sell","price":"2449.17000000","order_id":"610b0796-9f2e-441e-acba-8676194497da","remaining_size":"0.08985400","product_id":"BTC-USD","sequence":3342835598,"time":"2017-06-17T02:38:35.320000Z"}
{"type":"received","order_id":"61bb9c83-4f5b-4ff8-a2ed-be80f8689bab","order_type":"limit","size":"0.20000000","price":"2449.17000000","side":"sell","client_oid":"330de656-198f-47ff-b51a-dee926c75873","product_id":"BTC-USD","sequence":3342835599,"time":"2017-06-17T02:38:35.342000Z"}
{"type":"open","side":"sell","price":"2449.17000000","order_id":"61bb9c83-4f5b-4ff8-a2ed-be80f8689bab","remaining_size":"0.20000000","product_id":"BTC-USD","sequence":3342835600,"time":"2017-06-17T02:38:35.342000Z"}
{"type":"received","order_id":"13219b24-51e8-4b69-9d38-97c63e79b96e","order_type":"limit","size":"0.25000000","price":"2442.77000000","side":"buy","client_oid":"ef354515-23ce-4a8c-bb0a-4c3ee631e5c8","product_id":"BTC-USD","sequence":3342835601,"time":"2017-06-17T02:38:35.344000Z"}
{"type":"open","side":"buy","price":"2442.77000000","order_id":"13219b24-51e8-4b69-9d38-97c63e79b96e","remaining_size":"0.25000000","product_id":"BTC-USD","sequence":3342835602,"time":"2017-06-17T02:38:35.344000Z"}
{"type":"done","side":"sell","order_id":"8c4571e1-cf84-4b8b-aca3-23e85eb5c662","reason":"canceled","product_id":"BTC-USD","price":"2447.11000000","remaining_size":"0.10000000","sequence":3342835603,"time":"2017-06-17T02:38:35.352000Z"}
{"type":"done","side":"sell","order_id":"610b0796-9f2e-441e-acba-8676194497da","reason":"canceled","product_id":"BTC-USD","price":"2449.17000000","remaining_size":"0.08985400","sequence":3342835604,"time":"2017-06-17T02:38:35.357000Z"}
{"type":"received","order_id":"50bbca8d-b258-49f5-adde-fe0789aa2f04","order_type":"limit","size":"0.08985400","price":"2447.53000000","side":"sell","client_oid":"19f1dc97-6440-4ab8-b0a3-9388e0fab681","product_id":"BTC-USD","sequence":3342835605,"time":"2017-06-17T02:38:35.373000Z"}
{"type":"open","side":"sell","price":"2447.53000000","order_id":"50bbca8d-b258-49f5-adde-fe0789aa2f04","remaining_size":"0.08985400","product_id":"BTC-USD","sequence":3342835606,"time":"2017-06-17T02:38:35.373000Z"}
{"type":"done","side":"sell","order_id":"61bb9c83-4f5b-4ff8-a2ed-be80f8689bab","reason":"canceled","product_id":"BTC-USD","price":"2449.17000000","remaining_size":"0.20000000","sequence":3342835607,"time":"2017-06-17T02:38:35.376000Z"}
{"type":"received","order_id":"926c40f6-2d93-4f96-bdf4-c9da5f2ae1a3","order_type":"limit","size":"0.10000000","price":"2447.15000000","side":"sell","client_oid":"41fef688-7a96-4c38-bd5c-b8b093d0155c","product_id":"BTC-USD","sequence":3342835608,"time":"2017-06-17T02:38:35.394000Z"}
{"type":"open","side":"sell","price":"2447.15000000","order_id":"926c40f6-2d93-4f96-bdf4-c9da5f2ae1a3","remaining_size":"0.10000000","product_id":"BTC-USD","sequence":3342835609,"time":"2017-06-17T02:38:35.394000Z"}
{"type":"received","order_id":"ec49dbcd-384c-4796-9d85-af28e8544f16","order_type":"limit","size":"0.20000000","price":"2447.53000000","side":"sell","client_oid":"bfde9655-0982-41c5-8ea4-1b5888d49c9d","product_id":"BTC-USD","sequence":3342835610,"time":"2017-06-17T02:38:35.423000Z"}
{"type":"open","side":"sell","price":"2447.53000000","order_id":"ec49dbcd-384c-4796-9d85-af28e8544f16","remaining_size":"0.20000000","product_id":"BTC-USD","sequence":3342835611,"time":"2017-06-17T02:38:35.423000Z"}
{"type":"done","side":"sell","order_id":"926c40f6-2d93-4f96-bdf4-c9da5f2ae1a3","reason":"canceled","product_id":"BTC-USD","price":"2447.15000000","remaining_size":"0.10000000","sequence":3342835612,"time":"2017-06-17T02:38:35.430000Z"}
{"type":"done","side":"buy","order_id":"13219b24-51e8-4b69-9d38-97c63e79b96e","reason":"canceled","product_id":"BTC-USD","price":"2442.77000000","remaining_size":"0.25000000","sequence":3342835613,"time":"2017-06-17T02:38:35.434000Z"}
{"type":"received","order_id":"83f6972c-e271-45a8-ad25-13cab03461fa","order_type":"limit","size":"0.10000000","price":"2447.14000000","side":"sell","client_oid":"48dd726e-6939-4d3d-b657-52f11f93e9e8","product_id":"BTC-USD","sequence":3342835614,"time":"2017-06-17T02:38:35.440000Z"}
{"type":"open","side":"sell","price":"2447.14000000","order_id":"83f6972c-e271-45a8-ad25-13cab03461fa","remaining_size":"0.10000000","product_id":"BTC-USD","sequence":3342835615,"time":"2017-06-17T02:38:35.440000Z"}
{"type":"done","side":"sell","order_id":"50bbca8d-b258-49f5-adde-fe0789aa2f04","reason":"canceled","product_id":"BTC-USD","price":"2447.53000000","remaining_size":"0.08985400","sequence":3342835616,"time":"2017-06-17T02:38:35.457000Z"}
{"type":"done","side":"sell","order_id":"83f6972c-e271-45a8-ad25-13cab03461fa","reason":"canceled","product_id":"BTC-USD","price":"2447.14000000","remaining_size":"0.10000000","sequence":3342835617,"time":"2017-06-17T02:38:35.478000Z"}
{"type":"received","order_id":"95d07ef8-ce26-41eb-9ae8-e07c8ee22ae2","order_type":"limit","size":"0.10000000","price":"2447.13000000","side":"sell","client_oid":"e5127f7f-99b0-4703-ae42-6c18ee36fa87","product_id":"BTC-USD","sequence":3342835618,"time":"2017-06-17T02:38:35.485000Z"}
{"type":"open","side":"sell","price":"2447.13000000","order_id":"95d07ef8-ce26-41eb-9ae8-e07c8ee22ae2","remaining_size":"0.10000000","product_id":"BTC-USD","sequence":3342835619,"time":"2017-06-17T02:38:35.485000Z"}
{"type":"done","side":"sell","order_id":"ec49dbcd-384c-4796-9d85-af28e8544f16","reason":"canceled","product_id":"BTC-USD","price":"2447.53000000","remaining_size":"0.20000000","sequence":3342835620,"time":"2017-06-17T02:38:35.489000Z"}
{"type":"received","order_id":"35ff685e-ede4-4a3b-8959-213d2739a133","order_type":"limit","size":"0.08985400","price":"2447.52000000","side":"sell","client_oid":"c2fe1587-c438-4b00-b121-14f12ec07879","product_id":"BTC-USD","sequence":3342835621,"time":"2017-06-17T02:38:35.512000Z"}
{"type":"open","side":"sell","price":"2447.52000000","order_id":"35ff685e-ede4-4a3b-8959-213d2739a133","remaining_size":"0.08985400","product_id":"BTC-USD","sequence":3342835622,"time":"2017-06-17T02:38:35.512000Z"}
{"type":"done","side":"sell","order_id":"35ff685e-ede4-4a3b-8959-213d2739a133","reason":"canceled","product_id":"BTC-USD","price":"2447.52000000","remaining_size":"0.08985400","sequence":3342835623,"time":"2017-06-17T02:38:35.517000Z"}
{"type":"received","order_id":"3753ee26-dce4-46c4-9bfc-17389597a00f","order_type":"limit","size":"0.20000000","price":"2447.53000000","side":"sell","client_oid":"1be6f524-5c17-4a43-8cbc-e83e20c26a77","product_id":"BTC-USD","sequence":3342835624,"time":"2017-06-17T02:38:35.519000Z"}
{"type":"open","side":"sell","price":"2447.53000000","order_id":"3753ee26-dce4-46c4-9bfc-17389597a00f","remaining_size":"0.20000000","product_id":"BTC-USD","sequence":3342835625,"time":"2017-06-17T02:38:35.519000Z"}
{"type":"done","side":"sell","order_id":"95d07ef8-ce26-41eb-9ae8-e07c8ee22ae2","reason":"canceled","product_id":"BTC-USD","price":"2447.13000000","remaining_size":"0.10000000","sequence":3342835626,"time":"2017-06-17T02:38:35.521000Z"}
{"type":"received","order_id":"5c6f2d24-508b-4c53-8b57-43c273208e4f","order_type":"limit","size":"0.08985400","price":"2447.53000000","side":"sell","client_oid":"c129b6f3-8076-4ba9-8797-b9fd8e69c9e7","product_id":"BTC-USD","sequence":3342835627,"time":"2017-06-17T02:38:35.533000Z"}
{"type":"open","side":"sell","price":"2447.53000000","order_id":"5c6f2d24-508b-4c53-8b57-43c273208e4f","remaining_size":"0.08985400","product_id":"BTC-USD","sequence":3342835628,"time":"2017-06-17T02:38:35.533000Z"}
{"type":"done","side":"sell","order_id":"3753ee26-dce4-46c4-9bfc-17389597a00f","reason":"canceled","product_id":"BTC-USD","price":"2447.53000000","remaining_size":"0.20000000","sequence":3342835629,"time":"2017-06-17T02:38:35.548000Z"}
{"type":"received","order_id":"bd9aa2ff-005b-45b7-962c-414dc3c43911","order_type":"limit","size":"0.50000000","price":"2442.39000000","side":"buy","client_oid":"0fdc7e7c-487c-431e-ab85-89733ecab484","product_id":"BTC-USD","sequence":3342835630,"time":"2017-06-17T02:38:35.553000Z"}
